Workbook
Name _Toc95402285: Отель2!#REF!
Name _Toc95402285: Отель3!#REF!
Name _Toc95402285: Отель4!#REF!
Name _Toc95402285: Отель5!#REF!
Name _Toc95402285: Резиденции!#REF!
Name _Toc95402285: Хостел!#REF!
Name _Toc95402285: Шале!$C$12
Name flag: TRUE
Name vat: [1]Вводные!$D$10
Name vat: [2]Вводные!$D$9
Name vat: [3]Вводные!$D$10
Name vat: [1]Вводные!$D$10

Sheet PEAK'ING ---->>

Sheet Отель5
A1: 1
C2: Вводные технико-экономические показатели | E2: Гостиница 5* | F2: =F14 -> Mövenpick
E3: Ед. измерения | F3: Значение | J3: Предложения CW | N3: Комментарий CW
C4: 1 | D4: Предварительная общая площадь | E4: кв.м | F4: =Бюджет_Синара!B41 -> 11947.619 | N4: Предложение по увеличению количества номеров с сохранением общей площади номерного фонда
C5: =C4+1 -> 2 | D5: Класс объекта по стандартам РФ | F5: Гостиница "5 звезд" | J5: =F4/F6 -> 95.580951 | K5: кв.м общей S/номер
C6: =C5+1 -> 3 | D6: Количество номеров всего | E6: номера | F6: 125 | H6: мест/номер | I6: Мест всего | J6: кв.м/номер | K6: кв.м
D7: в т.ч. номера класса люкс | E7: номера | F7: =ROUND($F$6*G7,0) -> 13 | G7: 0.1 | H7: 4 | I7: =H7*F7 -> 52 | J7: =J8*1.5 -> 54 | K7: =F7*J7 -> 702
D8: в т.ч. номера класса твин и дабл (на 1 и 2 проживающих) | E8: номера | F8: =ROUND($F$6*G8,0) -> 106 | G8: 0.85 | H8: 2 | I8: =H8*F8 -> 212 | J8: 36 | K8: =F8*J8 -> 3816
D9: в т.ч. номера для ЛОВ | E9: номера | F9: =F6-F8-F7 -> 6 | G9: 0.05 | H9: 2 | I9: =H9*F9 -> 12 | J9: =J8 -> 36 | K9: =F9*J9 -> 216
C10: =C6+1 -> 4 | D10: Количество мест для проживающих (человек) | E10: мест | F10: =SUM(I7:I9) -> 276 | G10: =F10/F6 -> 2.208 | J10: S ном.фонда | K10: =SUM(K7:K9) -> 4734
C11: =C10+1 -> 5 | D11: Площадь номерного фонда | E11: кв.м | F11: =Бюджет_Синара!B7 -> 4750 | G11: =F11/F6 -> 38 | H11: кв.м/номер | K11: =K10/F6 -> 37.872 | L11: кв.м/номер
C12: =C11+1 -> 6 | D12: Наличие крытой парковки (количество мест) | F12: =Объекты!E66 -> 37.037037
C13: =C12+1 -> 7 | D13: Наличие СПА с бассейном: 2 бассейна в составе СПА, фитнес-зал | E13: кв.м в составе объекта | F13: =Бюджет_Синара!B19 -> 1943
C14: =C13+1 -> 8 | D14: Бренд | F14: Mövenpick
C15: =C14+1 -> 9 | D15: Ресторан - количество посадочных мест | E15: посадочных мест | F15: 100
C16: =C15+1 -> 10 | D16: Ресторан - площадь зала | E16: кв.м | F16: =Бюджет_Синара!B13 -> 327 | G16: =F16/F15 -> 3.27 | H16: кв.м/п.место
C17: =C16+1 -> 11 | D17: Залы и переговорные | E17: кв.м | F17: =Бюджет_Синара!B21 -> 175
C18: =C17+1 -> 12 | D18: Фойе | E18: кв.м | F18: =Бюджет_Синара!B23 -> 135
C19: =C18+1 -> 13 | D19: Размер номера люкс | F19: В соответствии с требованиями бренда
C20: =C19+1 -> 14 | D20: Размер номера дабл или твин
C21: =C20+1 -> 15 | D21: Этажность | E21: этажей | F21: Не более 5
C22: =C21+1 -> 16 | D22: Особые требования к компоновке объекта | F22: а) Здание должно быть объединено общими технологическими потоками с отелем 4*
F23: б) Между зданиями отель 5* и зданием отель 4* должен быть запланирован канал для инженерных коммуникаций под самым нижним этажом стилобата. Канал требуется разместить в между зданиями под пожарным проездом
F24: в) Executive Lounge и открытый бассейн должны быть расположены с западной стороны отеля
C25: =C22+1 -> 17 | D25: Наличие технологического этажа высотой до 1800 мм между жилыми этажами и этажами с размещением общественных зон | F25: Да, требуется
C26: =C25+1 -> 18 | D26: Дополнительные технологии в составе объекта | F26: Экзекьютив лаудж ( Executive Lounge ) 120 кв.м сблокированный, с панорамным бассейном. Бассейн с совмещенной внутренней и наружной чашей. Оба функционала разместить в составе одного из верхних этажей. Лыжехранилище - 20 кв.м

Sheet Отель4
A1: 1
C2: Вводные технико-экономические показатели | E2: Гостиница 4* | F2: =F13 -> Mercure
E3: Ед. измерения | F3: Значение | H3: Комментарий | K3: Предложения CW | O3: Комментарий CW
C4: 1 | D4: Предварительная общая площадь | E4: кв.м | F4: =Бюджет_Синара!B84 -> 12475 | O4: Предложение по увеличению количества номеров с сохранением общей площади номерного фонда
C5: =C4+1 -> 2 | D5: Класс объекта по стандартам РФ | F5: Гостиница "4 звезды" | K5: =F4/F6 -> 77.96875 | L5: кв.м общей S/номер
C6: =C5+1 -> 3 | D6: Количество номеров всего | E6: номера | F6: 160 | I6: мест/номер | J6: Мест всего | K6: кв.м/номер | L6: кв.м
D7: в т.ч. номера класса люкс | E7: номера | F7: =ROUND($F$6*G7,0) -> 13 | G7: 0.08 | I7: 4 | J7: =I7*F7 -> 52 | K7: =K8*1.25 -> 30 | L7: =F7*K7 -> 390
D8: в т.ч. номера класса твин и дабл (на 1 и 2 проживающих) | E8: номера | F8: =ROUND($F$6*G8,0) -> 147 | G8: 0.92 | I8: 2 | J8: =I8*F8 -> 294 | K8: 24 | L8: =F8*K8 -> 3528
C9: =C6+1 -> 4 | D9: Количество мест для проживающих (человек) | E9: мест | F9: =SUM(J7:J8) -> 346 | G9: =F9/F6 -> 2.1625
C10: =C9+1 -> 5 | D10: Площадь номерного фонда | E10: кв.м | F10: =Бюджет_Синара!B50 -> 3925 | G10: =F10/F6 -> 24.53125 | H10: кв.м/номер | K10: S ном.фонда | L10: =SUM(L7:L9) -> 3918
C11: =C10+1 -> 6 | D11: Наличие крытой парковки (количество мест) | F11: общая с гостиницей 5* | L11: =L10/F6 -> 24.4875 | M11: кв.м/номер
C12: =C11+1 -> 7 | D12: Наличие конференц-залов | E12: кв.м в составе объекта | F12: 300 | G12: Многофункциональный зал с возможностью временной перепланировки раздвижными стенами для организации трех залов с площадями 150, 100 и 50 кв.м
C13: =C12+1 -> 8 | D13: Бренд | F13: Mercure
C14: =C13+1 -> 9 | D14: Наличие СПА | E14: кв.м | F14: =Бюджет_Синара!B62 -> 3561
C15: =C14+1 -> 10 | D15: Ресторан - количество посадочных мест | E15: посадочных мест | F15: 150
C16: =C15+1 -> 11 | D16: Ресторан - площадь зала | E16: кв.м | F16: =Бюджет_Синара!B56 -> 313 | G16: =F16/F15 -> 2.0866667 | H16: кв.м/п.место
C17: =C16+1 -> 12 | D17: Залы и переговорные | E17: кв.м | F17: =Бюджет_Синара!B64 -> 520
C18: =C17+1 -> 13 | D18: Фойе | E18: кв.м | F18: =Бюджет_Синара!B66 -> 135
C19: =C18+1 -> 14 | D19: Размер номера люкс | F19: В соответствии с требованиями бренда
C20: =C19+1 -> 15 | D20: Размер номера дабл или твин
C21: =C20+1 -> 16 | D21: Этажность | E21: этажей | F21: Не более 5
C22: =C21+1 -> 17 | D22: Торговая зона отеля 4* | F22: =Бюджет_Синара!B83 -> 1000
C23: =C22+1 -> 18 | D23: Особые требования к компоновке объекта | F23: а) Здание должно быть объединено общими технологическими потоками с отелем 4*
F24: б) Между зданиями отель 5* и зданием отель 4* должен быть запланирован канал для инженерных коммуникаций под самым нижним этажом стилобата. Канал требуется разместить в между зданиями под пожарным проездом
F25: в) Торговая зона должна быть расположена с южной стороны отеля
C26: =C23+1 -> 19 | D26: Наличие технологического этажа высотой до 1800 мм между жилыми этажами и этажами с размещением общественных зон | F26: Да, требуется
C27: =C26+1 -> 20 | D27: Дополнительные технологии в составе объекта | F27: Торговая зона (1000 кв.м). Детский клуб (200 кв.м). Лыжехранилище 25 кв.м

Sheet Отель3
A1: 1
C2: Вводные технико-экономические показатели | E2: Гостиница 3* | F2: =F11 -> Ibis Styles
E3: Ед. измерения | F3: Значение | G3: Комментарий | K3: Предложения CW | O3: Комментарий CW
C4: 1 | D4: Предварительная общая площадь | E4: кв.м | F4: =Бюджет_Синара!B124 -> 6929 | O4: Предложение по увеличению количества номеров с сохранением общей площади номерного фонда
C5: 2 | D5: Класс объекта по стандартам РФ | F5: Гостиница "3 звезды" | K5: =F4/F6 -> 43.30625 | L5: кв.м общей S/номер
C6: 3 | D6: Количество номеров всего | E6: номера | F6: 160 | I6: мест/номер | J6: Мест всего | K6: кв.м/номер | L6: кв.м
D7: в т.ч. семейные номера на 4 человек (сьют) | E7: номера | F7: 30 | G7: 0.15 | I7: 4 | J7: =I7*F7 -> 120 | K7: =K8*1.35 -> 29.7 | L7: =F7*K7 -> 891
D8: в т.ч. номера класса твин и дабл (на 1 и 2 проживающих) | E8: номера | F8: 130 | G8: 0.85 | I8: 2 | J8: =I8*F8 -> 260 | K8: 22 | L8: =F8*K8 -> 2860
C9: =C6+1 -> 4 | D9: Количество мест для проживающих (человек) | E9: мест | F9: =SUM(J7:J8) -> 380 | G9: =F9/F6 -> 2.375
C10: =C9+1 -> 5 | D10: Площадь номерного фонда | E10: кв.м | F10: =Бюджет_Синара!B93 -> 3780 | G10: =F10/F6 -> 23.625 | H10: кв.м/номер | K10: S ном.фонда | L10: =SUM(L7:L9) -> 3751
C11: =C10+1 -> 6 | D11: Бренд | F11: Ibis Styles | L11: =L10/F6 -> 23.44375 | M11: кв.м/номер
C12: =C11+1 -> 7 | D12: Наличие СПА | E12: кв.м | F12: =Бюджет_Синара!B233 -> 1900 | G12: Отдельно стоящий корпус SPA-комплекса - учитывается в опер.деятельности гостиницы 3*
C13: =C12+1 -> 8 | D13: Ресторан - количество посадочных мест | E13: посадочных мест | F13: 160
C14: =C13+1 -> 9 | D14: Ресторан - площадь зала | E14: кв.м | F14: =Бюджет_Синара!B99 -> 300 | G14: =F14/F13 -> 1.875 | H14: кв.м/п.место
C15: =C14+1 -> 10 | D15: Залы и переговорные | E15: кв.м | F15: =Бюджет_Синара!B105 -> 100
C16: =C15+1 -> 11 | D16: Фойе | E16: кв.м | F16: =Бюджет_Синара!B107 -> 35
C17: =C16+1 -> 12 | D17: Размер номера на 4 проживающих | F17: В соответствии с требованиями бренда
C18: =C17+1 -> 13 | D18: Размер номера дабл или твин
C19: =C18+1 -> 14 | D19: Этажность | E19: этажей | F19: Не более 5
C20: =C19+1 -> 15 | D20: Особые требования к компоновке объекта | F20: Нет
C21: =C20+1 -> 16 | D21: Наличие технологического этажа высотой до 1800 мм между жилыми этажами и этажами с размещением общественных зон | F21: Возможно
C22: =C21+1 -> 17 | D22: Дополнительные технологии в составе объекта | F22: Лыжехранилище - 35 кв.м

Sheet Отель2
A1: 1
C2: Вводные технико-экономические показатели | E2: Гостиница 2* | F2: =F12 -> Ibis Budget
E3: Ед. измерения | F3: Значение | G3: Комментарий | J3: Предложения CW | N3: Комментарий CW
C4: 1 | D4: Предварительная общая площадь | E4: кв.м | F4: =Бюджет_Синара!B164 -> 3346.5 | N4: Предложение по увеличению количества номеров с сохранением общей площади номерного фонда
C5: =C4+1 -> 2 | D5: Класс объекта по стандартам РФ | F5: Гостиница "2 звезды" | J5: =F4/F6 -> 40.810976 | K5: кв.м общей S/номер
C6: =C5+1 -> 3 | D6: Количество номеров всего | E6: номера | F6: 82 | H6: мест/номер | I6: Мест всего | J6: кв.м/номер | K6: кв.м
D7: в т.ч. семейные номера на 4 человек (сьют) | E7: номера | F7: =ROUND($F$6*G7,0) -> 29 | G7: 0.35 | H7: 4 | I7: =H7*F7 -> 116 | J7: =J8*1.5 -> 27 | K7: =F7*J7 -> 783
D8: в т.ч. номера класса твин и дабл (на 1 и 2 проживающих) | E8: номера | F8: =ROUND($F$6*G8,0) -> 49 | G8: 0.6 | H8: 2 | I8: =H8*F8 -> 98 | J8: 18 | K8: =F8*J8 -> 882
D9: в т.ч. номера для ЛОВ | E9: номера | F9: =F6-F8-F7 -> 4 | G9: 0.05 | H9: 2 | I9: =H9*F9 -> 8 | J9: =J8 -> 18 | K9: =F9*J9 -> 72
C10: =C6+1 -> 4 | D10: Количество мест для проживающих (человек) | E10: мест | F10: =SUM(I7:I9) -> 222 | G10: =F10/F6 -> 2.7073171 | J10: S ном.фонда | K10: =SUM(K7:K9) -> 1737
C11: =C10+1 -> 5 | D11: Площадь номерного фонда | E11: кв.м | F11: =Бюджет_Синара!B133 -> 1750 | G11: =F11/F6 -> 21.341463 | H11: кв.м/номер | K11: =K10/F6 -> 21.182927 | L11: кв.м/номер
C12: =C11+1 -> 6 | D12: Бренд | F12: Ibis Budget
C13: =C12+1 -> 7 | D13: Ресторан - количество посадочных мест | E13: посадочных мест | F13: =ROUND(F14/G14,0) -> 20 | G13: сделана корректировка по кол-ву посадочных мест, исходя из площади зала ресторана
C14: =C13+1 -> 8 | D14: Ресторан - площадь зала | E14: кв.м | F14: =Бюджет_Синара!B139 -> 38 | G14: =Отель3!G14 -> 1.875 | H14: кв.м/п.место
C15: =C14+1 -> 9 | D15: Размер номера на 4 проживающих | F15: В соответствии с требованиями бренда
C16: =C15+1 -> 10 | D16: Размер номера дабл или твин
C17: =C16+1 -> 11 | D17: Этажность | E17: этажей | F17: Не более 5
C18: =C17+1 -> 12 | D18: Особые требования к компоновке объекта | F18: Торговая зона с южной стороны
C19: =C18+1 -> 13 | D19: Наличие технологического этажа высотой до 1800 мм между жилыми этажами и этажами с размещением общественных зон | F19: Возможно
C20: =C19+1 -> 14 | D20: Дополнительные технологии в составе объекта | F20: Лыжехранилище - 20 кв.м

Sheet Резиденции
A1: 1
C2: Вводные технико-экономические показатели | E2: Туристские резиденции | F2: =F17 -> Не брендируется
E3: Ед. измерения | F3: Значение | J3: Предложения CW | N3: Комментарий CW
C4: 1 | D4: Предварительная общая площадь | E4: кв.м | F4: =Бюджет_Синара!B206 -> 21950 | G4: =F4/F6 -> 57.012987 | N4: Корректировка по количеству номеров с сохранением общей площади номерного фонда
C5: =C4+1 -> 2 | D5: Класс объекта по стандартам РФ | F5: Гостиница "3 звезды"
C6: =C5+1 -> 3 | D6: Количество номеров всего | E6: номера | F6: =SUM(F7:F9) -> 385 | H6: мест/номер | I6: Мест всего | J6: кв.м/номер | K6: кв.м
D7: в т.ч. апартаменты студии | E7: номера | F7: 220 | G7: =F7/$F$6 -> 0.57142857 | H7: 2 | I7: =H7*F7 -> 440 | J7: 26 | K7: =J7*F7 -> 5720
D8: в т.ч. апартаменты на 1 спальню | E8: номера | F8: 120 | G8: =F8/$F$6 -> 0.31168831 | H8: 3 | I8: =H8*F8 -> 360 | J8: 40 | K8: =J8*F8 -> 4800
D9: в т.ч. апартаменты на 2 спальни | E9: номера | F9: 45 | G9: =F9/$F$6 -> 0.11688312 | H9: 4 | I9: =H9*F9 -> 180 | J9: =J8*1.25 -> 50 | K9: =J9*F9 -> 2250
D10: в т.ч. номера для ЛОВ | E10: номера | F10: 29
C11: =C6+1 -> 4 | D11: Количество мест для проживающих (человек) | E11: мест | F11: =SUM(I7:I9) -> 980 | G11: =F11/F6 -> 2.5454545
C12: =C11+1 -> 5 | D12: Площадь номерного фонда | E12: кв.м | F12: =Бюджет_Синара!B174 -> 14000 | G12: =F12/F6 -> 36.363636 | H12: кв.м/номер | K12: =SUM(K7:K11) -> 12770
C13: =C12+1 -> 6 | D13: Площадь резиденций | J13: S ном.фонда | K13: =K12*1.1 -> 14047
D14: апартаменты студии | E14: кв.м/единица | F14: =J7 -> 26 | K14: =K13/F6 -> 36.485714 | L14: кв.м/номер
D15: апартаменты на 1 спальню | F15: =J8 -> 40
D16: апартаменты на 2 спальни | F16: =J9 -> 50
C17: =C13+1 -> 7 | D17: Бренд | F17: Не брендируется
C18: =C17+1 -> 8 | D18: Ресторан - количество посадочных мест | E18: посадочных мест | F18: 200
C19: =C18+1 -> 9 | D19: Ресторан - площадь зала | E19: кв.м | F19: =Бюджет_Синара!B180 -> 400 | G19: =F19/F18 -> 2 | H19: кв.м/п.место
C20: =C19+1 -> 10 | D20: Торговая зона тур.резиденций | E20: кв.м | F20: 3400
C21: =C20+1 -> 11 | D21: Лыжная школа | E21: кв.м | F21: 200
C22: =C21+1 -> 12 | D22: Этажность | E22: этажей | F22: Не более 5 | G22: 5
C23: =C22+1 -> 13 | D23: Особые требования к компоновке объекта | F23: Выход из торговой зоны на юг. Выход из лыжной школы на север к восточному подъемнику
C24: =C23+1 -> 14 | D24: Наличие технологического этажа высотой до 1800 мм между жилыми этажами и этажами с размещением общественных зон | F24: Да
C25: =C24+1 -> 15 | D25: Дополнительные технологии в составе объекта | F25: Торговая зона 3400 кв.м, лыжная школа 200 кв.м
D28: Предварительная оценка пятнка застройки | E28: кв.м | F28: =F4/G22 -> 4390
D29: Пятно застройки, приходящееся на Резиденции | E29: кв.м | F29: =F12/F4*F28 -> 2800

Sheet Хостел
A1: 1
C2: Вводные технико-экономические показатели | E2: Хостел в составе МФЦ | F2: =F12 -> Jo&JOE
E3: Ед. измерения | F3: Значение | I3: Предложения CW | N3: Комментарий CW
C4: 1 | D4: Предварительная общая площадь | E4: кв.м | F4: =Бюджет_Синара!B221 -> 10800 | N4: Предложение по увеличению количества номеров с сохранением общей площади номерного фонда
C5: =C4+1 -> 2 | D5: Класс объекта по стандартам РФ | F5: Многофункциональное здание в соответствии с СП 160.1325800.2014 | G5: площадь на место
C6: =C5+1 -> 3 | D6: В том числе хостел | E6: кв.м | F6: 2500 | G6: =F6/J12 -> 6.0679612
C7: =C6+1 -> 4 | D7: Количество номеров, всего | E7: номера | F7: =SUM(F8:F11) -> 101 | I7: мест/номер | J7: Мест всего | K7: кв.м
D8: в т.ч. 6-местные номера | E8: номера | F8: 35 | G8: =F8/$F$7 -> 0.34653465 | I8: 6 | J8: =I8*F8 -> 210 | K8: =J8*4 -> 840
D9: в т.ч. 4-местные номера | E9: номера | F9: 35 | G9: =F9/$F$7 -> 0.34653465 | I9: 4 | J9: =I9*F9 -> 140 | K9: =J9*4 -> 560
D10: в т.ч. 2-местные номера | E10: номера | F10: 25 | G10: =F10/$F$7 -> 0.24752475 | I10: 2 | J10: =I10*F10 -> 50 | K10: =J10*4 -> 200
D11: в т.ч. номера для ЛОВ | E11: номера | F11: 6 | G11: =F11/$F$7 -> 0.059405941 | I11: 2 | J11: =I11*F11 -> 12 | K11: =J11*4 -> 48
C12: =C7+1 -> 5 | D12: Бренд | F12: Jo&JOE | J12: =SUM(J8:J11) -> 412 | K12: =SUM(K8:K11) -> 1648
C13: =C12+1 -> 6 | D13: Ресторан - количество посадочных мест | E13: посадочных мест | F13: 70 | K13: =K12*1.5 -> 2472
C14: =C13+1 -> 7 | D14: Ресторан - площадь зала | E14: кв.м | F14: =Бюджет_Синара!B215 -> 150 | G14: =F14/F13 -> 2.1428571
C15: =C14+1 -> 8 | D15: Общежитие служебное | E15: кв.м | F15: =Бюджет_Синара!B217 -> 1800
C16: =C15+1 -> 9 | D16: Общежитие служебное | E16: кол-во мест | F16: 300 | J16: =F16*4*1.3 -> 1560
C17: =C16+1 -> 10 | D17: Этажи для размещения общежития | E17: порядковый номер этажей | F17: 2-3
C18: =C17+1 -> 11 | D18: Торговая зона МФЦ | E18: кв.м | F18: =Бюджет_Синара!B218 -> 4000
C19: =C18+1 -> 12 | D19: Административная зона | E19: кв.м | F19: =Бюджет_Синара!B219 -> 900
C20: =C19+1 -> 13 | D20: Состав административной зоны | F20: Холл, ресепшн, офисы
C21: =C20+1 -> 14 | D21: Парковка | E21: кв.м | F21: =Бюджет_Синара!B220 -> 1200
C22: =C21+1 -> 15 | D22: Этажность | E22: этажей | F22: Не более 2
C23: =C22+1 -> 16 | D23: Наличие крытой парковки (количество мест) | E23: кол-во мест | F23: 400 | I23: =F21/F23 -> 3 | J23: кв.м/м-место
C24: =C23+1 -> 17 | D24: Особые требования к компоновке объекта | F24: Крытая или подземная парковка в 2 уровня

Sheet Шале
A1: 1
C2: Вводные технико-экономические показатели | E2: Шале | F2: =F8 -> Не брендируется (номерной фонд отеля 5*)
E3: Ед. измерения | F3: Значение
C4: 1 | D4: Предварительная общая площадь | E4: кв.м | F4: =G4*F6*1.2 -> 2340 | G4: =I24 -> 150
C5: =C4+1 -> 2 | D5: Класс объекта по стандартам РФ | F5: Апартаменты в соответствии с СП 118.13330.2012
C6: =C5+1 -> 3 | D6: Количество зданий всего | E6: здания / номера | F6: 13
C7: =C6+1 -> 4 | D7: Количество мест для проживающих (человек) | E7: мест | F7: 78 | G7: =F7/F6 -> 6
C8: =C7+1 -> 5 | D8: Бренд | F8: Не брендируется (номерной фонд отеля 5*)
C9: =C8+1 -> 6 | D9: Этажность | E9: этажей | F9: Не более 2
C10: =C9+1 -> 7 | D10: Детализация требований к технологии | F10: =_Toc95402285 -> Детализация объекта
C12: Детализация объекта
D13: Наименование помещения | E13: Кол-во | F13: Удельная площадь, кв.м/ед. | I13: ИТОГО площадь, кв.м
C14: 1 | D14: Гостиная совмещенная с кухней | E14: 1 | F14: 40 | G14: Корректировка CW | I14: =F14*E14 -> 40
C15: =C14+1 -> 2 | D15: Тамбур | E15: 1 | F15: 6 | I15: =F15*E15 -> 6
C16: =C15+1 -> 3 | D16: Су на первом этаже | E16: 1 | F16: 5 | G16: Корректировка CW | I16: =F16*E16 -> 5
C17: =C16+1 -> 4 | D17: Спальня на первом этаже | E17: 1 | F17: 16 | G17: Корректировка CW | I17: =F17*E17 -> 16
C18: =C17+1 -> 5 | D18: Спальня на втором этаже (2 шт) | E18: 2 | F18: 16 | G18: Корректировка CW | I18: =F18*E18 -> 32
C19: =C18+1 -> 6 | D19: Спальня на втором этаже (1 шт) | E19: 1 | F19: 15 | I19: =F19*E19 -> 15
C20: =C19+1 -> 7 | D20: Санузел на втором этаже (2 шт) | E20: 2 | F20: 6 | G20: Корректировка CW | I20: =F20*E20 -> 12
C21: =C20+1 -> 8 | D21: Лыжехранилище | E21: 1 | F21: 6 | G21: Корректировка CW | I21: =F21*E21 -> 6
C22: =C21+1 -> 9 | D22: Котельная (техническое помещение) | E22: 1 | F22: 8 | I22: =F22*E22 -> 8
C23: =C22+1 -> 10 | D23: Сауна | E23: 1 | F23: 10 | G23: Корректировка CW | I23: =F23*E23 -> 10
D24: ИТОГО | I24: =SUM(I14:I23) -> 150 | J24: Общая площадь объекта без изменений

Sheet Бюджет_Синара
A1: Источник: | B1: Расчет площадей 24.02.2022 с капексами
B2: Гостиница 5*
A4: Помещения департамента | B4: ПЛОЩАДЬ. КВ.М | C4: Стоимость 1 м2 отделка | D4: Итоговая стоимость отделки B*C | E4: Стоимость 1 м2 мебели и оборудования | F4: Итоговая стоимость мебели и оборудования B*E | G4: Стоимость 1 м2 стройка | H4: Итоговая стоимость стройки B*G | I4: Стоимость 1 м2 инж системы | J4: Итоговая стоимость инж системы B*I | K4: Итого D+F+G+J | L4: Capex за м.кв.
A5: A | B5: B | C5: C | D5: D | E5: E | F5: F | G5: G | H5: H | I5: I | J5: J | K5: K
A6: Служба размещения
A7: Номерной фонд (min/max) | B7: 4750 | C7: 37000 | D7: =B7*C7 -> 175750000 | E7: 65000 | F7: =B7*E7 -> 308750000 | G7: 52500 | H7: =B7*G7 -> 249375000 | I7: 25000 | J7: =B7*I7 -> 118750000 | K7: =D7+H7+J7+F7 -> 852625000 | L7: =K7/B7 -> 179500 | M7: =K7 -> 852625000
C8: 50000 | D8: =B7*C8 -> 237500000 | E8: 70000 | F8: =B7*E8 -> 332500000 | K8: =D8+H7+J7+F8 -> 938125000 | L8: 197500 | M8: средняя цена
A9: Циркуляция (лестницы. коридоры. холлы. лифты) | B9: 990 | C9: 35000 | D9: =B9*C9 -> 34650000 | E9: 0 | F9: =B9*E9 -> 0 | H9: =B9*G7 -> 51975000 | J9: =B9*I7 -> 24750000 | K9: =D9+H9+J9+F9 -> 111375000 | L9: =K9/B9 -> 112500 | M9: =K9 -> 111375000
A10: Служебные помещения на этаже | B10: 56 | C10: 11000 | D10: =B10*C10 -> 616000 | E10: 2000 | F10: =B10*E10 -> 112000 | H10: =B10*G7 -> 2940000 | J10: =B10*I7 -> 1400000 | K10: =D10+H10+J10+F10 -> 5068000 | L10: =K10/B10 -> 90500 | M10: =K10 -> 5068000
A11: B.O.H. служба размещения | B11: 49 | C11: 11000 | D11: =B11*C11 -> 539000 | E11: 2000 | F11: =B11*E11 -> 98000 | H11: =B11*G7 -> 2572500 | J11: =B11*I7 -> 1225000 | K11: =D11+H11+J11+F11 -> 4434500 | L11: =K11/B11 -> 90500 | M11: =K11 -> 4434500
A12: Рестораны и бары
A13: Рестораны и бары | B13: 327 | C13: 40000 | D13: =B13*C13 -> 13080000 | E13: 45000 | F13: =B13*E13 -> 14715000 | G13: 52500 | H13: =B13*G13 -> 17167500 | I13: 30000 | J13: =B13*I13 -> 9810000 | K13: =D13+H13+J13+F13 -> 54772500 | L13: =K13/B13 -> 167500 | M13: =K13 -> 54772500
A15: Кухня, рестораны и бары ( в т.ч. service areas), без циркуляции | B15: 330 | C15: 25000 | D15: =B15*C15 -> 8250000 | E15: 12000 | F15: =B15*E15 -> 3960000 | H15: =B15*G13 -> 17325000 | J15: =B15*I13 -> 9900000 | K15: =D15+H15+J15+F15 -> 39435000 | L15: =K15/B15 -> 119500 | M15: =K15 -> 39435000
A16: Циркуляция (лестницы. вход. лифтовые холлы. лифты) | B16: 111.16888 | C16: 15000 | D16: =B16*C16 -> 1667533.2 | E16: 2000 | F16: =B16*E16 -> 222337.76 | H16: =B16*G13 -> 5836366.1 | J16: =B16*I13 -> 3335066.3 | K16: =D16+H16+J16+F16 -> 11061303 | L16: =K16/B16 -> 99500 | M16: =K16 -> 11061303
A17: Прочие помещения | B17: 105.15 | C17: 11000 | D17: =B17*C17 -> 1156650 | E17: 2000 | F17: =B17*E17 -> 210300 | H17: =B17*G13 -> 5520375 | J17: =B17*I13 -> 3154500 | K17: =D17+H17+J17+F17 -> 10041825 | L17: =K17/B17 -> 95500 | M17: =K17 -> 10041825
A18: Оздоровительный центр/ СПА / фитнес
A19: СПА | B19: 1943 | C19: 55000 | D19: =B19*C19 -> 106865000 | E19: 30000 | F19: =B19*E19 -> 58290000 | G19: 52500 | H19: =B19*G19 -> 102007500 | I19: 75000 | J19: =B19*I19 -> 145725000 | K19: =D19+H19+J19+F19 -> 412887500 | L19: =K19/B19 -> 212500 | M19: =K19 -> 412887500
A20: Конференц-центр
A21: Залы и переговорные (min/max) | B21: 175 | C21: 37000 | D21: =B21*C21 -> 6475000 | E21: 15000 | F21: =B21*E21 -> 2625000 | G21: 52500 | H21: =B21*G21 -> 9187500 | I21: 25000 | J21: =B21*I21 -> 4375000 | K21: =D21+H21+J21+F21 -> 22662500 | L21: =K21/B21 -> 129500 | M21: =K21 -> 22662500
C22: 80000 | D22: =B21*C22 -> 14000000 | E22: 30000 | F22: =B21*E22 -> 5250000 | K22: =D22+H21+J21+F22 -> 32812500 | L22: =K22/B21 -> 187500 | M22: средняя цена
A23: Фойе (min/max) | B23: 135 | C23: 65000 | D23: =B23*C23 -> 8775000 | E23: 5000 | F23: =B23*E23 -> 675000 | H23: =B23*G21 -> 7087500 | J23: =B23*I21 -> 3375000 | K23: =D23+H23+J23+F23 -> 19912500 | L23: =K23/B23 -> 147500 | M23: =K23 -> 19912500
C24: 70000 | D24: =B23*C24 -> 9450000 | E24: 10000 | F24: =B23*E24 -> 1350000 | K24: =D24+H23+J23+F24 -> 21262500 | L24: =K24/B23 -> 157500 | M24: средняя цена
A25: Другие помещения | B25: 138 | C25: 11000 | D25: =B25*C25 -> 1518000 | E25: 1000 | F25: =B25*E25 -> 138000 | H25: =B25*G21 -> 7245000 | J25: =B25*I21 -> 3450000 | K25: =D25+H25+J25+F25 -> 12351000 | L25: =K25/B25 -> 89500 | M25: =K25 -> 12351000
A26: Лобби и общественные зоны
A27: Лобби и общественные зоны(min/max) | B27: 385 | C27: 42000 | D27: =B27*C27 -> 16170000 | E27: 65000 | F27: =B27*E27 -> 25025000 | G27: 52500 | H27: =B27*G27 -> 20212500 | I27: 25000 | J27: =B27*I27 -> 9625000 | K27: =D27+H27+J27+F27 -> 71032500 | L27: =K27/B27 -> 184500 | M27: =K27 -> 71032500
C28: 80000 | D28: =B27*C28 -> 30800000 | E28: 70000 | F28: =B27*E28 -> 26950000 | K28: =D28+H27+J27+F28 -> 87587500 | L28: =K28/B27 -> 227500 | M28: средняя цена
A29: Циркуляция (лестницы, вход, лифтовые холлы, лифты) | B29: 42 | C29: 35000 | D29: =B29*C29 -> 1470000 | E29: 2000 | F29: =B29*E29 -> 84000 | H29: =B29*G27 -> 2205000 | J29: =B29*I27 -> 1050000 | K29: =D29+H29+J29+F29 -> 4809000 | L29: =K29/B29 -> 114500 | M29: =K29 -> 4809000
A30: Административные помещения
A31: Административные помещения | B31: 7 | C31: 11000 | D31: =B31*C31 -> 77000 | E31: 2000 | F31: =B31*E31 -> 14000 | G31: 52500 | H31: =B31*G31 -> 367500 | I31: 25000 | J31: =B31*I31 -> 175000 | K31: =D31+H31+J31+F31 -> 633500 | L31: =K31/B31 -> 90500 | M31: =K31 -> 633500
A32: Циркуляция (лестницы, вход, лифтовые холлы, лифты) | B32: 20 | C32: 15000 | D32: =B32*C32 -> 300000 | E32: 1000 | F32: =B32*E32 -> 20000 | H32: =B32*G31 -> 1050000 | J32: =B32*I31 -> 500000 | K32: =D32+H32+J32+F32 -> 1870000 | L32: =K32/B32 -> 93500 | M32: =K32 -> 1870000
A33: Помещения персонала
A34: Помещения персонала | B34: 183 | C34: 11000 | D34: =B34*C34 -> 2013000 | E34: 1000 | F34: =B34*E34 -> 183000 | G34: 52500 | H34: =B34*G34 -> 9607500 | I34: 25000 | J34: =B34*I34 -> 4575000 | K34: =D34+H34+J34+F34 -> 16378500 | L34: =K34/B34 -> 89500 | M34: =K34 -> 16378500
A35: Циркуляция (лестницы, коридоры, холлы, лифты) | B35: 56.82 | C35: 15000 | D35: =B35*C35 -> 852300 | E35: 0 | F35: =B35*E35 -> 0 | H35: =B35*G34 -> 2983050 | J35: =B35*I34 -> 1420500 | K35: =D35+H35+J35+F35 -> 5255850 | L35: =K35/B35 -> 92500 | M35: =K35 -> 5255850
A36: Служба эксплуатации и ремонта
A37: Служба эксплуатации и ремонта | B37: 168 | C37: 11000 | D37: =B37*C37 -> 1848000 | E37: 1000 | F37: =B37*E37 -> 168000 | G37: 52500 | H37: =B37*G37 -> 8820000 | I37: 25000 | J37: =B37*I37 -> 4200000 | K37: =D37+H37+J37+F37 -> 15036000 | L37: =K37/B37 -> 89500 | M37: =K37 -> 15036000
A38: Циркуляция (лестницы, вход, лифтовые холлы, лифты) | B38: 33.3 | C38: 15000 | D38: =B38*C38 -> 499500 | E38: 0 | F38: =B38*E38 -> 0 | H38: =B38*G37 -> 1748250 | J38: =B38*I37 -> 832500 | K38: =D38+H38+J38+F38 -> 3080250 | L38: =K38/B38 -> 92500 | M38: =K38 -> 3080250
A39: Технические помещения | B39: 800 | C39: 8000 | D39: =B39*C39 -> 6400000 | E39: 0 | F39: =B39*E39 -> 0 | G39: 52500 | H39: =B39*G39 -> 42000000 | I39: 0 | J39: =B39*I39 -> 0 | K39: =D39+F39+H39+J39 -> 48400000 | L39: =K39/B39 -> 60500 | M39: 49948000
A40: Парковка | B40: 1200 | C40: 3000 | D40: =B40*C40 -> 3600000 | E40: 0 | F40: =B40*E40 -> 0 | G40: 33000 | H40: =G40*B40 -> 39600000 | I40: 15000 | J40: =I40*B40 -> 18000000 | K40: =J40+H40+F40+D40 -> 61200000 | L40: =K40/B40 -> 51000 | M40: =K40 -> 61200000
A41: проверочная сумма площадей | B41: =B7+B9+B10+B11+B13+B15+B16+B17+B19+B21+B23+B25+B27+B29+B31+B32+B34+B37+B38+B39+B40 -> 11947.619
A42: Общая площадь по заданию | B42: 11400* | F42: =F7+F9+F10+F11+F13+F15+F16+F17+F19+F21+F23+F25+F27+F29+F31+F34+F37 -> 4.1526964e+08 | N42: смр
...

Sheet CW --->>

Sheet Вводные
A1: 1
C2: ВВОДНЫЕ ДАННЫЕ
C3: Показатель | D3: Значение
C4: Дата анализа | D4: 44593
C5: Год анализа | D5: =YEAR(D4) -> 2022
C7: Начало строительства | D7: =D4 -> 44593
C9: Даты ввода в эксплуатацию - 1 очередь | D9: =MIN(D10:D16) -> 45839
C10: =Объекты!C5&" - "&Объекты!D5 -> Гостиница 5* - Mövenpick | D10: 46204
C11: =Объекты!C6&" - "&Объекты!D6 -> Гостиница 4* - Mercure | D11: 46204
C12: =Объекты!C7&" - "&Объекты!D7 -> Гостиница 3* - Возможный бренд: Ibis Styles | D12: 45839
C13: =Объекты!C8&" - "&Объекты!D8 -> Гостиница 2* - Ibis Budget
C14: =Объекты!C9&" - "&Объекты!D9 -> Хостел в составе МФЦ - Jo&JOE | D14: 45839
C15: =Объекты!C10 -> Шале | D15: 46204
C16: =Объекты!C13 -> Туристские резиденции | D16: 45839
C18: Курс руб./евро на дату анализа | D18: 86.5032 | E18: EUR
C19: Курс руб./долл. на дату анализа | D19: 77.4702 | E19: USD
C21: Доля собственных средств | D21: 0.2
C22: Доля заемных средств | D22: =1-D21 -> 0.8
C24: Налог на прибыль | D24: федеральн.бюджет | F24: регион.бюджет | H24: ИТОГО
C25: Период | D25: 2017-2024 гг. | E25: с 2025 г. | F25: 2017-2024 гг. | G25: с 2025 г. | H25: 2017-2024 гг. | I25: с 2025 г.
C26: Основная ставка налога на прибыль | D26: 0.03 | E26: 0.02 | F26: 0.17 | G26: 0.18 | H26: =D26+F26 -> 0.2 | I26: =E26+G26 -> 0.2
C27: Резиденты туристско-рекреационных ОЭЗ, объединенных в кластер | D27: 0 | E27: =E26 -> 0.02 | F27: 0.135 | G27: 0.135 | H27: =D27+F27 -> 0.135 | I27: =E27+G27 -> 0.155
D29: 10 лет | E29: с 11 года
C30: Ставка налога на имущество | D30: 0 | E30: 0.022
C31: Срок льготы по налогу на имущество, лет | D31: 10
C32: Премии к ФЗП | D32: =1/12 -> 0.083333333
C33: Страховые взносы с ФОТ | D33: =SUM(D34:D36) -> 0.3
C34: обязательное пенсионное страхование | D34: 0.22 | E34: статья 425 НК РФ с изменениям (Федеральный закон от 3 августа 2018 г. N 303-ФЗ)
C35: обязательное социальное страхование | D35: 0.029 | E35: статья 425 НК РФ
C36: обязательное медицинское страхование | D36: 0.051 | E36: статья 425 НК РФ
C37: Ставка страхования имущества | D37: 0.0025 | E37: от остаточной балансовой стоимости
C40: Условия управления
C41: ВЫБРАТЬ: | D41: 2 | E41: в расчетах утчено -->> | H41: =IF(D41=0,"без учета расходов на бренд",IF(D41=1,"прямое управление","франшиза для отелей 4* и 5*")) -> франшиза для отелей 4* и 5*
D42: 0 - без учета расходов на бренд
D43: 1 - прямое управление
D44: 2 - франшиза для отелей 4* и 5*
D46: NPV FCFE | E46: =KPI!D6 -> 67.805055
D47: IRR FCFE | E47: =KPI!D7 -> 0.14418346
D49: NPV FCFE TV | E49: =KPI!D11 -> 998.27965
D50: IRR FCFE TV | E50: =KPI!D12 -> 0.22612661

Sheet CPI
A1: 1
C2: МАКРОЭКОНОМИЧЕСКИЕ ПОКАЗАТЕЛИ
C3: Годовые показатели | E3: =Вводные!D5 -> 2022 | F3: =E3+1 -> 2023 | G3: =F3+1 -> 2024 | H3: =G3+1 -> 2025 | I3: =H3+1 -> 2026 | J3: =I3+1 -> 2027 | K3: =J3+1 -> 2028 | L3: =K3+1 -> 2029 | M3: =L3+1 -> 2030 | ... AN3: =AM3+1 -> 2057
C4: Инфляция за год | E4: 0.04 | F4: 0.04 | G4: 0.04 | H4: 0.04 | I4: 0.04 | J4: =I4 -> 0.04 | K4: =J4 -> 0.04 | L4: =K4 -> 0.04 | M4: =L4 -> 0.04 | N4: =M4 -> 0.04 | O4: =N4 -> 0.04 | P4: =O4 -> 0.04 | Q4: =P4 -> 0.04 | ... AN4: =AM4 -> 0.04
C5: Инфляция (накопленным итогом) | D5: 1 | E5: =(1+E4)*D5 -> 1.04 | F5: =(1+F4)*E5 -> 1.0816 | G5: =(1+G4)*F5 -> 1.124864 | H5: =(1+H4)*G5 -> 1.1698586 | I5: =(1+I4)*H5 -> 1.2166529 | J5: =(1+J4)*I5 -> 1.265319 | K5: =(1+K4)*J5 -> 1.3159318 | L5: =(1+L4)*K5 -> 1.3685691 | ... AN5: =(1+AN4)*AM5 -> 4.1039326
C6: Динамика земельных платежей | E6: 0 | F6: =E6 -> 0 | G6: =F6 -> 0 | H6: =G6 -> 0 | I6: 0.05 | J6: =E6 -> 0 | K6: =F6 -> 0 | L6: =G6 -> 0 | M6: =H6 -> 0 | N6: =I6 -> 0.05 | O6: =J6 -> 0 | P6: =K6 -> 0 | Q6: =L6 -> 0 | ... AN6: =AI6 -> 0
C7: Динамика земельных платежей (нак. итогом) | E7: 1 | F7: =(1+F6)*E7 -> 1 | G7: =(1+G6)*F7 -> 1 | H7: =(1+H6)*G7 -> 1 | I7: =(1+I6)*H7 -> 1.05 | J7: =(1+J6)*I7 -> 1.05 | K7: =(1+K6)*J7 -> 1.05 | L7: =(1+L6)*K7 -> 1.05 | M7: =(1+M6)*L7 -> 1.05 | ... AN7: =(1+AN6)*AM7 -> 1.4071004
C8: Инфляция заработных плат | E8: =E4 -> 0.04 | F8: =F4 -> 0.04 | G8: =G4 -> 0.04 | H8: =H4 -> 0.04 | I8: =I4 -> 0.04 | J8: =J4 -> 0.04 | K8: =K4 -> 0.04 | L8: =L4 -> 0.04 | ... AN8: =AN4 -> 0.04
C9: Инфляция заработных плат (нак. итогом) | E9: =E5 -> 1.04 | F9: =(1+F8)*E9 -> 1.0816 | G9: =(1+G8)*F9 -> 1.124864 | H9: =(1+H8)*G9 -> 1.1698586 | I9: =(1+I8)*H9 -> 1.2166529 | J9: =(1+J8)*I9 -> 1.265319 | K9: =(1+K8)*J9 -> 1.3159318 | L9: =(1+L8)*K9 -> 1.3685691 | M9: =(1+M8)*L9 -> 1.4233118 | ... AN9: =(1+AN8)*AM9 -> 4.1039326
C10: Руб./Евро | E10: 88.040608 | F10: 84.434627 | G10: 79.241197 | H10: =G10 -> 79.241197 | I10: =H10 -> 79.241197 | J10: =I10 -> 79.241197 | K10: =J10 -> 79.241197 | L10: =K10 -> 79.241197 | M10: =L10 -> 79.241197 | N10: =M10 -> 79.241197 | O10: =N10 -> 79.241197 | ... AN10: =AM10 -> 79.241197
C11: Руб./Долл. | E11: 80 | F11: =E11 -> 80 | G11: =F11 -> 80 | H11: =G11 -> 80 | I11: =H11 -> 80 | J11: =I11 -> 80 | K11: =J11 -> 80 | L11: =K11 -> 80 | M11: =L11 -> 80 | ... AN11: =AM11 -> 80
C12: Квартальные показатели | E12: =YEAR(E16) -> 2022 | F12: =YEAR(F16) -> 2022 | G12: =YEAR(G16) -> 2022 | H12: =YEAR(H16) -> 2022 | I12: =YEAR(I16) -> 2023 | J12: =YEAR(J16) -> 2023 | K12: =YEAR(K16) -> 2023 | L12: =YEAR(L16) -> 2023 | ... BL12: =YEAR(BL16) -> 2036
C13: Номер периода, п/п | E13: 1 | F13: 2 | G13: 3 | H13: 4 | I13: 5 | J13: 6 | K13: 7 | L13: 8 | M13: 9 | N13: 10 | O13: 11 | P13: 12 | Q13: 13 | R13: 14 | S13: 15 | T13: 16 | U13: 17 | V13: 18 | W13: 19 | X13: 20 | Y13: 21 | Z13: 22 | AA13: 23 | AB13: 24 | AC13: 25 | AD13: 26 | AE13: 27 | AF13: 28 | AG13: 29 | AH13: 30 | AI13: 31 | AJ13: 32 | AK13: 33 | AL13: 34 | AM13: 35 | AN13: 36 | AO13: 37 | AP13: 38 | AQ13: 39 | AR13: 40 | AS13: 41 | AT13: 42 | AU13: 43 | AV13: 44 | AW13: 45 | AX13: 46 | AY13: 47 | AZ13: 48 | BA13: 49 | BB13: 50 | BC13: 51 | BD13: 52 | BE13: 53 | BF13: 54 | BG13: 55 | BH13: 56 | BI13: 57 | BJ13: 58 | BK13: 59 | BL13: 60
C14: Квартал | E14: =IF(E15<>"",TRUNC((MONTH(E16)-1)/3, 0)+1,"") -> 1 | F14: =IF(F15<>"",TRUNC((MONTH(F16)-1)/3, 0)+1,"") -> 2 | G14: =IF(G15<>"",TRUNC((MONTH(G16)-1)/3, 0)+1,"") -> 3 | H14: =IF(H15<>"",TRUNC((MONTH(H16)-1)/3, 0)+1,"") -> 4 | I14: =IF(I15<>"",TRUNC((MONTH(I16)-1)/3, 0)+1,"") -> 1 | J14: =IF(J15<>"",TRUNC((MONTH(J16)-1)/3, 0)+1,"") -> 2 | K14: =IF(K15<>"",TRUNC((MONTH(K16)-1)/3, 0)+1,"") -> 3 | L14: =IF(L15<>"",TRUNC((MONTH(L16)-1)/3, 0)+1,"") -> 4 | ... BL14: =IF(BL15<>"",TRUNC((MONTH(BL16)-1)/3, 0)+1,"") -> 4
C15: Начало периода | E15: =Вводные!D4 -> 44593 | F15: =DATE(YEAR(E15),(TRUNC((MONTH(E15)-1)/3,0)+1)*3+1,1) -> 44652 | G15: =DATE(YEAR(F15),(TRUNC((MONTH(F15)-1)/3,0)+1)*3+1,1) -> 44743 | H15: =DATE(YEAR(G15),(TRUNC((MONTH(G15)-1)/3,0)+1)*3+1,1) -> 44835 | I15: =DATE(YEAR(H15),(TRUNC((MONTH(H15)-1)/3,0)+1)*3+1,1) -> 44927 | J15: =DATE(YEAR(I15),(TRUNC((MONTH(I15)-1)/3,0)+1)*3+1,1) -> 45017 | K15: =DATE(YEAR(J15),(TRUNC((MONTH(J15)-1)/3,0)+1)*3+1,1) -> 45108 | L15: =DATE(YEAR(K15),(TRUNC((MONTH(K15)-1)/3,0)+1)*3+1,1) -> 45200 | M15: =DATE(YEAR(L15),(TRUNC((MONTH(L15)-1)/3,0)+1)*3+1,1) -> 45292 | ... BL15: =DATE(YEAR(BK15),(TRUNC((MONTH(BK15)-1)/3,0)+1)*3+1,1) -> 49949
C16: Конец периода | E16: =DATE(YEAR(E15),((TRUNC((MONTH(E15)-1),0)+1)+2),1)-1 -> 44651 | F16: =DATE(YEAR(F15),((TRUNC((MONTH(F15)-1),0)+1)+1)+2,1)-1 -> 44742 | G16: =DATE(YEAR(G15),((TRUNC((MONTH(G15)-1),0)+1)+1)+2,1)-1 -> 44834 | H16: =DATE(YEAR(H15),((TRUNC((MONTH(H15)-1),0)+1)+1)+2,1)-1 -> 44926 | I16: =DATE(YEAR(I15),((TRUNC((MONTH(I15)-1),0)+1)+1)+2,1)-1 -> 45016 | J16: =DATE(YEAR(J15),((TRUNC((MONTH(J15)-1),0)+1)+1)+2,1)-1 -> 45107 | K16: =DATE(YEAR(K15),((TRUNC((MONTH(K15)-1),0)+1)+1)+2,1)-1 -> 45199 | L16: =DATE(YEAR(L15),((TRUNC((MONTH(L15)-1),0)+1)+1)+2,1)-1 -> 45291 | M16: =DATE(YEAR(M15),((TRUNC((MONTH(M15)-1),0)+1)+1)+2,1)-1 -> 45382 | ... BL16: =DATE(YEAR(BL15),((TRUNC((MONTH(BL15)-1),0)+1)+1)+2,1)-1 -> 50040
C17: Квартал | E17: =CONCATENATE(E14," кв. ",H99) -> 1 кв. | F17: =CONCATENATE(F14," кв. ",I99) -> 2 кв. | G17: =CONCATENATE(G14," кв. ",J99) -> 3 кв. | H17: =CONCATENATE(H14," кв. ",K99) -> 4 кв. | I17: =CONCATENATE(I14," кв. ",L99) -> 1 кв. | J17: =CONCATENATE(J14," кв. ",M99) -> 2 кв. | K17: =CONCATENATE(K14," кв. ",N99) -> 3 кв. | L17: =CONCATENATE(L14," кв. ",O99) -> 4 кв. | ... BL17: =CONCATENATE(BL14," кв. ",BO99) -> 4 кв.
C18: Дней в период | E18: =E16-E15+1 -> 59 | F18: =F16-F15+1 -> 91 | G18: =G16-G15+1 -> 92 | H18: =H16-H15+1 -> 92 | I18: =I16-I15+1 -> 90 | J18: =J16-J15+1 -> 91 | K18: =K16-K15+1 -> 92 | L18: =L16-L15+1 -> 92 | ... BL18: =BL16-BL15+1 -> 92
C19: Прогноз роста в период
C20: Инфляция | E20: =(1+SUMIF($E$3:$AN$3,E12,$E$4:$AN$4))^(1/4)-1 -> 0.0098534065 | F20: =(1+SUMIF($E$3:$AN$3,F12,$E$4:$AN$4))^(1/4)-1 -> 0.0098534065 | G20: =(1+SUMIF($E$3:$AN$3,G12,$E$4:$AN$4))^(1/4)-1 -> 0.0098534065 | H20: =(1+SUMIF($E$3:$AN$3,H12,$E$4:$AN$4))^(1/4)-1 -> 0.0098534065 | I20: =(1+SUMIF($E$3:$AN$3,I12,$E$4:$AN$4))^(1/4)-1 -> 0.0098534065 | J20: =(1+SUMIF($E$3:$AN$3,J12,$E$4:$AN$4))^(1/4)-1 -> 0.0098534065 | K20: =(1+SUMIF($E$3:$AN$3,K12,$E$4:$AN$4))^(1/4)-1 -> 0.0098534065 | L20: =(1+SUMIF($E$3:$AN$3,L12,$E$4:$AN$4))^(1/4)-1 -> 0.0098534065 | ... BL20: =(1+SUMIF($E$3:$AN$3,BL12,$E$4:$AN$4))^(1/4)-1 -> 0.0098534065
C21: Земельные платежи | E21: =(1+SUMIF($E$3:$AN$3,E12,$E$6:$AN$6))^(1/4)-1 -> 0 | F21: =(1+SUMIF($E$3:$AN$3,F12,$E$6:$AN$6))^(1/4)-1 -> 0 | G21: =(1+SUMIF($E$3:$AN$3,G12,$E$6:$AN$6))^(1/4)-1 -> 0 | H21: =(1+SUMIF($E$3:$AN$3,H12,$E$6:$AN$6))^(1/4)-1 -> 0 | I21: =(1+SUMIF($E$3:$AN$3,I12,$E$6:$AN$6))^(1/4)-1 -> 0 | J21: =(1+SUMIF($E$3:$AN$3,J12,$E$6:$AN$6))^(1/4)-1 -> 0 | K21: =(1+SUMIF($E$3:$AN$3,K12,$E$6:$AN$6))^(1/4)-1 -> 0 | L21: =(1+SUMIF($E$3:$AN$3,L12,$E$6:$AN$6))^(1/4)-1 -> 0 | ... BL21: =(1+SUMIF($E$3:$AN$3,BL12,$E$6:$AN$6))^(1/4)-1 -> 0.012272234
C22: Заработная плата | E22: =(1+SUMIF($E$3:$AN$3,E12,$E$8:$AN$8))^(1/4)-1 -> 0.0098534065 | F22: =(1+SUMIF($E$3:$AN$3,F12,$E$8:$AN$8))^(1/4)-1 -> 0.0098534065 | G22: =(1+SUMIF($E$3:$AN$3,G12,$E$8:$AN$8))^(1/4)-1 -> 0.0098534065 | H22: =(1+SUMIF($E$3:$AN$3,H12,$E$8:$AN$8))^(1/4)-1 -> 0.0098534065 | I22: =(1+SUMIF($E$3:$AN$3,I12,$E$8:$AN$8))^(1/4)-1 -> 0.0098534065 | J22: =(1+SUMIF($F$3:$AN$3,J12,$F$8:$AN$8))^(1/4)-1 -> 0.0098534065 | K22: =(1+SUMIF($F$3:$AN$3,K12,$F$8:$AN$8))^(1/4)-1 -> 0.0098534065 | L22: =(1+SUMIF($F$3:$AN$3,L12,$F$8:$AN$8))^(1/4)-1 -> 0.0098534065 | M22: =(1+SUMIF($F$3:$AN$3,M12,$F$8:$AN$8))^(1/4)-1 -> 0.0098534065 | N22: =(1+SUMIF($F$3:$AN$3,N12,$F$8:$AN$8))^(1/4)-1 -> 0.0098534065 | O22: =(1+SUMIF($F$3:$AN$3,O12,$F$8:$AN$8))^(1/4)-1 -> 0.0098534065 | P22: =(1+SUMIF($F$3:$AN$3,P12,$F$8:$AN$8))^(1/4)-1 -> 0.0098534065 | Q22: =(1+SUMIF($F$3:$AN$3,Q12,$F$8:$AN$8))^(1/4)-1 -> 0.0098534065 | ... BL22: =(1+SUMIF($F$3:$AN$3,BL12,$F$8:$AN$8))^(1/4)-1 -> 0.0098534065
C23: Накопленный рост (на конец периода)
C24: =C20 -> Инфляция | D24: 1 | E24: =(1+E20)*D24 -> 1.0098534 | F24: =(1+F20)*E24 -> 1.0198039 | G24: =(1+G20)*F24 -> 1.0298524 | H24: =(1+H20)*G24 -> 1.04 | I24: =(1+I20)*H24 -> 1.0502475 | J24: =(1+J20)*I24 -> 1.0605961 | K24: =(1+K20)*J24 -> 1.0710465 | L24: =(1+L20)*K24 -> 1.0816 | ... BL24: =(1+BL20)*BK24 -> 1.8009435
C25: =C21 -> Земельные платежи | D25: 1 | E25: =(1+E21)*D25 -> 1 | F25: =(1+F21)*E25 -> 1 | G25: =(1+G21)*F25 -> 1 | H25: =(1+H21)*G25 -> 1 | I25: =(1+I21)*H25 -> 1 | J25: =(1+J21)*I25 -> 1 | K25: =(1+K21)*J25 -> 1 | L25: =(1+L21)*K25 -> 1 | ... BL25: =(1+BL21)*BK25 -> 1.157625
C26: =C22 -> Заработная плата | D26: 1 | E26: =(1+E22)*D26 -> 1.0098534 | F26: =(1+F22)*E26 -> 1.0198039 | G26: =(1+G22)*F26 -> 1.0298524 | H26: =(1+H22)*G26 -> 1.04 | I26: =(1+I22)*H26 -> 1.0502475 | J26: =(1+J22)*I26 -> 1.0605961 | K26: =(1+K22)*J26 -> 1.0710465 | L26: =(1+L22)*K26 -> 1.0816 | ... BL26: =(1+BL22)*BK26 -> 1.8009435
C27: Проверка | H27: =H24=LOOKUP(H$12,$E$3:$AN$3,$E5:$AN5) -> TRUE | L27: =L24=LOOKUP(L$12,$E$3:$AN$3,$E5:$AN5) -> TRUE | P27: =P24=LOOKUP(P$12,$E$3:$AN$3,$E5:$AN5) -> TRUE | T27: =T24=LOOKUP(T$12,$E$3:$AN$3,$E5:$AN5) -> TRUE | X27: =X24=LOOKUP(X$12,$E$3:$AN$3,$E5:$AN5) -> TRUE | AB27: =AB24=LOOKUP(AB$12,$E$3:$AN$3,$E5:$AN5) -> TRUE
C28: Проверка | H28: =H25=LOOKUP(H$12,$E$3:$AN$3,$E7:$AN7) -> TRUE | L28: =L25=LOOKUP(L$12,$E$3:$AN$3,$E7:$AN7) -> TRUE | P28: =P25=LOOKUP(P$12,$E$3:$AN$3,$E7:$AN7) -> TRUE | T28: =T25=LOOKUP(T$12,$E$3:$AN$3,$E7:$AN7) -> TRUE | X28: =X25=LOOKUP(X$12,$E$3:$AN$3,$E7:$AN7) -> TRUE | AB28: =AB25=LOOKUP(AB$12,$E$3:$AN$3,$E7:$AN7) -> TRUE
C29: Проверка | H29: =H26=LOOKUP(H$12,$E$3:$AN$3,$E9:$AN9) -> TRUE | L29: =L26=LOOKUP(L$12,$E$3:$AN$3,$E9:$AN9) -> TRUE | P29: =P26=LOOKUP(P$12,$E$3:$AN$3,$E9:$AN9) -> TRUE | T29: =T26=LOOKUP(T$12,$E$3:$AN$3,$E9:$AN9) -> TRUE | X29: =X26=LOOKUP(X$12,$E$3:$AN$3,$E9:$AN9) -> TRUE | AB29: =AB26=LOOKUP(AB$12,$E$3:$AN$3,$E9:$AN9) -> TRUE

Sheet Земля
A1: 1
C3: ЗЕМЕЛЬНЫЕ ПЛАТЕЖИ - ВВОДНЫЕ ДАННЫЕ
C4: Кадастровый номер | D4: Площадь, кв.м | E4: Кадастровая стоимость, руб. | F4: Кадастровая стоимость, руб./ кв.м | G4: Вид права | H4: Размер платежа, % от кадастровой стоимости | I4: Размер платежа, руб./год | J4: Размер платежа, руб./кв.м/год | L4: Категория | M4: ВРИ
C5: 09:06:0021401:2308 | D5: 114723 | E5: 30157235 | F5: =E5/D5 -> 262.87 | G5: аренда | H5: 0.015 | I5: =H5*E5 -> 452358.53 | J5: =H5*F5 -> 3.94305 | L5: Земли особо охраняемых территорий и объектов | M5: Для туристско-рекреационной деятельности
C6: 09:06:0000000:16366 | D6: 21600 | E6: 5677992 | F6: =E6/D6 -> 262.87 | G6: аренда | H6: 0.015 | I6: =H6*E6 -> 85169.88 | J6: =H6*F6 -> 3.94305 | L6: Земли особо охраняемых территорий и объектов | M6: Для туристско-рекреационной деятельности
C7: ИТОГО, га | D7: =SUM(D5:D6)/10000 -> 13.6323
C13: Дата ввода в экспл-ю | D13: =Вводные!D9 -> 45839
C14: Год ввода в экспл-ю | D14: =YEAR(D13) -> 2025
B15: Примечание | C15: Доля 1 периода | D15: 1
C17: ПРОГНОЗ ЗЕМЕЛЬНЫХ ПЛАТЕЖЕЙ | E17: руб. | DN17: Мультипликатор | DO17: =10^6 -> 1000000 | DP17: =IF(DO17=1,"руб.",IF(DO17=1000,"тыс. руб.",IF(DO17=1000000,"млн руб.",IF(DO17=1000000000,"млрд руб.","Ошибка")))) -> млн руб.
C18: Показатель | E18: =YEAR(E19) -> 2022 | F18: =YEAR(F19) -> 2022 | G18: =YEAR(G19) -> 2022 | H18: =YEAR(H19) -> 2022 | I18: =YEAR(I19) -> 2023 | J18: =YEAR(J19) -> 2023 | K18: =YEAR(K19) -> 2023 | L18: =YEAR(L19) -> 2023 | ... DK18: =YEAR(DK19) -> 2049 | DM18: ГОД --->> | DN18: =E18 -> 2022 | DO18: =DN18+1 -> 2023 | DP18: =DO18+1 -> 2024 | DQ18: =DP18+1 -> 2025 | DR18: =DQ18+1 -> 2026 | DS18: =DR18+1 -> 2027 | DT18: =DS18+1 -> 2028 | DU18: =DT18+1 -> 2029 | DV18: =DU18+1 -> 2030 | ... EO18: =EN18+1 -> 2049
C19: Начало периода | E19: =Вводные!$D$4 -> 44593 | F19: =DATE(YEAR(E20),(TRUNC((MONTH(E20)-1)/3,0)+1)*3+1,1) -> 44652 | G19: =DATE(YEAR(F20),(TRUNC((MONTH(F20)-1)/3,0)+1)*3+1,1) -> 44743 | H19: =DATE(YEAR(G20),(TRUNC((MONTH(G20)-1)/3,0)+1)*3+1,1) -> 44835 | I19: =DATE(YEAR(H20),(TRUNC((MONTH(H20)-1)/3,0)+1)*3+1,1) -> 44927 | J19: =DATE(YEAR(I20),(TRUNC((MONTH(I20)-1)/3,0)+1)*3+1,1) -> 45017 | K19: =DATE(YEAR(J20),(TRUNC((MONTH(J20)-1)/3,0)+1)*3+1,1) -> 45108 | L19: =DATE(YEAR(K20),(TRUNC((MONTH(K20)-1)/3,0)+1)*3+1,1) -> 45200 | M19: =DATE(YEAR(L20),(TRUNC((MONTH(L20)-1)/3,0)+1)*3+1,1) -> 45292 | ... DK19: =DATE(YEAR(DJ20),(TRUNC((MONTH(DJ20)-1)/3,0)+1)*3+1,1) -> 54605
C20: Конец периода | E20: =DATE(YEAR(E19),((TRUNC((MONTH(E19)-1),0)+1)+2),1)-1 -> 44651 | F20: =DATE(YEAR(F19),((TRUNC((MONTH(F19)-1),0)+1)+1)+2,1)-1 -> 44742 | G20: =DATE(YEAR(G19),((TRUNC((MONTH(G19)-1),0)+1)+1)+2,1)-1 -> 44834 | H20: =DATE(YEAR(H19),((TRUNC((MONTH(H19)-1),0)+1)+1)+2,1)-1 -> 44926 | I20: =DATE(YEAR(I19),((TRUNC((MONTH(I19)-1),0)+1)+1)+2,1)-1 -> 45016 | J20: =DATE(YEAR(J19),((TRUNC((MONTH(J19)-1),0)+1)+1)+2,1)-1 -> 45107 | K20: =DATE(YEAR(K19),((TRUNC((MONTH(K19)-1),0)+1)+1)+2,1)-1 -> 45199 | L20: =DATE(YEAR(L19),((TRUNC((MONTH(L19)-1),0)+1)+1)+2,1)-1 -> 45291 | M20: =DATE(YEAR(M19),((TRUNC((MONTH(M19)-1),0)+1)+1)+2,1)-1 -> 45382 | ... DK20: =DATE(YEAR(DK19),((TRUNC((MONTH(DK19)-1),0)+1)+1)+2,1)-1 -> 54696
C21: Длина периода | E21: =E20-E19+1 -> 59 | F21: =F20-F19+1 -> 91 | G21: =G20-G19+1 -> 92 | H21: =H20-H19+1 -> 92 | I21: =I20-I19+1 -> 90 | J21: =J20-J19+1 -> 91 | K21: =K20-K19+1 -> 92 | L21: =L20-L19+1 -> 92 | ... DK21: =DK20-DK19+1 -> 92
C22: Площадь участка, кв.м | E22: =$D$5 -> 114723 | F22: =E22 -> 114723 | G22: =F22 -> 114723 | H22: =G22 -> 114723 | I22: =H22 -> 114723 | J22: =I22 -> 114723 | K22: =J22 -> 114723 | L22: =K22 -> 114723 | M22: =L22 -> 114723 | ... DK22: =DJ22 -> 114723
C23: Выбытие тур.резиденций ввиду продажи, кв.м | E23: =Резиденции!F29/(Земля!D5+Земля!D6) -> 0.020539454 | F23: =Резиденции!F12 -> 14000 | G23: =LOOKUP(G19,ПРОДАЖА_lease_back!$D$11:$CQ$11,ПРОДАЖА_lease_back!$D$22:$CQ$22) -> 0 | H23: =LOOKUP(H19,ПРОДАЖА_lease_back!$D$11:$CQ$11,ПРОДАЖА_lease_back!$D$22:$CQ$22) -> 0 | I23: =LOOKUP(I19,ПРОДАЖА_lease_back!$D$11:$CQ$11,ПРОДАЖА_lease_back!$D$22:$CQ$22) -> 0 | J23: =LOOKUP(J19,ПРОДАЖА_lease_back!$D$11:$CQ$11,ПРОДАЖА_lease_back!$D$22:$CQ$22) -> 0 | K23: =LOOKUP(K19,ПРОДАЖА_lease_back!$D$11:$CQ$11,ПРОДАЖА_lease_back!$D$22:$CQ$22) -> 0 | L23: =LOOKUP(L19,ПРОДАЖА_lease_back!$D$11:$CQ$11,ПРОДАЖА_lease_back!$D$22:$CQ$22) -> 0 | M23: =LOOKUP(M19,ПРОДАЖА_lease_back!$D$11:$CQ$11,ПРОДАЖА_lease_back!$D$22:$CQ$22) -> 0 | N23: =LOOKUP(N19,ПРОДАЖА_lease_back!$D$11:$CQ$11,ПРОДАЖА_lease_back!$D$22:$CQ$22) -> 0 | ... DK23: =LOOKUP(DK19,ПРОДАЖА_lease_back!$D$11:$CQ$11,ПРОДАЖА_lease_back!$D$22:$CQ$22) -> 0
C24: Выбытие зем./участков ввиду продажи тур.резиденций, кв.м | G24: =-$E$23*G22*(SUM($G$23:G23)/$F$23) -> 0 | H24: =-$E$23*H22*(SUM($G$23:H23)/$F$23) -> 0 | I24: =-$E$23*I22*(SUM($G$23:I23)/$F$23) -> 0 | J24: =-$E$23*J22*(SUM($G$23:J23)/$F$23) -> 0 | K24: =-$E$23*K22*(SUM($G$23:K23)/$F$23) -> 0 | L24: =-$E$23*L22*(SUM($G$23:L23)/$F$23) -> 0 | M24: =-$E$23*M22*(SUM($G$23:M23)/$F$23) -> 0 | N24: =-$E$23*N22*(SUM($G$23:N23)/$F$23) -> 0 | ... DK24: =-$E$23*DK22*(SUM($G$23:DK23)/$F$23) -> -2356.3478
C25: Итого, площадь участка, за который производится оплата земельных платежей, кв.м | E25: =SUM(E22,E24) -> 114723 | F25: =SUM(F22,F24) -> 114723 | G25: =SUM(G22,G24) -> 114723 | H25: =SUM(H22,H24) -> 114723 | I25: =SUM(I22,I24) -> 114723 | J25: =SUM(J22,J24) -> 114723 | K25: =SUM(K22,K24) -> 114723 | L25: =SUM(L22,L24) -> 114723 | ... DK25: =SUM(DK22,DK24) -> 112366.65
C26: Динамика изменения земельных платежей | E26: =F26 -> 1 | F26: =LOOKUP(F19,CPI!$15:$15,CPI!$25:$25) -> 1 | G26: =LOOKUP(G19,CPI!$15:$15,CPI!$25:$25) -> 1 | H26: =LOOKUP(H19,CPI!$15:$15,CPI!$25:$25) -> 1 | I26: =LOOKUP(I19,CPI!$15:$15,CPI!$25:$25) -> 1 | J26: =LOOKUP(J19,CPI!$15:$15,CPI!$25:$25) -> 1 | K26: =LOOKUP(K19,CPI!$15:$15,CPI!$25:$25) -> 1 | L26: =LOOKUP(L19,CPI!$15:$15,CPI!$25:$25) -> 1 | M26: =LOOKUP(M19,CPI!$15:$15,CPI!$25:$25) -> 1 | ... DK26: =LOOKUP(DK19,CPI!$15:$15,CPI!$25:$25) -> 1.157625
C27: Итого, все платежи | E27: =$J$5*E26*E25*E21/365 -> 73120.967 | F27: =$J$5*F26*F25*F21/365 -> 112779.8 | G27: =$J$5*G26*G25*G21/365 -> 114019.14 | H27: =$J$5*H26*H25*H21/365 -> 114019.14 | I27: =$J$5*I26*I25*I21/365 -> 111540.46 | J27: =$J$5*J26*J25*J21/365 -> 112779.8 | K27: =$J$5*K26*K25*K21/365 -> 114019.14 | L27: =$J$5*L26*L25*L21/365 -> 114019.14 | ... DK27: =$J$5*DK26*DK25*DK21/365 -> 129280.37 | DN27: =SUMIF($E$18:$DK$18,DN$18,$E27:$DK27)/$DO$17 -> 0.41393903 | DO27: =SUMIF($E$18:$DK$18,DO$18,$E27:$DK27)/$DO$17 -> 0.45235853 | DP27: =SUMIF($E$18:$DK$18,DP$18,$E27:$DK27)/$DO$17 -> 0.45359786 | DQ27: =SUMIF($E$18:$DK$18,DQ$18,$E27:$DK27)/$DO$17 -> 0.45235853 | DR27: =SUMIF($E$18:$DK$18,DR$18,$E27:$DK27)/$DO$17 -> 0.46508195 | DS27: =SUMIF($E$18:$DK$18,DS$18,$E27:$DK27)/$DO$17 -> 0.47008922 | DT27: =SUMIF($E$18:$DK$18,DT$18,$E27:$DK27)/$DO$17 -> 0.4676403 | DU27: =SUMIF($E$18:$DK$18,DU$18,$E27:$DK27)/$DO$17 -> 0.46522069 | ... EO27: =SUMIF($E$18:$DK$18,EO$18,$E27:$DK27)/$DO$17 -> 0.38362545
C30: ПРОГНОЗ ЗЕМЕЛЬНЫХ ПЛАТЕЖЕЙ - ПО ГОДАМ
C31: Показатель | E31: =E18 -> 2022 | F31: =E31+1 -> 2023 | G31: =F31+1 -> 2024 | H31: =G31+1 -> 2025 | I31: =H31+1 -> 2026 | J31: =I31+1 -> 2027 | K31: =J31+1 -> 2028 | L31: =K31+1 -> 2029 | M31: =L31+1 -> 2030 | ... AB31: =AA31+1 -> 2045
C32: Земельные платежи инвестиционного периода | E32: =IF(E31<$D$14,SUMIF(18:18,E31,27:27),0) -> 413939.45 | F32: =IF(F31<$D$14,SUMIF(18:18,F31,27:27),0) -> 452358.98 | G32: =IF(G31<$D$14,SUMIF(18:18,G31,27:27),0) -> 453598.32 | H32: =IF(H31<$D$14,SUMIF(18:18,H31,27:27),0) -> 0 | I32: =IF(I31<$D$14,SUMIF(18:18,I31,27:27),0) -> 0 | J32: =IF(J31<$D$14,SUMIF(18:18,J31,27:27),0) -> 0 | K32: =IF(K31<$D$14,SUMIF(18:18,K31,27:27),0) -> 0 | L32: =IF(L31<$D$14,SUMIF(18:18,L31,27:27),0) -> 0 | ... AB32: =IF(AB31<$D$14,SUMIF(18:18,AB31,27:27),0) -> 0
C33: Земельные платежи операционного периода | E33: =IF(E31>=$D$14,SUMIF(18:18,E31,27:27),0) -> 0 | F33: =IF(F31>=$D$14,SUMIF(18:18,F31,27:27),0) -> 0 | G33: =IF(G31>=$D$14,SUMIF(18:18,G31,27:27),0) -> 0 | H33: =IF(H31>=$D$14,SUMIF(18:18,H31,27:27),0) -> 452358.98 | I33: =IF(I31>=$D$14,SUMIF(18:18,I31,27:27),0) -> 465082.41 | J33: =IF(J31>=$D$14,SUMIF(18:18,J31,27:27),0) -> 470089.69 | K33: =IF(K31>=$D$14,SUMIF(18:18,K31,27:27),0) -> 467640.77 | L33: =IF(L31>=$D$14,SUMIF(18:18,L31,27:27),0) -> 465221.16 | ... AB33: =IF(AB31>=$D$14,SUMIF(18:18,AB31,27:27),0) -> 512906.33

Sheet Бюджетный эффект
C2: Год ввода 1 очереди | D2: =YEAR(Вводные!D9) -> 2025
H3: =C2 -> Год ввода 1 очереди
E4: =F4-1 -> 2022 | F4: =G4-1 -> 2023 | G4: =H4-1 -> 2024 | H4: =D2 -> 2025 | I4: =H4+1 -> 2026 | J4: =I4+1 -> 2027 | K4: =J4+1 -> 2028 | L4: =K4+1 -> 2029 | M4: =L4+1 -> 2030 | N4: =M4+1 -> 2031 | O4: =N4+1 -> 2032 | P4: =O4+1 -> 2033 | Q4: =P4+1 -> 2034
C5: Выручка, руб. без НДС
C6: Туристический комплекс "Лунная поляна" - Архыз | E6: =IFERROR(LOOKUP(E4,СВОД_PL!$D$3:$T$3,СВОД_PL!$D$32:$T$32),0)+IFERROR(LOOKUP(E4,Ресторан!$F$5:$V$5,Ресторан!$F$62:$V$62),0)+IFERROR(LOOKUP(E4,Retail!$D$21:$V$21,Retail!$D$49:$V$49),0)+IFERROR(LOOKUP(E4,Паркинг_PL!$D$9:$T$9,Паркинг_PL!$D$29:$T$29),0)+SUMIF(ПРОДАЖА_lease_back!$D$8:$CQ$8,E4,ПРОДАЖА_lease_back!$D$32:$CQ$32) -> 0 | F6: =IFERROR(LOOKUP(F4,СВОД_PL!$D$3:$T$3,СВОД_PL!$D$32:$T$32),0)+IFERROR(LOOKUP(F4,Ресторан!$F$5:$V$5,Ресторан!$F$62:$V$62),0)+IFERROR(LOOKUP(F4,Retail!$D$21:$V$21,Retail!$D$49:$V$49),0)+IFERROR(LOOKUP(F4,Паркинг_PL!$D$9:$T$9,Паркинг_PL!$D$29:$T$29),0)+SUMIF(ПРОДАЖА_lease_back!$D$8:$CQ$8,F4,ПРОДАЖА_lease_back!$D$32:$CQ$32) -> 0 | G6: =IFERROR(LOOKUP(G4,СВОД_PL!$D$3:$T$3,СВОД_PL!$D$32:$T$32),0)+IFERROR(LOOKUP(G4,Ресторан!$F$5:$V$5,Ресторан!$F$62:$V$62),0)+IFERROR(LOOKUP(G4,Retail!$D$21:$V$21,Retail!$D$49:$V$49),0)+IFERROR(LOOKUP(G4,Паркинг_PL!$D$9:$T$9,Паркинг_PL!$D$29:$T$29),0)+SUMIF(ПРОДАЖА_lease_back!$D$8:$CQ$8,G4,ПРОДАЖА_lease_back!$D$32:$CQ$32) -> 0 | H6: =IFERROR(LOOKUP(H4,СВОД_PL!$D$3:$T$3,СВОД_PL!$D$32:$T$32),0)+IFERROR(LOOKUP(H4,Ресторан!$F$5:$V$5,Ресторан!$F$62:$V$62),0)+IFERROR(LOOKUP(H4,Retail!$D$21:$V$21,Retail!$D$49:$V$49),0)+IFERROR(LOOKUP(H4,Паркинг_PL!$D$9:$T$9,Паркинг_PL!$D$29:$T$29),0)+SUMIF(ПРОДАЖА_lease_back!$D$8:$CQ$8,H4,ПРОДАЖА_lease_back!$D$32:$CQ$32) -> 4.1149352e+08 | I6: =IFERROR(LOOKUP(I4,СВОД_PL!$D$3:$T$3,СВОД_PL!$D$32:$T$32),0)+IFERROR(LOOKUP(I4,Ресторан!$F$5:$V$5,Ресторан!$F$62:$V$62),0)+IFERROR(LOOKUP(I4,Retail!$D$21:$V$21,Retail!$D$49:$V$49),0)+IFERROR(LOOKUP(I4,Паркинг_PL!$D$9:$T$9,Паркинг_PL!$D$29:$T$29),0)+SUMIF(ПРОДАЖА_lease_back!$D$8:$CQ$8,I4,ПРОДАЖА_lease_back!$D$32:$CQ$32) -> 2.7535099e+09 | J6: =IFERROR(LOOKUP(J4,СВОД_PL!$D$3:$T$3,СВОД_PL!$D$32:$T$32),0)+IFERROR(LOOKUP(J4,Ресторан!$F$5:$V$5,Ресторан!$F$62:$V$62),0)+IFERROR(LOOKUP(J4,Retail!$D$21:$V$21,Retail!$D$49:$V$49),0)+IFERROR(LOOKUP(J4,Паркинг_PL!$D$9:$T$9,Паркинг_PL!$D$29:$T$29),0)+SUMIF(ПРОДАЖА_lease_back!$D$8:$CQ$8,J4,ПРОДАЖА_lease_back!$D$32:$CQ$32) -> 4.2924276e+09 | K6: =IFERROR(LOOKUP(K4,СВОД_PL!$D$3:$T$3,СВОД_PL!$D$32:$T$32),0)+IFERROR(LOOKUP(K4,Ресторан!$F$5:$V$5,Ресторан!$F$62:$V$62),0)+IFERROR(LOOKUP(K4,Retail!$D$21:$V$21,Retail!$D$49:$V$49),0)+IFERROR(LOOKUP(K4,Паркинг_PL!$D$9:$T$9,Паркинг_PL!$D$29:$T$29),0)+SUMIF(ПРОДАЖА_lease_back!$D$8:$CQ$8,K4,ПРОДАЖА_lease_back!$D$32:$CQ$32) -> 4.2009615e+09 | L6: =IFERROR(LOOKUP(L4,СВОД_PL!$D$3:$T$3,СВОД_PL!$D$32:$T$32),0)+IFERROR(LOOKUP(L4,Ресторан!$F$5:$V$5,Ресторан!$F$62:$V$62),0)+IFERROR(LOOKUP(L4,Retail!$D$21:$V$21,Retail!$D$49:$V$49),0)+IFERROR(LOOKUP(L4,Паркинг_PL!$D$9:$T$9,Паркинг_PL!$D$29:$T$29),0)+SUMIF(ПРОДАЖА_lease_back!$D$8:$CQ$8,L4,ПРОДАЖА_lease_back!$D$32:$CQ$32) -> 2.647119e+09 | ... Q6: =IFERROR(LOOKUP(Q4,СВОД_PL!$D$3:$T$3,СВОД_PL!$D$32:$T$32),0)+IFERROR(LOOKUP(Q4,Ресторан!$F$5:$V$5,Ресторан!$F$62:$V$62),0)+IFERROR(LOOKUP(Q4,Retail!$D$21:$V$21,Retail!$D$49:$V$49),0)+IFERROR(LOOKUP(Q4,Паркинг_PL!$D$9:$T$9,Паркинг_PL!$D$29:$T$29),0)+SUMIF(ПРОДАЖА_lease_back!$D$8:$CQ$8,Q4,ПРОДАЖА_lease_back!$D$32:$CQ$32) -> 3.3121542e+09
C8: ЧОП
C9: =C6 -> Туристический комплекс "Лунная поляна" - Архыз | E9: =LOOKUP(E$4,CF_15!$D$5:$T$5,CF_15!$D$24:$T$24) -> 0 | F9: =LOOKUP(F$4,CF_15!$D$5:$T$5,CF_15!$D$24:$T$24) -> 0 | G9: =LOOKUP(G$4,CF_15!$D$5:$T$5,CF_15!$D$24:$T$24) -> 0 | H9: =LOOKUP(H$4,CF_15!$D$5:$T$5,CF_15!$D$24:$T$24) -> 1.0428256e+08 | I9: =LOOKUP(I$4,CF_15!$D$5:$T$5,CF_15!$D$24:$T$24) -> 1.4387461e+09 | J9: =LOOKUP(J$4,CF_15!$D$5:$T$5,CF_15!$D$24:$T$24) -> 2.4141395e+09 | K9: =LOOKUP(K$4,CF_15!$D$5:$T$5,CF_15!$D$24:$T$24) -> 2.2885779e+09 | L9: =LOOKUP(L$4,CF_15!$D$5:$T$5,CF_15!$D$24:$T$24) -> 9.737917e+08 | ... Q9: =LOOKUP(Q$4,CF_15!$D$5:$T$5,CF_15!$D$24:$T$24) -> 1.2404216e+09
C11: Расходы
C12: =C9 -> Туристический комплекс "Лунная поляна" - Архыз | E12: =E6-E9 -> 0 | F12: =F6-F9 -> 0 | G12: =G6-G9 -> 0 | H12: =H6-H9 -> 3.0721096e+08 | I12: =I6-I9 -> 1.3147638e+09 | J12: =J6-J9 -> 1.8782881e+09 | K12: =K6-K9 -> 1.9123836e+09 | L12: =L6-L9 -> 1.6733273e+09 | ... Q12: =Q6-Q9 -> 2.0717327e+09
C14: Доля расходов на персонал в выручке
C15: =C12 -> Туристический комплекс "Лунная поляна" - Архыз | H15: =H20/H6 -> 0.29676723 | I15: =I20/I6 -> 0.14008499 | J15: =J20/J6 -> 0.12526065 | K15: =K20/K6 -> 0.13284752 | L15: =L20/L6 -> 0.22129918 | M15: =M20/M6 -> 0.21682216 | N15: =N20/N6 -> 0.21682216 | O15: =O20/O6 -> 0.21681472 | ... Q15: =Q20/Q6 -> 0.21682216
C16: Доля расходов на персонал в расходах
C17: =C14 -> Доля расходов на персонал в выручке | H17: =H20/H12 -> 0.39750467 | I17: =I20/I12 -> 0.29338 | J17: =J20/J12 -> 0.28625656 | K17: =K20/K12 -> 0.29182813 | L17: =L20/L12 -> 0.35008409 | M17: =M20/M12 -> 0.34783083 | N17: =N20/N12 -> 0.3460461 | O17: =O20/O12 -> 0.34624756 | ... Q17: =Q20/Q12 -> 0.34664145
C19: Расходы на персонал
C20: =C15 -> Туристический комплекс "Лунная поляна" - Архыз | H20: =LOOKUP(H4,СВОД_PL!120:120,СВОД_PL!124:124) -> 1.2211779e+08 | I20: =LOOKUP(I4,СВОД_PL!120:120,СВОД_PL!124:124) -> 3.8572541e+08 | J20: =LOOKUP(J4,СВОД_PL!120:120,СВОД_PL!124:124) -> 5.376723e+08 | K20: =LOOKUP(K4,СВОД_PL!120:120,СВОД_PL!124:124) -> 5.5808732e+08 | L20: =LOOKUP(L4,СВОД_PL!120:120,СВОД_PL!124:124) -> 5.8580527e+08 | M20: =LOOKUP(M4,СВОД_PL!120:120,СВОД_PL!124:124) -> 6.1387628e+08 | N20: =LOOKUP(N4,СВОД_PL!120:120,СВОД_PL!124:124) -> 6.3843133e+08 | O20: =LOOKUP(O4,СВОД_PL!120:120,СВОД_PL!124:124) -> 6.6581461e+08 | ... Q20: =LOOKUP(Q4,СВОД_PL!120:120,СВОД_PL!124:124) -> 7.1814842e+08
C22: НДФЛ
C23: =C20 -> Туристический комплекс "Лунная поляна" - Архыз | H23: =$E$59*H20 -> 12211779 | I23: =$E$59*I20 -> 38572541 | J23: =$E$59*J20 -> 53767230 | K23: =$E$59*K20 -> 55808732 | L23: =$E$59*L20 -> 58580527 | M23: =$E$59*M20 -> 61387628 | N23: =$E$59*N20 -> 63843133 | O23: =$E$59*O20 -> 66581461 | ... Q23: =$E$59*Q20 -> 71814842 | R23: =SUM(H23:Q23) -> 5.516206e+08
C25: Социальные отчисления
C26: =C23 -> Туристический комплекс "Лунная поляна" - Архыз | H26: =$E$62*H20 -> 28181029 | I26: =$E$62*I20 -> 89013555 | J26: =$E$62*J20 -> 1.2407822e+08 | K26: =$E$62*K20 -> 1.2878938e+08 | L26: =$E$62*L20 -> 1.3518583e+08 | M26: =$E$62*M20 -> 1.4166376e+08 | N26: =$E$62*N20 -> 1.4733031e+08 | O26: =$E$62*O20 -> 1.5364953e+08 | ... Q26: =$E$62*Q20 -> 1.6572656e+08 | R26: =SUM(H26:Q26) -> 1.2729706e+09
C28: Налог на прибыль
C29: =C26 -> Туристический комплекс "Лунная поляна" - Архыз | E29: =-LOOKUP(E4,CF_15!5:5,CF_15!34:34) -> 0 | F29: =-LOOKUP(F4,CF_15!5:5,CF_15!34:34) -> 0 | G29: =-LOOKUP(G4,CF_15!5:5,CF_15!34:34) -> 0 | H29: =-LOOKUP(H4,CF_15!5:5,CF_15!34:34) -> 0 | I29: =-LOOKUP(I4,CF_15!5:5,CF_15!34:34) -> 51717310 | J29: =-LOOKUP(J4,CF_15!5:5,CF_15!34:34) -> 1.9663596e+08 | K29: =-LOOKUP(K4,CF_15!5:5,CF_15!34:34) -> 1.9104475e+08 | L29: =-LOOKUP(L4,CF_15!5:5,CF_15!34:34) -> 77573294 | ... Q29: =-LOOKUP(Q4,CF_15!5:5,CF_15!34:34) -> 1.3827964e+08 | R29: =SUM(H29:Q29) -> 1.0946181e+09
C30: в т.ч. в федеральный бюджет | E30: =E29*IF(E4<=$N$55,$N$60,$Q$60) -> 0 | F30: =F29*IF(F4<=$N$55,$N$60,$Q$60) -> 0 | G30: =G29*IF(G4<=$N$55,$N$60,$Q$60) -> 0 | H30: =H29*IF(H4<=$N$55,$N$60,$Q$60) -> 0 | I30: =I29*IF(I4<=$N$55,$N$60,$Q$60) -> 6673201.3 | J30: =J29*IF(J4<=$N$55,$N$60,$Q$60) -> 25372382 | K30: =K29*IF(K4<=$N$55,$N$60,$Q$60) -> 24650935 | L30: =L29*IF(L4<=$N$55,$N$60,$Q$60) -> 10009457 | ... Q30: =Q29*IF(Q4<=$N$55,$N$60,$Q$60) -> 17842535 | R30: =SUM(H30:Q30) -> 1.4124105e+08
C32: Налог на имущество
C33: =C29 -> Туристический комплекс "Лунная поляна" - Архыз | E33: =LOOKUP(E4,Амортизация!295:295,Амортизация!298:298)+LOOKUP(E4,Амортизация!295:295,Амортизация!314:314) -> 0 | F33: =LOOKUP(F4,Амортизация!295:295,Амортизация!298:298)+LOOKUP(F4,Амортизация!295:295,Амортизация!314:314) -> 0 | G33: =LOOKUP(G4,Амортизация!295:295,Амортизация!298:298)+LOOKUP(G4,Амортизация!295:295,Амортизация!314:314) -> 0 | H33: =LOOKUP(H4,Амортизация!295:295,Амортизация!298:298)+LOOKUP(H4,Амортизация!295:295,Амортизация!314:314) -> 0 | I33: =LOOKUP(I4,Амортизация!295:295,Амортизация!298:298)+LOOKUP(I4,Амортизация!295:295,Амортизация!314:314) -> 0 | J33: =LOOKUP(J4,Амортизация!295:295,Амортизация!298:298)+LOOKUP(J4,Амортизация!295:295,Амортизация!314:314) -> 0 | K33: =LOOKUP(K4,Амортизация!295:295,Амортизация!298:298)+LOOKUP(K4,Амортизация!295:295,Амортизация!314:314) -> 0 | L33: =LOOKUP(L4,Амортизация!295:295,Амортизация!298:298)+LOOKUP(L4,Амортизация!295:295,Амортизация!314:314) -> 0 | ... Q33: =LOOKUP(Q4,Амортизация!295:295,Амортизация!298:298)+LOOKUP(Q4,Амортизация!295:295,Амортизация!314:314) -> 0 | R33: =SUM(H33:Q33) -> 0 | S33: 10 лет - льгота по НнИ
C35: Налог на землю / Арендные платежи за землю
C36: =C33 -> Туристический комплекс "Лунная поляна" - Архыз | E36: =LOOKUP(E4,Земля!31:31,Земля!32:32) -> 413939.45 | F36: =LOOKUP(F4,Земля!31:31,Земля!32:32) -> 452358.98 | G36: =LOOKUP(G4,Земля!31:31,Земля!32:32) -> 453598.32 | H36: =LOOKUP(H4,Земля!31:31,Земля!33:33) -> 452358.98 | I36: =LOOKUP(I4,Земля!31:31,Земля!33:33) -> 465082.41 | J36: =LOOKUP(J4,Земля!31:31,Земля!33:33) -> 470089.69 | K36: =LOOKUP(K4,Земля!31:31,Земля!33:33) -> 467640.77 | L36: =LOOKUP(L4,Земля!31:31,Земля!33:33) -> 465221.16 | M36: =LOOKUP(M4,Земля!31:31,Земля!33:33) -> 465221.16 | N36: =LOOKUP(N4,Земля!31:31,Земля!33:33) -> 479726.66 | O36: =LOOKUP(O4,Земля!31:31,Земля!33:33) -> 489820.53 | ... Q36: =LOOKUP(Q4,Земля!31:31,Земля!33:33) -> 488482.22 | R36: =SUM(H36:Q36) -> 4732125.8
C38: НДС
C39: =C36 -> Туристический комплекс "Лунная поляна" - Архыз | H39: =H74 -> 47962420 | I39: =I74 -> 3.7692698e+08 | J39: =J74 -> 6.0391288e+08 | K39: =K74 -> 5.8384711e+08 | L39: =L74 -> 3.2750441e+08 | M39: =M74 -> 3.5276608e+08 | N39: =N74 -> 3.6543027e+08 | O39: =O74 -> 3.8134855e+08 | ... Q39: =Q74 -> 4.1177221e+08 | R39: =SUM(H39:Q39) -> 3.8471902e+09
C41: СВОД
F42: =F4 -> 2023 | G42: =G4 -> 2024 | H42: =H4 -> 2025 | I42: =I4 -> 2026 | J42: =J4 -> 2027 | K42: =K4 -> 2028 | L42: =L4 -> 2029 | M42: =M4 -> 2030 | ... Q42: =Q4 -> 2034 | S42: 2023-2024 гг. | T42: за 10 лет
C43: Федеральные налоги и сборы | F43: =F44+F45+F46+F47 -> 0 | G43: =G44+G45+G46+G47 -> 0 | H43: =H44+H45+H46+H47 -> 88355228 | I43: =I44+I45+I46+I47 -> 5.1118628e+08 | J43: =J44+J45+J46+J47 -> 8.0713071e+08 | K43: =K44+K45+K46+K47 -> 7.9309615e+08 | L43: =L44+L45+L46+L47 -> 5.3128023e+08 | M43: =M44+M45+M46+M47 -> 5.6805863e+08 | ... Q43: =Q44+Q45+Q46+Q47 -> 6.6715614e+08 | S43: =SUM(F43:G43) -> 0 | T43: =SUM(H43:Q43) -> 5.8130224e+09
C44: =C28 -> Налог на прибыль | F44: =F30 -> 0 | G44: =G30 -> 0 | H44: =H30 -> 0 | I44: =I30 -> 6673201.3 | J44: =J30 -> 25372382 | K44: =K30 -> 24650935 | L44: =L30 -> 10009457 | M44: =M30 -> 12241165 | ... Q44: =Q30 -> 17842535 | S44: =SUM(F44:G44) -> 0 | T44: =SUM(H44:Q44) -> 1.4124105e+08
C45: НДС | F45: =F39 -> 0 | G45: =G39 -> 0 | H45: =H39 -> 47962420 | I45: =I39 -> 3.7692698e+08 | J45: =J39 -> 6.0391288e+08 | K45: =K39 -> 5.8384711e+08 | L45: =L39 -> 3.2750441e+08 | M45: =M39 -> 3.5276608e+08 | ... Q45: =Q39 -> 4.1177221e+08 | S45: =SUM(F45:G45) -> 0 | T45: =SUM(H45:Q45) -> 3.8471902e+09
C46: =C22 -> НДФЛ | F46: =F23 -> 0 | G46: =G23 -> 0 | H46: =H23 -> 12211779 | I46: =I23 -> 38572541 | J46: =J23 -> 53767230 | K46: =K23 -> 55808732 | L46: =L23 -> 58580527 | M46: =M23 -> 61387628 | ... Q46: =Q23 -> 71814842 | S46: =SUM(F46:G46) -> 0 | T46: =SUM(H46:Q46) -> 5.516206e+08
