Workbook

Sheet Дашборд
A1: DEVELOPAID · ИНВЕСТИЦИОННЫЙ ДАШБОРД · ОФИС
A2: ='Вводные'!$B$6&" · класс "&'Вводные'!$B$7
A4: NPV · продажа, млн ₽ | E4: NPV · аренда, млн ₽ | I4: Доходность на затраты
A5: ='CF_Продажа'!$B$37 | E5: ='CF_Аренда'!$B$43 | I5: ='Выход'!$B$10
A8: Ставка капитализации | E8: Пик своих денег · продажа | I8: Пик своих денег · аренда
A9: ='Выход'!$B$5 | E9: ='CF_Продажа'!$B$41 | I9: ='CF_Аренда'!$B$47
A12: =IF(AND('ОТЧЕТ'!B12<0,'ОТЧЕТ'!C12<0),"Проект не окупается ни продажей, ни арендой. ","")&IF('ОТЧЕТ'!B12>'ОТЧЕТ'!C12,"Продажа выгоднее аренды.","Аренда выгоднее продажи.")&IF('Выход'!$B$11<0," Доходность на затраты ниже ставки капитализации: готовое здание стоит дешевле его стройки.","")

Sheet ОТЧЕТ
A1: DEVELOPAID · ОТЧЁТ · ДВА ПУТИ
A2: Все числа — ссылки на листы модели. млн ₽ с НДС.
A4: Показатель | B4: Продажа блоками | C4: Аренда и продажа здания
A5: Выручка | B5: ='CF_Продажа'!$B$7 | C5: ='CF_Аренда'!$B$7
A6: Все затраты на создание, с участком | B6: ='CAPEX'!$B$9 | C6: ='CAPEX'!$B$9
A7: Расходы на продажу или эксплуатацию | B7: ='CF_Продажа'!$B$8 | C7: ='CF_Аренда'!$B$8
A8: Проценты уплаченные и капитализированные | B8: ='CF_Продажа'!$B$18 | C8: ='CF_Аренда'!$B$18
A9: Комиссии банка | B9: ='CF_Продажа'!$B$29 | C9: ='CF_Аренда'!$B$35
A10: Налог на прибыль | B10: ='CF_Продажа'!$B$32 | C10: ='CF_Аренда'!$B$38
A11: Чистая прибыль | B11: ='CF_Продажа'!$B$42 | C11: ='CF_Аренда'!$B$48
A12: NPV проекта | B12: ='CF_Продажа'!$B$37 | C12: ='CF_Аренда'!$B$43
A13: IRR проекта (до кредита) | B13: ='CF_Продажа'!$B$38 | C13: ='CF_Аренда'!$B$44
A14: NPV собственника | B14: ='CF_Продажа'!$B$40 | C14: ='CF_Аренда'!$B$46
A15: Пик собственных денег | B15: ='CF_Продажа'!$B$41 | C15: ='CF_Аренда'!$B$47
A16: NOI года после заполнения | B16: не применяется | C16: ='Выход'!$B$9
A17: Доходность на затраты | B17: не применяется | C17: ='Выход'!$B$10
A18: Ставка капитализации | B18: не применяется | C18: ='Выход'!$B$5
A19: Стоимость здания при продаже | B19: не применяется | C19: ='Выход'!$B$6
A20: Пик долга | B20: =MAX('CF_Продажа'!D24:DM24) | C20: =MAX('CF_Аренда'!D30:DM30)
A23: По годам: поток собственника
A24: Год | B24: Продажа блоками | C24: Аренда и продажа здания
A25: 2027 | B25: =SUMPRODUCT(('СРОКИ'!$D$3:$DM$3>=DATE(2027,1,1))*('СРОКИ'!$D$3:$DM$3<DATE(2028,1,1))*'CF_Продажа'!$D$33:$DM$33) | C25: =SUMPRODUCT(('СРОКИ'!$D$3:$DM$3>=DATE(2027,1,1))*('СРОКИ'!$D$3:$DM$3<DATE(2028,1,1))*'CF_Аренда'!$D$39:$DM$39)
A26: 2028 | B26: =SUMPRODUCT(('СРОКИ'!$D$3:$DM$3>=DATE(2028,1,1))*('СРОКИ'!$D$3:$DM$3<DATE(2029,1,1))*'CF_Продажа'!$D$33:$DM$33) | C26: =SUMPRODUCT(('СРОКИ'!$D$3:$DM$3>=DATE(2028,1,1))*('СРОКИ'!$D$3:$DM$3<DATE(2029,1,1))*'CF_Аренда'!$D$39:$DM$39)
A27: 2029 | B27: =SUMPRODUCT(('СРОКИ'!$D$3:$DM$3>=DATE(2029,1,1))*('СРОКИ'!$D$3:$DM$3<DATE(2030,1,1))*'CF_Продажа'!$D$33:$DM$33) | C27: =SUMPRODUCT(('СРОКИ'!$D$3:$DM$3>=DATE(2029,1,1))*('СРОКИ'!$D$3:$DM$3<DATE(2030,1,1))*'CF_Аренда'!$D$39:$DM$39)
A28: 2030 | B28: =SUMPRODUCT(('СРОКИ'!$D$3:$DM$3>=DATE(2030,1,1))*('СРОКИ'!$D$3:$DM$3<DATE(2031,1,1))*'CF_Продажа'!$D$33:$DM$33) | C28: =SUMPRODUCT(('СРОКИ'!$D$3:$DM$3>=DATE(2030,1,1))*('СРОКИ'!$D$3:$DM$3<DATE(2031,1,1))*'CF_Аренда'!$D$39:$DM$39)
A29: 2031 | B29: =SUMPRODUCT(('СРОКИ'!$D$3:$DM$3>=DATE(2031,1,1))*('СРОКИ'!$D$3:$DM$3<DATE(2032,1,1))*'CF_Продажа'!$D$33:$DM$33) | C29: =SUMPRODUCT(('СРОКИ'!$D$3:$DM$3>=DATE(2031,1,1))*('СРОКИ'!$D$3:$DM$3<DATE(2032,1,1))*'CF_Аренда'!$D$39:$DM$39)
A30: 2032 | B30: =SUMPRODUCT(('СРОКИ'!$D$3:$DM$3>=DATE(2032,1,1))*('СРОКИ'!$D$3:$DM$3<DATE(2033,1,1))*'CF_Продажа'!$D$33:$DM$33) | C30: =SUMPRODUCT(('СРОКИ'!$D$3:$DM$3>=DATE(2032,1,1))*('СРОКИ'!$D$3:$DM$3<DATE(2033,1,1))*'CF_Аренда'!$D$39:$DM$39)
A31: 2033 | B31: =SUMPRODUCT(('СРОКИ'!$D$3:$DM$3>=DATE(2033,1,1))*('СРОКИ'!$D$3:$DM$3<DATE(2034,1,1))*'CF_Продажа'!$D$33:$DM$33) | C31: =SUMPRODUCT(('СРОКИ'!$D$3:$DM$3>=DATE(2033,1,1))*('СРОКИ'!$D$3:$DM$3<DATE(2034,1,1))*'CF_Аренда'!$D$39:$DM$39)
A32: 2034 | B32: =SUMPRODUCT(('СРОКИ'!$D$3:$DM$3>=DATE(2034,1,1))*('СРОКИ'!$D$3:$DM$3<DATE(2035,1,1))*'CF_Продажа'!$D$33:$DM$33) | C32: =SUMPRODUCT(('СРОКИ'!$D$3:$DM$3>=DATE(2034,1,1))*('СРОКИ'!$D$3:$DM$3<DATE(2035,1,1))*'CF_Аренда'!$D$39:$DM$39)
A33: 2035 | B33: =SUMPRODUCT(('СРОКИ'!$D$3:$DM$3>=DATE(2035,1,1))*('СРОКИ'!$D$3:$DM$3<DATE(2036,1,1))*'CF_Продажа'!$D$33:$DM$33) | C33: =SUMPRODUCT(('СРОКИ'!$D$3:$DM$3>=DATE(2035,1,1))*('СРОКИ'!$D$3:$DM$3<DATE(2036,1,1))*'CF_Аренда'!$D$39:$DM$39)
A34: 2036 | B34: =SUMPRODUCT(('СРОКИ'!$D$3:$DM$3>=DATE(2036,1,1))*('СРОКИ'!$D$3:$DM$3<DATE(2037,1,1))*'CF_Продажа'!$D$33:$DM$33) | C34: =SUMPRODUCT(('СРОКИ'!$D$3:$DM$3>=DATE(2036,1,1))*('СРОКИ'!$D$3:$DM$3<DATE(2037,1,1))*'CF_Аренда'!$D$39:$DM$39)

Sheet Вводные
A1: DEVELOPAID · ВВОДНЫЕ ОФИСНОГО ПРОЕКТА
A2: Печатают только здесь: жёлтые клетки. Класс офиса задаёт допущения аренды и продажи; число в колонке «Вручную» сильнее класса.
A5: Проект
A6: Проект | B6: Москва, Пролетарский проспект, вл. 20
A7: Класс офиса | B7: B+ и A− | D7: B и ниже · B+ и A− · A и выше
A8: Начало проекта | B8: 46388
A9: Документы до разрешения на стройку | B9: 18 | C9: мес.
A10: Стройка | B10: 24 | C10: мес.
A11: НДС | B11: 0.22
A12: Ставка дисконтирования | B12: 0.2 | C12: в год
A14: Площади (лист ТЭП)
A15: Наземная площадь здания | B15: 22842 | C15: м²
A16: Общая площадь | B16: 21472 | C16: м²
A17: Арендопригодная = продаваемая | B17: 15030 | C17: м²
A18: Подземный паркинг, мест | B18: 68 | C18: шт.
A19: Гостевые места (не продаются и не сдаются) | B19: 0.1
A20: Машино-места в продаже или аренде | B20: ='Вводные'!$B$18-ROUNDUP('Вводные'!$B$18*'Вводные'!$B$19,0) | C20: шт.
A22: Сделка
A23: Цена участка | B23: 5 | C23: млн ₽
A24: Выкуп участков и зданий у третьих лиц | B24: 675 | C24: млн ₽
A25: Цена входа | B25: ='Вводные'!$B$23+'Вводные'!$B$24 | C25: млн ₽
A27: Шкала класса офиса (стартовые допущения, Москва, с НДС)
A28: Допущение | B28: B и ниже | C28: B+ и A− | D28: A и выше | E28: Вручную | F28: В расчёт | G28: Ед.
A29: Стоимость стройки здания | B29: 175 | C29: 200 | D29: 225 | E29: 110 | F29: =IF(E29<>"",E29,INDEX(B29:D29,1,MATCH($B$7,$B$28:$D$28,0))) | G29: тыс. ₽/м² наземной
A30: Стартовая цена продажи | B30: 230 | C30: 300 | D30: 420 | E30: 273 | F30: =IF(E30<>"",E30,INDEX(B30:D30,1,MATCH($B$7,$B$28:$D$28,0))) | G30: тыс. ₽/м²
A31: Ставка аренды | B31: 24 | C31: 30 | D31: 42 | F31: =IF(E31<>"",E31,INDEX(B31:D31,1,MATCH($B$7,$B$28:$D$28,0))) | G31: тыс. ₽/м² в год
A32: Заполняемость после заполнения | B32: 0.9 | C32: 0.92 | D32: 0.94 | F32: =IF(E32<>"",E32,INDEX(B32:D32,1,MATCH($B$7,$B$28:$D$28,0)))
A33: Срок заполнения | B33: 18 | C33: 15 | D33: 12 | E33: 18 | F33: =IF(E33<>"",E33,INDEX(B33:D33,1,MATCH($B$7,$B$28:$D$28,0))) | G33: мес.
A34: Расходы эксплуатации, доля дохода | B34: 0.2 | C34: 0.18 | D34: 0.16 | F34: =IF(E34<>"",E34,INDEX(B34:D34,1,MATCH($B$7,$B$28:$D$28,0)))
A35: Ставка капитализации при продаже здания | B35: 0.115 | C35: 0.105 | D35: 0.095 | F35: =IF(E35<>"",E35,INDEX(B35:D35,1,MATCH($B$7,$B$28:$D$28,0)))
A37: Клетка «Вручную» заполнена — класс для этой строки не действует. В образце стоимость стройки и цена продажи заданы вручную по присланному отчёту.
A39: Путь 1. Продажа блоками
A40: Рост цены до ввода | B40: 0.015 | C40: в месяц
A41: Рост цены после ввода | B41: 0.0025 | C41: в месяц
A42: Срок продаж после ввода | B42: 12 | C42: мес.
A43: Маркетинг и брокеры | B43: 0.07 | C43: доля выручки
A44: Цена машино-места | B44: 1.5 | C44: млн ₽
A46: Путь 2. Аренда и продажа здания
A47: Заполняемость на открытии | B47: 0.55
A48: Индексация аренды | B48: 0.05 | C48: в год
...

Sheet ИНСТРУКЦИЯ
A1: ИНСТРУКЦИЯ
A2: Как устроена книга.
A4: Дашборд | B4: Главные числа обоих путей и вывод.
A5: ОТЧЕТ | B5: Два пути рядом и поток собственника по годам. Только ссылки.
A6: Вводные | B6: Единственное место правки: жёлтые клетки. Класс офиса задаёт шкалу; «Вручную» сильнее класса.
A7: СРОКИ | B7: Номер месяца, разрешение, ввод, окна продаж и аренды.
A8: CAPEX | B8: График затрат на создание.
A9: Ставки | B9: Ключевая ставка и ставка кредита по месяцам.
A10: Продажа | B10: Путь 1: цена, продажи, маркетинг, налог на имущество.
A11: Аренда | B11: Путь 2: заполнение, индексация, доход, эксплуатация, NOI, продажа здания.
A12: Выход | B12: Стоимость здания по ставке капитализации, доходность на затраты.
A13: CF_Продажа, CF_Аренда | B13: НДС, кредит двумя линиями, комиссии, поток собственника и проекта, NPV и IRR.
A14: ПРОВЕРКИ | B14: Каждый итог книги против расчёта движка.

Sheet СРОКИ
A1: СРОКИ · КАЛЕНДАРЬ ПРОЕКТА
A2: Номер месяца, этапы и окна продаж и аренды.
A3: Показатель | B3: Итого / вводная | C3: Ед. | D3: =DATE(2027,1,1) | E3: =EDATE(D3,1) | F3: =EDATE(E3,1) | G3: =EDATE(F3,1) | H3: =EDATE(G3,1) | I3: =EDATE(H3,1) | J3: =EDATE(I3,1) | K3: =EDATE(J3,1) | L3: =EDATE(K3,1) | ... DM3: =EDATE(DL3,1)
A4: Период | C4: № | D4: 0 | E4: 1 | F4: 2 | G4: 3 | H4: 4 | I4: 5 | J4: 6 | K4: 7 | L4: 8 | M4: 9 | N4: 10 | O4: 11 | P4: 12 | Q4: 13 | R4: 14 | S4: 15 | T4: 16 | U4: 17 | V4: 18 | W4: 19 | X4: 20 | Y4: 21 | Z4: 22 | AA4: 23 | AB4: 24 | AC4: 25 | AD4: 26 | AE4: 27 | AF4: 28 | AG4: 29 | AH4: 30 | AI4: 31 | AJ4: 32 | AK4: 33 | AL4: 34 | AM4: 35 | AN4: 36 | AO4: 37 | AP4: 38 | AQ4: 39 | AR4: 40 | AS4: 41 | AT4: 42 | AU4: 43 | AV4: 44 | AW4: 45 | AX4: 46 | AY4: 47 | AZ4: 48 | BA4: 49 | BB4: 50 | BC4: 51 | BD4: 52 | BE4: 53 | BF4: 54 | BG4: 55 | BH4: 56 | BI4: 57 | BJ4: 58 | BK4: 59 | BL4: 60 | BM4: 61 | BN4: 62 | BO4: 63 | BP4: 64 | BQ4: 65 | BR4: 66 | BS4: 67 | BT4: 68 | BU4: 69 | BV4: 70 | BW4: 71 | BX4: 72 | BY4: 73 | BZ4: 74 | CA4: 75 | CB4: 76 | CC4: 77 | CD4: 78 | CE4: 79 | CF4: 80 | CG4: 81 | CH4: 82 | CI4: 83 | CJ4: 84 | CK4: 85 | CL4: 86 | CM4: 87 | CN4: 88 | CO4: 89 | CP4: 90 | CQ4: 91 | CR4: 92 | CS4: 93 | CT4: 94 | CU4: 95 | CV4: 96 | CW4: 97 | CX4: 98 | CY4: 99 | CZ4: 100 | DA4: 101 | DB4: 102 | DC4: 103 | DD4: 104 | DE4: 105 | DF4: 106 | DG4: 107 | DH4: 108 | DI4: 109 | DJ4: 110 | DK4: 111 | DL4: 112 | DM4: 113
A5: Разрешение на стройку, № месяца | B5: ='Вводные'!$B$9 | C5: №
A6: Ввод, № месяца | B6: ='Вводные'!$B$9+'Вводные'!$B$10 | C6: №
A7: Последний месяц продаж (путь 1) | B7: ='СРОКИ'!$B$6+'Вводные'!$B$42-1 | C7: №
A8: Месяцев удержания (путь 2) | B8: ='Вводные'!$B$50*12 | C8: мес.
A9: Продажа здания, № месяца (путь 2) | B9: ='СРОКИ'!$B$6+'СРОКИ'!$B$8-1 | C9: №
A10: № месяца | C10: № | D10: =0 | E10: ='СРОКИ'!D10+1 | F10: ='СРОКИ'!E10+1 | G10: ='СРОКИ'!F10+1 | H10: ='СРОКИ'!G10+1 | I10: ='СРОКИ'!H10+1 | J10: ='СРОКИ'!I10+1 | K10: ='СРОКИ'!J10+1 | L10: ='СРОКИ'!K10+1 | ... DM10: ='СРОКИ'!DL10+1
A11: Идёт стройка | C11: 0/1 | D11: =IF(AND('СРОКИ'!D10>='СРОКИ'!$B$5,'СРОКИ'!D10<'СРОКИ'!$B$6),1,0) | E11: =IF(AND('СРОКИ'!E10>='СРОКИ'!$B$5,'СРОКИ'!E10<'СРОКИ'!$B$6),1,0) | F11: =IF(AND('СРОКИ'!F10>='СРОКИ'!$B$5,'СРОКИ'!F10<'СРОКИ'!$B$6),1,0) | G11: =IF(AND('СРОКИ'!G10>='СРОКИ'!$B$5,'СРОКИ'!G10<'СРОКИ'!$B$6),1,0) | H11: =IF(AND('СРОКИ'!H10>='СРОКИ'!$B$5,'СРОКИ'!H10<'СРОКИ'!$B$6),1,0) | I11: =IF(AND('СРОКИ'!I10>='СРОКИ'!$B$5,'СРОКИ'!I10<'СРОКИ'!$B$6),1,0) | J11: =IF(AND('СРОКИ'!J10>='СРОКИ'!$B$5,'СРОКИ'!J10<'СРОКИ'!$B$6),1,0) | K11: =IF(AND('СРОКИ'!K10>='СРОКИ'!$B$5,'СРОКИ'!K10<'СРОКИ'!$B$6),1,0) | ... DM11: =IF(AND('СРОКИ'!DM10>='СРОКИ'!$B$5,'СРОКИ'!DM10<'СРОКИ'!$B$6),1,0)
A12: Месяц ввода | C12: 0/1 | D12: =IF('СРОКИ'!D10='СРОКИ'!$B$6,1,0) | E12: =IF('СРОКИ'!E10='СРОКИ'!$B$6,1,0) | F12: =IF('СРОКИ'!F10='СРОКИ'!$B$6,1,0) | G12: =IF('СРОКИ'!G10='СРОКИ'!$B$6,1,0) | H12: =IF('СРОКИ'!H10='СРОКИ'!$B$6,1,0) | I12: =IF('СРОКИ'!I10='СРОКИ'!$B$6,1,0) | J12: =IF('СРОКИ'!J10='СРОКИ'!$B$6,1,0) | K12: =IF('СРОКИ'!K10='СРОКИ'!$B$6,1,0) | ... DM12: =IF('СРОКИ'!DM10='СРОКИ'!$B$6,1,0)
A13: Окно продаж (путь 1) | C13: 0/1 | D13: =IF(AND('СРОКИ'!D10>='СРОКИ'!$B$6,'СРОКИ'!D10<='СРОКИ'!$B$7),1,0) | E13: =IF(AND('СРОКИ'!E10>='СРОКИ'!$B$6,'СРОКИ'!E10<='СРОКИ'!$B$7),1,0) | F13: =IF(AND('СРОКИ'!F10>='СРОКИ'!$B$6,'СРОКИ'!F10<='СРОКИ'!$B$7),1,0) | G13: =IF(AND('СРОКИ'!G10>='СРОКИ'!$B$6,'СРОКИ'!G10<='СРОКИ'!$B$7),1,0) | H13: =IF(AND('СРОКИ'!H10>='СРОКИ'!$B$6,'СРОКИ'!H10<='СРОКИ'!$B$7),1,0) | I13: =IF(AND('СРОКИ'!I10>='СРОКИ'!$B$6,'СРОКИ'!I10<='СРОКИ'!$B$7),1,0) | J13: =IF(AND('СРОКИ'!J10>='СРОКИ'!$B$6,'СРОКИ'!J10<='СРОКИ'!$B$7),1,0) | K13: =IF(AND('СРОКИ'!K10>='СРОКИ'!$B$6,'СРОКИ'!K10<='СРОКИ'!$B$7),1,0) | ... DM13: =IF(AND('СРОКИ'!DM10>='СРОКИ'!$B$6,'СРОКИ'!DM10<='СРОКИ'!$B$7),1,0)
A14: Месяц эксплуатации (путь 2) | C14: № | D14: =IF('СРОКИ'!D10>='СРОКИ'!$B$6,'СРОКИ'!D10-'СРОКИ'!$B$6+1,0) | E14: =IF('СРОКИ'!E10>='СРОКИ'!$B$6,'СРОКИ'!E10-'СРОКИ'!$B$6+1,0) | F14: =IF('СРОКИ'!F10>='СРОКИ'!$B$6,'СРОКИ'!F10-'СРОКИ'!$B$6+1,0) | G14: =IF('СРОКИ'!G10>='СРОКИ'!$B$6,'СРОКИ'!G10-'СРОКИ'!$B$6+1,0) | H14: =IF('СРОКИ'!H10>='СРОКИ'!$B$6,'СРОКИ'!H10-'СРОКИ'!$B$6+1,0) | I14: =IF('СРОКИ'!I10>='СРОКИ'!$B$6,'СРОКИ'!I10-'СРОКИ'!$B$6+1,0) | J14: =IF('СРОКИ'!J10>='СРОКИ'!$B$6,'СРОКИ'!J10-'СРОКИ'!$B$6+1,0) | K14: =IF('СРОКИ'!K10>='СРОКИ'!$B$6,'СРОКИ'!K10-'СРОКИ'!$B$6+1,0) | ... DM14: =IF('СРОКИ'!DM10>='СРОКИ'!$B$6,'СРОКИ'!DM10-'СРОКИ'!$B$6+1,0)
A15: Удержание (путь 2) | C15: 0/1 | D15: =IF(AND('СРОКИ'!D14>=1,'СРОКИ'!D14<='СРОКИ'!$B$8),1,0) | E15: =IF(AND('СРОКИ'!E14>=1,'СРОКИ'!E14<='СРОКИ'!$B$8),1,0) | F15: =IF(AND('СРОКИ'!F14>=1,'СРОКИ'!F14<='СРОКИ'!$B$8),1,0) | G15: =IF(AND('СРОКИ'!G14>=1,'СРОКИ'!G14<='СРОКИ'!$B$8),1,0) | H15: =IF(AND('СРОКИ'!H14>=1,'СРОКИ'!H14<='СРОКИ'!$B$8),1,0) | I15: =IF(AND('СРОКИ'!I14>=1,'СРОКИ'!I14<='СРОКИ'!$B$8),1,0) | J15: =IF(AND('СРОКИ'!J14>=1,'СРОКИ'!J14<='СРОКИ'!$B$8),1,0) | K15: =IF(AND('СРОКИ'!K14>=1,'СРОКИ'!K14<='СРОКИ'!$B$8),1,0) | ... DM15: =IF(AND('СРОКИ'!DM14>=1,'СРОКИ'!DM14<='СРОКИ'!$B$8),1,0)
A16: Год покупателя после продажи здания | C16: 0/1 | D16: =IF(AND('СРОКИ'!D14>'СРОКИ'!$B$8,'СРОКИ'!D14<='СРОКИ'!$B$8+12),1,0) | E16: =IF(AND('СРОКИ'!E14>'СРОКИ'!$B$8,'СРОКИ'!E14<='СРОКИ'!$B$8+12),1,0) | F16: =IF(AND('СРОКИ'!F14>'СРОКИ'!$B$8,'СРОКИ'!F14<='СРОКИ'!$B$8+12),1,0) | G16: =IF(AND('СРОКИ'!G14>'СРОКИ'!$B$8,'СРОКИ'!G14<='СРОКИ'!$B$8+12),1,0) | H16: =IF(AND('СРОКИ'!H14>'СРОКИ'!$B$8,'СРОКИ'!H14<='СРОКИ'!$B$8+12),1,0) | I16: =IF(AND('СРОКИ'!I14>'СРОКИ'!$B$8,'СРОКИ'!I14<='СРОКИ'!$B$8+12),1,0) | J16: =IF(AND('СРОКИ'!J14>'СРОКИ'!$B$8,'СРОКИ'!J14<='СРОКИ'!$B$8+12),1,0) | K16: =IF(AND('СРОКИ'!K14>'СРОКИ'!$B$8,'СРОКИ'!K14<='СРОКИ'!$B$8+12),1,0) | ... DM16: =IF(AND('СРОКИ'!DM14>'СРОКИ'!$B$8,'СРОКИ'!DM14<='СРОКИ'!$B$8+12),1,0)

Sheet CAPEX
A1: CAPEX · ЗАТРАТЫ НА СОЗДАНИЕ
A2: Курсив — график затрат движка. В рабочей книге — статьи сметы формулами, как лист CAPEX жилой v4.
A3: Показатель | B3: Итого / вводная | C3: Ед. | D3: =СРОКИ!D3 | E3: =СРОКИ!E3 | F3: =СРОКИ!F3 | G3: =СРОКИ!G3 | H3: =СРОКИ!H3 | I3: =СРОКИ!I3 | J3: =СРОКИ!J3 | K3: =СРОКИ!K3 | ... DM3: =СРОКИ!DM3
A4: Период | C4: № | D4: 0 | E4: 1 | F4: 2 | G4: 3 | H4: 4 | I4: 5 | J4: 6 | K4: 7 | L4: 8 | M4: 9 | N4: 10 | O4: 11 | P4: 12 | Q4: 13 | R4: 14 | S4: 15 | T4: 16 | U4: 17 | V4: 18 | W4: 19 | X4: 20 | Y4: 21 | Z4: 22 | AA4: 23 | AB4: 24 | AC4: 25 | AD4: 26 | AE4: 27 | AF4: 28 | AG4: 29 | AH4: 30 | AI4: 31 | AJ4: 32 | AK4: 33 | AL4: 34 | AM4: 35 | AN4: 36 | AO4: 37 | AP4: 38 | AQ4: 39 | AR4: 40 | AS4: 41 | AT4: 42 | AU4: 43 | AV4: 44 | AW4: 45 | AX4: 46 | AY4: 47 | AZ4: 48 | BA4: 49 | BB4: 50 | BC4: 51 | BD4: 52 | BE4: 53 | BF4: 54 | BG4: 55 | BH4: 56 | BI4: 57 | BJ4: 58 | BK4: 59 | BL4: 60 | BM4: 61 | BN4: 62 | BO4: 63 | BP4: 64 | BQ4: 65 | BR4: 66 | BS4: 67 | BT4: 68 | BU4: 69 | BV4: 70 | BW4: 71 | BX4: 72 | BY4: 73 | BZ4: 74 | CA4: 75 | CB4: 76 | CC4: 77 | CD4: 78 | CE4: 79 | CF4: 80 | CG4: 81 | CH4: 82 | CI4: 83 | CJ4: 84 | CK4: 85 | CL4: 86 | CM4: 87 | CN4: 88 | CO4: 89 | CP4: 90 | CQ4: 91 | CR4: 92 | CS4: 93 | CT4: 94 | CU4: 95 | CV4: 96 | CW4: 97 | CX4: 98 | CY4: 99 | CZ4: 100 | DA4: 101 | DB4: 102 | DC4: 103 | DD4: 104 | DE4: 105 | DF4: 106 | DG4: 107 | DH4: 108 | DI4: 109 | DJ4: 110 | DK4: 111 | DL4: 112 | DM4: 113
A5: Стройка здания, с НДС | B5: =SUM(D5:DM5) | C5: млн ₽ | D5: 0 | E5: 0 | F5: 0 | G5: 0 | H5: 0 | I5: 0 | J5: 0 | K5: 0 | L5: 0 | M5: 0 | N5: 0 | O5: 0 | P5: 0 | Q5: 0 | R5: 0 | S5: 0 | T5: 0 | U5: 0 | V5: 66.935902 | W5: 66.935902 | X5: 66.935902 | Y5: 66.935902 | Z5: 133.8718 | AA5: 133.8718 | AB5: 133.8718 | AC5: 133.8718 | AD5: 133.8718 | AE5: 133.8718 | AF5: 133.8718 | AG5: 133.8718 | AH5: 133.8718 | AI5: 133.8718 | AJ5: 133.8718 | AK5: 133.8718 | AL5: 133.8718 | AM5: 133.8718 | AN5: 133.8718 | AO5: 89.247869 | AP5: 89.247869 | AQ5: 89.247869 | AR5: 89.247869 | AS5: 89.247869 | AT5: 0 | AU5: 0 | AV5: 0 | AW5: 0 | AX5: 0 | AY5: 0 | AZ5: 0 | BA5: 0 | BB5: 0 | BC5: 0 | BD5: 0 | BE5: 0 | BF5: 0 | BG5: 0 | BH5: 0 | BI5: 0 | BJ5: 0 | BK5: 0 | BL5: 0 | BM5: 0 | BN5: 0 | BO5: 0 | BP5: 0 | BQ5: 0 | BR5: 0 | BS5: 0 | BT5: 0 | BU5: 0 | BV5: 0 | BW5: 0 | BX5: 0 | BY5: 0 | BZ5: 0 | CA5: 0 | CB5: 0 | CC5: 0 | CD5: 0 | CE5: 0 | CF5: 0 | CG5: 0 | CH5: 0 | CI5: 0 | CJ5: 0 | CK5: 0 | CL5: 0 | CM5: 0 | CN5: 0 | CO5: 0 | CP5: 0 | CQ5: 0 | CR5: 0 | CS5: 0 | CT5: 0 | CU5: 0 | CV5: 0 | CW5: 0 | CX5: 0 | CY5: 0 | CZ5: 0 | DA5: 0 | DB5: 0 | DC5: 0 | DD5: 0 | DE5: 0 | DF5: 0 | DG5: 0 | DH5: 0 | DI5: 0 | DJ5: 0 | DK5: 0 | DL5: 0 | DM5: 0
A6: Общие затраты проекта с участком, с НДС | B6: =SUM(D6:DM6) | C6: млн ₽ | D6: 681.69609 | E6: 1.6960872 | F6: 1.6960872 | G6: 1.6960872 | H6: 1.6960872 | I6: 1.6960872 | J6: 1.6960872 | K6: 1.6960872 | L6: 1.6960872 | M6: 1.6960872 | N6: 1.6960872 | O6: 1.6960872 | P6: 89.468599 | Q6: 89.468599 | R6: 89.468599 | S6: 89.468599 | T6: 89.468599 | U6: 89.468599 | V6: 24.624201 | W6: 24.624201 | X6: 24.624201 | Y6: 24.624201 | Z6: 49.248403 | AA6: 49.248403 | AB6: 49.248403 | AC6: 49.248403 | AD6: 49.248403 | AE6: 49.248403 | AF6: 49.248403 | AG6: 49.248403 | AH6: 49.248403 | AI6: 49.248403 | AJ6: 49.248403 | AK6: 49.248403 | AL6: 49.248403 | AM6: 49.248403 | AN6: 49.248403 | AO6: 32.832269 | AP6: 32.832269 | AQ6: 41.239602 | AR6: 41.239602 | AS6: 41.239602 | AT6: 0 | AU6: 0 | AV6: 0 | AW6: 0 | AX6: 0 | AY6: 0 | AZ6: 0 | BA6: 0 | BB6: 0 | BC6: 0 | BD6: 0 | BE6: 0 | BF6: 0 | BG6: 0 | BH6: 0 | BI6: 0 | BJ6: 0 | BK6: 0 | BL6: 0 | BM6: 0 | BN6: 0 | BO6: 0 | BP6: 0 | BQ6: 0 | BR6: 0 | BS6: 0 | BT6: 0 | BU6: 0 | BV6: 0 | BW6: 0 | BX6: 0 | BY6: 0 | BZ6: 0 | CA6: 0 | CB6: 0 | CC6: 0 | CD6: 0 | CE6: 0 | CF6: 0 | CG6: 0 | CH6: 0 | CI6: 0 | CJ6: 0 | CK6: 0 | CL6: 0 | CM6: 0 | CN6: 0 | CO6: 0 | CP6: 0 | CQ6: 0 | CR6: 0 | CS6: 0 | CT6: 0 | CU6: 0 | CV6: 0 | CW6: 0 | CX6: 0 | CY6: 0 | CZ6: 0 | DA6: 0 | DB6: 0 | DC6: 0 | DD6: 0 | DE6: 0 | DF6: 0 | DG6: 0 | DH6: 0 | DI6: 0 | DJ6: 0 | DK6: 0 | DL6: 0 | DM6: 0
A7: Все затраты на создание | B7: =SUM(D7:DM7) | C7: млн ₽ | D7: ='CAPEX'!D5+'CAPEX'!D6 | E7: ='CAPEX'!E5+'CAPEX'!E6 | F7: ='CAPEX'!F5+'CAPEX'!F6 | G7: ='CAPEX'!G5+'CAPEX'!G6 | H7: ='CAPEX'!H5+'CAPEX'!H6 | I7: ='CAPEX'!I5+'CAPEX'!I6 | J7: ='CAPEX'!J5+'CAPEX'!J6 | K7: ='CAPEX'!K5+'CAPEX'!K6 | ... DM7: ='CAPEX'!DM5+'CAPEX'!DM6
A8: Стоимость здания без НДС (база налога на имущество) | B8: ='CAPEX'!B5*(1-'Вводные'!$B$11/(1+'Вводные'!$B$11)) | C8: млн ₽
A9: Все затраты на создание, итого | B9: ='CAPEX'!B7 | C9: млн ₽

Sheet Ставки
A1: СТАВКИ
A2: Ключевая ставка — сценарий движка (значения). Ставка кредита = ключевая + надбавка.
A3: Показатель | B3: Итого / вводная | C3: Ед. | D3: =СРОКИ!D3 | E3: =СРОКИ!E3 | F3: =СРОКИ!F3 | G3: =СРОКИ!G3 | H3: =СРОКИ!H3 | I3: =СРОКИ!I3 | J3: =СРОКИ!J3 | K3: =СРОКИ!K3 | ... DM3: =СРОКИ!DM3
A4: Период | C4: № | D4: 0 | E4: 1 | F4: 2 | G4: 3 | H4: 4 | I4: 5 | J4: 6 | K4: 7 | L4: 8 | M4: 9 | N4: 10 | O4: 11 | P4: 12 | Q4: 13 | R4: 14 | S4: 15 | T4: 16 | U4: 17 | V4: 18 | W4: 19 | X4: 20 | Y4: 21 | Z4: 22 | AA4: 23 | AB4: 24 | AC4: 25 | AD4: 26 | AE4: 27 | AF4: 28 | AG4: 29 | AH4: 30 | AI4: 31 | AJ4: 32 | AK4: 33 | AL4: 34 | AM4: 35 | AN4: 36 | AO4: 37 | AP4: 38 | AQ4: 39 | AR4: 40 | AS4: 41 | AT4: 42 | AU4: 43 | AV4: 44 | AW4: 45 | AX4: 46 | AY4: 47 | AZ4: 48 | BA4: 49 | BB4: 50 | BC4: 51 | BD4: 52 | BE4: 53 | BF4: 54 | BG4: 55 | BH4: 56 | BI4: 57 | BJ4: 58 | BK4: 59 | BL4: 60 | BM4: 61 | BN4: 62 | BO4: 63 | BP4: 64 | BQ4: 65 | BR4: 66 | BS4: 67 | BT4: 68 | BU4: 69 | BV4: 70 | BW4: 71 | BX4: 72 | BY4: 73 | BZ4: 74 | CA4: 75 | CB4: 76 | CC4: 77 | CD4: 78 | CE4: 79 | CF4: 80 | CG4: 81 | CH4: 82 | CI4: 83 | CJ4: 84 | CK4: 85 | CL4: 86 | CM4: 87 | CN4: 88 | CO4: 89 | CP4: 90 | CQ4: 91 | CR4: 92 | CS4: 93 | CT4: 94 | CU4: 95 | CV4: 96 | CW4: 97 | CX4: 98 | CY4: 99 | CZ4: 100 | DA4: 101 | DB4: 102 | DC4: 103 | DD4: 104 | DE4: 105 | DF4: 106 | DG4: 107 | DH4: 108 | DI4: 109 | DJ4: 110 | DK4: 111 | DL4: 112 | DM4: 113
A5: Ключевая ставка | D5: 0.12029529 | E5: 0.11724729 | F5: 0.11444299 | G5: 0.11186292 | H5: 0.10948913 | I5: 0.10730514 | J5: 0.10529578 | K5: 0.10344707 | L5: 0.10174618 | M5: 0.10018128 | N5: 0.09874151 | O5: 0.097416855 | P5: 0.096198113 | Q5: 0.095076816 | R5: 0.094045173 | S5: 0.093096016 | T5: 0.092222749 | U5: 0.091419305 | V5: 0.090680101 | W5: 0.09 | X5: 0.09 | Y5: 0.09 | Z5: 0.09 | AA5: 0.09 | AB5: 0.09 | AC5: 0.09 | AD5: 0.09 | AE5: 0.09 | AF5: 0.09 | AG5: 0.09 | AH5: 0.09 | AI5: 0.09 | AJ5: 0.09 | AK5: 0.09 | AL5: 0.09 | AM5: 0.09 | AN5: 0.09 | AO5: 0.09 | AP5: 0.09 | AQ5: 0.09 | AR5: 0.09 | AS5: 0.09 | AT5: 0.09 | AU5: 0.09 | AV5: 0.09 | AW5: 0.09 | AX5: 0.09 | AY5: 0.09 | AZ5: 0.09 | BA5: 0.09 | BB5: 0.09 | BC5: 0.09 | BD5: 0.09 | BE5: 0.09 | BF5: 0.09 | BG5: 0.09 | BH5: 0.09 | BI5: 0.09 | BJ5: 0.09 | BK5: 0.09 | BL5: 0.09 | BM5: 0.09 | BN5: 0.09 | BO5: 0.09 | BP5: 0.09 | BQ5: 0.09 | BR5: 0.09 | BS5: 0.09 | BT5: 0.09 | BU5: 0.09 | BV5: 0.09 | BW5: 0.09 | BX5: 0.09 | BY5: 0.09 | BZ5: 0.09 | CA5: 0.09 | CB5: 0.09 | CC5: 0.09 | CD5: 0.09 | CE5: 0.09 | CF5: 0.09 | CG5: 0.09 | CH5: 0.09 | CI5: 0.09 | CJ5: 0.09 | CK5: 0.09 | CL5: 0.09 | CM5: 0.09 | CN5: 0.09 | CO5: 0.09 | CP5: 0.09 | CQ5: 0.09 | CR5: 0.09 | CS5: 0.09 | CT5: 0.09 | CU5: 0.09 | CV5: 0.09 | CW5: 0.09 | CX5: 0.09 | CY5: 0.09 | CZ5: 0.09 | DA5: 0.09 | DB5: 0.09 | DC5: 0.09 | DD5: 0.09 | DE5: 0.09 | DF5: 0.09 | DG5: 0.09 | DH5: 0.09 | DI5: 0.09 | DJ5: 0.09 | DK5: 0.09 | DL5: 0.09 | DM5: 0.09
A6: Ставка кредита | D6: ='Ставки'!D5+'Вводные'!$B$56 | E6: ='Ставки'!E5+'Вводные'!$B$56 | F6: ='Ставки'!F5+'Вводные'!$B$56 | G6: ='Ставки'!G5+'Вводные'!$B$56 | H6: ='Ставки'!H5+'Вводные'!$B$56 | I6: ='Ставки'!I5+'Вводные'!$B$56 | J6: ='Ставки'!J5+'Вводные'!$B$56 | K6: ='Ставки'!K5+'Вводные'!$B$56 | ... DM6: ='Ставки'!DM5+'Вводные'!$B$56

Sheet Продажа
A1: ПУТЬ 1 · ПРОДАЖА БЛОКАМИ
A2: Договоры купли-продажи после ввода, без ДДУ и эскроу. млн ₽ с НДС.
A3: Показатель | B3: Итого / вводная | C3: Ед. | D3: =СРОКИ!D3 | E3: =СРОКИ!E3 | F3: =СРОКИ!F3 | G3: =СРОКИ!G3 | H3: =СРОКИ!H3 | I3: =СРОКИ!I3 | J3: =СРОКИ!J3 | K3: =СРОКИ!K3 | ... DM3: =СРОКИ!DM3
A4: Период | C4: № | D4: 0 | E4: 1 | F4: 2 | G4: 3 | H4: 4 | I4: 5 | J4: 6 | K4: 7 | L4: 8 | M4: 9 | N4: 10 | O4: 11 | P4: 12 | Q4: 13 | R4: 14 | S4: 15 | T4: 16 | U4: 17 | V4: 18 | W4: 19 | X4: 20 | Y4: 21 | Z4: 22 | AA4: 23 | AB4: 24 | AC4: 25 | AD4: 26 | AE4: 27 | AF4: 28 | AG4: 29 | AH4: 30 | AI4: 31 | AJ4: 32 | AK4: 33 | AL4: 34 | AM4: 35 | AN4: 36 | AO4: 37 | AP4: 38 | AQ4: 39 | AR4: 40 | AS4: 41 | AT4: 42 | AU4: 43 | AV4: 44 | AW4: 45 | AX4: 46 | AY4: 47 | AZ4: 48 | BA4: 49 | BB4: 50 | BC4: 51 | BD4: 52 | BE4: 53 | BF4: 54 | BG4: 55 | BH4: 56 | BI4: 57 | BJ4: 58 | BK4: 59 | BL4: 60 | BM4: 61 | BN4: 62 | BO4: 63 | BP4: 64 | BQ4: 65 | BR4: 66 | BS4: 67 | BT4: 68 | BU4: 69 | BV4: 70 | BW4: 71 | BX4: 72 | BY4: 73 | BZ4: 74 | CA4: 75 | CB4: 76 | CC4: 77 | CD4: 78 | CE4: 79 | CF4: 80 | CG4: 81 | CH4: 82 | CI4: 83 | CJ4: 84 | CK4: 85 | CL4: 86 | CM4: 87 | CN4: 88 | CO4: 89 | CP4: 90 | CQ4: 91 | CR4: 92 | CS4: 93 | CT4: 94 | CU4: 95 | CV4: 96 | CW4: 97 | CX4: 98 | CY4: 99 | CZ4: 100 | DA4: 101 | DB4: 102 | DC4: 103 | DD4: 104 | DE4: 105 | DF4: 106 | DG4: 107 | DH4: 108 | DI4: 109 | DJ4: 110 | DK4: 111 | DL4: 112 | DM4: 113
A5: Отсчёт цены, № месяца (старт продаж ДДУ по вводным) | B5: 18 | C5: №
A6: Индекс цены | C6: × | D6: =(1+'Вводные'!$B$40)^MAX(0,MIN('СРОКИ'!D10-'Продажа'!$B$5,'СРОКИ'!$B$6-'Продажа'!$B$5))*(1+'Вводные'!$B$41)^MAX(0,'СРОКИ'!D10-MAX('Продажа'!$B$5,'СРОКИ'!$B$6)) | E6: =(1+'Вводные'!$B$40)^MAX(0,MIN('СРОКИ'!E10-'Продажа'!$B$5,'СРОКИ'!$B$6-'Продажа'!$B$5))*(1+'Вводные'!$B$41)^MAX(0,'СРОКИ'!E10-MAX('Продажа'!$B$5,'СРОКИ'!$B$6)) | F6: =(1+'Вводные'!$B$40)^MAX(0,MIN('СРОКИ'!F10-'Продажа'!$B$5,'СРОКИ'!$B$6-'Продажа'!$B$5))*(1+'Вводные'!$B$41)^MAX(0,'СРОКИ'!F10-MAX('Продажа'!$B$5,'СРОКИ'!$B$6)) | G6: =(1+'Вводные'!$B$40)^MAX(0,MIN('СРОКИ'!G10-'Продажа'!$B$5,'СРОКИ'!$B$6-'Продажа'!$B$5))*(1+'Вводные'!$B$41)^MAX(0,'СРОКИ'!G10-MAX('Продажа'!$B$5,'СРОКИ'!$B$6)) | H6: =(1+'Вводные'!$B$40)^MAX(0,MIN('СРОКИ'!H10-'Продажа'!$B$5,'СРОКИ'!$B$6-'Продажа'!$B$5))*(1+'Вводные'!$B$41)^MAX(0,'СРОКИ'!H10-MAX('Продажа'!$B$5,'СРОКИ'!$B$6)) | I6: =(1+'Вводные'!$B$40)^MAX(0,MIN('СРОКИ'!I10-'Продажа'!$B$5,'СРОКИ'!$B$6-'Продажа'!$B$5))*(1+'Вводные'!$B$41)^MAX(0,'СРОКИ'!I10-MAX('Продажа'!$B$5,'СРОКИ'!$B$6)) | J6: =(1+'Вводные'!$B$40)^MAX(0,MIN('СРОКИ'!J10-'Продажа'!$B$5,'СРОКИ'!$B$6-'Продажа'!$B$5))*(1+'Вводные'!$B$41)^MAX(0,'СРОКИ'!J10-MAX('Продажа'!$B$5,'СРОКИ'!$B$6)) | K6: =(1+'Вводные'!$B$40)^MAX(0,MIN('СРОКИ'!K10-'Продажа'!$B$5,'СРОКИ'!$B$6-'Продажа'!$B$5))*(1+'Вводные'!$B$41)^MAX(0,'СРОКИ'!K10-MAX('Продажа'!$B$5,'СРОКИ'!$B$6)) | ... DM6: =(1+'Вводные'!$B$40)^MAX(0,MIN('СРОКИ'!DM10-'Продажа'!$B$5,'СРОКИ'!$B$6-'Продажа'!$B$5))*(1+'Вводные'!$B$41)^MAX(0,'СРОКИ'!DM10-MAX('Продажа'!$B$5,'СРОКИ'!$B$6))
A7: Доля продаж месяца | B7: =SUM(D7:DM7) | D7: ='СРОКИ'!D13/'Вводные'!$B$42 | E7: ='СРОКИ'!E13/'Вводные'!$B$42 | F7: ='СРОКИ'!F13/'Вводные'!$B$42 | G7: ='СРОКИ'!G13/'Вводные'!$B$42 | H7: ='СРОКИ'!H13/'Вводные'!$B$42 | I7: ='СРОКИ'!I13/'Вводные'!$B$42 | J7: ='СРОКИ'!J13/'Вводные'!$B$42 | K7: ='СРОКИ'!K13/'Вводные'!$B$42 | ... DM7: ='СРОКИ'!DM13/'Вводные'!$B$42
A8: Выручка | B8: =SUM(D8:DM8) | C8: млн ₽ | D8: =('Вводные'!$B$17*'Вводные'!$F$30/1000+'Вводные'!$B$20*'Вводные'!$B$44)*'Продажа'!D6*'Продажа'!D7 | E8: =('Вводные'!$B$17*'Вводные'!$F$30/1000+'Вводные'!$B$20*'Вводные'!$B$44)*'Продажа'!E6*'Продажа'!E7 | F8: =('Вводные'!$B$17*'Вводные'!$F$30/1000+'Вводные'!$B$20*'Вводные'!$B$44)*'Продажа'!F6*'Продажа'!F7 | G8: =('Вводные'!$B$17*'Вводные'!$F$30/1000+'Вводные'!$B$20*'Вводные'!$B$44)*'Продажа'!G6*'Продажа'!G7 | H8: =('Вводные'!$B$17*'Вводные'!$F$30/1000+'Вводные'!$B$20*'Вводные'!$B$44)*'Продажа'!H6*'Продажа'!H7 | I8: =('Вводные'!$B$17*'Вводные'!$F$30/1000+'Вводные'!$B$20*'Вводные'!$B$44)*'Продажа'!I6*'Продажа'!I7 | J8: =('Вводные'!$B$17*'Вводные'!$F$30/1000+'Вводные'!$B$20*'Вводные'!$B$44)*'Продажа'!J6*'Продажа'!J7 | K8: =('Вводные'!$B$17*'Вводные'!$F$30/1000+'Вводные'!$B$20*'Вводные'!$B$44)*'Продажа'!K6*'Продажа'!K7 | ... DM8: =('Вводные'!$B$17*'Вводные'!$F$30/1000+'Вводные'!$B$20*'Вводные'!$B$44)*'Продажа'!DM6*'Продажа'!DM7
A9: Маркетинг и брокеры | B9: =SUM(D9:DM9) | C9: млн ₽ | D9: ='Продажа'!D8*'Вводные'!$B$43 | E9: ='Продажа'!E8*'Вводные'!$B$43 | F9: ='Продажа'!F8*'Вводные'!$B$43 | G9: ='Продажа'!G8*'Вводные'!$B$43 | H9: ='Продажа'!H8*'Вводные'!$B$43 | I9: ='Продажа'!I8*'Вводные'!$B$43 | J9: ='Продажа'!J8*'Вводные'!$B$43 | K9: ='Продажа'!K8*'Вводные'!$B$43 | ... DM9: ='Продажа'!DM8*'Вводные'!$B$43
A10: Не продано на начало месяца | C10: доля | D10: =1 | E10: =IF('СРОКИ'!E10<'СРОКИ'!$B$6,1,'Продажа'!D10-'Продажа'!D7*IF('СРОКИ'!E10-1>='СРОКИ'!$B$6,1,0)) | F10: =IF('СРОКИ'!F10<'СРОКИ'!$B$6,1,'Продажа'!E10-'Продажа'!E7*IF('СРОКИ'!F10-1>='СРОКИ'!$B$6,1,0)) | G10: =IF('СРОКИ'!G10<'СРОКИ'!$B$6,1,'Продажа'!F10-'Продажа'!F7*IF('СРОКИ'!G10-1>='СРОКИ'!$B$6,1,0)) | H10: =IF('СРОКИ'!H10<'СРОКИ'!$B$6,1,'Продажа'!G10-'Продажа'!G7*IF('СРОКИ'!H10-1>='СРОКИ'!$B$6,1,0)) | I10: =IF('СРОКИ'!I10<'СРОКИ'!$B$6,1,'Продажа'!H10-'Продажа'!H7*IF('СРОКИ'!I10-1>='СРОКИ'!$B$6,1,0)) | J10: =IF('СРОКИ'!J10<'СРОКИ'!$B$6,1,'Продажа'!I10-'Продажа'!I7*IF('СРОКИ'!J10-1>='СРОКИ'!$B$6,1,0)) | K10: =IF('СРОКИ'!K10<'СРОКИ'!$B$6,1,'Продажа'!J10-'Продажа'!J7*IF('СРОКИ'!K10-1>='СРОКИ'!$B$6,1,0)) | L10: =IF('СРОКИ'!L10<'СРОКИ'!$B$6,1,'Продажа'!K10-'Продажа'!K7*IF('СРОКИ'!L10-1>='СРОКИ'!$B$6,1,0)) | ... DM10: =IF('СРОКИ'!DM10<'СРОКИ'!$B$6,1,'Продажа'!DL10-'Продажа'!DL7*IF('СРОКИ'!DM10-1>='СРОКИ'!$B$6,1,0))
A11: Налог на имущество с непроданной части | B11: =SUM(D11:DM11) | C11: млн ₽ | D11: =IF(AND('СРОКИ'!D10>='СРОКИ'!$B$6,'СРОКИ'!D10<='СРОКИ'!$B$7),'CAPEX'!$B$8*'Вводные'!$B$52/12*'Продажа'!D10,0) | E11: =IF(AND('СРОКИ'!E10>='СРОКИ'!$B$6,'СРОКИ'!E10<='СРОКИ'!$B$7),'CAPEX'!$B$8*'Вводные'!$B$52/12*'Продажа'!E10,0) | F11: =IF(AND('СРОКИ'!F10>='СРОКИ'!$B$6,'СРОКИ'!F10<='СРОКИ'!$B$7),'CAPEX'!$B$8*'Вводные'!$B$52/12*'Продажа'!F10,0) | G11: =IF(AND('СРОКИ'!G10>='СРОКИ'!$B$6,'СРОКИ'!G10<='СРОКИ'!$B$7),'CAPEX'!$B$8*'Вводные'!$B$52/12*'Продажа'!G10,0) | H11: =IF(AND('СРОКИ'!H10>='СРОКИ'!$B$6,'СРОКИ'!H10<='СРОКИ'!$B$7),'CAPEX'!$B$8*'Вводные'!$B$52/12*'Продажа'!H10,0) | I11: =IF(AND('СРОКИ'!I10>='СРОКИ'!$B$6,'СРОКИ'!I10<='СРОКИ'!$B$7),'CAPEX'!$B$8*'Вводные'!$B$52/12*'Продажа'!I10,0) | J11: =IF(AND('СРОКИ'!J10>='СРОКИ'!$B$6,'СРОКИ'!J10<='СРОКИ'!$B$7),'CAPEX'!$B$8*'Вводные'!$B$52/12*'Продажа'!J10,0) | K11: =IF(AND('СРОКИ'!K10>='СРОКИ'!$B$6,'СРОКИ'!K10<='СРОКИ'!$B$7),'CAPEX'!$B$8*'Вводные'!$B$52/12*'Продажа'!K10,0) | ... DM11: =IF(AND('СРОКИ'!DM10>='СРОКИ'!$B$6,'СРОКИ'!DM10<='СРОКИ'!$B$7),'CAPEX'!$B$8*'Вводные'!$B$52/12*'Продажа'!DM10,0)

Sheet Аренда
A1: ПУТЬ 2 · АРЕНДА
A2: Заполнение, индексация, расходы эксплуатации, налог на имущество, NOI. млн ₽ с НДС.
A3: Показатель | B3: Итого / вводная | C3: Ед. | D3: =СРОКИ!D3 | E3: =СРОКИ!E3 | F3: =СРОКИ!F3 | G3: =СРОКИ!G3 | H3: =СРОКИ!H3 | I3: =СРОКИ!I3 | J3: =СРОКИ!J3 | K3: =СРОКИ!K3 | ... DM3: =СРОКИ!DM3
A4: Период | C4: № | D4: 0 | E4: 1 | F4: 2 | G4: 3 | H4: 4 | I4: 5 | J4: 6 | K4: 7 | L4: 8 | M4: 9 | N4: 10 | O4: 11 | P4: 12 | Q4: 13 | R4: 14 | S4: 15 | T4: 16 | U4: 17 | V4: 18 | W4: 19 | X4: 20 | Y4: 21 | Z4: 22 | AA4: 23 | AB4: 24 | AC4: 25 | AD4: 26 | AE4: 27 | AF4: 28 | AG4: 29 | AH4: 30 | AI4: 31 | AJ4: 32 | AK4: 33 | AL4: 34 | AM4: 35 | AN4: 36 | AO4: 37 | AP4: 38 | AQ4: 39 | AR4: 40 | AS4: 41 | AT4: 42 | AU4: 43 | AV4: 44 | AW4: 45 | AX4: 46 | AY4: 47 | AZ4: 48 | BA4: 49 | BB4: 50 | BC4: 51 | BD4: 52 | BE4: 53 | BF4: 54 | BG4: 55 | BH4: 56 | BI4: 57 | BJ4: 58 | BK4: 59 | BL4: 60 | BM4: 61 | BN4: 62 | BO4: 63 | BP4: 64 | BQ4: 65 | BR4: 66 | BS4: 67 | BT4: 68 | BU4: 69 | BV4: 70 | BW4: 71 | BX4: 72 | BY4: 73 | BZ4: 74 | CA4: 75 | CB4: 76 | CC4: 77 | CD4: 78 | CE4: 79 | CF4: 80 | CG4: 81 | CH4: 82 | CI4: 83 | CJ4: 84 | CK4: 85 | CL4: 86 | CM4: 87 | CN4: 88 | CO4: 89 | CP4: 90 | CQ4: 91 | CR4: 92 | CS4: 93 | CT4: 94 | CU4: 95 | CV4: 96 | CW4: 97 | CX4: 98 | CY4: 99 | CZ4: 100 | DA4: 101 | DB4: 102 | DC4: 103 | DD4: 104 | DE4: 105 | DF4: 106 | DG4: 107 | DH4: 108 | DI4: 109 | DJ4: 110 | DK4: 111 | DL4: 112 | DM4: 113
A5: Заполняемость | D5: =IF('СРОКИ'!D14<=0,0,MIN('Вводные'!$B$47,'Вводные'!$F$32)+('Вводные'!$F$32-MIN('Вводные'!$B$47,'Вводные'!$F$32))*IF('Вводные'!$F$33<=1,1,MIN(1,MAX(0,('СРОКИ'!D14-1)/('Вводные'!$F$33-1))))) | E5: =IF('СРОКИ'!E14<=0,0,MIN('Вводные'!$B$47,'Вводные'!$F$32)+('Вводные'!$F$32-MIN('Вводные'!$B$47,'Вводные'!$F$32))*IF('Вводные'!$F$33<=1,1,MIN(1,MAX(0,('СРОКИ'!E14-1)/('Вводные'!$F$33-1))))) | F5: =IF('СРОКИ'!F14<=0,0,MIN('Вводные'!$B$47,'Вводные'!$F$32)+('Вводные'!$F$32-MIN('Вводные'!$B$47,'Вводные'!$F$32))*IF('Вводные'!$F$33<=1,1,MIN(1,MAX(0,('СРОКИ'!F14-1)/('Вводные'!$F$33-1))))) | G5: =IF('СРОКИ'!G14<=0,0,MIN('Вводные'!$B$47,'Вводные'!$F$32)+('Вводные'!$F$32-MIN('Вводные'!$B$47,'Вводные'!$F$32))*IF('Вводные'!$F$33<=1,1,MIN(1,MAX(0,('СРОКИ'!G14-1)/('Вводные'!$F$33-1))))) | H5: =IF('СРОКИ'!H14<=0,0,MIN('Вводные'!$B$47,'Вводные'!$F$32)+('Вводные'!$F$32-MIN('Вводные'!$B$47,'Вводные'!$F$32))*IF('Вводные'!$F$33<=1,1,MIN(1,MAX(0,('СРОКИ'!H14-1)/('Вводные'!$F$33-1))))) | I5: =IF('СРОКИ'!I14<=0,0,MIN('Вводные'!$B$47,'Вводные'!$F$32)+('Вводные'!$F$32-MIN('Вводные'!$B$47,'Вводные'!$F$32))*IF('Вводные'!$F$33<=1,1,MIN(1,MAX(0,('СРОКИ'!I14-1)/('Вводные'!$F$33-1))))) | J5: =IF('СРОКИ'!J14<=0,0,MIN('Вводные'!$B$47,'Вводные'!$F$32)+('Вводные'!$F$32-MIN('Вводные'!$B$47,'Вводные'!$F$32))*IF('Вводные'!$F$33<=1,1,MIN(1,MAX(0,('СРОКИ'!J14-1)/('Вводные'!$F$33-1))))) | K5: =IF('СРОКИ'!K14<=0,0,MIN('Вводные'!$B$47,'Вводные'!$F$32)+('Вводные'!$F$32-MIN('Вводные'!$B$47,'Вводные'!$F$32))*IF('Вводные'!$F$33<=1,1,MIN(1,MAX(0,('СРОКИ'!K14-1)/('Вводные'!$F$33-1))))) | ... DM5: =IF('СРОКИ'!DM14<=0,0,MIN('Вводные'!$B$47,'Вводные'!$F$32)+('Вводные'!$F$32-MIN('Вводные'!$B$47,'Вводные'!$F$32))*IF('Вводные'!$F$33<=1,1,MIN(1,MAX(0,('СРОКИ'!DM14-1)/('Вводные'!$F$33-1)))))
A6: Индекс аренды | C6: × | D6: =IF('СРОКИ'!D14<=0,0,(1+'Вводные'!$B$48)^(('СРОКИ'!D14-1)/12)) | E6: =IF('СРОКИ'!E14<=0,0,(1+'Вводные'!$B$48)^(('СРОКИ'!E14-1)/12)) | F6: =IF('СРОКИ'!F14<=0,0,(1+'Вводные'!$B$48)^(('СРОКИ'!F14-1)/12)) | G6: =IF('СРОКИ'!G14<=0,0,(1+'Вводные'!$B$48)^(('СРОКИ'!G14-1)/12)) | H6: =IF('СРОКИ'!H14<=0,0,(1+'Вводные'!$B$48)^(('СРОКИ'!H14-1)/12)) | I6: =IF('СРОКИ'!I14<=0,0,(1+'Вводные'!$B$48)^(('СРОКИ'!I14-1)/12)) | J6: =IF('СРОКИ'!J14<=0,0,(1+'Вводные'!$B$48)^(('СРОКИ'!J14-1)/12)) | K6: =IF('СРОКИ'!K14<=0,0,(1+'Вводные'!$B$48)^(('СРОКИ'!K14-1)/12)) | ... DM6: =IF('СРОКИ'!DM14<=0,0,(1+'Вводные'!$B$48)^(('СРОКИ'!DM14-1)/12))
A7: Доход аренды (по всем месяцам эксплуатации) | C7: млн ₽ | D7: =('Вводные'!$B$17*'Вводные'!$F$31/12/1000+'Вводные'!$B$20*'Вводные'!$B$49/1000)*'Аренда'!D6*'Аренда'!D5 | E7: =('Вводные'!$B$17*'Вводные'!$F$31/12/1000+'Вводные'!$B$20*'Вводные'!$B$49/1000)*'Аренда'!E6*'Аренда'!E5 | F7: =('Вводные'!$B$17*'Вводные'!$F$31/12/1000+'Вводные'!$B$20*'Вводные'!$B$49/1000)*'Аренда'!F6*'Аренда'!F5 | G7: =('Вводные'!$B$17*'Вводные'!$F$31/12/1000+'Вводные'!$B$20*'Вводные'!$B$49/1000)*'Аренда'!G6*'Аренда'!G5 | H7: =('Вводные'!$B$17*'Вводные'!$F$31/12/1000+'Вводные'!$B$20*'Вводные'!$B$49/1000)*'Аренда'!H6*'Аренда'!H5 | I7: =('Вводные'!$B$17*'Вводные'!$F$31/12/1000+'Вводные'!$B$20*'Вводные'!$B$49/1000)*'Аренда'!I6*'Аренда'!I5 | J7: =('Вводные'!$B$17*'Вводные'!$F$31/12/1000+'Вводные'!$B$20*'Вводные'!$B$49/1000)*'Аренда'!J6*'Аренда'!J5 | K7: =('Вводные'!$B$17*'Вводные'!$F$31/12/1000+'Вводные'!$B$20*'Вводные'!$B$49/1000)*'Аренда'!K6*'Аренда'!K5 | ... DM7: =('Вводные'!$B$17*'Вводные'!$F$31/12/1000+'Вводные'!$B$20*'Вводные'!$B$49/1000)*'Аренда'!DM6*'Аренда'!DM5
A8: Доход аренды | B8: =SUM(D8:DM8) | C8: млн ₽ | D8: ='Аренда'!D7*'СРОКИ'!D15 | E8: ='Аренда'!E7*'СРОКИ'!E15 | F8: ='Аренда'!F7*'СРОКИ'!F15 | G8: ='Аренда'!G7*'СРОКИ'!G15 | H8: ='Аренда'!H7*'СРОКИ'!H15 | I8: ='Аренда'!I7*'СРОКИ'!I15 | J8: ='Аренда'!J7*'СРОКИ'!J15 | K8: ='Аренда'!K7*'СРОКИ'!K15 | ... DM8: ='Аренда'!DM7*'СРОКИ'!DM15
A9: Расходы эксплуатации | B9: =SUM(D9:DM9) | C9: млн ₽ | D9: ='Аренда'!D8*'Вводные'!$F$34 | E9: ='Аренда'!E8*'Вводные'!$F$34 | F9: ='Аренда'!F8*'Вводные'!$F$34 | G9: ='Аренда'!G8*'Вводные'!$F$34 | H9: ='Аренда'!H8*'Вводные'!$F$34 | I9: ='Аренда'!I8*'Вводные'!$F$34 | J9: ='Аренда'!J8*'Вводные'!$F$34 | K9: ='Аренда'!K8*'Вводные'!$F$34 | ... DM9: ='Аренда'!DM8*'Вводные'!$F$34
A10: Налог на имущество | B10: =SUM(D10:DM10) | C10: млн ₽ | D10: ='CAPEX'!$B$8*'Вводные'!$B$52/12*'СРОКИ'!D15 | E10: ='CAPEX'!$B$8*'Вводные'!$B$52/12*'СРОКИ'!E15 | F10: ='CAPEX'!$B$8*'Вводные'!$B$52/12*'СРОКИ'!F15 | G10: ='CAPEX'!$B$8*'Вводные'!$B$52/12*'СРОКИ'!G15 | H10: ='CAPEX'!$B$8*'Вводные'!$B$52/12*'СРОКИ'!H15 | I10: ='CAPEX'!$B$8*'Вводные'!$B$52/12*'СРОКИ'!I15 | J10: ='CAPEX'!$B$8*'Вводные'!$B$52/12*'СРОКИ'!J15 | K10: ='CAPEX'!$B$8*'Вводные'!$B$52/12*'СРОКИ'!K15 | ... DM10: ='CAPEX'!$B$8*'Вводные'!$B$52/12*'СРОКИ'!DM15
A11: NOI | B11: =SUM(D11:DM11) | C11: млн ₽ | D11: ='Аренда'!D8-'Аренда'!D9-'Аренда'!D10 | E11: ='Аренда'!E8-'Аренда'!E9-'Аренда'!E10 | F11: ='Аренда'!F8-'Аренда'!F9-'Аренда'!F10 | G11: ='Аренда'!G8-'Аренда'!G9-'Аренда'!G10 | H11: ='Аренда'!H8-'Аренда'!H9-'Аренда'!H10 | I11: ='Аренда'!I8-'Аренда'!I9-'Аренда'!I10 | J11: ='Аренда'!J8-'Аренда'!J9-'Аренда'!J10 | K11: ='Аренда'!K8-'Аренда'!K9-'Аренда'!K10 | ... DM11: ='Аренда'!DM8-'Аренда'!DM9-'Аренда'!DM10
A12: NOI покупателя: год после продажи здания (до налога на имущество) | B12: =SUM(D12:DM12) | C12: млн ₽ | D12: ='Аренда'!D7*(1-'Вводные'!$F$34)*'СРОКИ'!D16 | E12: ='Аренда'!E7*(1-'Вводные'!$F$34)*'СРОКИ'!E16 | F12: ='Аренда'!F7*(1-'Вводные'!$F$34)*'СРОКИ'!F16 | G12: ='Аренда'!G7*(1-'Вводные'!$F$34)*'СРОКИ'!G16 | H12: ='Аренда'!H7*(1-'Вводные'!$F$34)*'СРОКИ'!H16 | I12: ='Аренда'!I7*(1-'Вводные'!$F$34)*'СРОКИ'!I16 | J12: ='Аренда'!J7*(1-'Вводные'!$F$34)*'СРОКИ'!J16 | K12: ='Аренда'!K7*(1-'Вводные'!$F$34)*'СРОКИ'!K16 | ... DM12: ='Аренда'!DM7*(1-'Вводные'!$F$34)*'СРОКИ'!DM16
A13: Продажа здания | B13: =SUM(D13:DM13) | C13: млн ₽ | D13: =IF('СРОКИ'!D10='СРОКИ'!$B$9,'Выход'!$B$6,0) | E13: =IF('СРОКИ'!E10='СРОКИ'!$B$9,'Выход'!$B$6,0) | F13: =IF('СРОКИ'!F10='СРОКИ'!$B$9,'Выход'!$B$6,0) | G13: =IF('СРОКИ'!G10='СРОКИ'!$B$9,'Выход'!$B$6,0) | H13: =IF('СРОКИ'!H10='СРОКИ'!$B$9,'Выход'!$B$6,0) | I13: =IF('СРОКИ'!I10='СРОКИ'!$B$9,'Выход'!$B$6,0) | J13: =IF('СРОКИ'!J10='СРОКИ'!$B$9,'Выход'!$B$6,0) | K13: =IF('СРОКИ'!K10='СРОКИ'!$B$9,'Выход'!$B$6,0) | ... DM13: =IF('СРОКИ'!DM10='СРОКИ'!$B$9,'Выход'!$B$6,0)
A14: Расходы на сделку | B14: =SUM(D14:DM14) | C14: млн ₽ | D14: =IF('СРОКИ'!D10='СРОКИ'!$B$9,'Выход'!$B$7,0) | E14: =IF('СРОКИ'!E10='СРОКИ'!$B$9,'Выход'!$B$7,0) | F14: =IF('СРОКИ'!F10='СРОКИ'!$B$9,'Выход'!$B$7,0) | G14: =IF('СРОКИ'!G10='СРОКИ'!$B$9,'Выход'!$B$7,0) | H14: =IF('СРОКИ'!H10='СРОКИ'!$B$9,'Выход'!$B$7,0) | I14: =IF('СРОКИ'!I10='СРОКИ'!$B$9,'Выход'!$B$7,0) | J14: =IF('СРОКИ'!J10='СРОКИ'!$B$9,'Выход'!$B$7,0) | K14: =IF('СРОКИ'!K10='СРОКИ'!$B$9,'Выход'!$B$7,0) | ... DM14: =IF('СРОКИ'!DM10='СРОКИ'!$B$9,'Выход'!$B$7,0)

Sheet Выход
A1: ПУТЬ 2 · ПРОДАЖА ЗДАНИЯ
A2: Стоимость = NOI следующего года / ставка капитализации.
A4: NOI следующих 12 месяцев после срока удержания | B4: ='Аренда'!B12-'CAPEX'!$B$8*'Вводные'!$B$52 | C4: млн ₽
A5: Ставка капитализации | B5: ='Вводные'!$F$35
A6: Стоимость здания | B6: ='Выход'!$B$4/'Выход'!$B$5 | C6: млн ₽
A7: Расходы на сделку | B7: ='Выход'!$B$6*'Вводные'!$B$51 | C7: млн ₽
A8: Получено от продажи здания | B8: ='Выход'!$B$6-'Выход'!$B$7 | C8: млн ₽
A9: NOI года после заполнения | B9: =SUMPRODUCT(('СРОКИ'!D14:DM14>='Вводные'!$F$33)*('СРОКИ'!D14:DM14<='Вводные'!$F$33+11)*'Аренда'!D7:DM7)*(1-'Вводные'!$F$34)-'CAPEX'!$B$8*'Вводные'!$B$52 | C9: млн ₽
A10: Доходность на затраты = NOI года после заполнения / все затраты | B10: ='Выход'!$B$9/'CAPEX'!$B$9
A11: Доходность на затраты минус ставка капитализации | B11: ='Выход'!$B$10-'Выход'!$B$5
A13: Меньше нуля — готовое здание стоит дешевле, чем его стройка: строить, чтобы сдавать, невыгодно.

Sheet CF_Продажа
A1: CF_ПРОДАЖА · НДС, КРЕДИТ, ДЕНЬГИ СОБСТВЕННИКА
A2: Кредит: выборка — доля затрат до ввода; проценты до ввода капитализируются; после ввода — погашение.
A3: Показатель | B3: Итого / вводная | C3: Ед. | D3: =СРОКИ!D3 | E3: =СРОКИ!E3 | F3: =СРОКИ!F3 | G3: =СРОКИ!G3 | H3: =СРОКИ!H3 | I3: =СРОКИ!I3 | J3: =СРОКИ!J3 | K3: =СРОКИ!K3 | ... DM3: =СРОКИ!DM3
A4: Период | C4: № | D4: 0 | E4: 1 | F4: 2 | G4: 3 | H4: 4 | I4: 5 | J4: 6 | K4: 7 | L4: 8 | M4: 9 | N4: 10 | O4: 11 | P4: 12 | Q4: 13 | R4: 14 | S4: 15 | T4: 16 | U4: 17 | V4: 18 | W4: 19 | X4: 20 | Y4: 21 | Z4: 22 | AA4: 23 | AB4: 24 | AC4: 25 | AD4: 26 | AE4: 27 | AF4: 28 | AG4: 29 | AH4: 30 | AI4: 31 | AJ4: 32 | AK4: 33 | AL4: 34 | AM4: 35 | AN4: 36 | AO4: 37 | AP4: 38 | AQ4: 39 | AR4: 40 | AS4: 41 | AT4: 42 | AU4: 43 | AV4: 44 | AW4: 45 | AX4: 46 | AY4: 47 | AZ4: 48 | BA4: 49 | BB4: 50 | BC4: 51 | BD4: 52 | BE4: 53 | BF4: 54 | BG4: 55 | BH4: 56 | BI4: 57 | BJ4: 58 | BK4: 59 | BL4: 60 | BM4: 61 | BN4: 62 | BO4: 63 | BP4: 64 | BQ4: 65 | BR4: 66 | BS4: 67 | BT4: 68 | BU4: 69 | BV4: 70 | BW4: 71 | BX4: 72 | BY4: 73 | BZ4: 74 | CA4: 75 | CB4: 76 | CC4: 77 | CD4: 78 | CE4: 79 | CF4: 80 | CG4: 81 | CH4: 82 | CI4: 83 | CJ4: 84 | CK4: 85 | CL4: 86 | CM4: 87 | CN4: 88 | CO4: 89 | CP4: 90 | CQ4: 91 | CR4: 92 | CS4: 93 | CT4: 94 | CU4: 95 | CV4: 96 | CW4: 97 | CX4: 98 | CY4: 99 | CZ4: 100 | DA4: 101 | DB4: 102 | DC4: 103 | DD4: 104 | DE4: 105 | DF4: 106 | DG4: 107 | DH4: 108 | DI4: 109 | DJ4: 110 | DK4: 111 | DL4: 112 | DM4: 113
A5: Последний месяц пути | B5: ='СРОКИ'!$B$7 | C5: №
A6: Месяц пути | C6: 0/1 | D6: =IF('СРОКИ'!D10<='CF_Продажа'!$B$5,1,0) | E6: =IF('СРОКИ'!E10<='CF_Продажа'!$B$5,1,0) | F6: =IF('СРОКИ'!F10<='CF_Продажа'!$B$5,1,0) | G6: =IF('СРОКИ'!G10<='CF_Продажа'!$B$5,1,0) | H6: =IF('СРОКИ'!H10<='CF_Продажа'!$B$5,1,0) | I6: =IF('СРОКИ'!I10<='CF_Продажа'!$B$5,1,0) | J6: =IF('СРОКИ'!J10<='CF_Продажа'!$B$5,1,0) | K6: =IF('СРОКИ'!K10<='CF_Продажа'!$B$5,1,0) | ... DM6: =IF('СРОКИ'!DM10<='CF_Продажа'!$B$5,1,0)
A7: Выручка пути | B7: =SUM(D7:DM7) | C7: млн ₽ | D7: ='Продажа'!D8*'CF_Продажа'!D6 | E7: ='Продажа'!E8*'CF_Продажа'!E6 | F7: ='Продажа'!F8*'CF_Продажа'!F6 | G7: ='Продажа'!G8*'CF_Продажа'!G6 | H7: ='Продажа'!H8*'CF_Продажа'!H6 | I7: ='Продажа'!I8*'CF_Продажа'!I6 | J7: ='Продажа'!J8*'CF_Продажа'!J6 | K7: ='Продажа'!K8*'CF_Продажа'!K6 | ... DM7: ='Продажа'!DM8*'CF_Продажа'!DM6
A8: Расходы продаж и эксплуатации | B8: =SUM(D8:DM8) | C8: млн ₽ | D8: =('Продажа'!D9+'Продажа'!D11)*'CF_Продажа'!D6 | E8: =('Продажа'!E9+'Продажа'!E11)*'CF_Продажа'!E6 | F8: =('Продажа'!F9+'Продажа'!F11)*'CF_Продажа'!F6 | G8: =('Продажа'!G9+'Продажа'!G11)*'CF_Продажа'!G6 | H8: =('Продажа'!H9+'Продажа'!H11)*'CF_Продажа'!H6 | I8: =('Продажа'!I9+'Продажа'!I11)*'CF_Продажа'!I6 | J8: =('Продажа'!J9+'Продажа'!J11)*'CF_Продажа'!J6 | K8: =('Продажа'!K9+'Продажа'!K11)*'CF_Продажа'!K6 | ... DM8: =('Продажа'!DM9+'Продажа'!DM11)*'CF_Продажа'!DM6
A10: НДС
A11: НДС начислен | B11: =SUM(D11:DM11) | C11: млн ₽ | D11: ='CF_Продажа'!D7*'Вводные'!$B$11/(1+'Вводные'!$B$11) | E11: ='CF_Продажа'!E7*'Вводные'!$B$11/(1+'Вводные'!$B$11) | F11: ='CF_Продажа'!F7*'Вводные'!$B$11/(1+'Вводные'!$B$11) | G11: ='CF_Продажа'!G7*'Вводные'!$B$11/(1+'Вводные'!$B$11) | H11: ='CF_Продажа'!H7*'Вводные'!$B$11/(1+'Вводные'!$B$11) | I11: ='CF_Продажа'!I7*'Вводные'!$B$11/(1+'Вводные'!$B$11) | J11: ='CF_Продажа'!J7*'Вводные'!$B$11/(1+'Вводные'!$B$11) | K11: ='CF_Продажа'!K7*'Вводные'!$B$11/(1+'Вводные'!$B$11) | ... DM11: ='CF_Продажа'!DM7*'Вводные'!$B$11/(1+'Вводные'!$B$11)
A12: НДС к вычету накоплено до зачёта | C12: млн ₽ | D12: ='CAPEX'!D5*'Вводные'!$B$11/(1+'Вводные'!$B$11)-'CF_Продажа'!D11 | E12: ='CF_Продажа'!D14+'CAPEX'!E5*'Вводные'!$B$11/(1+'Вводные'!$B$11)*'CF_Продажа'!E6-'CF_Продажа'!E11 | F12: ='CF_Продажа'!E14+'CAPEX'!F5*'Вводные'!$B$11/(1+'Вводные'!$B$11)*'CF_Продажа'!F6-'CF_Продажа'!F11 | G12: ='CF_Продажа'!F14+'CAPEX'!G5*'Вводные'!$B$11/(1+'Вводные'!$B$11)*'CF_Продажа'!G6-'CF_Продажа'!G11 | H12: ='CF_Продажа'!G14+'CAPEX'!H5*'Вводные'!$B$11/(1+'Вводные'!$B$11)*'CF_Продажа'!H6-'CF_Продажа'!H11 | I12: ='CF_Продажа'!H14+'CAPEX'!I5*'Вводные'!$B$11/(1+'Вводные'!$B$11)*'CF_Продажа'!I6-'CF_Продажа'!I11 | J12: ='CF_Продажа'!I14+'CAPEX'!J5*'Вводные'!$B$11/(1+'Вводные'!$B$11)*'CF_Продажа'!J6-'CF_Продажа'!J11 | K12: ='CF_Продажа'!J14+'CAPEX'!K5*'Вводные'!$B$11/(1+'Вводные'!$B$11)*'CF_Продажа'!K6-'CF_Продажа'!K11 | L12: ='CF_Продажа'!K14+'CAPEX'!L5*'Вводные'!$B$11/(1+'Вводные'!$B$11)*'CF_Продажа'!L6-'CF_Продажа'!L11 | ... DM12: ='CF_Продажа'!DL14+'CAPEX'!DM5*'Вводные'!$B$11/(1+'Вводные'!$B$11)*'CF_Продажа'!DM6-'CF_Продажа'!DM11
A13: НДС уплачен (минус — возмещён) | B13: =SUM(D13:DM13) | C13: млн ₽ | D13: =IF(AND('СРОКИ'!D12=1,'CF_Продажа'!D12>0),-'CF_Продажа'!D12,IF('CF_Продажа'!D12<0,-'CF_Продажа'!D12,0))*'CF_Продажа'!D6 | E13: =IF(AND('СРОКИ'!E12=1,'CF_Продажа'!E12>0),-'CF_Продажа'!E12,IF('CF_Продажа'!E12<0,-'CF_Продажа'!E12,0))*'CF_Продажа'!E6 | F13: =IF(AND('СРОКИ'!F12=1,'CF_Продажа'!F12>0),-'CF_Продажа'!F12,IF('CF_Продажа'!F12<0,-'CF_Продажа'!F12,0))*'CF_Продажа'!F6 | G13: =IF(AND('СРОКИ'!G12=1,'CF_Продажа'!G12>0),-'CF_Продажа'!G12,IF('CF_Продажа'!G12<0,-'CF_Продажа'!G12,0))*'CF_Продажа'!G6 | H13: =IF(AND('СРОКИ'!H12=1,'CF_Продажа'!H12>0),-'CF_Продажа'!H12,IF('CF_Продажа'!H12<0,-'CF_Продажа'!H12,0))*'CF_Продажа'!H6 | I13: =IF(AND('СРОКИ'!I12=1,'CF_Продажа'!I12>0),-'CF_Продажа'!I12,IF('CF_Продажа'!I12<0,-'CF_Продажа'!I12,0))*'CF_Продажа'!I6 | J13: =IF(AND('СРОКИ'!J12=1,'CF_Продажа'!J12>0),-'CF_Продажа'!J12,IF('CF_Продажа'!J12<0,-'CF_Продажа'!J12,0))*'CF_Продажа'!J6 | K13: =IF(AND('СРОКИ'!K12=1,'CF_Продажа'!K12>0),-'CF_Продажа'!K12,IF('CF_Продажа'!K12<0,-'CF_Продажа'!K12,0))*'CF_Продажа'!K6 | ... DM13: =IF(AND('СРОКИ'!DM12=1,'CF_Продажа'!DM12>0),-'CF_Продажа'!DM12,IF('CF_Продажа'!DM12<0,-'CF_Продажа'!DM12,0))*'CF_Продажа'!DM6
A14: НДС к вычету на конец месяца | C14: млн ₽ | D14: ='CF_Продажа'!D12+'CF_Продажа'!D13 | E14: ='CF_Продажа'!E12+'CF_Продажа'!E13 | F14: ='CF_Продажа'!F12+'CF_Продажа'!F13 | G14: ='CF_Продажа'!G12+'CF_Продажа'!G13 | H14: ='CF_Продажа'!H12+'CF_Продажа'!H13 | I14: ='CF_Продажа'!I12+'CF_Продажа'!I13 | J14: ='CF_Продажа'!J12+'CF_Продажа'!J13 | K14: ='CF_Продажа'!K12+'CF_Продажа'!K13 | ... DM14: ='CF_Продажа'!DM12+'CF_Продажа'!DM13
A16: Кредит
A17: Выдача | B17: =SUM(D17:DM17) | C17: млн ₽ | D17: =IF('СРОКИ'!D10<='СРОКИ'!$B$6,'CAPEX'!D7*'Вводные'!$B$55,0) | E17: =IF('СРОКИ'!E10<='СРОКИ'!$B$6,'CAPEX'!E7*'Вводные'!$B$55,0) | F17: =IF('СРОКИ'!F10<='СРОКИ'!$B$6,'CAPEX'!F7*'Вводные'!$B$55,0) | G17: =IF('СРОКИ'!G10<='СРОКИ'!$B$6,'CAPEX'!G7*'Вводные'!$B$55,0) | H17: =IF('СРОКИ'!H10<='СРОКИ'!$B$6,'CAPEX'!H7*'Вводные'!$B$55,0) | I17: =IF('СРОКИ'!I10<='СРОКИ'!$B$6,'CAPEX'!I7*'Вводные'!$B$55,0) | J17: =IF('СРОКИ'!J10<='СРОКИ'!$B$6,'CAPEX'!J7*'Вводные'!$B$55,0) | K17: =IF('СРОКИ'!K10<='СРОКИ'!$B$6,'CAPEX'!K7*'Вводные'!$B$55,0) | ... DM17: =IF('СРОКИ'!DM10<='СРОКИ'!$B$6,'CAPEX'!DM7*'Вводные'!$B$55,0)
A18: Проценты месяца | B18: =SUM(D18:DM18) | C18: млн ₽ | D18: =0 | E18: ='CF_Продажа'!D24*'Ставки'!E6/12 | F18: ='CF_Продажа'!E24*'Ставки'!F6/12 | G18: ='CF_Продажа'!F24*'Ставки'!G6/12 | H18: ='CF_Продажа'!G24*'Ставки'!H6/12 | I18: ='CF_Продажа'!H24*'Ставки'!I6/12 | J18: ='CF_Продажа'!I24*'Ставки'!J6/12 | K18: ='CF_Продажа'!J24*'Ставки'!K6/12 | L18: ='CF_Продажа'!K24*'Ставки'!L6/12 | ... DM18: ='CF_Продажа'!DL24*'Ставки'!DM6/12
A19: Проценты капитализированы (до ввода) | B19: =SUM(D19:DM19) | C19: млн ₽ | D19: =IF('СРОКИ'!D10<'СРОКИ'!$B$6,'CF_Продажа'!D18,0) | E19: =IF('СРОКИ'!E10<'СРОКИ'!$B$6,'CF_Продажа'!E18,0) | F19: =IF('СРОКИ'!F10<'СРОКИ'!$B$6,'CF_Продажа'!F18,0) | G19: =IF('СРОКИ'!G10<'СРОКИ'!$B$6,'CF_Продажа'!G18,0) | H19: =IF('СРОКИ'!H10<'СРОКИ'!$B$6,'CF_Продажа'!H18,0) | I19: =IF('СРОКИ'!I10<'СРОКИ'!$B$6,'CF_Продажа'!I18,0) | J19: =IF('СРОКИ'!J10<'СРОКИ'!$B$6,'CF_Продажа'!J18,0) | K19: =IF('СРОКИ'!K10<'СРОКИ'!$B$6,'CF_Продажа'!K18,0) | ... DM19: =IF('СРОКИ'!DM10<'СРОКИ'!$B$6,'CF_Продажа'!DM18,0)
A20: Проценты уплачены | B20: =SUM(D20:DM20) | C20: млн ₽ | D20: =IF('СРОКИ'!D10>='СРОКИ'!$B$6,'CF_Продажа'!D18,0)*'CF_Продажа'!D6 | E20: =IF('СРОКИ'!E10>='СРОКИ'!$B$6,'CF_Продажа'!E18,0)*'CF_Продажа'!E6 | F20: =IF('СРОКИ'!F10>='СРОКИ'!$B$6,'CF_Продажа'!F18,0)*'CF_Продажа'!F6 | G20: =IF('СРОКИ'!G10>='СРОКИ'!$B$6,'CF_Продажа'!G18,0)*'CF_Продажа'!G6 | H20: =IF('СРОКИ'!H10>='СРОКИ'!$B$6,'CF_Продажа'!H18,0)*'CF_Продажа'!H6 | I20: =IF('СРОКИ'!I10>='СРОКИ'!$B$6,'CF_Продажа'!I18,0)*'CF_Продажа'!I6 | J20: =IF('СРОКИ'!J10>='СРОКИ'!$B$6,'CF_Продажа'!J18,0)*'CF_Продажа'!J6 | K20: =IF('СРОКИ'!K10>='СРОКИ'!$B$6,'CF_Продажа'!K18,0)*'CF_Продажа'!K6 | ... DM20: =IF('СРОКИ'!DM10>='СРОКИ'!$B$6,'CF_Продажа'!DM18,0)*'CF_Продажа'!DM6
A21: Долг до погашения | C21: млн ₽ | D21: ='CF_Продажа'!D19+'CF_Продажа'!D17 | E21: ='CF_Продажа'!D24+'CF_Продажа'!E19+'CF_Продажа'!E17 | F21: ='CF_Продажа'!E24+'CF_Продажа'!F19+'CF_Продажа'!F17 | G21: ='CF_Продажа'!F24+'CF_Продажа'!G19+'CF_Продажа'!G17 | H21: ='CF_Продажа'!G24+'CF_Продажа'!H19+'CF_Продажа'!H17 | I21: ='CF_Продажа'!H24+'CF_Продажа'!I19+'CF_Продажа'!I17 | J21: ='CF_Продажа'!I24+'CF_Продажа'!J19+'CF_Продажа'!J17 | K21: ='CF_Продажа'!J24+'CF_Продажа'!K19+'CF_Продажа'!K17 | L21: ='CF_Продажа'!K24+'CF_Продажа'!L19+'CF_Продажа'!L17 | ... DM21: ='CF_Продажа'!DL24+'CF_Продажа'!DM19+'CF_Продажа'!DM17
A22: Деньги на погашение | B22: =SUM(D22:DM22) | C22: млн ₽ | D22: ='CF_Продажа'!D7-'CF_Продажа'!D8-'CF_Продажа'!D13-'CF_Продажа'!D20 | E22: ='CF_Продажа'!E7-'CF_Продажа'!E8-'CF_Продажа'!E13-'CF_Продажа'!E20 | F22: ='CF_Продажа'!F7-'CF_Продажа'!F8-'CF_Продажа'!F13-'CF_Продажа'!F20 | G22: ='CF_Продажа'!G7-'CF_Продажа'!G8-'CF_Продажа'!G13-'CF_Продажа'!G20 | H22: ='CF_Продажа'!H7-'CF_Продажа'!H8-'CF_Продажа'!H13-'CF_Продажа'!H20 | I22: ='CF_Продажа'!I7-'CF_Продажа'!I8-'CF_Продажа'!I13-'CF_Продажа'!I20 | J22: ='CF_Продажа'!J7-'CF_Продажа'!J8-'CF_Продажа'!J13-'CF_Продажа'!J20 | K22: ='CF_Продажа'!K7-'CF_Продажа'!K8-'CF_Продажа'!K13-'CF_Продажа'!K20 | ... DM22: ='CF_Продажа'!DM7-'CF_Продажа'!DM8-'CF_Продажа'!DM13-'CF_Продажа'!DM20
A23: Погашение | B23: =SUM(D23:DM23) | C23: млн ₽ | D23: =IF('CF_Продажа'!D21<=0,0,IF('СРОКИ'!D10='CF_Продажа'!$B$5,'CF_Продажа'!D21,MIN('CF_Продажа'!D21,MAX(0,'CF_Продажа'!D22))))*'CF_Продажа'!D6 | E23: =IF('CF_Продажа'!E21<=0,0,IF('СРОКИ'!E10='CF_Продажа'!$B$5,'CF_Продажа'!E21,MIN('CF_Продажа'!E21,MAX(0,'CF_Продажа'!E22))))*'CF_Продажа'!E6 | F23: =IF('CF_Продажа'!F21<=0,0,IF('СРОКИ'!F10='CF_Продажа'!$B$5,'CF_Продажа'!F21,MIN('CF_Продажа'!F21,MAX(0,'CF_Продажа'!F22))))*'CF_Продажа'!F6 | G23: =IF('CF_Продажа'!G21<=0,0,IF('СРОКИ'!G10='CF_Продажа'!$B$5,'CF_Продажа'!G21,MIN('CF_Продажа'!G21,MAX(0,'CF_Продажа'!G22))))*'CF_Продажа'!G6 | H23: =IF('CF_Продажа'!H21<=0,0,IF('СРОКИ'!H10='CF_Продажа'!$B$5,'CF_Продажа'!H21,MIN('CF_Продажа'!H21,MAX(0,'CF_Продажа'!H22))))*'CF_Продажа'!H6 | I23: =IF('CF_Продажа'!I21<=0,0,IF('СРОКИ'!I10='CF_Продажа'!$B$5,'CF_Продажа'!I21,MIN('CF_Продажа'!I21,MAX(0,'CF_Продажа'!I22))))*'CF_Продажа'!I6 | J23: =IF('CF_Продажа'!J21<=0,0,IF('СРОКИ'!J10='CF_Продажа'!$B$5,'CF_Продажа'!J21,MIN('CF_Продажа'!J21,MAX(0,'CF_Продажа'!J22))))*'CF_Продажа'!J6 | K23: =IF('CF_Продажа'!K21<=0,0,IF('СРОКИ'!K10='CF_Продажа'!$B$5,'CF_Продажа'!K21,MIN('CF_Продажа'!K21,MAX(0,'CF_Продажа'!K22))))*'CF_Продажа'!K6 | ... DM23: =IF('CF_Продажа'!DM21<=0,0,IF('СРОКИ'!DM10='CF_Продажа'!$B$5,'CF_Продажа'!DM21,MIN('CF_Продажа'!DM21,MAX(0,'CF_Продажа'!DM22))))*'CF_Продажа'!DM6
A24: Долг на конец месяца | C24: млн ₽ | D24: ='CF_Продажа'!D21-'CF_Продажа'!D23 | E24: ='CF_Продажа'!E21-'CF_Продажа'!E23 | F24: ='CF_Продажа'!F21-'CF_Продажа'!F23 | G24: ='CF_Продажа'!G21-'CF_Продажа'!G23 | H24: ='CF_Продажа'!H21-'CF_Продажа'!H23 | I24: ='CF_Продажа'!I21-'CF_Продажа'!I23 | J24: ='CF_Продажа'!J21-'CF_Продажа'!J23 | K24: ='CF_Продажа'!K21-'CF_Продажа'!K23 | ... DM24: ='CF_Продажа'!DM21-'CF_Продажа'!DM23
A25: Выдача линии 1 (до разрешения) | B25: =SUM(D25:DM25) | C25: млн ₽ | D25: =IF('СРОКИ'!D10<'СРОКИ'!$B$5,'CF_Продажа'!D17,0) | E25: =IF('СРОКИ'!E10<'СРОКИ'!$B$5,'CF_Продажа'!E17,0) | F25: =IF('СРОКИ'!F10<'СРОКИ'!$B$5,'CF_Продажа'!F17,0) | G25: =IF('СРОКИ'!G10<'СРОКИ'!$B$5,'CF_Продажа'!G17,0) | H25: =IF('СРОКИ'!H10<'СРОКИ'!$B$5,'CF_Продажа'!H17,0) | I25: =IF('СРОКИ'!I10<'СРОКИ'!$B$5,'CF_Продажа'!I17,0) | J25: =IF('СРОКИ'!J10<'СРОКИ'!$B$5,'CF_Продажа'!J17,0) | K25: =IF('СРОКИ'!K10<'СРОКИ'!$B$5,'CF_Продажа'!K17,0) | ... DM25: =IF('СРОКИ'!DM10<'СРОКИ'!$B$5,'CF_Продажа'!DM17,0)
A26: Выдача линии 2 (стройка) | B26: =SUM(D26:DM26) | C26: млн ₽ | D26: =IF('СРОКИ'!D10>='СРОКИ'!$B$5,'CF_Продажа'!D17,0) | E26: =IF('СРОКИ'!E10>='СРОКИ'!$B$5,'CF_Продажа'!E17,0) | F26: =IF('СРОКИ'!F10>='СРОКИ'!$B$5,'CF_Продажа'!F17,0) | G26: =IF('СРОКИ'!G10>='СРОКИ'!$B$5,'CF_Продажа'!G17,0) | H26: =IF('СРОКИ'!H10>='СРОКИ'!$B$5,'CF_Продажа'!H17,0) | I26: =IF('СРОКИ'!I10>='СРОКИ'!$B$5,'CF_Продажа'!I17,0) | J26: =IF('СРОКИ'!J10>='СРОКИ'!$B$5,'CF_Продажа'!J17,0) | K26: =IF('СРОКИ'!K10>='СРОКИ'!$B$5,'CF_Продажа'!K17,0) | ... DM26: =IF('СРОКИ'!DM10>='СРОКИ'!$B$5,'CF_Продажа'!DM17,0)
A27: Выбрано линии 1 нарастающим | C27: млн ₽ | D27: ='CF_Продажа'!D25 | E27: ='CF_Продажа'!D27+'CF_Продажа'!E25 | F27: ='CF_Продажа'!E27+'CF_Продажа'!F25 | G27: ='CF_Продажа'!F27+'CF_Продажа'!G25 | H27: ='CF_Продажа'!G27+'CF_Продажа'!H25 | I27: ='CF_Продажа'!H27+'CF_Продажа'!I25 | J27: ='CF_Продажа'!I27+'CF_Продажа'!J25 | K27: ='CF_Продажа'!J27+'CF_Продажа'!K25 | L27: ='CF_Продажа'!K27+'CF_Продажа'!L25 | ... DM27: ='CF_Продажа'!DL27+'CF_Продажа'!DM25
A28: Выбрано линии 2 нарастающим | C28: млн ₽ | D28: ='CF_Продажа'!D26 | E28: ='CF_Продажа'!D28+'CF_Продажа'!E26 | F28: ='CF_Продажа'!E28+'CF_Продажа'!F26 | G28: ='CF_Продажа'!F28+'CF_Продажа'!G26 | H28: ='CF_Продажа'!G28+'CF_Продажа'!H26 | I28: ='CF_Продажа'!H28+'CF_Продажа'!I26 | J28: ='CF_Продажа'!I28+'CF_Продажа'!J26 | K28: ='CF_Продажа'!J28+'CF_Продажа'!K26 | L28: ='CF_Продажа'!K28+'CF_Продажа'!L26 | ... DM28: ='CF_Продажа'!DL28+'CF_Продажа'!DM26
A29: Комиссии банка | B29: =SUM(D29:DM29) | C29: млн ₽ | D29: ='CF_Продажа'!D17*'Вводные'!$B$57+IF('CF_Продажа'!D25>0,'CF_Продажа'!$B$25*'Вводные'!$B$58+('CF_Продажа'!$B$25-'CF_Продажа'!D27)*'Вводные'!$B$59/12,0) | E29: ='CF_Продажа'!E17*'Вводные'!$B$57+IF(AND('CF_Продажа'!E25>0,'CF_Продажа'!D27=0),'CF_Продажа'!$B$25*'Вводные'!$B$58,0)+IF(AND('CF_Продажа'!E26>0,'CF_Продажа'!D28=0),'CF_Продажа'!$B$26*'Вводные'!$B$58,0)+IF(AND('CF_Продажа'!E27>0,'СРОКИ'!E10<'СРОКИ'!$B$5),('CF_Продажа'!$B$25-'CF_Продажа'!E27)*'Вводные'!$B$59/12,0)+IF(AND('CF_Продажа'!E28>0,'СРОКИ'!E10<='СРОКИ'!$B$6),('CF_Продажа'!$B$26-'CF_Продажа'!E28)*'Вводные'!$B$59/12,0) | F29: ='CF_Продажа'!F17*'Вводные'!$B$57+IF(AND('CF_Продажа'!F25>0,'CF_Продажа'!E27=0),'CF_Продажа'!$B$25*'Вводные'!$B$58,0)+IF(AND('CF_Продажа'!F26>0,'CF_Продажа'!E28=0),'CF_Продажа'!$B$26*'Вводные'!$B$58,0)+IF(AND('CF_Продажа'!F27>0,'СРОКИ'!F10<'СРОКИ'!$B$5),('CF_Продажа'!$B$25-'CF_Продажа'!F27)*'Вводные'!$B$59/12,0)+IF(AND('CF_Продажа'!F28>0,'СРОКИ'!F10<='СРОКИ'!$B$6),('CF_Продажа'!$B$26-'CF_Продажа'!F28)*'Вводные'!$B$59/12,0) | G29: ='CF_Продажа'!G17*'Вводные'!$B$57+IF(AND('CF_Продажа'!G25>0,'CF_Продажа'!F27=0),'CF_Продажа'!$B$25*'Вводные'!$B$58,0)+IF(AND('CF_Продажа'!G26>0,'CF_Продажа'!F28=0),'CF_Продажа'!$B$26*'Вводные'!$B$58,0)+IF(AND('CF_Продажа'!G27>0,'СРОКИ'!G10<'СРОКИ'!$B$5),('CF_Продажа'!$B$25-'CF_Продажа'!G27)*'Вводные'!$B$59/12,0)+IF(AND('CF_Продажа'!G28>0,'СРОКИ'!G10<='СРОКИ'!$B$6),('CF_Продажа'!$B$26-'CF_Продажа'!G28)*'Вводные'!$B$59/12,0) | H29: ='CF_Продажа'!H17*'Вводные'!$B$57+IF(AND('CF_Продажа'!H25>0,'CF_Продажа'!G27=0),'CF_Продажа'!$B$25*'Вводные'!$B$58,0)+IF(AND('CF_Продажа'!H26>0,'CF_Продажа'!G28=0),'CF_Продажа'!$B$26*'Вводные'!$B$58,0)+IF(AND('CF_Продажа'!H27>0,'СРОКИ'!H10<'СРОКИ'!$B$5),('CF_Продажа'!$B$25-'CF_Продажа'!H27)*'Вводные'!$B$59/12,0)+IF(AND('CF_Продажа'!H28>0,'СРОКИ'!H10<='СРОКИ'!$B$6),('CF_Продажа'!$B$26-'CF_Продажа'!H28)*'Вводные'!$B$59/12,0) | I29: ='CF_Продажа'!I17*'Вводные'!$B$57+IF(AND('CF_Продажа'!I25>0,'CF_Продажа'!H27=0),'CF_Продажа'!$B$25*'Вводные'!$B$58,0)+IF(AND('CF_Продажа'!I26>0,'CF_Продажа'!H28=0),'CF_Продажа'!$B$26*'Вводные'!$B$58,0)+IF(AND('CF_Продажа'!I27>0,'СРОКИ'!I10<'СРОКИ'!$B$5),('CF_Продажа'!$B$25-'CF_Продажа'!I27)*'Вводные'!$B$59/12,0)+IF(AND('CF_Продажа'!I28>0,'СРОКИ'!I10<='СРОКИ'!$B$6),('CF_Продажа'!$B$26-'CF_Продажа'!I28)*'Вводные'!$B$59/12,0) | J29: ='CF_Продажа'!J17*'Вводные'!$B$57+IF(AND('CF_Продажа'!J25>0,'CF_Продажа'!I27=0),'CF_Продажа'!$B$25*'Вводные'!$B$58,0)+IF(AND('CF_Продажа'!J26>0,'CF_Продажа'!I28=0),'CF_Продажа'!$B$26*'Вводные'!$B$58,0)+IF(AND('CF_Продажа'!J27>0,'СРОКИ'!J10<'СРОКИ'!$B$5),('CF_Продажа'!$B$25-'CF_Продажа'!J27)*'Вводные'!$B$59/12,0)+IF(AND('CF_Продажа'!J28>0,'СРОКИ'!J10<='СРОКИ'!$B$6),('CF_Продажа'!$B$26-'CF_Продажа'!J28)*'Вводные'!$B$59/12,0) | K29: ='CF_Продажа'!K17*'Вводные'!$B$57+IF(AND('CF_Продажа'!K25>0,'CF_Продажа'!J27=0),'CF_Продажа'!$B$25*'Вводные'!$B$58,0)+IF(AND('CF_Продажа'!K26>0,'CF_Продажа'!J28=0),'CF_Продажа'!$B$26*'Вводные'!$B$58,0)+IF(AND('CF_Продажа'!K27>0,'СРОКИ'!K10<'СРОКИ'!$B$5),('CF_Продажа'!$B$25-'CF_Продажа'!K27)*'Вводные'!$B$59/12,0)+IF(AND('CF_Продажа'!K28>0,'СРОКИ'!K10<='СРОКИ'!$B$6),('CF_Продажа'!$B$26-'CF_Продажа'!K28)*'Вводные'!$B$59/12,0) | L29: ='CF_Продажа'!L17*'Вводные'!$B$57+IF(AND('CF_Продажа'!L25>0,'CF_Продажа'!K27=0),'CF_Продажа'!$B$25*'Вводные'!$B$58,0)+IF(AND('CF_Продажа'!L26>0,'CF_Продажа'!K28=0),'CF_Продажа'!$B$26*'Вводные'!$B$58,0)+IF(AND('CF_Продажа'!L27>0,'СРОКИ'!L10<'СРОКИ'!$B$5),('CF_Продажа'!$B$25-'CF_Продажа'!L27)*'Вводные'!$B$59/12,0)+IF(AND('CF_Продажа'!L28>0,'СРОКИ'!L10<='СРОКИ'!$B$6),('CF_Продажа'!$B$26-'CF_Продажа'!L28)*'Вводные'!$B$59/12,0) | ... DM29: ='CF_Продажа'!DM17*'Вводные'!$B$57+IF(AND('CF_Продажа'!DM25>0,'CF_Продажа'!DL27=0),'CF_Продажа'!$B$25*'Вводные'!$B$58,0)+IF(AND('CF_Продажа'!DM26>0,'CF_Продажа'!DL28=0),'CF_Продажа'!$B$26*'Вводные'!$B$58,0)+IF(AND('CF_Продажа'!DM27>0,'СРОКИ'!DM10<'СРОКИ'!$B$5),('CF_Продажа'!$B$25-'CF_Продажа'!DM27)*'Вводные'!$B$59/12,0)+IF(AND('CF_Продажа'!DM28>0,'СРОКИ'!DM10<='СРОКИ'!$B$6),('CF_Продажа'!$B$26-'CF_Продажа'!DM28)*'Вводные'!$B$59/12,0)
A31: Деньги собственника
A32: Налог на прибыль проекта к уплате (движок; в рабочей книге — лист «Налоги») | B32: =SUM(D32:DM32) | C32: млн ₽ | D32: 0 | E32: 0 | F32: 0 | G32: 0 | H32: 0 | I32: 0 | J32: 0 | K32: 0 | L32: 0 | M32: 0 | N32: 0 | O32: 0 | P32: 0 | Q32: 0 | R32: 0 | S32: 0 | T32: 0 | U32: 0 | V32: 0 | W32: 0 | X32: 0 | Y32: 0 | Z32: 0 | AA32: 0 | AB32: 0 | AC32: 0 | AD32: 0 | AE32: 0 | AF32: 0 | AG32: 0 | AH32: 0 | AI32: 0 | AJ32: 0 | AK32: 0 | AL32: 0 | AM32: 0 | AN32: 0 | AO32: 0 | AP32: 0 | AQ32: 0 | AR32: 0 | AS32: 0 | AT32: 0 | AU32: 0 | AV32: 0 | AW32: 0 | AX32: 0 | AY32: 0 | AZ32: 0 | BA32: 0 | BB32: 0 | BC32: 69.79166 | BD32: 0 | BE32: 0 | BF32: 74.04879 | BG32: 0 | BH32: 0 | BI32: 0 | BJ32: 0 | BK32: 0 | BL32: 0 | BM32: 0 | BN32: 0 | BO32: 0 | BP32: 0 | BQ32: 0 | BR32: 0 | BS32: 0 | BT32: 0 | BU32: 0 | BV32: 0 | BW32: 0 | BX32: 0 | BY32: 0 | BZ32: 0 | CA32: 0 | CB32: 0 | CC32: 0 | CD32: 0 | CE32: 0 | CF32: 0 | CG32: 0 | CH32: 0 | CI32: 0 | CJ32: 0 | CK32: 0 | CL32: 0 | CM32: 0 | CN32: 0 | CO32: 0 | CP32: 0 | CQ32: 0 | CR32: 0 | CS32: 0 | CT32: 0 | CU32: 0 | CV32: 0 | CW32: 0 | CX32: 0 | CY32: 0 | CZ32: 0 | DA32: 0 | DB32: 0 | DC32: 0 | DD32: 0 | DE32: 0 | DF32: 0 | DG32: 0 | DH32: 0 | DI32: 0 | DJ32: 0 | DK32: 0 | DL32: 0 | DM32: 0
A33: Поток собственника | B33: =SUM(D33:DM33) | C33: млн ₽ | D33: ='CF_Продажа'!D7-'CF_Продажа'!D8-'CF_Продажа'!D13-'CF_Продажа'!D20-'CF_Продажа'!D29+'CF_Продажа'!D17-'CF_Продажа'!D23-'CAPEX'!D7*IF('СРОКИ'!D10<='СРОКИ'!$B$6,1,0)-'CF_Продажа'!D32 | E33: ='CF_Продажа'!E7-'CF_Продажа'!E8-'CF_Продажа'!E13-'CF_Продажа'!E20-'CF_Продажа'!E29+'CF_Продажа'!E17-'CF_Продажа'!E23-'CAPEX'!E7*IF('СРОКИ'!E10<='СРОКИ'!$B$6,1,0)-'CF_Продажа'!E32 | F33: ='CF_Продажа'!F7-'CF_Продажа'!F8-'CF_Продажа'!F13-'CF_Продажа'!F20-'CF_Продажа'!F29+'CF_Продажа'!F17-'CF_Продажа'!F23-'CAPEX'!F7*IF('СРОКИ'!F10<='СРОКИ'!$B$6,1,0)-'CF_Продажа'!F32 | G33: ='CF_Продажа'!G7-'CF_Продажа'!G8-'CF_Продажа'!G13-'CF_Продажа'!G20-'CF_Продажа'!G29+'CF_Продажа'!G17-'CF_Продажа'!G23-'CAPEX'!G7*IF('СРОКИ'!G10<='СРОКИ'!$B$6,1,0)-'CF_Продажа'!G32 | H33: ='CF_Продажа'!H7-'CF_Продажа'!H8-'CF_Продажа'!H13-'CF_Продажа'!H20-'CF_Продажа'!H29+'CF_Продажа'!H17-'CF_Продажа'!H23-'CAPEX'!H7*IF('СРОКИ'!H10<='СРОКИ'!$B$6,1,0)-'CF_Продажа'!H32 | I33: ='CF_Продажа'!I7-'CF_Продажа'!I8-'CF_Продажа'!I13-'CF_Продажа'!I20-'CF_Продажа'!I29+'CF_Продажа'!I17-'CF_Продажа'!I23-'CAPEX'!I7*IF('СРОКИ'!I10<='СРОКИ'!$B$6,1,0)-'CF_Продажа'!I32 | J33: ='CF_Продажа'!J7-'CF_Продажа'!J8-'CF_Продажа'!J13-'CF_Продажа'!J20-'CF_Продажа'!J29+'CF_Продажа'!J17-'CF_Продажа'!J23-'CAPEX'!J7*IF('СРОКИ'!J10<='СРОКИ'!$B$6,1,0)-'CF_Продажа'!J32 | K33: ='CF_Продажа'!K7-'CF_Продажа'!K8-'CF_Продажа'!K13-'CF_Продажа'!K20-'CF_Продажа'!K29+'CF_Продажа'!K17-'CF_Продажа'!K23-'CAPEX'!K7*IF('СРОКИ'!K10<='СРОКИ'!$B$6,1,0)-'CF_Продажа'!K32 | ... DM33: ='CF_Продажа'!DM7-'CF_Продажа'!DM8-'CF_Продажа'!DM13-'CF_Продажа'!DM20-'CF_Продажа'!DM29+'CF_Продажа'!DM17-'CF_Продажа'!DM23-'CAPEX'!DM7*IF('СРОКИ'!DM10<='СРОКИ'!$B$6,1,0)-'CF_Продажа'!DM32
A34: Поток собственника нарастающим | C34: млн ₽ | D34: ='CF_Продажа'!D33 | E34: ='CF_Продажа'!D34+'CF_Продажа'!E33 | F34: ='CF_Продажа'!E34+'CF_Продажа'!F33 | G34: ='CF_Продажа'!F34+'CF_Продажа'!G33 | H34: ='CF_Продажа'!G34+'CF_Продажа'!H33 | I34: ='CF_Продажа'!H34+'CF_Продажа'!I33 | J34: ='CF_Продажа'!I34+'CF_Продажа'!J33 | K34: ='CF_Продажа'!J34+'CF_Продажа'!K33 | L34: ='CF_Продажа'!K34+'CF_Продажа'!L33 | ... DM34: ='CF_Продажа'!DL34+'CF_Продажа'!DM33
