Workbook

Sheet Дашборд
A1: ПЛАТО | DEVELOPMENT MODEL
A3: ="Проект: "&ОТЧЕТ!C1 -> Проект: Мишина | I3: Сценарий | L3: =Вводные!C3 -> Базовый
A5: ВЫРУЧКА, МЛН ₽ | D5: EBITDA, МЛН ₽ | G5: ЧИСТАЯ ПРИБЫЛЬ, МЛН ₽ | J5: МАРЖИНАЛЬНОСТЬ | M5: IRR EQUITY
A6: =ОТЧЕТ!C4 -> 21875.892 | D6: =ОТЧЕТ!C21 -> 5232.5088 | G6: =ОТЧЕТ!C24 -> 2849.8068 | J6: =ОТЧЕТ!C27 -> 0.13027157 | M6: =ОТЧЕТ!C29 -> N/A
A10: NPV @20%, МЛН ₽ | D10: LLCR С УЧЕТОМ БРИДЖ | G10: РАСЧЕТНЫЙ БРИДЖ, МЛН ₽ | J10: ФАКТИЧЕСКИЙ БРИДЖ, МЛН ₽ | M10: ПФ, МЛН ₽
A11: =ОТЧЕТ!C28 -> 2680.6691 | D11: =ОТЧЕТ!C30 -> 1.1968375 | G11: =Финансирование!C7 -> 1898.297 | J11: =ОТЧЕТ!C25 -> 1048.6505 | M11: =ОТЧЕТ!C26 -> 14264.843
A15: ЭКОНОМИКА ПРОЕКТА | J15: КЛЮЧЕВЫЕ ПАРАМЕТРЫ
A16: Стоимость покупки, млн ₽ | F16: =Вводные!G6 -> 700 | J16: Стартовая цена квартир, тыс. ₽/м² | M16: =Вводные!G11 -> 675
A17: Стоимость смены ВРИ, млн ₽ | F17: ='Расчет ВРИ (ТЭП)'!D73 -> 2141.838 | J17: Рост цены до РВЭ, %/мес. | M17: =Вводные!G46 -> 0.010991815
A18: Социальный платеж, млн ₽ | F18: ='Расчет ВРИ (ТЭП)'!D83 -> 988.447 | J18: Цена квартир на РВЭ, тыс. ₽/м² | M18: =IFERROR(INDEX(ПОДБОР_КВ.М!H64:DC64,1,MATCH(EDATE(Вводные!G8,Вводные!G9),ПОДБОР_КВ.М!H2:DC2,0)),0) -> 877.5
A19: Проектирование П и РД, млн ₽ | F19: =-ОТЧЕТ!C35 -> 230.055 | J19: Цена последних продаж, тыс. ₽/м² | M19: =IFERROR(LOOKUP(2,1/(ПОДБОР_КВ.М!H61:DC61>0),ПОДБОР_КВ.М!H64:DC64),0) -> 890.56523
J20: Средняя цена квартир, тыс. ₽/м² | M20: =F21 -> 788.59515
A21: Средневзвешенная цена квартир, тыс. ₽/м², NSA | F21: =IFERROR(ОТЧЕТ!C5*1000/ТЭП!G7,0) -> 788.59515 | J21: Расчетный БРИДЖ, млн ₽ | M21: =Финансирование!C7 -> 1898.297
A22: Полная себестоимость, тыс. ₽/м², NSA | F22: =-ОТЧЕТ!D13 -> 585.90477 | J22: Фактический БРИДЖ, млн ₽ | M22: =ОТЧЕТ!C25 -> 1048.6505
A23: Строительная себестоимость, тыс. ₽/м², NSA | F23: =-ОТЧЕТ!D18 -> 330.82291 | J23: Процентные расходы, млн ₽ | M23: =-ОТЧЕТ!C22 -> 1432.7396
A26: СТРУКТУРА ВЫРУЧКИ | I26: СТРУКТУРА ЗАТРАТ
A45: СТАВКИ, БРИДЖ, ПФ, ЭСКРОУ И LLCR
A46: Показатель | E46: Значение | G46: Ед. | H46: Комментарий | J46: БРИДЖ И КЛЮЧЕВЫЕ ДАТЫ
A47: Средневзвешенная ставка ПФ | E47: =Ставки!B4 -> 0.058023046 | G47: % год | H47: По ежемесячному остатку ПФ | J47: Покупка / начало проекта | N47: =Вводные!G7 -> 46266
A48: Средняя ставка БРИДЖ | E48: =Ставки!B5 -> 0.18924731 | G48: % год | H48: За период действия БРИДЖ | J48: Срок ИРД | N48: =Вводные!G48 -> 18
A49: Средневзвешенная совокупная ставка | E49: =Ставки!B6 -> 0.06810413 | G49: % год | H49: БРИДЖ + ПФ | J49: Дата РнС | N49: =Вводные!G8 -> 46813
A50: Расчетный лимит БРИДЖ | E50: =Ставки!B7 -> 931.04345 | G50: млн ₽ | H50: Потребность по модели | J50: Погашение БРИДЖ | N50: =EDATE(Вводные!G8,Вводные!G50) -> 46813
A51: Пиковая выборка БРИДЖ | E51: =Ставки!B8 -> 700.84525 | G51: млн ₽ | H51: Максимальный фактический остаток | J51: Срок БРИДЖ | N51: =Ставки!G6 -> 18
A52: Пиковая выборка ПФ | E52: =Ставки!B9 -> 14264.843 | G52: млн ₽ | H52: Максимальный остаток ПФ | J52: Старт продаж | N52: =Вводные!G10 -> 46813
A53: Среднее покрытие ПФ эскроу | E53: =Ставки!B11 -> 1.9901741 | G53: x | H53: Эскроу / ПФ | J53: РВЭ / окончание строительства | N53: =EDATE(Вводные!G8,Вводные!G9) -> 47543
A54: LLCR с учетом БРИДЖ | E54: =LLCR!C18 -> 1.1968375 | G54: x | H54: Без двойного учета перенесенных процентов | J54: Окончание продаж | N54: =EDATE(EDATE(Вводные!G8,Вводные!G9),Вводные!G51) -> 47727
A55: Корректировка процентов БРИДЖ | E55: =LLCR!C16 -> 200.58366 | G55: млн ₽ | H55: Исключается при переносе в ПФ | J55: Срок строительства | N55: =Вводные!G9 -> 24
A77: LLCR рассчитывается на дату окончательного погашения. При капитализации процентов БРИДЖ их отдельная строка исключается из знаменателя, поскольку эти проценты уже перенесены в ПФ. Подробная расшифровка — на листе «LLCR».

Sheet Вводные
A1: ПЛАТО — ВВОДНЫЕ ДАННЫЕ
A3: Активный сценарий | C3: Базовый
A5: Блок | B5: Параметр | C5: Ед. изм. | D5: Консервативный | E5: Базовый | F5: Оптимистичный | G5: Выбрано | H5: Исходная ячейка | I5: До изменения | J5: Комментарий
A6: Сделка | B6: Стоимость покупки / цена входа | C6: млн ₽ | D6: 700 | E6: 700 | F6: 700 | G6: =INDEX($D6:$F6,1,MATCH($C$3,$D$5:$F$5,0)) -> 700 | H6: ОТЧЕТ!C14 | I6: 3500 | J6: Вводится здесь; в ОТЧЕТ C14 передается со знаком минус
A7: Общие | B7: Начало проекта | C7: дата | D7: 46266 | E7: 46266 | F7: 46266 | G7: =INDEX($D7:$F7,1,MATCH($C$3,$D$5:$F$5,0)) -> 46266 | H7: ТЭП!C1 | I7: 46388
A8: Сроки | B8: Дата РнС | C8: дата | D8: =EDATE(D7,D48) -> 46997 | E8: =EDATE(E7,E48) -> 46813 | F8: =EDATE(F7,F48) -> 46692 | G8: =INDEX($D8:$F8,1,MATCH($C$3,$D$5:$F$5,0)) -> 46813 | H8: СРОКИ!C17 | I8: 46631 | J8: Дата рассчитывается автоматически: начало проекта + срок ИРД до РнС (строка 48).
A9: Сроки | B9: Срок строительства | C9: мес. | D9: 26 | E9: 24 | F9: 22 | G9: =INDEX($D9:$F9,1,MATCH($C$3,$D$5:$F$5,0)) -> 24 | H9: СРОКИ!C18 | I9: 24
A10: Сроки | B10: Старт продаж | C10: дата | D10: =EDATE(D8,D49) -> 47027 | E10: =EDATE(E8,E49) -> 46813 | F10: =EDATE(F8,F49) -> 46692 | G10: =INDEX($D10:$F10,1,MATCH($C$3,$D$5:$F$5,0)) -> 46813 | H10: СРОКИ!C16 | I10: 46661 | J10: Дата рассчитывается автоматически: РнС + лаг старта продаж (строка 49).
A11: Продажи | B11: Стартовая цена квартир | C11: тыс. ₽/м² | D11: 650 | E11: 675 | F11: 700 | G11: =INDEX($D11:$F11,1,MATCH($C$3,$D$5:$F$5,0)) -> 675 | H11: ПОДБОР_КВ.М!D33 | I11: 550
A12: Продажи | B12: Стартовая цена коммерции | C12: тыс. ₽/м² | D12: 500 | E12: 650 | F12: 575 | G12: =INDEX($D12:$F12,1,MATCH($C$3,$D$5:$F$5,0)) -> 650 | H12: ПОДБОР_КВ.М!D70 | I12: 500
A13: Продажи | B13: Цена машино-места | C13: тыс. ₽/шт. | D13: 3000 | E13: 4000 | F13: 5000 | G13: =INDEX($D13:$F13,1,MATCH($C$3,$D$5:$F$5,0)) -> 4000 | H13: ПОДБОР_КВ.М!D71 | I13: 5000
A14: Продажи | B14: Цена кладовой | C14: тыс. ₽/шт. | D14: 900 | E14: 1000 | F14: 1100 | G14: =INDEX($D14:$F14,1,MATCH($C$3,$D$5:$F$5,0)) -> 1000 | H14: ПОДБОР_КВ.М!D72 | I14: 1000
A15: Продажи | B15: Доля продаж до РВЭ | C15: % | D15: 0.8 | E15: 0.85 | F15: 0.9 | G15: =INDEX($D15:$F15,1,MATCH($C$3,$D$5:$F$5,0)) -> 0.85 | H15: ПОДБОР_КВ.М!D66 | I15: 6
A16: Продажи | B16: Смещение темпа продаж к поздним месяцам | C16: % | D16: 0.2 | E16: 0.25 | F16: 0.3 | G16: =INDEX($D16:$F16,1,MATCH($C$3,$D$5:$F$5,0)) -> 0.25 | H16: ПОДБОР_КВ.М!D17 | I16: 0.25 | J16: 0% = равномерный профиль (с учётом сезонности). Положительное значение плавно увеличивает вес более поздних месяцев до РВЭ; общий объём продаж не меняется.
A17: Продажи | B17: Инфляция после РВЭ | C17: % год | D17: 0.02 | E17: 0.03 | F17: 0.04 | G17: =INDEX($D17:$F17,1,MATCH($C$3,$D$5:$F$5,0)) -> 0.03 | H17: ПОДБОР_КВ.М!D18 | I17: 0.03
A18: Продажи | B18: Сезонное снижение темпа | C18: % | D18: -0.2 | E18: -0.15 | F18: -0.1 | G18: =INDEX($D18:$F18,1,MATCH($C$3,$D$5:$F$5,0)) -> -0.15 | H18: ПОДБОР_КВ.М!D10:D14 | I18: -0.15 | J18: Применяется к январю и маю–августу
A19: Продажи | B19: Рост цены — этап 1 | C19: % | D19: 0 | E19: 0 | F19: 0 | G19: =INDEX($D19:$F19,1,MATCH($C$3,$D$5:$F$5,0)) -> 0 | H19: ПОДБОР_КВ.М!F25 | I19: 0.15 | J19: Устаревший параметр: новый движок продаж не использует этапные скачки цены по строительной готовности.
A20: Продажи | B20: Рост цены — этап 2 | C20: % | D20: 0 | E20: 0 | F20: 0 | G20: =INDEX($D20:$F20,1,MATCH($C$3,$D$5:$F$5,0)) -> 0 | H20: ПОДБОР_КВ.М!F26 | I20: 0.15 | J20: Устаревший параметр: новый движок продаж не использует этапные скачки цены по строительной готовности.
A21: Продажи | B21: Рост цены — этап 3 | C21: % | D21: 0 | E21: 0 | F21: 0 | G21: =INDEX($D21:$F21,1,MATCH($C$3,$D$5:$F$5,0)) -> 0 | H21: ПОДБОР_КВ.М!F27 | I21: 0.05 | J21: Устаревший параметр: новый движок продаж не использует этапные скачки цены по строительной готовности.
A22: Продажи | B22: Рост цены — этап 4 | C22: % | D22: 0 | E22: 0 | F22: 0 | G22: =INDEX($D22:$F22,1,MATCH($C$3,$D$5:$F$5,0)) -> 0 | H22: ПОДБОР_КВ.М!F28 | I22: 0.05 | J22: Устаревший параметр: новый движок продаж не использует этапные скачки цены по строительной готовности.
A23: Строительство | B23: ИРД и согласования | C23: тыс. ₽/м² GBA | D23: 1.1 | E23: 1 | F23: 0.95 | G23: =INDEX($D23:$F23,1,MATCH($C$3,$D$5:$F$5,0)) -> 1 | H23: СРОКИ!C40 | I23: 1
A24: Строительство | B24: Проектирование стадии П | C24: тыс. ₽/м² GBA | D24: 2.75 | E24: 2.5 | F24: 2.35 | G24: =INDEX($D24:$F24,1,MATCH($C$3,$D$5:$F$5,0)) -> 2.5 | H24: СРОКИ!C41 | I24: 2.5
A25: Строительство | B25: Проектирование стадии РД | C25: тыс. ₽/м² GBA | D25: 2.75 | E25: 2.5 | F25: 2.35 | G25: =INDEX($D25:$F25,1,MATCH($C$3,$D$5:$F$5,0)) -> 2.5 | H25: СРОКИ!C42 | I25: 2.5
A26: Строительство | B26: Подготовительные работы | C26: тыс. ₽/м² GBA | D26: 1.2 | E26: 1 | F26: 0.9 | G26: =INDEX($D26:$F26,1,MATCH($C$3,$D$5:$F$5,0)) -> 1 | H26: СРОКИ!C43 | I26: 1
A27: Строительство | B27: Основное строительство ЖК | C27: тыс. ₽/м² GBA | D27: 225 | E27: 190 | F27: 175 | G27: =INDEX($D27:$F27,1,MATCH($C$3,$D$5:$F$5,0)) -> 190 | H27: СРОКИ!C44 | I27: 165
A28: Строительство | B28: Наружные инженерные сети | C28: тыс. ₽/м² GBA | D28: 8 | E28: 7 | F28: 6 | G28: =INDEX($D28:$F28,1,MATCH($C$3,$D$5:$F$5,0)) -> 7 | H28: СРОКИ!C49 | I28: 7.5
A29: Строительство | B29: Благоустройство | C29: тыс. ₽/м² GBA | D29: 4 | E29: 3.5 | F29: 4 | G29: =INDEX($D29:$F29,1,MATCH($C$3,$D$5:$F$5,0)) -> 3.5 | H29: СРОКИ!C50 | I29: 5
A30: Строительство | B30: Сдача и ввод | C30: тыс. ₽/м² GBA | D30: 1.1 | E30: 1 | F30: 0.9 | G30: =INDEX($D30:$F30,1,MATCH($C$3,$D$5:$F$5,0)) -> 1 | H30: СРОКИ!C51 | I30: 1
A31: Строительство | B31: Содержание стройплощадки | C31: тыс. ₽/м² GBA | D31: 1.2 | E31: 1 | F31: 0.9 | G31: =INDEX($D31:$F31,1,MATCH($C$3,$D$5:$F$5,0)) -> 1 | H31: СРОКИ!C52 | I31: 1
A32: Строительство | B32: Вознаграждение генподрядчика | C32: % СМР | D32: 0.08 | E32: 0.07 | F32: 0.05 | G32: =INDEX($D32:$F32,1,MATCH($C$3,$D$5:$F$5,0)) -> 0.07 | H32: cf_1/cf_2!E129 | I32: 0.035
A33: Строительство | B33: Резерв | C33: % | D33: 0.07 | E33: 0.05 | F33: 0.03 | G33: =INDEX($D33:$F33,1,MATCH($C$3,$D$5:$F$5,0)) -> 0.05 | H33: cf_1/cf_2!E180 | I33: 0.05
A34: Строительство | B34: Управление проектом | C34: % | D34: 0.06 | E34: 0.05 | F34: 0.04 | G34: =INDEX($D34:$F34,1,MATCH($C$3,$D$5:$F$5,0)) -> 0.05 | H34: cf_1/cf_2!E182 | I34: 0.05
... A38: Налоги | B38: НДС | C38: % | D38: 0.22 | E38: 0.22 | F38: 0.22 | G38: =INDEX($D38:$F38,1,MATCH($C$3,$D$5:$F$5,0)) -> 0.22 | H38: cf_1/cf_2!E66 | I38: 0.22
A39: Финансирование | B39: Спред БРИДЖ | C39: п.п. | D39: 0.07 | E39: 0.06 | F39: 0.05 | G39: =INDEX($D39:$F39,1,MATCH($C$3,$D$5:$F$5,0)) -> 0.06 | H39: КРЕДИТЫ!D13 | I39: 0.06 | J39: Размер БРИДЖ не вводится — рассчитывается на листе Финансирование
A40: Финансирование | B40: Спред капитализации БРИДЖ | C40: п.п. | D40: 0.07 | E40: 0.06 | F40: 0.05 | G40: =INDEX($D40:$F40,1,MATCH($C$3,$D$5:$F$5,0)) -> 0.06 | H40: КРЕДИТЫ!D14 | I40: 0.06
A41: Финансирование | B41: Спред ПФ | C41: п.п. | D41: 0.055 | E41: 0.045 | F41: 0.035 | G41: =INDEX($D41:$F41,1,MATCH($C$3,$D$5:$F$5,0)) -> 0.045 | H41: КРЕДИТЫ!D15 | I41: 0.045
A42: Финансирование | B42: Специальная ставка ПФ | C42: % | D42: 0.05 | E42: 0.045 | F42: 0.04 | G42: =INDEX($D42:$F42,1,MATCH($C$3,$D$5:$F$5,0)) -> 0.045 | H42: КРЕДИТЫ!D16 | I42: 0.045
A43: Финансирование | B43: Плата за лимит | C43: % | D43: 0.0075 | E43: 0.005 | F43: 0.0035 | G43: =INDEX($D43:$F43,1,MATCH($C$3,$D$5:$F$5,0)) -> 0.005 | H43: КРЕДИТЫ!D19 | I43: 0.005
A44: Финансирование | B44: Плата за резервирование | C44: % | D44: 0.0075 | E44: 0.005 | F44: 0.0035 | G44: =INDEX($D44:$F44,1,MATCH($C$3,$D$5:$F$5,0)) -> 0.005 | H44: КРЕДИТЫ!D20 | I44: 0.005
A45: Оценка | B45: Ставка дисконтирования | C45: % | D45: 0.25 | E45: 0.2 | F45: 0.18 | G45: =INDEX($D45:$F45,1,MATCH($C$3,$D$5:$F$5,0)) -> 0.2 | H45: CF!I94 | I45: 0.2
...

Sheet ОТЧЕТ
B1: ПРОЕКТ: | C1: Мишина | AZ1: Месяц | BA1: Темп продаж квартир, м²/мес | BB1: Цена квартир, тыс. ₽/м² | BD1: Месяц | BE1: Эскроу, остаток, млн ₽ | BF1: Затраты проекта, нараст., млн ₽ | BG1: Остаток ПФ, млн ₽
B2: ФЭП | G2: ТЭП | AZ2: ='План продаж'!B22 -> 46266 | BA2: =IFERROR('План продаж'!G22,0) -> 0 | BB2: =IFERROR('План продаж'!I22/1000,0) -> 0 | BD2: =INDEX(КРЕДИТЫ!$S$3:$EO$3,1,ROW()-1) -> 46266 | BE2: =(SUM(cf_1!$S$9:INDEX(cf_1!$S$9:$EO$9,1,ROW()-1))+SUM(cf_2!$S$9:INDEX(cf_2!$S$9:$EO$9,1,ROW()-1))-SUM(cf_1!$S$209:INDEX(cf_1!$S$209:$EO$209,1,ROW()-1))-SUM(cf_2!$S$209:INDEX(cf_2!$S$209:$EO$209,1,ROW()-1)))/1000000 -> 0 | BF2: =(SUM(cf_1!$S$183:INDEX(cf_1!$S$183:$EO$183,1,ROW()-1))+SUM(cf_2!$S$183:INDEX(cf_2!$S$183:$EO$183,1,ROW()-1)))/1000000 -> 0 | BG2: =(INDEX(КРЕДИТЫ!$S$52:$EO$52,1,ROW()-1)+INDEX(КРЕДИТЫ!$S$75:$EO$75,1,ROW()-1))/1000000 -> 0
B3: Показатель | C3: ИТОГО млн.р | D3: Тыс. руб/кв.м NSA | E3: Тыс. руб/кв.м GBA | G3: Показатель | H3: ГНС, кв.м | I3: Общая площадь, кв.м | J3: k выхода полезной площади | K3: Полезная площадь, кв.м | L3: Продаваемая площадь, кв.м | M3: Передаваемая площадь, кв.м | N3: Штуки | O3: ср S, кв.м | AZ3: ='План продаж'!B23 -> 46296 | BA3: =IFERROR('План продаж'!G23,0) -> 0 | BB3: =IFERROR('План продаж'!I23/1000,0) -> 0 | BD3: =INDEX(КРЕДИТЫ!$S$3:$EO$3,1,ROW()-1) -> 46296 | BE3: =(SUM(cf_1!$S$9:INDEX(cf_1!$S$9:$EO$9,1,ROW()-1))+SUM(cf_2!$S$9:INDEX(cf_2!$S$9:$EO$9,1,ROW()-1))-SUM(cf_1!$S$209:INDEX(cf_1!$S$209:$EO$209,1,ROW()-1))-SUM(cf_2!$S$209:INDEX(cf_2!$S$209:$EO$209,1,ROW()-1)))/1000000 -> 0 | BF3: =(SUM(cf_1!$S$183:INDEX(cf_1!$S$183:$EO$183,1,ROW()-1))+SUM(cf_2!$S$183:INDEX(cf_2!$S$183:$EO$183,1,ROW()-1)))/1000000 -> 0 | BG3: =(INDEX(КРЕДИТЫ!$S$52:$EO$52,1,ROW()-1)+INDEX(КРЕДИТЫ!$S$75:$EO$75,1,ROW()-1))/1000000 -> 0
B4: Поступления | C4: =SUM(C5:C12) -> 21875.892 | D4: =IFERROR(C4/$L$4*1000,0) -> 673.66404 | E4: =IFERROR(C4/$I$4*1000,0) -> 521.22688 | G4: ИТОГО | H4: =H5+H16+H9+H10+H11 -> 46011 | I4: =I5+I16+I9+I10+I11 -> 41970 | K4: =K5+K16+K9+K10+K11 -> 32473 | L4: =L5+L16+L9+L10+L11 -> 32473 | AZ4: ='План продаж'!B24 -> 46327 | BA4: =IFERROR('План продаж'!G24,0) -> 0 | BB4: =IFERROR('План продаж'!I24/1000,0) -> 0 | BD4: =INDEX(КРЕДИТЫ!$S$3:$EO$3,1,ROW()-1) -> 46327 | BE4: =(SUM(cf_1!$S$9:INDEX(cf_1!$S$9:$EO$9,1,ROW()-1))+SUM(cf_2!$S$9:INDEX(cf_2!$S$9:$EO$9,1,ROW()-1))-SUM(cf_1!$S$209:INDEX(cf_1!$S$209:$EO$209,1,ROW()-1))-SUM(cf_2!$S$209:INDEX(cf_2!$S$209:$EO$209,1,ROW()-1)))/1000000 -> 0 | BF4: =(SUM(cf_1!$S$183:INDEX(cf_1!$S$183:$EO$183,1,ROW()-1))+SUM(cf_2!$S$183:INDEX(cf_2!$S$183:$EO$183,1,ROW()-1)))/1000000 -> 0.84525 | BG4: =(INDEX(КРЕДИТЫ!$S$52:$EO$52,1,ROW()-1)+INDEX(КРЕДИТЫ!$S$75:$EO$75,1,ROW()-1))/1000000 -> 0
B5: Квартиры | C5: =CF!I13 -> 19471.203 | D5: =IFERROR(C5/$L$7*1000,0) -> 788.59515 | E5: =IFERROR(C5/$H$7*1000,0) -> 512.58892 | G5: Основные объекты | H5: =H6+H13 -> 46011 | I5: =I6+I13 -> 41970 | K5: =K6+K13 -> 32473 | L5: =L6+L13 -> 32473 | M5: =M6+M13 -> 0 | AZ5: ='План продаж'!B25 -> 46357 | BA5: =IFERROR('План продаж'!G25,0) -> 0 | BB5: =IFERROR('План продаж'!I25/1000,0) -> 0 | BD5: =INDEX(КРЕДИТЫ!$S$3:$EO$3,1,ROW()-1) -> 46357 | BE5: =(SUM(cf_1!$S$9:INDEX(cf_1!$S$9:$EO$9,1,ROW()-1))+SUM(cf_2!$S$9:INDEX(cf_2!$S$9:$EO$9,1,ROW()-1))-SUM(cf_1!$S$209:INDEX(cf_1!$S$209:$EO$209,1,ROW()-1))-SUM(cf_2!$S$209:INDEX(cf_2!$S$209:$EO$209,1,ROW()-1)))/1000000 -> 0 | BF5: =(SUM(cf_1!$S$183:INDEX(cf_1!$S$183:$EO$183,1,ROW()-1))+SUM(cf_2!$S$183:INDEX(cf_2!$S$183:$EO$183,1,ROW()-1)))/1000000 -> 701.6905 | BG5: =(INDEX(КРЕДИТЫ!$S$52:$EO$52,1,ROW()-1)+INDEX(КРЕДИТЫ!$S$75:$EO$75,1,ROW()-1))/1000000 -> 0
B6: Коммерция 1 эт. | C6: =CF!I14 -> 1656.9844 | D6: =IFERROR(C6/$L$8*1000,0) -> 759.38792 | E6: =IFERROR(C6/$H$8*1000,0) -> 683.29256 | G6: Наземная часть | H6: =SUM(H7:H8) -> 40411 | I6: =SUM(I7:I8) -> 36370 | J6: =IFERROR(K6/I6,0) -> 0.7388782 | K6: =SUM(K7:K8) -> 26873 | L6: =SUM(L7:L8) -> 26873 | M6: =SUM(M7:M8) -> 0 | AZ6: ='План продаж'!B26 -> 46388 | BA6: =IFERROR('План продаж'!G26,0) -> 0 | BB6: =IFERROR('План продаж'!I26/1000,0) -> 0 | BD6: =INDEX(КРЕДИТЫ!$S$3:$EO$3,1,ROW()-1) -> 46388 | BE6: =(SUM(cf_1!$S$9:INDEX(cf_1!$S$9:$EO$9,1,ROW()-1))+SUM(cf_2!$S$9:INDEX(cf_2!$S$9:$EO$9,1,ROW()-1))-SUM(cf_1!$S$209:INDEX(cf_1!$S$209:$EO$209,1,ROW()-1))-SUM(cf_2!$S$209:INDEX(cf_2!$S$209:$EO$209,1,ROW()-1)))/1000000 -> 0 | BF6: =(SUM(cf_1!$S$183:INDEX(cf_1!$S$183:$EO$183,1,ROW()-1))+SUM(cf_2!$S$183:INDEX(cf_2!$S$183:$EO$183,1,ROW()-1)))/1000000 -> 702.53575 | BG6: =(INDEX(КРЕДИТЫ!$S$52:$EO$52,1,ROW()-1)+INDEX(КРЕДИТЫ!$S$75:$EO$75,1,ROW()-1))/1000000 -> 0
B7: Коммерция ОСЗ | C7: =CF!I7 -> 0 | D7: =IFERROR(C7/$L$4*1000,0) -> 0 | E7: =IFERROR(C7/$I$4*1000,0) -> 0 | G7: Квартиры | H7: =ТЭП!C7 -> 37986 | I7: =ТЭП!D7 -> 34188 | J7: =IFERROR(K7/I7,0) -> 0.72221247 | K7: =ТЭП!F7 -> 24691 | L7: =ТЭП!G7 -> 24691 | M7: =ТЭП!H7 -> 0 | N7: =ТЭП!I7 -> 357 | O7: =K7/N7 -> 69.162465 | AZ7: ='План продаж'!B27 -> 46419 | BA7: =IFERROR('План продаж'!G27,0) -> 0 | BB7: =IFERROR('План продаж'!I27/1000,0) -> 0 | BD7: =INDEX(КРЕДИТЫ!$S$3:$EO$3,1,ROW()-1) -> 46419 | BE7: =(SUM(cf_1!$S$9:INDEX(cf_1!$S$9:$EO$9,1,ROW()-1))+SUM(cf_2!$S$9:INDEX(cf_2!$S$9:$EO$9,1,ROW()-1))-SUM(cf_1!$S$209:INDEX(cf_1!$S$209:$EO$209,1,ROW()-1))-SUM(cf_2!$S$209:INDEX(cf_2!$S$209:$EO$209,1,ROW()-1)))/1000000 -> 0 | BF7: =(SUM(cf_1!$S$183:INDEX(cf_1!$S$183:$EO$183,1,ROW()-1))+SUM(cf_2!$S$183:INDEX(cf_2!$S$183:$EO$183,1,ROW()-1)))/1000000 -> 703.381 | BG7: =(INDEX(КРЕДИТЫ!$S$52:$EO$52,1,ROW()-1)+INDEX(КРЕДИТЫ!$S$75:$EO$75,1,ROW()-1))/1000000 -> 0
B8: Офисы | C8: =CF!I6 -> 0 | D8: =IFERROR(C8/$L$10*1000,0) -> 0 | E8: =IFERROR(C8/$H$10*1000,0) -> 0 | G8: Коммерция 1 эт. | H8: =ТЭП!C8 -> 2425 | I8: =ТЭП!D8 -> 2182 | J8: =IFERROR(K8/I8,0) -> 1 | K8: =ТЭП!F8 -> 2182 | L8: =ТЭП!G8 -> 2182 | M8: =ТЭП!H8 -> 0 | N8: =ТЭП!I8 -> 0 | AZ8: ='План продаж'!B28 -> 46447 | BA8: =IFERROR('План продаж'!G28,0) -> 0 | BB8: =IFERROR('План продаж'!I28/1000,0) -> 0 | BD8: =INDEX(КРЕДИТЫ!$S$3:$EO$3,1,ROW()-1) -> 46447 | BE8: =(SUM(cf_1!$S$9:INDEX(cf_1!$S$9:$EO$9,1,ROW()-1))+SUM(cf_2!$S$9:INDEX(cf_2!$S$9:$EO$9,1,ROW()-1))-SUM(cf_1!$S$209:INDEX(cf_1!$S$209:$EO$209,1,ROW()-1))-SUM(cf_2!$S$209:INDEX(cf_2!$S$209:$EO$209,1,ROW()-1)))/1000000 -> 0 | BF8: =(SUM(cf_1!$S$183:INDEX(cf_1!$S$183:$EO$183,1,ROW()-1))+SUM(cf_2!$S$183:INDEX(cf_2!$S$183:$EO$183,1,ROW()-1)))/1000000 -> 704.22625 | BG8: =(INDEX(КРЕДИТЫ!$S$52:$EO$52,1,ROW()-1)+INDEX(КРЕДИТЫ!$S$75:$EO$75,1,ROW()-1))/1000000 -> 0
B9: Подземный паркинг | C9: =CF!I16 -> 747.70503 | D9: =IFERROR(C9/$L$14*1000,0) -> 133.51876 | E9: =IFERROR(C9/$I$14*1000,0) -> 133.51876 | G9: Коммерция ОСЗ | H9: =ТЭП!C9 -> 0 | I9: =ТЭП!D9 -> 0 | J9: =IFERROR(K9/I9,0) -> 0 | K9: =ТЭП!F9 -> 0 | L9: =ТЭП!G9 -> 0 | M9: =ТЭП!H9 -> 0 | N9: =ТЭП!I9 -> 0 | AZ9: ='План продаж'!B29 -> 46478 | BA9: =IFERROR('План продаж'!G29,0) -> 0 | BB9: =IFERROR('План продаж'!I29/1000,0) -> 0 | BD9: =INDEX(КРЕДИТЫ!$S$3:$EO$3,1,ROW()-1) -> 46478 | BE9: =(SUM(cf_1!$S$9:INDEX(cf_1!$S$9:$EO$9,1,ROW()-1))+SUM(cf_2!$S$9:INDEX(cf_2!$S$9:$EO$9,1,ROW()-1))-SUM(cf_1!$S$209:INDEX(cf_1!$S$209:$EO$209,1,ROW()-1))-SUM(cf_2!$S$209:INDEX(cf_2!$S$209:$EO$209,1,ROW()-1)))/1000000 -> 0 | BF9: =(SUM(cf_1!$S$183:INDEX(cf_1!$S$183:$EO$183,1,ROW()-1))+SUM(cf_2!$S$183:INDEX(cf_2!$S$183:$EO$183,1,ROW()-1)))/1000000 -> 705.0715 | BG9: =(INDEX(КРЕДИТЫ!$S$52:$EO$52,1,ROW()-1)+INDEX(КРЕДИТЫ!$S$75:$EO$75,1,ROW()-1))/1000000 -> 0
B10: Наземный паркинг | C10: =CF!I15 -> 0 | D10: =IFERROR(C10/$L$4*1000,0) -> 0 | E10: =IFERROR(C10/$I$4*1000,0) -> 0 | G10: Офисы | H10: =ТЭП!C10 -> 0 | I10: =ТЭП!D10 -> 0 | J10: =IFERROR(K10/I10,0) -> 0 | K10: =ТЭП!F10 -> 0 | L10: =ТЭП!G10 -> 0 | M10: =ТЭП!H10 -> 0 | N10: =ТЭП!I10 -> 0 | AZ10: ='План продаж'!B30 -> 46508 | BA10: =IFERROR('План продаж'!G30,0) -> 0 | BB10: =IFERROR('План продаж'!I30/1000,0) -> 0 | BD10: =INDEX(КРЕДИТЫ!$S$3:$EO$3,1,ROW()-1) -> 46508 | BE10: =(SUM(cf_1!$S$9:INDEX(cf_1!$S$9:$EO$9,1,ROW()-1))+SUM(cf_2!$S$9:INDEX(cf_2!$S$9:$EO$9,1,ROW()-1))-SUM(cf_1!$S$209:INDEX(cf_1!$S$209:$EO$209,1,ROW()-1))-SUM(cf_2!$S$209:INDEX(cf_2!$S$209:$EO$209,1,ROW()-1)))/1000000 -> 0 | BF10: =(SUM(cf_1!$S$183:INDEX(cf_1!$S$183:$EO$183,1,ROW()-1))+SUM(cf_2!$S$183:INDEX(cf_2!$S$183:$EO$183,1,ROW()-1)))/1000000 -> 705.91675 | BG10: =(INDEX(КРЕДИТЫ!$S$52:$EO$52,1,ROW()-1)+INDEX(КРЕДИТЫ!$S$75:$EO$75,1,ROW()-1))/1000000 -> 0
B11: Кладовки | C11: =CF!I17 -> 0 | D11: =IFERROR(C11/$L$4*1000,0) -> 0 | E11: =IFERROR(C11/$I$4*1000,0) -> 0 | G11: Наземный паркинг | H11: =ТЭП!C11 -> 0 | I11: =ТЭП!D11 -> 0 | J11: =IFERROR(K11/I11,0) -> 0 | K11: =ТЭП!F11 -> 0 | L11: =ТЭП!G11 -> 0 | M11: =ТЭП!H11 -> 0 | N11: =ТЭП!I11 -> 0 | AZ11: ='План продаж'!B31 -> 46539 | BA11: =IFERROR('План продаж'!G31,0) -> 0 | BB11: =IFERROR('План продаж'!I31/1000,0) -> 0 | BD11: =INDEX(КРЕДИТЫ!$S$3:$EO$3,1,ROW()-1) -> 46539 | BE11: =(SUM(cf_1!$S$9:INDEX(cf_1!$S$9:$EO$9,1,ROW()-1))+SUM(cf_2!$S$9:INDEX(cf_2!$S$9:$EO$9,1,ROW()-1))-SUM(cf_1!$S$209:INDEX(cf_1!$S$209:$EO$209,1,ROW()-1))-SUM(cf_2!$S$209:INDEX(cf_2!$S$209:$EO$209,1,ROW()-1)))/1000000 -> 0 | BF11: =(SUM(cf_1!$S$183:INDEX(cf_1!$S$183:$EO$183,1,ROW()-1))+SUM(cf_2!$S$183:INDEX(cf_2!$S$183:$EO$183,1,ROW()-1)))/1000000 -> 706.762 | BG11: =(INDEX(КРЕДИТЫ!$S$52:$EO$52,1,ROW()-1)+INDEX(КРЕДИТЫ!$S$75:$EO$75,1,ROW()-1))/1000000 -> 0
B12: Прочие | C12: =SUM(CF!I8:I10) -> 0 | D12: =IFERROR(C12/$L$4*1000,0) -> 0 | E12: =IFERROR(C12/$I$4*1000,0) -> 0 | G12: Прочие | H12: =ТЭП!C12 -> 0 | I12: =ТЭП!D12 -> 0 | J12: =IFERROR(K12/I12,0) -> 0 | K12: =ТЭП!F12 -> 0 | L12: =ТЭП!G12 -> 0 | M12: =ТЭП!H12 -> 0 | N12: =ТЭП!I12 -> 0 | AZ12: ='План продаж'!B32 -> 46569 | BA12: =IFERROR('План продаж'!G32,0) -> 0 | BB12: =IFERROR('План продаж'!I32/1000,0) -> 0 | BD12: =INDEX(КРЕДИТЫ!$S$3:$EO$3,1,ROW()-1) -> 46569 | BE12: =(SUM(cf_1!$S$9:INDEX(cf_1!$S$9:$EO$9,1,ROW()-1))+SUM(cf_2!$S$9:INDEX(cf_2!$S$9:$EO$9,1,ROW()-1))-SUM(cf_1!$S$209:INDEX(cf_1!$S$209:$EO$209,1,ROW()-1))-SUM(cf_2!$S$209:INDEX(cf_2!$S$209:$EO$209,1,ROW()-1)))/1000000 -> 0 | BF12: =(SUM(cf_1!$S$183:INDEX(cf_1!$S$183:$EO$183,1,ROW()-1))+SUM(cf_2!$S$183:INDEX(cf_2!$S$183:$EO$183,1,ROW()-1)))/1000000 -> 707.60725 | BG12: =(INDEX(КРЕДИТЫ!$S$52:$EO$52,1,ROW()-1)+INDEX(КРЕДИТЫ!$S$75:$EO$75,1,ROW()-1))/1000000 -> 0
B13: Расходы | C13: =SUM(C14:C20)+SUM(C22:C23) -> -19026.086 | D13: =IFERROR(C13/$L$4*1000,0) -> -585.90477 | E13: =IFERROR(C13/$I$4*1000,0) -> -453.32584 | G13: Подземная часть | H13: =SUM(H14:H15) -> 5600 | I13: =SUM(I14:I15) -> 5600 | K13: =SUM(K14:K15) -> 5600 | L13: =SUM(L14:L15) -> 5600 | M13: =SUM(M14:M15) -> 0 | AZ13: ='План продаж'!B33 -> 46600 | BA13: =IFERROR('План продаж'!G33,0) -> 0 | BB13: =IFERROR('План продаж'!I33/1000,0) -> 0 | BD13: =INDEX(КРЕДИТЫ!$S$3:$EO$3,1,ROW()-1) -> 46600 | BE13: =(SUM(cf_1!$S$9:INDEX(cf_1!$S$9:$EO$9,1,ROW()-1))+SUM(cf_2!$S$9:INDEX(cf_2!$S$9:$EO$9,1,ROW()-1))-SUM(cf_1!$S$209:INDEX(cf_1!$S$209:$EO$209,1,ROW()-1))-SUM(cf_2!$S$209:INDEX(cf_2!$S$209:$EO$209,1,ROW()-1)))/1000000 -> 0 | BF13: =(SUM(cf_1!$S$183:INDEX(cf_1!$S$183:$EO$183,1,ROW()-1))+SUM(cf_2!$S$183:INDEX(cf_2!$S$183:$EO$183,1,ROW()-1)))/1000000 -> 708.4525 | BG13: =(INDEX(КРЕДИТЫ!$S$52:$EO$52,1,ROW()-1)+INDEX(КРЕДИТЫ!$S$75:$EO$75,1,ROW()-1))/1000000 -> 0
B14: Вход | C14: =-Вводные!G6 -> -700 | D14: =IFERROR(C14/$L$4*1000,0) -> -21.55637 | E14: =IFERROR(C14/$I$4*1000,0) -> -16.67858 | G14: Подземный паркинг | H14: =ТЭП!C14 -> 5600 | I14: =ТЭП!D14 -> 5600 | K14: =ТЭП!F14 -> 5600 | L14: =ТЭП!G14 -> 5600 | M14: =ТЭП!H14 -> 0 | N14: =ТЭП!I14 -> 160 | AZ14: ='План продаж'!B34 -> 46631 | BA14: =IFERROR('План продаж'!G34,0) -> 0 | BB14: =IFERROR('План продаж'!I34/1000,0) -> 0 | BD14: =INDEX(КРЕДИТЫ!$S$3:$EO$3,1,ROW()-1) -> 46631 | BE14: =(SUM(cf_1!$S$9:INDEX(cf_1!$S$9:$EO$9,1,ROW()-1))+SUM(cf_2!$S$9:INDEX(cf_2!$S$9:$EO$9,1,ROW()-1))-SUM(cf_1!$S$209:INDEX(cf_1!$S$209:$EO$209,1,ROW()-1))-SUM(cf_2!$S$209:INDEX(cf_2!$S$209:$EO$209,1,ROW()-1)))/1000000 -> 0 | BF14: =(SUM(cf_1!$S$183:INDEX(cf_1!$S$183:$EO$183,1,ROW()-1))+SUM(cf_2!$S$183:INDEX(cf_2!$S$183:$EO$183,1,ROW()-1)))/1000000 -> 764.65473 | BG14: =(INDEX(КРЕДИТЫ!$S$52:$EO$52,1,ROW()-1)+INDEX(КРЕДИТЫ!$S$75:$EO$75,1,ROW()-1))/1000000 -> 0
B15: Обременения / денежная компенсация | C15: =IF(Вводные!G82="Денежная компенсация",-Вводные!G100,0) -> -988.447 | D15: =IFERROR(C15/$L$4*1000,0) -> -30.439042 | E15: =IFERROR(C15/$I$4*1000,0) -> -23.551275 | G15: Кладовки | H15: =ТЭП!C15 -> 0 | I15: =ТЭП!D15 -> 0 | K15: =ТЭП!F15 -> 0 | L15: =ТЭП!G15 -> 0 | M15: =ТЭП!H15 -> 0 | N15: =ТЭП!I15 -> 0 | AZ15: ='План продаж'!B35 -> 46661 | BA15: =IFERROR('План продаж'!G35,0) -> 0 | BB15: =IFERROR('План продаж'!I35/1000,0) -> 0 | BD15: =INDEX(КРЕДИТЫ!$S$3:$EO$3,1,ROW()-1) -> 46661 | BE15: =(SUM(cf_1!$S$9:INDEX(cf_1!$S$9:$EO$9,1,ROW()-1))+SUM(cf_2!$S$9:INDEX(cf_2!$S$9:$EO$9,1,ROW()-1))-SUM(cf_1!$S$209:INDEX(cf_1!$S$209:$EO$209,1,ROW()-1))-SUM(cf_2!$S$209:INDEX(cf_2!$S$209:$EO$209,1,ROW()-1)))/1000000 -> 0 | BF15: =(SUM(cf_1!$S$183:INDEX(cf_1!$S$183:$EO$183,1,ROW()-1))+SUM(cf_2!$S$183:INDEX(cf_2!$S$183:$EO$183,1,ROW()-1)))/1000000 -> 795.49341 | BG15: =(INDEX(КРЕДИТЫ!$S$52:$EO$52,1,ROW()-1)+INDEX(КРЕДИТЫ!$S$75:$EO$75,1,ROW()-1))/1000000 -> 0
B16: Расходы на ЗУ | C16: =CF!I27+CF!I29 -> -2169.2493 | D16: =IFERROR(C16/$L$4*1000,0) -> -66.80163 | E16: =IFERROR(C16/$I$4*1000,0) -> -51.685712 | G16: Социальные объекты | H16: =SUM(H17:H19) -> 0 | I16: =SUM(I17:I19) -> 0 | K16: =SUM(K17:K19) -> 0 | L16: =SUM(L17:L19) -> 0 | M16: =SUM(M17:M19) -> 0 | N16: =SUM(N17:N19) -> 0 | AZ16: ='План продаж'!B36 -> 46692 | BA16: =IFERROR('План продаж'!G36,0) -> 0 | BB16: =IFERROR('План продаж'!I36/1000,0) -> 0 | BD16: =INDEX(КРЕДИТЫ!$S$3:$EO$3,1,ROW()-1) -> 46692 | BE16: =(SUM(cf_1!$S$9:INDEX(cf_1!$S$9:$EO$9,1,ROW()-1))+SUM(cf_2!$S$9:INDEX(cf_2!$S$9:$EO$9,1,ROW()-1))-SUM(cf_1!$S$209:INDEX(cf_1!$S$209:$EO$209,1,ROW()-1))-SUM(cf_2!$S$209:INDEX(cf_2!$S$209:$EO$209,1,ROW()-1)))/1000000 -> 0 | BF16: =(SUM(cf_1!$S$183:INDEX(cf_1!$S$183:$EO$183,1,ROW()-1))+SUM(cf_2!$S$183:INDEX(cf_2!$S$183:$EO$183,1,ROW()-1)))/1000000 -> 826.33208 | BG16: =(INDEX(КРЕДИТЫ!$S$52:$EO$52,1,ROW()-1)+INDEX(КРЕДИТЫ!$S$75:$EO$75,1,ROW()-1))/1000000 -> 0
B17: Строительство соцобъектов | C17: =IF(Вводные!G82="Строительство",SUM(CF!I36:I38),0) -> 0 | D17: =IFERROR(C17/$L$4*1000,0) -> 0 | E17: =IFERROR(C17/$I$4*1000,0) -> 0 | G17: ДОУ | H17: =ТЭП!C17 -> 0 | I17: =ТЭП!D17 -> 0 | K17: =ТЭП!F17 -> 0 | L17: =ТЭП!G17 -> 0 | M17: =ТЭП!H17 -> 0 | N17: =ТЭП!I17 -> 0 | AZ17: ='План продаж'!B37 -> 46722 | BA17: =IFERROR('План продаж'!G37,0) -> 0 | BB17: =IFERROR('План продаж'!I37/1000,0) -> 0 | BD17: =INDEX(КРЕДИТЫ!$S$3:$EO$3,1,ROW()-1) -> 46722 | BE17: =(SUM(cf_1!$S$9:INDEX(cf_1!$S$9:$EO$9,1,ROW()-1))+SUM(cf_2!$S$9:INDEX(cf_2!$S$9:$EO$9,1,ROW()-1))-SUM(cf_1!$S$209:INDEX(cf_1!$S$209:$EO$209,1,ROW()-1))-SUM(cf_2!$S$209:INDEX(cf_2!$S$209:$EO$209,1,ROW()-1)))/1000000 -> 0 | BF17: =(SUM(cf_1!$S$183:INDEX(cf_1!$S$183:$EO$183,1,ROW()-1))+SUM(cf_2!$S$183:INDEX(cf_2!$S$183:$EO$183,1,ROW()-1)))/1000000 -> 957.6069 | BG17: =(INDEX(КРЕДИТЫ!$S$52:$EO$52,1,ROW()-1)+INDEX(КРЕДИТЫ!$S$75:$EO$75,1,ROW()-1))/1000000 -> 0
B18: Расходы на строительство (+расшифровка) | C18: =C33 -> -10742.812 | D18: =IFERROR(C18/$L$4*1000,0) -> -330.82291 | E18: =IFERROR(C18/$I$4*1000,0) -> -255.96408 | G18: СОШ | H18: =ТЭП!C18 -> 0 | I18: =ТЭП!D18 -> 0 | K18: =ТЭП!F18 -> 0 | L18: =ТЭП!G18 -> 0 | M18: =ТЭП!H18 -> 0 | N18: =ТЭП!I18 -> 0 | AZ18: ='План продаж'!B38 -> 46753 | BA18: =IFERROR('План продаж'!G38,0) -> 0 | BB18: =IFERROR('План продаж'!I38/1000,0) -> 0 | BD18: =INDEX(КРЕДИТЫ!$S$3:$EO$3,1,ROW()-1) -> 46753 | BE18: =(SUM(cf_1!$S$9:INDEX(cf_1!$S$9:$EO$9,1,ROW()-1))+SUM(cf_2!$S$9:INDEX(cf_2!$S$9:$EO$9,1,ROW()-1))-SUM(cf_1!$S$209:INDEX(cf_1!$S$209:$EO$209,1,ROW()-1))-SUM(cf_2!$S$209:INDEX(cf_2!$S$209:$EO$209,1,ROW()-1)))/1000000 -> 0 | BF18: =(SUM(cf_1!$S$183:INDEX(cf_1!$S$183:$EO$183,1,ROW()-1))+SUM(cf_2!$S$183:INDEX(cf_2!$S$183:$EO$183,1,ROW()-1)))/1000000 -> 1003.1287 | BG18: =(INDEX(КРЕДИТЫ!$S$52:$EO$52,1,ROW()-1)+INDEX(КРЕДИТЫ!$S$75:$EO$75,1,ROW()-1))/1000000 -> 0
B19: Управление проектом (+расшифровка) | C19: =C46 -> -511.56249 | D19: =IFERROR(C19/$L$4*1000,0) -> -15.753472 | E19: =IFERROR(C19/$I$4*1000,0) -> -12.188766 | G19: Поликлиника | H19: =ТЭП!C19 -> 0 | I19: =ТЭП!D19 -> 0 | K19: =ТЭП!F19 -> 0 | L19: =ТЭП!G19 -> 0 | M19: =ТЭП!H19 -> 0 | N19: =ТЭП!I19 -> 0 | AZ19: ='План продаж'!B39 -> 46784 | BA19: =IFERROR('План продаж'!G39,0) -> 0 | BB19: =IFERROR('План продаж'!I39/1000,0) -> 0 | BD19: =INDEX(КРЕДИТЫ!$S$3:$EO$3,1,ROW()-1) -> 46784 | BE19: =(SUM(cf_1!$S$9:INDEX(cf_1!$S$9:$EO$9,1,ROW()-1))+SUM(cf_2!$S$9:INDEX(cf_2!$S$9:$EO$9,1,ROW()-1))-SUM(cf_1!$S$209:INDEX(cf_1!$S$209:$EO$209,1,ROW()-1))-SUM(cf_2!$S$209:INDEX(cf_2!$S$209:$EO$209,1,ROW()-1)))/1000000 -> 0 | BF19: =(SUM(cf_1!$S$183:INDEX(cf_1!$S$183:$EO$183,1,ROW()-1))+SUM(cf_2!$S$183:INDEX(cf_2!$S$183:$EO$183,1,ROW()-1)))/1000000 -> 1048.6505 | BG19: =(INDEX(КРЕДИТЫ!$S$52:$EO$52,1,ROW()-1)+INDEX(КРЕДИТЫ!$S$75:$EO$75,1,ROW()-1))/1000000 -> 0
B20: Коммерческие | C20: =CF!I22 -> -1531.3125 | D20: =IFERROR(C20/$L$4*1000,0) -> -47.156483 | E20: =IFERROR(C20/$I$4*1000,0) -> -36.485882 | AZ20: ='План продаж'!B40 -> 46813 | BA20: =IFERROR('План продаж'!G40,0) -> 832.62485 | BB20: =IFERROR('План продаж'!I40/1000,0) -> 675 | BD20: =INDEX(КРЕДИТЫ!$S$3:$EO$3,1,ROW()-1) -> 46813 | BE20: =(SUM(cf_1!$S$9:INDEX(cf_1!$S$9:$EO$9,1,ROW()-1))+SUM(cf_2!$S$9:INDEX(cf_2!$S$9:$EO$9,1,ROW()-1))-SUM(cf_1!$S$209:INDEX(cf_1!$S$209:$EO$209,1,ROW()-1))-SUM(cf_2!$S$209:INDEX(cf_2!$S$209:$EO$209,1,ROW()-1)))/1000000 -> 541.50786 | BF20: =(SUM(cf_1!$S$183:INDEX(cf_1!$S$183:$EO$183,1,ROW()-1))+SUM(cf_2!$S$183:INDEX(cf_2!$S$183:$EO$183,1,ROW()-1)))/1000000 -> 2372.4516 | BG20: =(INDEX(КРЕДИТЫ!$S$52:$EO$52,1,ROW()-1)+INDEX(КРЕДИТЫ!$S$75:$EO$75,1,ROW()-1))/1000000 -> 2573.0352
B21: EBITDA | C21: =C4+SUM(C14:C20) -> 5232.5088 | D21: =IFERROR(C21/$L$4*1000,0) -> 161.13413 | E21: =IFERROR(C21/$I$4*1000,0) -> 124.67259 | AZ21: ='План продаж'!B41 -> 46844 | BA21: =IFERROR('План продаж'!G41,0) -> 841.29802 | BB21: =IFERROR('План продаж'!I41/1000,0) -> 682.41948 | BD21: =INDEX(КРЕДИТЫ!$S$3:$EO$3,1,ROW()-1) -> 46844 | BE21: =(SUM(cf_1!$S$9:INDEX(cf_1!$S$9:$EO$9,1,ROW()-1))+SUM(cf_2!$S$9:INDEX(cf_2!$S$9:$EO$9,1,ROW()-1))-SUM(cf_1!$S$209:INDEX(cf_1!$S$209:$EO$209,1,ROW()-1))-SUM(cf_2!$S$209:INDEX(cf_2!$S$209:$EO$209,1,ROW()-1)))/1000000 -> 1095.5698 | BF21: =(SUM(cf_1!$S$183:INDEX(cf_1!$S$183:$EO$183,1,ROW()-1))+SUM(cf_2!$S$183:INDEX(cf_2!$S$183:$EO$183,1,ROW()-1)))/1000000 -> 3785.525 | BG21: =(INDEX(КРЕДИТЫ!$S$52:$EO$52,1,ROW()-1)+INDEX(КРЕДИТЫ!$S$75:$EO$75,1,ROW()-1))/1000000 -> 3986.1086
B22: %% по кредитам | C22: =CF!I52 -> -1432.7396 | D22: =IFERROR(C22/$L$4*1000,0) -> -44.120948 | E22: =IFERROR(C22/$I$4*1000,0) -> -34.13723 | G22: Темп продаж | K22: Цены продаж | AZ22: ='План продаж'!B42 -> 46874 | BA22: =IFERROR('План продаж'!G42,0) -> 722.47552 | BB22: =IFERROR('План продаж'!I42/1000,0) -> 689.9205 | BD22: =INDEX(КРЕДИТЫ!$S$3:$EO$3,1,ROW()-1) -> 46874 | BE22: =(SUM(cf_1!$S$9:INDEX(cf_1!$S$9:$EO$9,1,ROW()-1))+SUM(cf_2!$S$9:INDEX(cf_2!$S$9:$EO$9,1,ROW()-1))-SUM(cf_1!$S$209:INDEX(cf_1!$S$209:$EO$209,1,ROW()-1))-SUM(cf_2!$S$209:INDEX(cf_2!$S$209:$EO$209,1,ROW()-1)))/1000000 -> 1577.6448 | BF22: =(SUM(cf_1!$S$183:INDEX(cf_1!$S$183:$EO$183,1,ROW()-1))+SUM(cf_2!$S$183:INDEX(cf_2!$S$183:$EO$183,1,ROW()-1)))/1000000 -> 4204.1124 | BG22: =(INDEX(КРЕДИТЫ!$S$52:$EO$52,1,ROW()-1)+INDEX(КРЕДИТЫ!$S$75:$EO$75,1,ROW()-1))/1000000 -> 4404.6961
B23: Налог на прибыль / прочие налоги | C23: =CF!I24 -> -949.96238 | D23: =IFERROR(C23/$L$4*1000,0) -> -29.253915 | E23: =IFERROR(C23/$I$4*1000,0) -> -22.634319 | G23: Объект недвижимости | H23: кв.м./мес | I23: шт/мес | J23: % до РНВ | K23: Объект недвижимости | L23: Цена, тыс. руб./кв.м. | AZ23: ='План продаж'!B43 -> 46905 | BA23: =IFERROR('План продаж'!G43,0) -> 729.84772 | BB23: =IFERROR('План продаж'!I43/1000,0) -> 697.50398 | BD23: =INDEX(КРЕДИТЫ!$S$3:$EO$3,1,ROW()-1) -> 46905 | BE23: =(SUM(cf_1!$S$9:INDEX(cf_1!$S$9:$EO$9,1,ROW()-1))+SUM(cf_2!$S$9:INDEX(cf_2!$S$9:$EO$9,1,ROW()-1))-SUM(cf_1!$S$209:INDEX(cf_1!$S$209:$EO$209,1,ROW()-1))-SUM(cf_2!$S$209:INDEX(cf_2!$S$209:$EO$209,1,ROW()-1)))/1000000 -> 2070.7506 | BF23: =(SUM(cf_1!$S$183:INDEX(cf_1!$S$183:$EO$183,1,ROW()-1))+SUM(cf_2!$S$183:INDEX(cf_2!$S$183:$EO$183,1,ROW()-1)))/1000000 -> 4622.6999 | BG23: =(INDEX(КРЕДИТЫ!$S$52:$EO$52,1,ROW()-1)+INDEX(КРЕДИТЫ!$S$75:$EO$75,1,ROW()-1))/1000000 -> 4823.2835
B24: Чистая прибыль | C24: =C4+C13 -> 2849.8068 | D24: =IFERROR(C24/$L$4*1000,0) -> 87.759272 | E24: =IFERROR(C24/$I$4*1000,0) -> 67.901044 | L24: Старт | M24: Финиш | O24: Средняя | AZ24: ='План продаж'!B44 -> 46935 | BA24: =IFERROR('План продаж'!G44,0) -> 737.21991 | BB24: =IFERROR('План продаж'!I44/1000,0) -> 705.17082 | BD24: =INDEX(КРЕДИТЫ!$S$3:$EO$3,1,ROW()-1) -> 46935 | BE24: =(SUM(cf_1!$S$9:INDEX(cf_1!$S$9:$EO$9,1,ROW()-1))+SUM(cf_2!$S$9:INDEX(cf_2!$S$9:$EO$9,1,ROW()-1))-SUM(cf_1!$S$209:INDEX(cf_1!$S$209:$EO$209,1,ROW()-1))-SUM(cf_2!$S$209:INDEX(cf_2!$S$209:$EO$209,1,ROW()-1)))/1000000 -> 2575.0712 | BF24: =(SUM(cf_1!$S$183:INDEX(cf_1!$S$183:$EO$183,1,ROW()-1))+SUM(cf_2!$S$183:INDEX(cf_2!$S$183:$EO$183,1,ROW()-1)))/1000000 -> 5041.2873 | BG24: =(INDEX(КРЕДИТЫ!$S$52:$EO$52,1,ROW()-1)+INDEX(КРЕДИТЫ!$S$75:$EO$75,1,ROW()-1))/1000000 -> 5241.871
B25: Получение кредитов БРИДЖ | C25: =CF!I65 -> 1048.6505 | G25: Квартиры | H25: =cf_0!D23 -> 796.48387 | I25: =H25/O7 -> 11.516129 | J25: =cf_0!E23 -> 0 | K25: Квартиры | L25: =cf_0!E29/1000 -> 675 | M25: =cf_0!F29/1000 -> 890.56523 | O25: =C5/K7*1000 -> 788.59515 | AZ25: ='План продаж'!B45 -> 46966 | BA25: =IFERROR('План продаж'!G45,0) -> 744.59211 | BB25: =IFERROR('План продаж'!I45/1000,0) -> 712.92193 | BD25: =INDEX(КРЕДИТЫ!$S$3:$EO$3,1,ROW()-1) -> 46966 | BE25: =(SUM(cf_1!$S$9:INDEX(cf_1!$S$9:$EO$9,1,ROW()-1))+SUM(cf_2!$S$9:INDEX(cf_2!$S$9:$EO$9,1,ROW()-1))-SUM(cf_1!$S$209:INDEX(cf_1!$S$209:$EO$209,1,ROW()-1))-SUM(cf_2!$S$209:INDEX(cf_2!$S$209:$EO$209,1,ROW()-1)))/1000000 -> 3090.7932 | BF25: =(SUM(cf_1!$S$183:INDEX(cf_1!$S$183:$EO$183,1,ROW()-1))+SUM(cf_2!$S$183:INDEX(cf_2!$S$183:$EO$183,1,ROW()-1)))/1000000 -> 5459.8748 | BG25: =(INDEX(КРЕДИТЫ!$S$52:$EO$52,1,ROW()-1)+INDEX(КРЕДИТЫ!$S$75:$EO$75,1,ROW()-1))/1000000 -> 5660.4584
B26: Получение кредитов ПФ | C26: =CF!I66 -> 14264.843 | G26: Коммерция 1 эт. | H26: =cf_0!D24 -> 70.387097 | J26: =cf_0!E24 -> 0 | K26: Коммерция 1 эт. | L26: =cf_0!E30/1000 -> 650 | M26: =cf_0!F30/1000 -> 857.58134 | O26: =C6/K8*1000 -> 759.38792 | AZ26: ='План продаж'!B46 -> 46997 | BA26: =IFERROR('План продаж'!G46,0) -> 884.6639 | BB26: =IFERROR('План продаж'!I46/1000,0) -> 720.75823 | BD26: =INDEX(КРЕДИТЫ!$S$3:$EO$3,1,ROW()-1) -> 46997 | BE26: =(SUM(cf_1!$S$9:INDEX(cf_1!$S$9:$EO$9,1,ROW()-1))+SUM(cf_2!$S$9:INDEX(cf_2!$S$9:$EO$9,1,ROW()-1))-SUM(cf_1!$S$209:INDEX(cf_1!$S$209:$EO$209,1,ROW()-1))-SUM(cf_2!$S$209:INDEX(cf_2!$S$209:$EO$209,1,ROW()-1)))/1000000 -> 3710.2594 | BF26: =(SUM(cf_1!$S$183:INDEX(cf_1!$S$183:$EO$183,1,ROW()-1))+SUM(cf_2!$S$183:INDEX(cf_2!$S$183:$EO$183,1,ROW()-1)))/1000000 -> 5878.4622 | BG26: =(INDEX(КРЕДИТЫ!$S$52:$EO$52,1,ROW()-1)+INDEX(КРЕДИТЫ!$S$75:$EO$75,1,ROW()-1))/1000000 -> 6079.0459
B27: Маржинальность | C27: =IFERROR(C24/C4,0) -> 0.13027157 | G27: Коммерция ОСЗ | K27: Коммерция ОСЗ | AZ27: ='План продаж'!B47 -> 47027 | BA27: =IFERROR('План продаж'!G47,0) -> 893.33707 | BB27: =IFERROR('План продаж'!I47/1000,0) -> 728.68067 | BD27: =INDEX(КРЕДИТЫ!$S$3:$EO$3,1,ROW()-1) -> 47027 | BE27: =(SUM(cf_1!$S$9:INDEX(cf_1!$S$9:$EO$9,1,ROW()-1))+SUM(cf_2!$S$9:INDEX(cf_2!$S$9:$EO$9,1,ROW()-1))-SUM(cf_1!$S$209:INDEX(cf_1!$S$209:$EO$209,1,ROW()-1))-SUM(cf_2!$S$209:INDEX(cf_2!$S$209:$EO$209,1,ROW()-1)))/1000000 -> 4343.588 | BF27: =(SUM(cf_1!$S$183:INDEX(cf_1!$S$183:$EO$183,1,ROW()-1))+SUM(cf_2!$S$183:INDEX(cf_2!$S$183:$EO$183,1,ROW()-1)))/1000000 -> 6297.0497 | BG27: =(INDEX(КРЕДИТЫ!$S$52:$EO$52,1,ROW()-1)+INDEX(КРЕДИТЫ!$S$75:$EO$75,1,ROW()-1))/1000000 -> 6497.6333
B28: NPV @20% | C28: =CF!I95 -> 2680.6691 | G28: Офисы | K28: Офисы | AZ28: ='План продаж'!B48 -> 47058 | BA28: =IFERROR('План продаж'!G48,0) -> 902.01025 | BB28: =IFERROR('План продаж'!I48/1000,0) -> 736.6902 | BD28: =INDEX(КРЕДИТЫ!$S$3:$EO$3,1,ROW()-1) -> 47058 | BE28: =(SUM(cf_1!$S$9:INDEX(cf_1!$S$9:$EO$9,1,ROW()-1))+SUM(cf_2!$S$9:INDEX(cf_2!$S$9:$EO$9,1,ROW()-1))-SUM(cf_1!$S$209:INDEX(cf_1!$S$209:$EO$209,1,ROW()-1))-SUM(cf_2!$S$209:INDEX(cf_2!$S$209:$EO$209,1,ROW()-1)))/1000000 -> 4991.0084 | BF28: =(SUM(cf_1!$S$183:INDEX(cf_1!$S$183:$EO$183,1,ROW()-1))+SUM(cf_2!$S$183:INDEX(cf_2!$S$183:$EO$183,1,ROW()-1)))/1000000 -> 6715.6371 | BG28: =(INDEX(КРЕДИТЫ!$S$52:$EO$52,1,ROW()-1)+INDEX(КРЕДИТЫ!$S$75:$EO$75,1,ROW()-1))/1000000 -> 6916.2208
B29: IRR (акц) | C29: =CF!I96 -> N/A | G29: Наземный паркинг | K29: Наземный паркинг | AZ29: ='План продаж'!B49 -> 47088 | BA29: =IFERROR('План продаж'!G49,0) -> 910.68342 | BB29: =IFERROR('План продаж'!I49/1000,0) -> 744.78776 | BD29: =INDEX(КРЕДИТЫ!$S$3:$EO$3,1,ROW()-1) -> 47088 | BE29: =(SUM(cf_1!$S$9:INDEX(cf_1!$S$9:$EO$9,1,ROW()-1))+SUM(cf_2!$S$9:INDEX(cf_2!$S$9:$EO$9,1,ROW()-1))-SUM(cf_1!$S$209:INDEX(cf_1!$S$209:$EO$209,1,ROW()-1))-SUM(cf_2!$S$209:INDEX(cf_2!$S$209:$EO$209,1,ROW()-1)))/1000000 -> 5652.7533 | BF29: =(SUM(cf_1!$S$183:INDEX(cf_1!$S$183:$EO$183,1,ROW()-1))+SUM(cf_2!$S$183:INDEX(cf_2!$S$183:$EO$183,1,ROW()-1)))/1000000 -> 7134.2246 | BG29: =(INDEX(КРЕДИТЫ!$S$52:$EO$52,1,ROW()-1)+INDEX(КРЕДИТЫ!$S$75:$EO$75,1,ROW()-1))/1000000 -> 7334.8083
B30: LLCR | C30: =LLCR!C18 -> 1.1968375 | G30: Подземный паркинг | I30: =cf_0!D25 -> 5.1612903 | J30: =cf_0!E25 -> 0 | K30: Подземный паркинг | L30: =cf_0!E31/1000 -> 4000 | M30: =cf_0!F31/1000 -> 5277.4236 | O30: =C9/N14*1000 -> 4673.1564 | AZ30: ='План продаж'!B50 -> 47119 | BA30: =IFERROR('План продаж'!G50,0) -> 781.45311 | BB30: =IFERROR('План продаж'!I50/1000,0) -> 752.97433 | BD30: =INDEX(КРЕДИТЫ!$S$3:$EO$3,1,ROW()-1) -> 47119 | BE30: =(SUM(cf_1!$S$9:INDEX(cf_1!$S$9:$EO$9,1,ROW()-1))+SUM(cf_2!$S$9:INDEX(cf_2!$S$9:$EO$9,1,ROW()-1))-SUM(cf_1!$S$209:INDEX(cf_1!$S$209:$EO$209,1,ROW()-1))-SUM(cf_2!$S$209:INDEX(cf_2!$S$209:$EO$209,1,ROW()-1)))/1000000 -> 6229.0113 | BF30: =(SUM(cf_1!$S$183:INDEX(cf_1!$S$183:$EO$183,1,ROW()-1))+SUM(cf_2!$S$183:INDEX(cf_2!$S$183:$EO$183,1,ROW()-1)))/1000000 -> 7552.812 | BG30: =(INDEX(КРЕДИТЫ!$S$52:$EO$52,1,ROW()-1)+INDEX(КРЕДИТЫ!$S$75:$EO$75,1,ROW()-1))/1000000 -> 7753.3957
AZ31: ='План продаж'!B51 -> 47150 | BA31: =IFERROR('План продаж'!G51,0) -> 928.02978 | BB31: =IFERROR('План продаж'!I51/1000,0) -> 761.25088 | BD31: =INDEX(КРЕДИТЫ!$S$3:$EO$3,1,ROW()-1) -> 47150 | BE31: =(SUM(cf_1!$S$9:INDEX(cf_1!$S$9:$EO$9,1,ROW()-1))+SUM(cf_2!$S$9:INDEX(cf_2!$S$9:$EO$9,1,ROW()-1))-SUM(cf_1!$S$209:INDEX(cf_1!$S$209:$EO$209,1,ROW()-1))-SUM(cf_2!$S$209:INDEX(cf_2!$S$209:$EO$209,1,ROW()-1)))/1000000 -> 6919.9514 | BF31: =(SUM(cf_1!$S$183:INDEX(cf_1!$S$183:$EO$183,1,ROW()-1))+SUM(cf_2!$S$183:INDEX(cf_2!$S$183:$EO$183,1,ROW()-1)))/1000000 -> 7971.3995 | BG31: =(INDEX(КРЕДИТЫ!$S$52:$EO$52,1,ROW()-1)+INDEX(КРЕДИТЫ!$S$75:$EO$75,1,ROW()-1))/1000000 -> 8171.9832
B32: Расшифровка статей | C32: ИТОГО млн.р | D32: т. руб/кв.м NSA | E32: т. руб/кв.м GBA | G32: Себестоимость строительства | AZ32: ='План продаж'!B52 -> 47178 | BA32: =IFERROR('План продаж'!G52,0) -> 936.70295 | BB32: =IFERROR('План продаж'!I52/1000,0) -> 769.61841 | BD32: =INDEX(КРЕДИТЫ!$S$3:$EO$3,1,ROW()-1) -> 47178 | BE32: =(SUM(cf_1!$S$9:INDEX(cf_1!$S$9:$EO$9,1,ROW()-1))+SUM(cf_2!$S$9:INDEX(cf_2!$S$9:$EO$9,1,ROW()-1))-SUM(cf_1!$S$209:INDEX(cf_1!$S$209:$EO$209,1,ROW()-1))-SUM(cf_2!$S$209:INDEX(cf_2!$S$209:$EO$209,1,ROW()-1)))/1000000 -> 7625.935 | BF32: =(SUM(cf_1!$S$183:INDEX(cf_1!$S$183:$EO$183,1,ROW()-1))+SUM(cf_2!$S$183:INDEX(cf_2!$S$183:$EO$183,1,ROW()-1)))/1000000 -> 8389.987 | BG32: =(INDEX(КРЕДИТЫ!$S$52:$EO$52,1,ROW()-1)+INDEX(КРЕДИТЫ!$S$75:$EO$75,1,ROW()-1))/1000000 -> 8590.5706
B33: Расходы на строительство | C33: =SUM(C34:C45) -> -10742.812 | D33: =IFERROR(C33/$L$4*1000,0) -> -330.82291 | E33: =IFERROR(C33/$I$4*1000,0) -> -255.96408 | G33: Показатель | J33: Ед. | K33: Выбрано | AZ33: ='План продаж'!B53 -> 47209 | BA33: =IFERROR('План продаж'!G53,0) -> 945.37613 | BB33: =IFERROR('План продаж'!I53/1000,0) -> 778.07792 | BD33: =INDEX(КРЕДИТЫ!$S$3:$EO$3,1,ROW()-1) -> 47209 | BE33: =(SUM(cf_1!$S$9:INDEX(cf_1!$S$9:$EO$9,1,ROW()-1))+SUM(cf_2!$S$9:INDEX(cf_2!$S$9:$EO$9,1,ROW()-1))-SUM(cf_1!$S$209:INDEX(cf_1!$S$209:$EO$209,1,ROW()-1))-SUM(cf_2!$S$209:INDEX(cf_2!$S$209:$EO$209,1,ROW()-1)))/1000000 -> 8347.209 | BF33: =(SUM(cf_1!$S$183:INDEX(cf_1!$S$183:$EO$183,1,ROW()-1))+SUM(cf_2!$S$183:INDEX(cf_2!$S$183:$EO$183,1,ROW()-1)))/1000000 -> 8808.5744 | BG33: =(INDEX(КРЕДИТЫ!$S$52:$EO$52,1,ROW()-1)+INDEX(КРЕДИТЫ!$S$75:$EO$75,1,ROW()-1))/1000000 -> 9009.1581
B34: Получение ИРД и согласования | C34: =CF!I30+CF!I32+CF!I33 -> -65.561 | D34: =IFERROR(C34/$L$4*1000,0) -> -2.0189388 | E34: =IFERROR(C34/$I$4*1000,0) -> -1.562092 | G34: ИРД и согласования | J34: =Вводные!C23 -> тыс. ₽/м² GBA | K34: =Вводные!G23 -> 1 | AZ34: ='План продаж'!B54 -> 47239 | BA34: =IFERROR('План продаж'!G54,0) -> 810.94191 | BB34: =IFERROR('План продаж'!I54/1000,0) -> 786.6304 | BD34: =INDEX(КРЕДИТЫ!$S$3:$EO$3,1,ROW()-1) -> 47239 | BE34: =(SUM(cf_1!$S$9:INDEX(cf_1!$S$9:$EO$9,1,ROW()-1))+SUM(cf_2!$S$9:INDEX(cf_2!$S$9:$EO$9,1,ROW()-1))-SUM(cf_1!$S$209:INDEX(cf_1!$S$209:$EO$209,1,ROW()-1))-SUM(cf_2!$S$209:INDEX(cf_2!$S$209:$EO$209,1,ROW()-1)))/1000000 -> 8975.56 | BF34: =(SUM(cf_1!$S$183:INDEX(cf_1!$S$183:$EO$183,1,ROW()-1))+SUM(cf_2!$S$183:INDEX(cf_2!$S$183:$EO$183,1,ROW()-1)))/1000000 -> 9227.1619 | BG34: =(INDEX(КРЕДИТЫ!$S$52:$EO$52,1,ROW()-1)+INDEX(КРЕДИТЫ!$S$75:$EO$75,1,ROW()-1))/1000000 -> 9427.7455
B35: Разработка проекта стадии "П" и "РД" | C35: =CF!I31 -> -230.055 | D35: =IFERROR(C35/$L$4*1000,0) -> -7.084501 | E35: =IFERROR(C35/$I$4*1000,0) -> -5.4814153 | G35: Проектирование стадии "П" | J35: =Вводные!C24 -> тыс. ₽/м² GBA | K35: =Вводные!G24 -> 2.5 | AZ35: ='План продаж'!B55 -> 47270 | BA35: =IFERROR('План продаж'!G55,0) -> 818.31411 | BB35: =IFERROR('План продаж'!I55/1000,0) -> 795.2769 | BD35: =INDEX(КРЕДИТЫ!$S$3:$EO$3,1,ROW()-1) -> 47270 | BE35: =(SUM(cf_1!$S$9:INDEX(cf_1!$S$9:$EO$9,1,ROW()-1))+SUM(cf_2!$S$9:INDEX(cf_2!$S$9:$EO$9,1,ROW()-1))-SUM(cf_1!$S$209:INDEX(cf_1!$S$209:$EO$209,1,ROW()-1))-SUM(cf_2!$S$209:INDEX(cf_2!$S$209:$EO$209,1,ROW()-1)))/1000000 -> 9617.3364 | BF35: =(SUM(cf_1!$S$183:INDEX(cf_1!$S$183:$EO$183,1,ROW()-1))+SUM(cf_2!$S$183:INDEX(cf_2!$S$183:$EO$183,1,ROW()-1)))/1000000 -> 9645.7493 | BG35: =(INDEX(КРЕДИТЫ!$S$52:$EO$52,1,ROW()-1)+INDEX(КРЕДИТЫ!$S$75:$EO$75,1,ROW()-1))/1000000 -> 9846.333
B36: Подготовительный период | C36: =CF!I34 -> -46.011 | D36: =IFERROR(C36/$L$4*1000,0) -> -1.4169002 | E36: =IFERROR(C36/$I$4*1000,0) -> -1.0962831 | G36: Проектирование стадии "РД" | J36: =Вводные!C25 -> тыс. ₽/м² GBA | K36: =Вводные!G25 -> 2.5 | AZ36: ='План продаж'!B56 -> 47300 | BA36: =IFERROR('План продаж'!G56,0) -> 825.6863 | BB36: =IFERROR('План продаж'!I56/1000,0) -> 804.01844 | BD36: =INDEX(КРЕДИТЫ!$S$3:$EO$3,1,ROW()-1) -> 47300 | BE36: =(SUM(cf_1!$S$9:INDEX(cf_1!$S$9:$EO$9,1,ROW()-1))+SUM(cf_2!$S$9:INDEX(cf_2!$S$9:$EO$9,1,ROW()-1))-SUM(cf_1!$S$209:INDEX(cf_1!$S$209:$EO$209,1,ROW()-1))-SUM(cf_2!$S$209:INDEX(cf_2!$S$209:$EO$209,1,ROW()-1)))/1000000 -> 10272.757 | BF36: =(SUM(cf_1!$S$183:INDEX(cf_1!$S$183:$EO$183,1,ROW()-1))+SUM(cf_2!$S$183:INDEX(cf_2!$S$183:$EO$183,1,ROW()-1)))/1000000 -> 10064.337 | BG36: =(INDEX(КРЕДИТЫ!$S$52:$EO$52,1,ROW()-1)+INDEX(КРЕДИТЫ!$S$75:$EO$75,1,ROW()-1))/1000000 -> 10264.92
B37: Строительство основных объектов | C37: =CF!I35 -> -8742.09 | D37: =IFERROR(C37/$L$4*1000,0) -> -269.21104 | E37: =IFERROR(C37/$I$4*1000,0) -> -208.29378 | G37: Подготовительные работы | J37: =Вводные!C26 -> тыс. ₽/м² GBA | K37: =Вводные!G26 -> 1 | AZ37: ='План продаж'!B57 -> 47331 | BA37: =IFERROR('План продаж'!G57,0) -> 833.0585 | BB37: =IFERROR('План продаж'!I57/1000,0) -> 812.85606 | BD37: =INDEX(КРЕДИТЫ!$S$3:$EO$3,1,ROW()-1) -> 47331 | BE37: =(SUM(cf_1!$S$9:INDEX(cf_1!$S$9:$EO$9,1,ROW()-1))+SUM(cf_2!$S$9:INDEX(cf_2!$S$9:$EO$9,1,ROW()-1))-SUM(cf_1!$S$209:INDEX(cf_1!$S$209:$EO$209,1,ROW()-1))-SUM(cf_2!$S$209:INDEX(cf_2!$S$209:$EO$209,1,ROW()-1)))/1000000 -> 10942.045 | BF37: =(SUM(cf_1!$S$183:INDEX(cf_1!$S$183:$EO$183,1,ROW()-1))+SUM(cf_2!$S$183:INDEX(cf_2!$S$183:$EO$183,1,ROW()-1)))/1000000 -> 10482.924 | BG37: =(INDEX(КРЕДИТЫ!$S$52:$EO$52,1,ROW()-1)+INDEX(КРЕДИТЫ!$S$75:$EO$75,1,ROW()-1))/1000000 -> 10683.508
B38: Строительство отдельных коммерческих объектов | C38: =CF!I40 -> 0 | D38: =IFERROR(C38/$L$10*1000,0) -> 0 | E38: =IFERROR(C38/$I$10*1000,0) -> 0 | G38: Основное строительство ЖК | J38: =Вводные!C27 -> тыс. ₽/м² GBA | K38: =Вводные!G27 -> 190 | AZ38: ='План продаж'!B58 -> 47362 | BA38: =IFERROR('План продаж'!G58,0) -> 988.742 | BB38: =IFERROR('План продаж'!I58/1000,0) -> 821.79082 | BD38: =INDEX(КРЕДИТЫ!$S$3:$EO$3,1,ROW()-1) -> 47362 | BE38: =(SUM(cf_1!$S$9:INDEX(cf_1!$S$9:$EO$9,1,ROW()-1))+SUM(cf_2!$S$9:INDEX(cf_2!$S$9:$EO$9,1,ROW()-1))-SUM(cf_1!$S$209:INDEX(cf_1!$S$209:$EO$209,1,ROW()-1))-SUM(cf_2!$S$209:INDEX(cf_2!$S$209:$EO$209,1,ROW()-1)))/1000000 -> 11742.857 | BF38: =(SUM(cf_1!$S$183:INDEX(cf_1!$S$183:$EO$183,1,ROW()-1))+SUM(cf_2!$S$183:INDEX(cf_2!$S$183:$EO$183,1,ROW()-1)))/1000000 -> 10901.512 | BG38: =(INDEX(КРЕДИТЫ!$S$52:$EO$52,1,ROW()-1)+INDEX(КРЕДИТЫ!$S$75:$EO$75,1,ROW()-1))/1000000 -> 11102.095
B39: Вознаграждение Генподрядчика | C39: =CF!I39 -> -611.9463 | D39: =IFERROR(C39/$L$4*1000,0) -> -18.844773 | E39: =IFERROR(C39/$I$4*1000,0) -> -14.580565 | G39: Наружные инженерные сети | J39: =Вводные!C28 -> тыс. ₽/м² GBA | K39: =Вводные!G28 -> 7 | AZ39: ='План продаж'!B59 -> 47392 | BA39: =IFERROR('План продаж'!G59,0) -> 997.41518 | BB39: =IFERROR('План продаж'!I59/1000,0) -> 830.8238 | BD39: =INDEX(КРЕДИТЫ!$S$3:$EO$3,1,ROW()-1) -> 47392 | BE39: =(SUM(cf_1!$S$9:INDEX(cf_1!$S$9:$EO$9,1,ROW()-1))+SUM(cf_2!$S$9:INDEX(cf_2!$S$9:$EO$9,1,ROW()-1))-SUM(cf_1!$S$209:INDEX(cf_1!$S$209:$EO$209,1,ROW()-1))-SUM(cf_2!$S$209:INDEX(cf_2!$S$209:$EO$209,1,ROW()-1)))/1000000 -> 12693.106 | BF39: =(SUM(cf_1!$S$183:INDEX(cf_1!$S$183:$EO$183,1,ROW()-1))+SUM(cf_2!$S$183:INDEX(cf_2!$S$183:$EO$183,1,ROW()-1)))/1000000 -> 11320.099 | BG39: =(INDEX(КРЕДИТЫ!$S$52:$EO$52,1,ROW()-1)+INDEX(КРЕДИТЫ!$S$75:$EO$75,1,ROW()-1))/1000000 -> 11520.683
B40: Вынос инженерных сетей | C40: =CF!I42 -> 0 | D40: =IFERROR(C40/$L$4*1000,0) -> 0 | E40: =IFERROR(C40/$I$4*1000,0) -> 0 | G40: Благоустройство | J40: =Вводные!C29 -> тыс. ₽/м² GBA | K40: =Вводные!G29 -> 3.5 | AZ40: ='План продаж'!B60 -> 47423 | BA40: =IFERROR('План продаж'!G60,0) -> 1006.0884 | BB40: =IFERROR('План продаж'!I60/1000,0) -> 839.95606 | BD40: =INDEX(КРЕДИТЫ!$S$3:$EO$3,1,ROW()-1) -> 47423 | BE40: =(SUM(cf_1!$S$9:INDEX(cf_1!$S$9:$EO$9,1,ROW()-1))+SUM(cf_2!$S$9:INDEX(cf_2!$S$9:$EO$9,1,ROW()-1))-SUM(cf_1!$S$209:INDEX(cf_1!$S$209:$EO$209,1,ROW()-1))-SUM(cf_2!$S$209:INDEX(cf_2!$S$209:$EO$209,1,ROW()-1)))/1000000 -> 13661.773 | BF40: =(SUM(cf_1!$S$183:INDEX(cf_1!$S$183:$EO$183,1,ROW()-1))+SUM(cf_2!$S$183:INDEX(cf_2!$S$183:$EO$183,1,ROW()-1)))/1000000 -> 11738.687 | BG40: =(INDEX(КРЕДИТЫ!$S$52:$EO$52,1,ROW()-1)+INDEX(КРЕДИТЫ!$S$75:$EO$75,1,ROW()-1))/1000000 -> 11939.27
...

Sheet Расчет ВРИ (ТЭП)
A1: № | B1: Наименования | C1: Единицы измерения | D1: Показатель
A2: 1 | B2: Площадь территории проектирования | C2: га | D2: 1,155
A3: 2 | B3: Плотность от СПП | C3: тыс.кв.м./га | D3: 35
A4: 3 | B4: Плотность от НП | C4: тыс.кв.м./га | D4: 31,5
A5: 4 | B5: Население | C5: чел. | D5: 749 | E5: 28
A6: 5 | B6: Количество квартир | C6: шт. | D6: 357 | E6: 2.0980392
B7: СПП в ГНС:
A8: 6 | B8: СПП, всего: | C8: тыс.кв.м. | D8: 40411 | E8: 1154.6
A9: 7 | B9: СПП жилых зданий, в т.ч.: | C9: тыс.кв.м. | D9: 40411 | E9: 1
A10: 7.1 | B10: СПП жилая | C10: тыс.кв.м. | D10: 37986 | E10: 0.93999159
A11: 7.2 | B11: СПП нежилой части жилых зданий | C11: тыс.кв.м. | D11: 2425 | E11: 0.060008414
A12: 8 | B12: СПП нежилых зданий, в т.ч.: | C12: тыс.кв.м. | D12: 0
A13: 8.1 | B13: СПП общественных, производственных объектов | C13: тыс.кв.м. | D13: 0
A14: 8.2 | B14: СПП социальных объектов | C14: тыс.кв.м. | D14: 0
B15: Наземная площадь:
A16: 9 | B16: НП, всего: | C16: тыс.кв.м. | D16: 36370 | E16: 0.90000247
A17: 9.1 | B17: НП жилых зданий, в т.ч.: | C17: тыс.кв.м. | D17: 36370 | E17: 0.90000247
A18: 9.1.1 | B18: НП жилая | C18: тыс.кв.м. | D18: 34188 | E18: 0.9000158
A19: 9.1.2 | B19: НП нежилой части жилых зданий | C19: тыс.кв.м. | D19: 2182 | E19: 0.89979381
A20: 9.2 | B20: НП нежилых зданий, в т.ч.: | C20: тыс.кв.м. | D20: 0
A21: 9.2.1 | B21: НП общественных, производственных объектов | C21: тыс.кв.м. | D21: 0
A22: 9.2.2 | B22: НП социальных объектов | C22: тыс.кв.м. | D22: 0
B23: Единый показатель:
A24: 10 | B24: Площадь квартир | C24: тыс.кв.м. | D24: 24691 | E24: 0.68
A25: 11 | B25: Нежилая наземная площадь (ННП) | C25: тыс.кв.м. | D25: 2182 | E25: 0.8 | F25: 0.08
B26: Баланс территории:
A27: 12 | B27: Территория жилых зданий, в т.ч.: | C27: га | D27: 1,155 (100,0%)
A28: 12.1 | B28: участки многоквартирных жилых зданий | C28: га | D28: 1,155 (100,0%)
A29: 12.2 | B29: незастраиваемая территория | C29: га | D29: 0 (0,0%)
A30: 13 | B30: Участки социальных объектов | C30: га | D30: 0 (0,0%)
A31: 14 | B31: Участки общественных, производственных объектов | C31: га | D31: 0 (0,0%)
B32: Расчётная плотность территории от СПП:
A33: 15 | B33: жилых участков | C33: тыс.кв.м./га | D33: 35,00 | E33: 34.987879
A34: 16 | B34: социальных объектов | C34: тыс.кв.м./га | D34: 0,00
A35: 17 | B35: общественных, производственных объектов | C35: тыс.кв.м./га | D35: 0,00
B36: ДОО:
A37: 18 | B37: количество мест | C37: мест | D37: 0
A38: 19 | B38: СПП | C38: тыс.кв.м. | D38: 0,000
A39: 20 | B39: наземная площадь | C39: тыс.кв.м. | D39: 0,000
A40: 21 | B40: площадь земельного участка | C40: га | D40: 0,0000
...

Sheet ТЭП
B1: Начало проекта | C1: =Вводные!G7 -> 46266
B2: Общие ТЭП
B3: Показатель | C3: ГНС, кв.м. | D3: Общая площадь, кв.м. | E3: k выхода полезной площади | F3: Полезная площадь | G3: Продаваемая площадь, кв.м. | H3: Передаваемая площадь, кв.м. | I3: Штуки
B4: ИТОГО | C4: =C5+C16 -> 46011 | D4: =D5+D16 -> 41970 | F4: =F5+F16 -> 32473 | G4: =G5+G16 -> 32473 | H4: =H5+H16 -> 0 | I4: =I5+I16 -> 517
B5: Основные объекты | C5: =C6+C13+C9+C10+C11 -> 46011 | D5: =D6+D13+D9+D10+D11 -> 41970 | F5: =F6+F13+F9+F10+F11 -> 32473 | G5: =G6+G13+G9+G10+G11 -> 32473 | H5: =H6+H13+H9+H10+H11 -> 0 | I5: =I6+I13 -> 517
B6: Наземная часть | C6: =SUM(C7:C8) -> 40411 | D6: =SUM(D7:D8) -> 36370 | F6: =SUM(F7:F8) -> 26873 | G6: =SUM(G7:G8) -> 26873 | H6: =SUM(H7:H12) -> 0 | I6: =SUM(I7:I12) -> 357
B7: Квартиры | C7: =C26+C45 -> 37986 | D7: =D26+D45 -> 34188 | E7: =IFERROR(F7/D7,0) -> 0.72221247 | F7: =F26+F45 -> 24691 | G7: =G26+G45 -> 24691 | H7: =H26+H45 -> 0 | I7: =I26+I45 -> 357
B8: Коммерция 1 эт. | C8: =C27+C46 -> 2425 | D8: =D27+D46 -> 2182 | E8: =IFERROR(F8/D8,0) -> 1 | F8: =F27+F46 -> 2182 | G8: =G27+G46 -> 2182 | H8: =H27+H46 -> 0 | I8: =I27+I46 -> 0
B9: Коммерция ОСЗ | C9: =C28+C47 -> 0 | D9: =D28+D47 -> 0 | E9: =IFERROR(F9/D9,0) -> 0 | F9: =F28+F47 -> 0 | G9: =G28+G47 -> 0 | H9: =H28+H47 -> 0 | I9: =I28+I47 -> 0
B10: Офисы | C10: =C29+C48 -> 0 | D10: =D29+D48 -> 0 | E10: =IFERROR(F10/D10,0) -> 0 | F10: =F29+F48 -> 0 | G10: =G29+G48 -> 0 | H10: =H29+H48 -> 0 | I10: =I29+I48 -> 0
B11: Наземный паркинг | C11: =C30+C49 -> 0 | D11: =D30+D49 -> 0 | F11: =F30+F49 -> 0 | G11: =G30+G49 -> 0 | H11: =H30+H49 -> 0 | I11: =I30+I49 -> 0
B12: Прочие | C12: =C31+C50 -> 0 | D12: =D31+D50 -> 0 | F12: =F31+F50 -> 0 | G12: =G31+G50 -> 0 | H12: =H31+H50 -> 0 | I12: =I31+I50 -> 0
B13: Подземная часть | C13: =SUM(C14:C15) -> 5600 | D13: =SUM(D14:D15) -> 5600 | F13: =SUM(F14:F15) -> 5600 | G13: =SUM(G14:G15) -> 5600 | H13: =SUM(H14:H15) -> 0 | I13: =SUM(I14:I15) -> 160
B14: Подземный паркинг | C14: =C33+C52 -> 5600 | D14: =D33+D52 -> 5600 | F14: =F33+F52 -> 5600 | G14: =G33+G52 -> 5600 | H14: =H33+H52 -> 0 | I14: =I33+I52 -> 160
B15: Кладовки | C15: =C34+C53 -> 0 | D15: =D34+D53 -> 0 | F15: =F34+F53 -> 0 | G15: =G34+G53 -> 0 | H15: =H34+H53 -> 0 | I15: =I34+I53 -> 0
B16: Социальные объекты | C16: =SUM(C17:C19) -> 0 | D16: =SUM(D17:D19) -> 0 | F16: =SUM(F17:F19) -> 0 | G16: =SUM(G17:G19) -> 0 | H16: =SUM(H17:H19) -> 0 | I16: =SUM(I17:I19) -> 0
B17: ДОУ | C17: =C36+C55 -> 0 | D17: =D36+D55 -> 0 | F17: =F36+F55 -> 0 | G17: =G36+G55 -> 0 | H17: =H36+H55 -> 0 | I17: =I36+I55 -> 0
B18: СОШ | C18: =C37+C56 -> 0 | D18: =D37+D56 -> 0 | F18: =F37+F56 -> 0 | G18: =G37+G56 -> 0 | H18: =H37+H56 -> 0 | I18: =I37+I56 -> 0
B19: Поликлиника | C19: =C38+C57 -> 0 | D19: =D38+D57 -> 0 | F19: =F38+F57 -> 0 | G19: =G38+G57 -> 0 | H19: =H38+H57 -> 0 | I19: =I38+I57 -> 0
B21: 1 очередь | J21: РнС | K21: РВЭ | L21: Продажи
B22: Показатель | C22: ГНС, кв.м. | D22: Общая площадь, кв.м. | F22: Полезная площадь | G22: Продаваемая площадь, кв.м. | H22: Передаваемая площадь, кв.м. | I22: Штуки | J22: =СРОКИ!C17 -> 46813 | K22: =СРОКИ!C19 -> 47543 | L22: =СРОКИ!C16 -> 46813
B23: ИТОГО | C23: =C24+C35 -> 46011 | D23: =D24+D35 -> 41970 | F23: =F24+F35 -> 32473 | G23: =G24+G35 -> 32473 | H23: =H24+H35 -> 0 | I23: =I24+I35 -> 0 | K23: =IF(DATEDIF(EDATE(J22,0),EDATE(K22,0),"Y")>5,DATEDIF(EDATE(J22,0),EDATE(K22,0),"Y")&"л ",IF(DATEDIF(EDATE(J22,0),EDATE(K22,0),"Y")>0,DATEDIF(EDATE(J22,0),EDATE(K22,0),"Y")&"г ",""))& DATEDIF(EDATE(J22,0),EDATE(K22,0),"M")-DATEDIF(EDATE(J22,0),EDATE(K22,0),"Y")*12&" мес" -> 2г 0 мес
B24: Основные объекты | C24: =C25+C32+C28+C29+C30 -> 46011 | D24: =D25+D32+D28+D29+D30 -> 41970 | F24: =F25+F32+F28+F29+F30 -> 32473 | G24: =G25+G32+G28+G29+G30 -> 32473 | H24: =H25+H32+H28+H29+H30 -> 0
B25: Наземная часть | C25: =SUM(C26:C27) -> 40411 | D25: =SUM(D26:D27) -> 36370 | F25: =SUM(F26:F27) -> 26873 | G25: =SUM(G26:G27) -> 26873 | H25: =SUM(H26:H27) -> 0 | I25: =SUM(I26:I27) -> 357
B26: Квартиры | C26: ='Расчет ВРИ (ТЭП)'!D10 -> 37986 | D26: ='Расчет ВРИ (ТЭП)'!D18 -> 34188 | E26: ='Расчет ВРИ (ТЭП)'!E24 -> 0.68 | F26: ='Расчет ВРИ (ТЭП)'!D24 -> 24691 | G26: =F26 -> 24691 | H26: 0 | I26: ='Расчет ВРИ (ТЭП)'!D6 -> 357
B27: Коммерция 1 эт. | C27: ='Расчет ВРИ (ТЭП)'!D11 -> 2425 | D27: ='Расчет ВРИ (ТЭП)'!D19 -> 2182 | E27: 0.9 | F27: ='Расчет ВРИ (ТЭП)'!D25 -> 2182 | G27: =F27 -> 2182 | H27: 0
B28: Коммерция ОСЗ | C28: =IF(Вводные!G119="Да",Вводные!G120,0) -> 0 | D28: =C28 -> 0 | E28: =IFERROR(F28/D28,0) -> 0 | F28: =IF(Вводные!G119="Да",Вводные!G121,0) -> 0 | G28: =F28 -> 0 | H28: =0 -> 0 | I28: =0 -> 0
B29: Офисы | C29: =IF(Вводные!G106="Да",Вводные!G107,0) -> 0 | D29: =C29 -> 0 | E29: =IFERROR(F29/D29,0) -> 0 | F29: =IF(Вводные!G106="Да",Вводные!G108,0) -> 0 | G29: =F29 -> 0 | H29: =0 -> 0 | I29: =0 -> 0
B30: Наземный паркинг | C30: =IF(Вводные!G132="Да",Вводные!G144,0) -> 0 | D30: =C30 -> 0 | F30: =D30 -> 0 | G30: =F30 -> 0 | H30: =0 -> 0 | I30: =IF(Вводные!G132="Да",Вводные!G133,0) -> 0
B31: Прочие
B32: Подземная часть | C32: =SUM(C33:C34) -> 5600 | D32: =SUM(D33:D34) -> 5600 | F32: =SUM(F33:F34) -> 5600 | G32: =SUM(G33:G34) -> 5600 | H32: =SUM(H33:H34) -> 0 | I32: =SUM(I33:I34) -> 160
B33: Подземный паркинг | C33: =I33*35 -> 5600 | D33: =I33*35 -> 5600 | F33: =D33 -> 5600 | G33: =D33 -> 5600 | I33: ='Расчет ВРИ (ТЭП)'!D68+'Расчет ВРИ (ТЭП)'!D69 -> 160
B34: Кладовки
B35: Социальные объекты | C35: =SUM(C36:C38) -> 0 | D35: =SUM(D36:D38) -> 0 | F35: =SUM(F36:F38) -> 0 | G35: =SUM(G36:G38) -> 0 | H35: =SUM(H36:H38) -> 0 | I35: =SUM(I36:I38) -> 0
B36: ДОУ | C36: =IF(Вводные!G82="Строительство",Вводные!G148,0) -> 0 | D36: =C36 -> 0 | F36: =0 -> 0 | G36: =0 -> 0 | H36: =D36 -> 0 | I36: =IF(Вводные!G82="Строительство",Вводные!G84,0) -> 0
B37: СОШ | C37: =IF(Вводные!G82="Строительство",Вводные!G149,0) -> 0 | D37: =C37 -> 0 | F37: =0 -> 0 | G37: =0 -> 0 | H37: =D37 -> 0 | I37: =IF(Вводные!G82="Строительство",Вводные!G89,0) -> 0
B38: Поликлиника | C38: =IF(Вводные!G82="Строительство",Вводные!G150,0) -> 0 | D38: =C38 -> 0 | F38: =0 -> 0 | G38: =0 -> 0 | H38: =D38 -> 0 | I38: =IF(Вводные!G82="Строительство",Вводные!G94,0) -> 0
B40: 2 очередь | J40: РнС | K40: РВЭ | L40: РВЭ
B41: Показатель | C41: ГНС, кв.м. | D41: Общая площадь, кв.м. | F41: Полезная площадь | G41: Продаваемая площадь, кв.м. | H41: Передаваемая площадь, кв.м. | I41: Штуки
B42: ИТОГО | C42: =C43+C54 -> 0 | D42: =D43+D54 -> 0 | F42: =F43+F54 -> 0 | G42: =G43+G54 -> 0 | H42: =H43+H54 -> 0 | I42: =I43+I54 -> 0 | K42: =IF(DATEDIF(EDATE(J41,0),EDATE(K41,0),"Y")>5,DATEDIF(EDATE(J41,0),EDATE(K41,0),"Y")&"л ",IF(DATEDIF(EDATE(J41,0),EDATE(K41,0),"Y")>0,DATEDIF(EDATE(J41,0),EDATE(K41,0),"Y")&"г ",""))& DATEDIF(EDATE(J41,0),EDATE(K41,0),"M")-DATEDIF(EDATE(J41,0),EDATE(K41,0),"Y")*12&" мес" -> 0 мес
...

Sheet Календарь
A1: ПЛАТО — КАЛЕНДАРНЫЙ ГРАФИК ПРОЕКТА
A3: Событие / этап | B3: Начало | C3: Окончание | D3: Комментарий
A4: Сделка / начало проекта | B4: =Вводные!G7 -> 46266 | C4: =Вводные!G7 -> 46266 | D4: Покупка площадки
A5: ИРД | B5: =Вводные!G7 -> 46266 | C5: =EDATE(Вводные!G8,-1) -> 46784 | D5: Базовый срок — 18 месяцев
A6: БРИДЖ | B6: =Вводные!G7 -> 46266 | C6: =EDATE(Вводные!G8,Вводные!G50) -> 46813 | D6: До рефинансирования после РнС
A7: РнС | B7: =Вводные!G8 -> 46813 | C7: =Вводные!G8 -> 46813 | D7: Начало строительной стадии
A8: Строительство | B8: =Вводные!G8 -> 46813 | C8: =EDATE(Вводные!G8,Вводные!G9) -> 47543 | D8: Срок из листа «Вводные»
A9: Продажи | B9: =Вводные!G10 -> 46813 | C9: =EDATE(EDATE(Вводные!G8,Вводные!G9),Вводные!G51) -> 47727 | D9: Включая остаточные продажи
A10: РВЭ / РНВ | B10: =EDATE(Вводные!G8,Вводные!G9) -> 47543 | C10: =EDATE(Вводные!G8,Вводные!G9) -> 47543 | D10: Окончание строительства
A11: Окончание продаж | B11: =EDATE(EDATE(Вводные!G8,Вводные!G9),Вводные!G51) -> 47727 | C11: =EDATE(EDATE(Вводные!G8,Вводные!G9),Вводные!G51) -> 47727 | D11: Плановая дата
A14: Этап | B14: Старт | C14: Финиш | D14: Длительность, мес. | F14: =Вводные!G7 -> 46266 | G14: =EDATE(F14,1) -> 46296 | H14: =EDATE(G14,1) -> 46327 | I14: =EDATE(H14,1) -> 46357 | J14: =EDATE(I14,1) -> 46388 | K14: =EDATE(J14,1) -> 46419 | L14: =EDATE(K14,1) -> 46447 | M14: =EDATE(L14,1) -> 46478 | N14: =EDATE(M14,1) -> 46508 | ... BX14: =EDATE(BW14,1) -> 48396
A16: ИРД | B16: =Вводные!G7 -> 46266 | C16: =EDATE(Вводные!G8,-1) -> 46784 | D16: =Вводные!G48 -> 18 | F16: =--AND(F$14>=EOMONTH($B16,-1)+1,F$14<=EOMONTH($C16,0)) -> 1 | G16: =--AND(G$14>=EOMONTH($B16,-1)+1,G$14<=EOMONTH($C16,0)) -> 1 | H16: =--AND(H$14>=EOMONTH($B16,-1)+1,H$14<=EOMONTH($C16,0)) -> 1 | I16: =--AND(I$14>=EOMONTH($B16,-1)+1,I$14<=EOMONTH($C16,0)) -> 1 | J16: =--AND(J$14>=EOMONTH($B16,-1)+1,J$14<=EOMONTH($C16,0)) -> 1 | K16: =--AND(K$14>=EOMONTH($B16,-1)+1,K$14<=EOMONTH($C16,0)) -> 1 | L16: =--AND(L$14>=EOMONTH($B16,-1)+1,L$14<=EOMONTH($C16,0)) -> 1 | M16: =--AND(M$14>=EOMONTH($B16,-1)+1,M$14<=EOMONTH($C16,0)) -> 1 | ... BX16: =--AND(BX$14>=EOMONTH($B16,-1)+1,BX$14<=EOMONTH($C16,0)) -> 0
A17: БРИДЖ | B17: =Вводные!G7 -> 46266 | C17: =EDATE(Вводные!G8,Вводные!G50) -> 46813 | D17: =Ставки!G6 -> 18 | F17: =--AND(F$14>=EOMONTH($B17,-1)+1,F$14<=EOMONTH($C17,0)) -> 1 | G17: =--AND(G$14>=EOMONTH($B17,-1)+1,G$14<=EOMONTH($C17,0)) -> 1 | H17: =--AND(H$14>=EOMONTH($B17,-1)+1,H$14<=EOMONTH($C17,0)) -> 1 | I17: =--AND(I$14>=EOMONTH($B17,-1)+1,I$14<=EOMONTH($C17,0)) -> 1 | J17: =--AND(J$14>=EOMONTH($B17,-1)+1,J$14<=EOMONTH($C17,0)) -> 1 | K17: =--AND(K$14>=EOMONTH($B17,-1)+1,K$14<=EOMONTH($C17,0)) -> 1 | L17: =--AND(L$14>=EOMONTH($B17,-1)+1,L$14<=EOMONTH($C17,0)) -> 1 | M17: =--AND(M$14>=EOMONTH($B17,-1)+1,M$14<=EOMONTH($C17,0)) -> 1 | ... BX17: =--AND(BX$14>=EOMONTH($B17,-1)+1,BX$14<=EOMONTH($C17,0)) -> 0
