Workbook

Sheet ИНСТРУКЦИЯ
A1: ПЛАТО — КОНСОЛИДАТОР 4 ОЧЕРЕДЕЙ
A3: Консолидатор берет ключевые показатели напрямую с листов «ОТЧЕТ» четырех моделей, а помесячные данные — с листов «CF» и «КРЕДИТЫ».
A6: Шаг | B6: Что сделать | C6: Важно
A7: 1 | B7: Положить консолидатор и четыре модели очередей в одну папку | C7: Для динамических ссылок все четыре исходных файла должны быть открыты
A8: 2 | B8: На листе «НАСТРОЙКИ» ввести фактические имена файлов в D5:D8 | C8: Можно использовать любые имена, включая пробелы и русские буквы
A9: 3 | B9: Открыть все указанные файлы моделей одновременно с консолидатором | C9: ДВССЫЛ / INDIRECT не считывает данные из закрытых внешних книг
A10: 4 | B10: Использовать одну и ту же версию модели для всех очередей | C10: Структура ОТЧЕТ / CF / КРЕДИТЫ должна совпадать
A11: 5 | B11: Выбрать режим БРИДЖ | C11: Режим в консолидаторе должен совпадать с формулами моделей очередей
A12: 6 | B12: Проверить свод, помесячный поток и контроль БРИДЖ | C12: Если источник закрыт или имя введено неверно, показатели будут равны нулю
A15: ЦВЕТОВАЯ ЛОГИКА
A16: Синий текст | B16: Ручные вводные
A17: Зеленый текст | B17: Внутренние формулы
A18: Красный текст | B18: Внешние ссылки на модели очередей
A19: Желтая заливка | B19: Поля для проверки / заполнения

Sheet НАСТРОЙКИ
A1: НАСТРОЙКИ КОНСОЛИДАТОРА
A3: ФАЙЛЫ, ОЧЕРЕДИ И РАСПРЕДЕЛЕНИЕ ОБЩИХ ЗАТРАТ
A4: № | B4: Активна | C4: Очередь | D4: Имя файла | E4: Ручная доля БРИДЖ | F4: Эффективная доля | G4: Тело БРИДЖ | H4: Проценты БРИДЖ | I4: ВРИ | J4: Комментарий
A5: 1 | B5: Да | C5: Очередь 1 | D5: PLATO_M-1.xlsx | E5: 0.25 | F5: =IF($B$14="Весь БРИДЖ в О1",1,E5) -> 1 | G5: =$B$16*F5 -> 0 | H5: =$B$17*F5 -> 0 | I5: =$B$18*F5 -> 0 | J5: Исправлена помесячная разбивка П, РД, подготовительных работ и наружных сетей без изменения общей суммы до РнС.
A6: 2 | B6: Да | C6: Очередь 2 | D6: Plato_M-2.xlsx | E6: 0.25 | F6: =IF($B$14="Весь БРИДЖ в О1",0,E6) -> 0 | G6: =$B$16*F6 -> 0 | H6: =$B$17*F6 -> 0 | I6: =$B$18*F6 -> 0 | J6: Введите фактическое имя файла. Для динамической связи файл должен быть открыт.
A7: 3 | B7: Да | C7: Очередь 3 | D7: Plato_M-3.xlsx | E7: 0.25 | F7: =IF($B$14="Весь БРИДЖ в О1",0,E7) -> 0 | G7: =$B$16*F7 -> 0 | H7: =$B$17*F7 -> 0 | I7: =$B$18*F7 -> 0 | J7: Введите фактическое имя файла. Для динамической связи файл должен быть открыт.
A8: 4 | B8: Нет | C8: Очередь 4 | E8: 0.25 | F8: =IF($B$14="Весь БРИДЖ в О1",0,E8) -> 0 | G8: =$B$16*F8 -> 0 | H8: =$B$17*F8 -> 0 | I8: =$B$18*F8 -> 0 | J8: Введите фактическое имя файла. Для динамической связи файл должен быть открыт.
C9: ИТОГО / КОНТРОЛЬ | E9: =SUM(E5:E8) -> 1 | F9: =SUM(F5:F8) -> 1 | G9: =SUM(G5:G8) -> 0 | H9: =SUM(H5:H8) -> 0 | I9: =SUM(I5:I8) -> 0 | J9: =IF(ABS(F9-1)<0.0001,"OK","ПРОВЕРИТЬ ДОЛИ") -> OK
A12: ОБЩЕПРОЕКТНЫЙ БРИДЖ И ВРИ
A13: Параметр | B13: Значение | C13: Ед. изм. | D13: Комментарий
A14: Режим рефинансирования БРИДЖ | B14: Весь БРИДЖ в О1 | D14: Либо 100% в О1, либо по ручным долям
A15: БРИДЖ уже включен в ПФ моделей | B15: Да | D15: «Да» исключает повторное добавление в скорректированный ПФ
A16: Общий основной долг БРИДЖ | B16: 0 | C16: млн ₽ | D16: Ручная общепроектная сумма
A17: Накопленные проценты БРИДЖ | B17: 0 | C17: млн ₽ | D17: На дату перехода в ПФ
A18: Общий платеж за смену ВРИ | B18: 0 | C18: млн ₽ | D18: Общепроектный платеж
A19: Дата начала БРИДЖ | B19: 46388 | C19: дата | D19: Контроль календаря
A20: Ставка дисконтирования свода | B20: 0.2 | C20: % год | D20: Для NPV консолидированного потока
A23: ПОМЕСЯЧНЫЙ ГОРИЗОНТ
A24: Параметр | B24: Значение | C24: Ед. изм. | D24: Комментарий
A25: Первый месяц свода | B25: 46388 | C25: дата | D25: Можно изменить
A26: Количество месяцев | B26: 108 | C26: мес. | D26: 9-летний горизонт
A27: Конец горизонта | B27: =EDATE(B25,B26-1) -> 49644 | C27: дата | D27: Считается автоматически
A29: ВАЖНО: достаточно изменить имя файла в D5:D8 — формулы на листах «СВОД» и «ПО МЕСЯЦАМ» перестроятся автоматически. Исходные книги должны быть открыты одновременно с консолидатором; это ограничение функции ДВССЫЛ / INDIRECT для внешних файлов.

Sheet СВОД
A1: ПЛАТО — СВОД ПО ОЧЕРЕДЯМ
A3: Выручка, млн ₽ | C3: Расходы, млн ₽ | E3: Чистая прибыль, млн ₽ | G3: Маржа | I3: ПФ скорр., млн ₽ | K3: Пик ПФ, млн ₽ | M3: Мин. LLCR | O3: NPV свода, млн ₽ | Q3: IRR свода | S3: Пик долга, млн ₽
A4: =G14 -> 113938.28 | C4: =H14 -> 100706.19 | E4: =K14 -> 13232.087 | G4: =L14 -> 0.11613382 | I4: =R14 -> 81620.877 | K4: ='ПО МЕСЯЦАМ'!B13 -> 43581.872 | M4: =O14 -> 0 | O4: ='ПО МЕСЯЦАМ'!B17 -> 0 | Q4: ='ПО МЕСЯЦАМ'!B18 -> 0 | S4: ='ПО МЕСЯЦАМ'!B16 -> 43759.526
A9: Активна | B9: Очередь | C9: Файл | D9: Старт | E9: РнС | F9: РВЭ | G9: Выручка, млн ₽ | H9: Расходы, млн ₽ | I9: EBITDA, млн ₽ | J9: Проценты, млн ₽ | K9: Чистая прибыль, млн ₽ | L9: Маржа | M9: NPV, млн ₽ | N9: IRR | O9: LLCR | P9: БРИДЖ, млн ₽ | Q9: ПФ по модели, млн ₽ | R9: ПФ скорр., млн ₽ | S9: Пик ПФ, млн ₽ | T9: Пик эскроу, млн ₽ | V9: Очередь | W9: Выручка | X9: Расходы | Y9: Чистая прибыль
A10: =НАСТРОЙКИ!B5 -> Да | B10: =НАСТРОЙКИ!C5 -> Очередь 1 | C10: =НАСТРОЙКИ!D5 -> PLATO_M-1.xlsx | D10: =IF(НАСТРОЙКИ!$B$5<>"Да",0,IFERROR(INDIRECT("'["&НАСТРОЙКИ!$D$5&"]Вводные'!$G$7"),0)) -> 46388 | E10: =IF(НАСТРОЙКИ!$B$5<>"Да",0,IFERROR(INDIRECT("'["&НАСТРОЙКИ!$D$5&"]Вводные'!$G$8"),0)) -> 46935 | F10: =IF(НАСТРОЙКИ!$B$5<>"Да",0,IFERROR(EDATE(INDIRECT("'["&НАСТРОЙКИ!$D$5&"]Вводные'!$G$8"),INDIRECT("'["&НАСТРОЙКИ!$D$5&"]Вводные'!$G$9")),0)) -> 47665 | G10: =IF(НАСТРОЙКИ!$B$5<>"Да",0,IFERROR(INDIRECT("'["&НАСТРОЙКИ!$D$5&"]ОТЧЕТ'!$C$4"),0)) -> 42105.39 | H10: =IF(НАСТРОЙКИ!$B$5<>"Да",0,-IFERROR(INDIRECT("'["&НАСТРОЙКИ!$D$5&"]ОТЧЕТ'!$C$13"),0)) -> 38826.961 | I10: =IF(НАСТРОЙКИ!$B$5<>"Да",0,IFERROR(INDIRECT("'["&НАСТРОЙКИ!$D$5&"]ОТЧЕТ'!$C$21"),0)) -> 8222.4964 | J10: =IF(НАСТРОЙКИ!$B$5<>"Да",0,-IFERROR(INDIRECT("'["&НАСТРОЙКИ!$D$5&"]ОТЧЕТ'!$C$22"),0)) -> 2173.0861 | K10: =IF(НАСТРОЙКИ!$B$5<>"Да",0,IFERROR(INDIRECT("'["&НАСТРОЙКИ!$D$5&"]ОТЧЕТ'!$C$24"),0)) -> 3278.4292 | L10: =IFERROR(K10/G10,0) -> 0.077862459 | M10: =IF(НАСТРОЙКИ!$B$5<>"Да",0,IFERROR(INDIRECT("'["&НАСТРОЙКИ!$D$5&"]ОТЧЕТ'!$C$28"),0)) -> 2503.3531 | N10: =IF(НАСТРОЙКИ!$B$5<>"Да",0,IFERROR(INDIRECT("'["&НАСТРОЙКИ!$D$5&"]ОТЧЕТ'!$C$29"),0)) -> N/A | O10: =IF(НАСТРОЙКИ!$B$5<>"Да",0,IFERROR(INDIRECT("'["&НАСТРОЙКИ!$D$5&"]ОТЧЕТ'!$C$30"),0)) -> 1.1039561 | P10: =IF(НАСТРОЙКИ!$B$5<>"Да",0,IFERROR(INDIRECT("'["&НАСТРОЙКИ!$D$5&"]ОТЧЕТ'!$C$25"),0)) -> 1345.83 | Q10: =IF(НАСТРОЙКИ!$B$5<>"Да",0,IFERROR(INDIRECT("'["&НАСТРОЙКИ!$D$5&"]ОТЧЕТ'!$C$26"),0)) -> 30011.506 | R10: =IF(НАСТРОЙКИ!$B$5<>"Да",0,IF(НАСТРОЙКИ!$B$15="Да",Q10,Q10+НАСТРОЙКИ!G5+НАСТРОЙКИ!H5+НАСТРОЙКИ!I5)) -> 30011.506 | S10: =IF(НАСТРОЙКИ!$B$5<>"Да",0,IFERROR(INDIRECT("'["&НАСТРОЙКИ!$D$5&"]Ставки'!$B$9"),0)) -> 30011.506 | T10: =IF(НАСТРОЙКИ!$B$5<>"Да",0,IFERROR(INDIRECT("'["&НАСТРОЙКИ!$D$5&"]Ставки'!$B$10"),0)) -> 31556.603 | V10: =B10 -> Очередь 1 | W10: =G10 -> 42105.39 | X10: =H10 -> 38826.961 | Y10: =K10 -> 3278.4292
A11: =НАСТРОЙКИ!B6 -> Да | B11: =НАСТРОЙКИ!C6 -> Очередь 2 | C11: =НАСТРОЙКИ!D6 -> Plato_M-2.xlsx | D11: =IF(НАСТРОЙКИ!$B$6<>"Да",0,IFERROR(INDIRECT("'["&НАСТРОЙКИ!$D$6&"]Вводные'!$G$7"),0)) -> 47119 | E11: =IF(НАСТРОЙКИ!$B$6<>"Да",0,IFERROR(INDIRECT("'["&НАСТРОЙКИ!$D$6&"]Вводные'!$G$8"),0)) -> 47300 | F11: =IF(НАСТРОЙКИ!$B$6<>"Да",0,IFERROR(EDATE(INDIRECT("'["&НАСТРОЙКИ!$D$6&"]Вводные'!$G$8"),INDIRECT("'["&НАСТРОЙКИ!$D$6&"]Вводные'!$G$9")),0)) -> 48030 | G11: =IF(НАСТРОЙКИ!$B$6<>"Да",0,IFERROR(INDIRECT("'["&НАСТРОЙКИ!$D$6&"]ОТЧЕТ'!$C$4"),0)) -> 38215.078 | H11: =IF(НАСТРОЙКИ!$B$6<>"Да",0,-IFERROR(INDIRECT("'["&НАСТРОЙКИ!$D$6&"]ОТЧЕТ'!$C$13"),0)) -> 33373.827 | I11: =IF(НАСТРОЙКИ!$B$6<>"Да",0,IFERROR(INDIRECT("'["&НАСТРОЙКИ!$D$6&"]ОТЧЕТ'!$C$21"),0)) -> 8894.8323 | J11: =IF(НАСТРОЙКИ!$B$6<>"Да",0,-IFERROR(INDIRECT("'["&НАСТРОЙКИ!$D$6&"]ОТЧЕТ'!$C$22"),0)) -> 1829.8732 | K11: =IF(НАСТРОЙКИ!$B$6<>"Да",0,IFERROR(INDIRECT("'["&НАСТРОЙКИ!$D$6&"]ОТЧЕТ'!$C$24"),0)) -> 4841.251 | L11: =IFERROR(K11/G11,0) -> 0.12668432 | M11: =IF(НАСТРОЙКИ!$B$6<>"Да",0,IFERROR(INDIRECT("'["&НАСТРОЙКИ!$D$6&"]ОТЧЕТ'!$C$28"),0)) -> 1635.7837 | N11: =IF(НАСТРОЙКИ!$B$6<>"Да",0,IFERROR(INDIRECT("'["&НАСТРОЙКИ!$D$6&"]ОТЧЕТ'!$C$29"),0)) -> N/A | O11: =IF(НАСТРОЙКИ!$B$6<>"Да",0,IFERROR(INDIRECT("'["&НАСТРОЙКИ!$D$6&"]ОТЧЕТ'!$C$30"),0)) -> 1.1645186 | P11: =IF(НАСТРОЙКИ!$B$6<>"Да",0,IFERROR(INDIRECT("'["&НАСТРОЙКИ!$D$6&"]ОТЧЕТ'!$C$25"),0)) -> 887.76042 | Q11: =IF(НАСТРОЙКИ!$B$6<>"Да",0,IFERROR(INDIRECT("'["&НАСТРОЙКИ!$D$6&"]ОТЧЕТ'!$C$26"),0)) -> 27765.555 | R11: =IF(НАСТРОЙКИ!$B$6<>"Да",0,IF(НАСТРОЙКИ!$B$15="Да",Q11,Q11+НАСТРОЙКИ!G6+НАСТРОЙКИ!H6+НАСТРОЙКИ!I6)) -> 27765.555 | S11: =IF(НАСТРОЙКИ!$B$6<>"Да",0,IFERROR(INDIRECT("'["&НАСТРОЙКИ!$D$6&"]Ставки'!$B$9"),0)) -> 27765.555 | T11: =IF(НАСТРОЙКИ!$B$6<>"Да",0,IFERROR(INDIRECT("'["&НАСТРОЙКИ!$D$6&"]Ставки'!$B$10"),0)) -> 28610.957 | V11: =B11 -> Очередь 2 | W11: =G11 -> 38215.078 | X11: =H11 -> 33373.827 | Y11: =K11 -> 4841.251
A12: =НАСТРОЙКИ!B7 -> Да | B12: =НАСТРОЙКИ!C7 -> Очередь 3 | C12: =НАСТРОЙКИ!D7 -> Plato_M-3.xlsx | D12: =IF(НАСТРОЙКИ!$B$7<>"Да",0,IFERROR(INDIRECT("'["&НАСТРОЙКИ!$D$7&"]Вводные'!$G$7"),0)) -> 47484 | E12: =IF(НАСТРОЙКИ!$B$7<>"Да",0,IFERROR(INDIRECT("'["&НАСТРОЙКИ!$D$7&"]Вводные'!$G$8"),0)) -> 47665 | F12: =IF(НАСТРОЙКИ!$B$7<>"Да",0,IFERROR(EDATE(INDIRECT("'["&НАСТРОЙКИ!$D$7&"]Вводные'!$G$8"),INDIRECT("'["&НАСТРОЙКИ!$D$7&"]Вводные'!$G$9")),0)) -> 48396 | G12: =IF(НАСТРОЙКИ!$B$7<>"Да",0,IFERROR(INDIRECT("'["&НАСТРОЙКИ!$D$7&"]ОТЧЕТ'!$C$4"),0)) -> 33617.809 | H12: =IF(НАСТРОЙКИ!$B$7<>"Да",0,-IFERROR(INDIRECT("'["&НАСТРОЙКИ!$D$7&"]ОТЧЕТ'!$C$13"),0)) -> 28505.402 | I12: =IF(НАСТРОЙКИ!$B$7<>"Да",0,IFERROR(INDIRECT("'["&НАСТРОЙКИ!$D$7&"]ОТЧЕТ'!$C$21"),0)) -> 8948.2061 | J12: =IF(НАСТРОЙКИ!$B$7<>"Да",0,-IFERROR(INDIRECT("'["&НАСТРОЙКИ!$D$7&"]ОТЧЕТ'!$C$22"),0)) -> 1598.7474 | K12: =IF(НАСТРОЙКИ!$B$7<>"Да",0,IFERROR(INDIRECT("'["&НАСТРОЙКИ!$D$7&"]ОТЧЕТ'!$C$24"),0)) -> 5112.4072 | L12: =IFERROR(K12/G12,0) -> 0.15207437 | M12: =IF(НАСТРОЙКИ!$B$7<>"Да",0,IFERROR(INDIRECT("'["&НАСТРОЙКИ!$D$7&"]ОТЧЕТ'!$C$28"),0)) -> 1449.4477 | N12: =IF(НАСТРОЙКИ!$B$7<>"Да",0,IFERROR(INDIRECT("'["&НАСТРОЙКИ!$D$7&"]ОТЧЕТ'!$C$29"),0)) -> N/A | O12: =IF(НАСТРОЙКИ!$B$7<>"Да",0,IFERROR(INDIRECT("'["&НАСТРОЙКИ!$D$7&"]ОТЧЕТ'!$C$30"),0)) -> 1.2019669 | P12: =IF(НАСТРОЙКИ!$B$7<>"Да",0,IFERROR(INDIRECT("'["&НАСТРОЙКИ!$D$7&"]ОТЧЕТ'!$C$25"),0)) -> 846.52292 | Q12: =IF(НАСТРОЙКИ!$B$7<>"Да",0,IFERROR(INDIRECT("'["&НАСТРОЙКИ!$D$7&"]ОТЧЕТ'!$C$26"),0)) -> 23843.816 | R12: =IF(НАСТРОЙКИ!$B$7<>"Да",0,IF(НАСТРОЙКИ!$B$15="Да",Q12,Q12+НАСТРОЙКИ!G7+НАСТРОЙКИ!H7+НАСТРОЙКИ!I7)) -> 23843.816 | S12: =IF(НАСТРОЙКИ!$B$7<>"Да",0,IFERROR(INDIRECT("'["&НАСТРОЙКИ!$D$7&"]Ставки'!$B$9"),0)) -> 23843.816 | T12: =IF(НАСТРОЙКИ!$B$7<>"Да",0,IFERROR(INDIRECT("'["&НАСТРОЙКИ!$D$7&"]Ставки'!$B$10"),0)) -> 25190.384 | V12: =B12 -> Очередь 3 | W12: =G12 -> 33617.809 | X12: =H12 -> 28505.402 | Y12: =K12 -> 5112.4072
A13: =НАСТРОЙКИ!B8 -> Нет | B13: =НАСТРОЙКИ!C8 -> Очередь 4 | C13: =НАСТРОЙКИ!D8 -> 0 | D13: =IF(НАСТРОЙКИ!$B$8<>"Да",0,IFERROR(INDIRECT("'["&НАСТРОЙКИ!$D$8&"]Вводные'!$G$7"),0)) -> 0 | E13: =IF(НАСТРОЙКИ!$B$8<>"Да",0,IFERROR(INDIRECT("'["&НАСТРОЙКИ!$D$8&"]Вводные'!$G$8"),0)) -> 0 | F13: =IF(НАСТРОЙКИ!$B$8<>"Да",0,IFERROR(EDATE(INDIRECT("'["&НАСТРОЙКИ!$D$8&"]Вводные'!$G$8"),INDIRECT("'["&НАСТРОЙКИ!$D$8&"]Вводные'!$G$9")),0)) -> 0 | G13: =IF(НАСТРОЙКИ!$B$8<>"Да",0,IFERROR(INDIRECT("'["&НАСТРОЙКИ!$D$8&"]ОТЧЕТ'!$C$4"),0)) -> 0 | H13: =IF(НАСТРОЙКИ!$B$8<>"Да",0,-IFERROR(INDIRECT("'["&НАСТРОЙКИ!$D$8&"]ОТЧЕТ'!$C$13"),0)) -> 0 | I13: =IF(НАСТРОЙКИ!$B$8<>"Да",0,IFERROR(INDIRECT("'["&НАСТРОЙКИ!$D$8&"]ОТЧЕТ'!$C$21"),0)) -> 0 | J13: =IF(НАСТРОЙКИ!$B$8<>"Да",0,-IFERROR(INDIRECT("'["&НАСТРОЙКИ!$D$8&"]ОТЧЕТ'!$C$22"),0)) -> 0 | K13: =IF(НАСТРОЙКИ!$B$8<>"Да",0,IFERROR(INDIRECT("'["&НАСТРОЙКИ!$D$8&"]ОТЧЕТ'!$C$24"),0)) -> 0 | L13: =IFERROR(K13/G13,0) -> 0 | M13: =IF(НАСТРОЙКИ!$B$8<>"Да",0,IFERROR(INDIRECT("'["&НАСТРОЙКИ!$D$8&"]ОТЧЕТ'!$C$28"),0)) -> 0 | N13: =IF(НАСТРОЙКИ!$B$8<>"Да",0,IFERROR(INDIRECT("'["&НАСТРОЙКИ!$D$8&"]ОТЧЕТ'!$C$29"),0)) -> 0 | O13: =IF(НАСТРОЙКИ!$B$8<>"Да",0,IFERROR(INDIRECT("'["&НАСТРОЙКИ!$D$8&"]ОТЧЕТ'!$C$30"),0)) -> 0 | P13: =IF(НАСТРОЙКИ!$B$8<>"Да",0,IFERROR(INDIRECT("'["&НАСТРОЙКИ!$D$8&"]ОТЧЕТ'!$C$25"),0)) -> 0 | Q13: =IF(НАСТРОЙКИ!$B$8<>"Да",0,IFERROR(INDIRECT("'["&НАСТРОЙКИ!$D$8&"]ОТЧЕТ'!$C$26"),0)) -> 0 | R13: =IF(НАСТРОЙКИ!$B$8<>"Да",0,IF(НАСТРОЙКИ!$B$15="Да",Q13,Q13+НАСТРОЙКИ!G8+НАСТРОЙКИ!H8+НАСТРОЙКИ!I8)) -> 0 | S13: =IF(НАСТРОЙКИ!$B$8<>"Да",0,IFERROR(INDIRECT("'["&НАСТРОЙКИ!$D$8&"]Ставки'!$B$9"),0)) -> 0 | T13: =IF(НАСТРОЙКИ!$B$8<>"Да",0,IFERROR(INDIRECT("'["&НАСТРОЙКИ!$D$8&"]Ставки'!$B$10"),0)) -> 0 | V13: =B13 -> Очередь 4 | W13: =G13 -> 0 | X13: =H13 -> 0 | Y13: =K13 -> 0
B14: ИТОГО / ПРОЕКТ | G14: =SUM(G10:G13) -> 113938.28 | H14: =SUM(H10:H13) -> 100706.19 | I14: =SUM(I10:I13) -> 26065.535 | J14: =SUM(J10:J13) -> 5601.7067 | K14: =SUM(K10:K13) -> 13232.087 | L14: =IFERROR(K14/G14,0) -> 0.11613382 | M14: =SUM(M10:M13) -> 5588.5845 | N14: ='ПО МЕСЯЦАМ'!B18 -> 0 | O14: =MIN(O10:O13) -> 0 | P14: =SUM(P10:P13) -> 3080.1133 | Q14: =SUM(Q10:Q13) -> 81620.877 | R14: =SUM(R10:R13) -> 81620.877 | S14: ='ПО МЕСЯЦАМ'!B13 -> 43581.872 | T14: ='ПО МЕСЯЦАМ'!B11 -> 50989.543 | V14: ИТОГО | W14: =SUM(W10:W13) -> 113938.28 | X14: =SUM(X10:X13) -> 100706.19 | Y14: =SUM(Y10:Y13) -> 13232.087
A16: Имена файлов задаются на листе «НАСТРОЙКИ» в D5:D8. После изменения имени откройте соответствующий файл модели: динамические внешние ссылки через ДВССЫЛ / INDIRECT работают только с открытыми исходными книгами.
V17: Очередь | W17: ПФ по модели | X17: ПФ скорр. | Y17: Пик ПФ
V18: =B10 -> Очередь 1 | W18: =Q10 -> 30011.506 | X18: =R10 -> 30011.506 | Y18: =S10 -> 30011.506
V19: =B11 -> Очередь 2 | W19: =Q11 -> 27765.555 | X19: =R11 -> 27765.555 | Y19: =S11 -> 27765.555
V20: =B12 -> Очередь 3 | W20: =Q12 -> 23843.816 | X20: =R12 -> 23843.816 | Y20: =S12 -> 23843.816
V21: =B13 -> Очередь 4 | W21: =Q13 -> 0 | X21: =R13 -> 0 | Y21: =S13 -> 0
V22: ИТОГО | W22: =SUM(W18:W21) -> 81620.877 | X22: =SUM(X18:X21) -> 81620.877 | Y22: =MAX(Y18:Y21) -> 30011.506

Sheet ПО МЕСЯЦАМ
A1: ПЛАТО — КОНСОЛИДИРОВАННЫЙ ПОМЕСЯЧНЫЙ ДЕНЕЖНЫЙ ПОТОК
A4: Показатель | B4: Значение
A5: Совокупная выручка, млн ₽ | B5: =IF(SUM(C24:DF24)<>0,SUM(C24:DF24),КЭШ_СВОД!B2) -> 113938.28
A6: Совокупные расходы проекта, млн ₽ | B6: =IF(-SUM(C25:DF27)<>0,-SUM(C25:DF27),КЭШ_СВОД!B3) -> 101111.01
A7: Чистый проектный CF до финансирования, млн ₽ | B7: =IF(SUM(C28:DF28)<>0,SUM(C28:DF28),КЭШ_СВОД!B4) -> 7153.285
A8: Получение БРИДЖ, млн ₽ | B8: =IF(SUM(C29:DF29)<>0,SUM(C29:DF29),КЭШ_СВОД!B5) -> 3203.8258
A9: Получение ПФ, млн ₽ | B9: =IF(SUM(C30:DF30)<>0,SUM(C30:DF30),КЭШ_СВОД!B6) -> 82066.815
A10: Погашение долга, млн ₽ | B10: =-SUM(C31:DF31) -> 84700.99
A11: Пик эскроу, млн ₽ | B11: =MAX(C34:DF34) -> 50989.543
A12: Пик БРИДЖ, млн ₽ | B12: =MAX(C35:DF35) -> 530.3764
A13: Пик ПФ, млн ₽ | B13: =MAX(C36:DF36) -> 43581.872
A14: Минимальное покрытие эскроу / ПФ | B14: =IFERROR(MINIFS(C38:DF38,C36:DF36,">0"),0) -> 0
A15: Остаток денежных средств на конец, млн ₽ | B15: =DF33 -> -84700.99
A16: Пик совокупного долга, млн ₽ | B16: =MAX(C37:DF37) -> 43759.526
A17: NPV свода, млн ₽ | B17: =SUMPRODUCT(C28:DF28,C40:DF40) -> 0
A18: IRR свода | B18: =IFERROR((1+IRR(C28:DF28))^12-1,0) -> 0
C22: =НАСТРОЙКИ!B25 -> 46388 | D22: =EDATE(C22,1) -> 46419 | E22: =EDATE(D22,1) -> 46447 | F22: =EDATE(E22,1) -> 46478 | G22: =EDATE(F22,1) -> 46508 | H22: =EDATE(G22,1) -> 46539 | I22: =EDATE(H22,1) -> 46569 | J22: =EDATE(I22,1) -> 46600 | K22: =EDATE(J22,1) -> 46631 | ... DF22: =EDATE(DE22,1) -> 49644
A23: КОНСОЛИДИРОВАНО | B23: Ед. изм.
A24: Выручка | B24: млн ₽ | C24: =C45+C61+C77+C93 -> 0 | D24: =D45+D61+D77+D93 -> 0 | E24: =E45+E61+E77+E93 -> 0 | F24: =F45+F61+F77+F93 -> 0 | G24: =G45+G61+G77+G93 -> 0 | H24: =H45+H61+H77+H93 -> 0 | I24: =I45+I61+I77+I93 -> 0 | J24: =J45+J61+J77+J93 -> 0 | ... DF24: =DF45+DF61+DF77+DF93 -> 0
A25: Операционные расходы | B25: млн ₽ | C25: =C46+C62+C78+C94 -> 0 | D25: =D46+D62+D78+D94 -> 0 | E25: =E46+E62+E78+E94 -> 0 | F25: =F46+F62+F78+F94 -> 0 | G25: =G46+G62+G78+G94 -> 0 | H25: =H46+H62+H78+H94 -> 0 | I25: =I46+I62+I78+I94 -> 0 | J25: =J46+J62+J78+J94 -> 0 | ... DF25: =DF46+DF62+DF78+DF94 -> 0
A26: Инвестиционные расходы | B26: млн ₽ | C26: =C47+C63+C79+C95 -> 0 | D26: =D47+D63+D79+D95 -> 0 | E26: =E47+E63+E79+E95 -> 0 | F26: =F47+F63+F79+F95 -> 0 | G26: =G47+G63+G79+G95 -> 0 | H26: =H47+H63+H79+H95 -> 0 | I26: =I47+I63+I79+I95 -> 0 | J26: =J47+J63+J79+J95 -> 0 | ... DF26: =DF47+DF63+DF79+DF95 -> 0
A27: Проценты и комиссии | B27: млн ₽ | C27: =C48+C64+C80+C96 -> 0 | D27: =D48+D64+D80+D96 -> 0 | E27: =E48+E64+E80+E96 -> 0 | F27: =F48+F64+F80+F96 -> 0 | G27: =G48+G64+G80+G96 -> 0 | H27: =H48+H64+H80+H96 -> 0 | I27: =I48+I64+I80+I96 -> 0 | J27: =J48+J64+J80+J96 -> 0 | ... DF27: =DF48+DF64+DF80+DF96 -> 0
A28: CF до финансирования | B28: млн ₽ | C28: =C49+C65+C81+C97 -> 0 | D28: =D49+D65+D81+D97 -> 0 | E28: =E49+E65+E81+E97 -> 0 | F28: =F49+F65+F81+F97 -> 0 | G28: =G49+G65+G81+G97 -> 0 | H28: =H49+H65+H81+H97 -> 0 | I28: =I49+I65+I81+I97 -> 0 | J28: =J49+J65+J81+J97 -> 0 | ... DF28: =DF49+DF65+DF81+DF97 -> 0
A29: Получение БРИДЖ | B29: млн ₽ | C29: =C50+C66+C82+C98 -> 0 | D29: =D50+D66+D82+D98 -> 0 | E29: =E50+E66+E82+E98 -> 0 | F29: =F50+F66+F82+F98 -> 0 | G29: =G50+G66+G82+G98 -> 0 | H29: =H50+H66+H82+H98 -> 0 | I29: =I50+I66+I82+I98 -> 0 | J29: =J50+J66+J82+J98 -> 0 | ... DF29: =DF50+DF66+DF82+DF98 -> 0
A30: Получение ПФ | B30: млн ₽ | C30: =C51+C67+C83+C99 -> 0 | D30: =D51+D67+D83+D99 -> 0 | E30: =E51+E67+E83+E99 -> 0 | F30: =F51+F67+F83+F99 -> 0 | G30: =G51+G67+G83+G99 -> 0 | H30: =H51+H67+H83+H99 -> 0 | I30: =I51+I67+I83+I99 -> 0 | J30: =J51+J67+J83+J99 -> 0 | ... DF30: =DF51+DF67+DF83+DF99 -> 0
A31: Погашение долга | B31: млн ₽ | C31: =C52+C68+C84+C100 -> 0 | D31: =D52+D68+D84+D100 -> 0 | E31: =E52+E68+E84+E100 -> 0 | F31: =F52+F68+F84+F100 -> 0 | G31: =G52+G68+G84+G100 -> 0 | H31: =H52+H68+H84+H100 -> 0 | I31: =I52+I68+I84+I100 -> 0 | J31: =J52+J68+J84+J100 -> 0 | ... DF31: =DF52+DF68+DF84+DF100 -> 0
A32: CF после финансирования | B32: млн ₽ | C32: =C53+C69+C85+C101 -> 0 | D32: =D53+D69+D85+D101 -> 0 | E32: =E53+E69+E85+E101 -> 0 | F32: =F53+F69+F85+F101 -> 0 | G32: =G53+G69+G85+G101 -> 0 | H32: =H53+H69+H85+H101 -> 0 | I32: =I53+I69+I85+I101 -> 0 | J32: =J53+J69+J85+J101 -> 0 | ... DF32: =DF53+DF69+DF85+DF101 -> 0
A33: Накопленный денежный поток | B33: млн ₽ | C33: =C32 -> 0 | D33: =C33+D32 -> 0 | E33: =D33+E32 -> 0 | F33: =E33+F32 -> 0 | G33: =F33+G32 -> 0 | H33: =G33+H32 -> 0 | I33: =H33+I32 -> 0 | J33: =I33+J32 -> 0 | K33: =J33+K32 -> 0 | ... DF33: =DE33+DF32 -> -84700.99
A34: Средства на эскроу | B34: млн ₽ | C34: =C54+C70+C86+C102 -> 0 | D34: =D54+D70+D86+D102 -> 0 | E34: =E54+E70+E86+E102 -> 0 | F34: =F54+F70+F86+F102 -> 0 | G34: =G54+G70+G86+G102 -> 0 | H34: =H54+H70+H86+H102 -> 0 | I34: =I54+I70+I86+I102 -> 0 | J34: =J54+J70+J86+J102 -> 0 | ... DF34: =DF54+DF70+DF86+DF102 -> 20223.516
A35: Остаток БРИДЖ | B35: млн ₽ | C35: =C55+C71+C87+C103 -> 0 | D35: =D55+D71+D87+D103 -> 0 | E35: =E55+E71+E87+E103 -> 0.84525 | F35: =F55+F71+F87+F103 -> 0.84525 | G35: =G55+G71+G87+G103 -> 0.84525 | H35: =H55+H71+H87+H103 -> 0.84525 | I35: =I55+I71+I87+I103 -> 0.84525 | J35: =J55+J71+J87+J103 -> 0.84525 | ... DF35: =DF55+DF71+DF87+DF103 -> 0
A36: Остаток ПФ | B36: млн ₽ | C36: =C56+C72+C88+C104 -> 0 | D36: =D56+D72+D88+D104 -> 0 | E36: =E56+E72+E88+E104 -> 0 | F36: =F56+F72+F88+F104 -> 0 | G36: =G56+G72+G88+G104 -> 0 | H36: =H56+H72+H88+H104 -> 0 | I36: =I56+I72+I88+I104 -> 0 | J36: =J56+J72+J88+J104 -> 0 | ... DF36: =DF56+DF72+DF88+DF104 -> 0
A37: Совокупный долг | B37: млн ₽ | C37: =C57+C73+C89+C105 -> 0 | D37: =D57+D73+D89+D105 -> 0 | E37: =E57+E73+E89+E105 -> 0.84525 | F37: =F57+F73+F89+F105 -> 0.84525 | G37: =G57+G73+G89+G105 -> 0.84525 | H37: =H57+H73+H89+H105 -> 0.84525 | I37: =I57+I73+I89+I105 -> 0.84525 | J37: =J57+J73+J89+J105 -> 0.84525 | ... DF37: =DF57+DF73+DF89+DF105 -> 0
A38: Покрытие эскроу / ПФ | B38: x | C38: =IFERROR(C34/C36,0) -> 0 | D38: =IFERROR(D34/D36,0) -> 0 | E38: =IFERROR(E34/E36,0) -> 0 | F38: =IFERROR(F34/F36,0) -> 0 | G38: =IFERROR(G34/G36,0) -> 0 | H38: =IFERROR(H34/H36,0) -> 0 | I38: =IFERROR(I34/I36,0) -> 0 | J38: =IFERROR(J34/J36,0) -> 0 | ... DF38: =IFERROR(DF34/DF36,0) -> 0
A40: Коэффициент дисконтирования | B40: служебно | C40: =1/(1+НАСТРОЙКИ!$B$20)^(0/12) -> 1 | D40: =1/(1+НАСТРОЙКИ!$B$20)^(1/12) -> 0.98492138 | E40: =1/(1+НАСТРОЙКИ!$B$20)^(2/12) -> 0.97007012 | F40: =1/(1+НАСТРОЙКИ!$B$20)^(3/12) -> 0.95544279 | G40: =1/(1+НАСТРОЙКИ!$B$20)^(4/12) -> 0.94103603 | H40: =1/(1+НАСТРОЙКИ!$B$20)^(5/12) -> 0.9268465 | I40: =1/(1+НАСТРОЙКИ!$B$20)^(6/12) -> 0.91287093 | J40: =1/(1+НАСТРОЙКИ!$B$20)^(7/12) -> 0.89910609 | K40: =1/(1+НАСТРОЙКИ!$B$20)^(8/12) -> 0.88554881 | L40: =1/(1+НАСТРОЙКИ!$B$20)^(9/12) -> 0.87219595 | M40: =1/(1+НАСТРОЙКИ!$B$20)^(10/12) -> 0.85904443 | N40: =1/(1+НАСТРОЙКИ!$B$20)^(11/12) -> 0.84609123 | O40: =1/(1+НАСТРОЙКИ!$B$20)^(12/12) -> 0.83333333 | P40: =1/(1+НАСТРОЙКИ!$B$20)^(13/12) -> 0.82076781 | Q40: =1/(1+НАСТРОЙКИ!$B$20)^(14/12) -> 0.80839176 | R40: =1/(1+НАСТРОЙКИ!$B$20)^(15/12) -> 0.79620233 | S40: =1/(1+НАСТРОЙКИ!$B$20)^(16/12) -> 0.78419669 | T40: =1/(1+НАСТРОЙКИ!$B$20)^(17/12) -> 0.77237208 | U40: =1/(1+НАСТРОЙКИ!$B$20)^(18/12) -> 0.76072577 | V40: =1/(1+НАСТРОЙКИ!$B$20)^(19/12) -> 0.74925508 | W40: =1/(1+НАСТРОЙКИ!$B$20)^(20/12) -> 0.73795734 | X40: =1/(1+НАСТРОЙКИ!$B$20)^(21/12) -> 0.72682996 | Y40: =1/(1+НАСТРОЙКИ!$B$20)^(22/12) -> 0.71587036 | Z40: =1/(1+НАСТРОЙКИ!$B$20)^(23/12) -> 0.70507602 | AA40: =1/(1+НАСТРОЙКИ!$B$20)^(24/12) -> 0.69444444 | AB40: =1/(1+НАСТРОЙКИ!$B$20)^(25/12) -> 0.68397318 | AC40: =1/(1+НАСТРОЙКИ!$B$20)^(26/12) -> 0.6736598 | AD40: =1/(1+НАСТРОЙКИ!$B$20)^(27/12) -> 0.66350194 | AE40: =1/(1+НАСТРОЙКИ!$B$20)^(28/12) -> 0.65349724 | AF40: =1/(1+НАСТРОЙКИ!$B$20)^(29/12) -> 0.6436434 | AG40: =1/(1+НАСТРОЙКИ!$B$20)^(30/12) -> 0.63393815 | AH40: =1/(1+НАСТРОЙКИ!$B$20)^(31/12) -> 0.62437923 | AI40: =1/(1+НАСТРОЙКИ!$B$20)^(32/12) -> 0.61496445 | AJ40: =1/(1+НАСТРОЙКИ!$B$20)^(33/12) -> 0.60569163 | AK40: =1/(1+НАСТРОЙКИ!$B$20)^(34/12) -> 0.59655863 | AL40: =1/(1+НАСТРОЙКИ!$B$20)^(35/12) -> 0.58756335 | AM40: =1/(1+НАСТРОЙКИ!$B$20)^(36/12) -> 0.5787037 | AN40: =1/(1+НАСТРОЙКИ!$B$20)^(37/12) -> 0.56997765 | AO40: =1/(1+НАСТРОЙКИ!$B$20)^(38/12) -> 0.56138317 | AP40: =1/(1+НАСТРОЙКИ!$B$20)^(39/12) -> 0.55291828 | AQ40: =1/(1+НАСТРОЙКИ!$B$20)^(40/12) -> 0.54458104 | AR40: =1/(1+НАСТРОЙКИ!$B$20)^(41/12) -> 0.5363695 | AS40: =1/(1+НАСТРОЙКИ!$B$20)^(42/12) -> 0.52828179 | AT40: =1/(1+НАСТРОЙКИ!$B$20)^(43/12) -> 0.52031602 | AU40: =1/(1+НАСТРОЙКИ!$B$20)^(44/12) -> 0.51247037 | AV40: =1/(1+НАСТРОЙКИ!$B$20)^(45/12) -> 0.50474303 | AW40: =1/(1+НАСТРОЙКИ!$B$20)^(46/12) -> 0.4971322 | AX40: =1/(1+НАСТРОЙКИ!$B$20)^(47/12) -> 0.48963613 | AY40: =1/(1+НАСТРОЙКИ!$B$20)^(48/12) -> 0.48225309 | AZ40: =1/(1+НАСТРОЙКИ!$B$20)^(49/12) -> 0.47498137 | BA40: =1/(1+НАСТРОЙКИ!$B$20)^(50/12) -> 0.46781931 | BB40: =1/(1+НАСТРОЙКИ!$B$20)^(51/12) -> 0.46076524 | BC40: =1/(1+НАСТРОЙКИ!$B$20)^(52/12) -> 0.45381753 | BD40: =1/(1+НАСТРОЙКИ!$B$20)^(53/12) -> 0.44697459 | BE40: =1/(1+НАСТРОЙКИ!$B$20)^(54/12) -> 0.44023482 | BF40: =1/(1+НАСТРОЙКИ!$B$20)^(55/12) -> 0.43359669 | BG40: =1/(1+НАСТРОЙКИ!$B$20)^(56/12) -> 0.42705865 | BH40: =1/(1+НАСТРОЙКИ!$B$20)^(57/12) -> 0.42061919 | BI40: =1/(1+НАСТРОЙКИ!$B$20)^(58/12) -> 0.41427683 | BJ40: =1/(1+НАСТРОЙКИ!$B$20)^(59/12) -> 0.4080301 | BK40: =1/(1+НАСТРОЙКИ!$B$20)^(60/12) -> 0.40187757 | BL40: =1/(1+НАСТРОЙКИ!$B$20)^(61/12) -> 0.39581781 | BM40: =1/(1+НАСТРОЙКИ!$B$20)^(62/12) -> 0.38984942 | BN40: =1/(1+НАСТРОЙКИ!$B$20)^(63/12) -> 0.38397103 | BO40: =1/(1+НАСТРОЙКИ!$B$20)^(64/12) -> 0.37818127 | BP40: =1/(1+НАСТРОЙКИ!$B$20)^(65/12) -> 0.37247882 | BQ40: =1/(1+НАСТРОЙКИ!$B$20)^(66/12) -> 0.36686235 | BR40: =1/(1+НАСТРОЙКИ!$B$20)^(67/12) -> 0.36133057 | BS40: =1/(1+НАСТРОЙКИ!$B$20)^(68/12) -> 0.3558822 | BT40: =1/(1+НАСТРОЙКИ!$B$20)^(69/12) -> 0.35051599 | BU40: =1/(1+НАСТРОЙКИ!$B$20)^(70/12) -> 0.34523069 | BV40: =1/(1+НАСТРОЙКИ!$B$20)^(71/12) -> 0.34002509 | BW40: =1/(1+НАСТРОЙКИ!$B$20)^(72/12) -> 0.33489798 | BX40: =1/(1+НАСТРОЙКИ!$B$20)^(73/12) -> 0.32984818 | BY40: =1/(1+НАСТРОЙКИ!$B$20)^(74/12) -> 0.32487452 | BZ40: =1/(1+НАСТРОЙКИ!$B$20)^(75/12) -> 0.31997586 | CA40: =1/(1+НАСТРОЙКИ!$B$20)^(76/12) -> 0.31515106 | CB40: =1/(1+НАСТРОЙКИ!$B$20)^(77/12) -> 0.31039902 | CC40: =1/(1+НАСТРОЙКИ!$B$20)^(78/12) -> 0.30571863 | CD40: =1/(1+НАСТРОЙКИ!$B$20)^(79/12) -> 0.30110881 | CE40: =1/(1+НАСТРОЙКИ!$B$20)^(80/12) -> 0.2965685 | CF40: =1/(1+НАСТРОЙКИ!$B$20)^(81/12) -> 0.29209666 | CG40: =1/(1+НАСТРОЙКИ!$B$20)^(82/12) -> 0.28769224 | CH40: =1/(1+НАСТРОЙКИ!$B$20)^(83/12) -> 0.28335424 | CI40: =1/(1+НАСТРОЙКИ!$B$20)^(84/12) -> 0.27908165 | CJ40: =1/(1+НАСТРОЙКИ!$B$20)^(85/12) -> 0.27487348 | CK40: =1/(1+НАСТРОЙКИ!$B$20)^(86/12) -> 0.27072877 | CL40: =1/(1+НАСТРОЙКИ!$B$20)^(87/12) -> 0.26664655 | CM40: =1/(1+НАСТРОЙКИ!$B$20)^(88/12) -> 0.26262589 | CN40: =1/(1+НАСТРОЙКИ!$B$20)^(89/12) -> 0.25866585 | CO40: =1/(1+НАСТРОЙКИ!$B$20)^(90/12) -> 0.25476552 | CP40: =1/(1+НАСТРОЙКИ!$B$20)^(91/12) -> 0.25092401 | CQ40: =1/(1+НАСТРОЙКИ!$B$20)^(92/12) -> 0.24714042 | CR40: =1/(1+НАСТРОЙКИ!$B$20)^(93/12) -> 0.24341388 | CS40: =1/(1+НАСТРОЙКИ!$B$20)^(94/12) -> 0.23974354 | CT40: =1/(1+НАСТРОЙКИ!$B$20)^(95/12) -> 0.23612853 | CU40: =1/(1+НАСТРОЙКИ!$B$20)^(96/12) -> 0.23256804 | CV40: =1/(1+НАСТРОЙКИ!$B$20)^(97/12) -> 0.22906123 | CW40: =1/(1+НАСТРОЙКИ!$B$20)^(98/12) -> 0.2256073 | CX40: =1/(1+НАСТРОЙКИ!$B$20)^(99/12) -> 0.22220546 | CY40: =1/(1+НАСТРОЙКИ!$B$20)^(100/12) -> 0.2188549 | CZ40: =1/(1+НАСТРОЙКИ!$B$20)^(101/12) -> 0.21555487 | DA40: =1/(1+НАСТРОЙКИ!$B$20)^(102/12) -> 0.2123046 | DB40: =1/(1+НАСТРОЙКИ!$B$20)^(103/12) -> 0.20910334 | DC40: =1/(1+НАСТРОЙКИ!$B$20)^(104/12) -> 0.20595035 | DD40: =1/(1+НАСТРОЙКИ!$B$20)^(105/12) -> 0.2028449 | DE40: =1/(1+НАСТРОЙКИ!$B$20)^(106/12) -> 0.19978628 | DF40: =1/(1+НАСТРОЙКИ!$B$20)^(107/12) -> 0.19677378
A43: ="ОЧЕРЕДЬ 1 — "&НАСТРОЙКИ!D5 -> ОЧЕРЕДЬ 1 — PLATO_M-1.xlsx
A44: Показатель | B44: Ед. изм.
A45: Выручка | B45: млн ₽ | C45: =IF(НАСТРОЙКИ!$B$5<>"Да",0,IFERROR(SUMIF(INDIRECT("'["&НАСТРОЙКИ!$D$5&"]CF'!$L$3:$EO$3"),C$22,INDIRECT("'["&НАСТРОЙКИ!$D$5&"]CF'!$L$18:$EO$18")),0)) -> 0 | D45: =IF(НАСТРОЙКИ!$B$5<>"Да",0,IFERROR(SUMIF(INDIRECT("'["&НАСТРОЙКИ!$D$5&"]CF'!$L$3:$EO$3"),D$22,INDIRECT("'["&НАСТРОЙКИ!$D$5&"]CF'!$L$18:$EO$18")),0)) -> 0 | E45: =IF(НАСТРОЙКИ!$B$5<>"Да",0,IFERROR(SUMIF(INDIRECT("'["&НАСТРОЙКИ!$D$5&"]CF'!$L$3:$EO$3"),E$22,INDIRECT("'["&НАСТРОЙКИ!$D$5&"]CF'!$L$18:$EO$18")),0)) -> 0 | F45: =IF(НАСТРОЙКИ!$B$5<>"Да",0,IFERROR(SUMIF(INDIRECT("'["&НАСТРОЙКИ!$D$5&"]CF'!$L$3:$EO$3"),F$22,INDIRECT("'["&НАСТРОЙКИ!$D$5&"]CF'!$L$18:$EO$18")),0)) -> 0 | G45: =IF(НАСТРОЙКИ!$B$5<>"Да",0,IFERROR(SUMIF(INDIRECT("'["&НАСТРОЙКИ!$D$5&"]CF'!$L$3:$EO$3"),G$22,INDIRECT("'["&НАСТРОЙКИ!$D$5&"]CF'!$L$18:$EO$18")),0)) -> 0 | H45: =IF(НАСТРОЙКИ!$B$5<>"Да",0,IFERROR(SUMIF(INDIRECT("'["&НАСТРОЙКИ!$D$5&"]CF'!$L$3:$EO$3"),H$22,INDIRECT("'["&НАСТРОЙКИ!$D$5&"]CF'!$L$18:$EO$18")),0)) -> 0 | I45: =IF(НАСТРОЙКИ!$B$5<>"Да",0,IFERROR(SUMIF(INDIRECT("'["&НАСТРОЙКИ!$D$5&"]CF'!$L$3:$EO$3"),I$22,INDIRECT("'["&НАСТРОЙКИ!$D$5&"]CF'!$L$18:$EO$18")),0)) -> 0 | J45: =IF(НАСТРОЙКИ!$B$5<>"Да",0,IFERROR(SUMIF(INDIRECT("'["&НАСТРОЙКИ!$D$5&"]CF'!$L$3:$EO$3"),J$22,INDIRECT("'["&НАСТРОЙКИ!$D$5&"]CF'!$L$18:$EO$18")),0)) -> 0 | ... DF45: =IF(НАСТРОЙКИ!$B$5<>"Да",0,IFERROR(SUMIF(INDIRECT("'["&НАСТРОЙКИ!$D$5&"]CF'!$L$3:$EO$3"),DF$22,INDIRECT("'["&НАСТРОЙКИ!$D$5&"]CF'!$L$18:$EO$18")),0)) -> 0
A46: Операционные расходы | B46: млн ₽ | C46: =IF(НАСТРОЙКИ!$B$5<>"Да",0,IFERROR(SUMIF(INDIRECT("'["&НАСТРОЙКИ!$D$5&"]CF'!$L$3:$EO$3"),C$22,INDIRECT("'["&НАСТРОЙКИ!$D$5&"]CF'!$L$20:$EO$20")),0)) -> 0 | D46: =IF(НАСТРОЙКИ!$B$5<>"Да",0,IFERROR(SUMIF(INDIRECT("'["&НАСТРОЙКИ!$D$5&"]CF'!$L$3:$EO$3"),D$22,INDIRECT("'["&НАСТРОЙКИ!$D$5&"]CF'!$L$20:$EO$20")),0)) -> 0 | E46: =IF(НАСТРОЙКИ!$B$5<>"Да",0,IFERROR(SUMIF(INDIRECT("'["&НАСТРОЙКИ!$D$5&"]CF'!$L$3:$EO$3"),E$22,INDIRECT("'["&НАСТРОЙКИ!$D$5&"]CF'!$L$20:$EO$20")),0)) -> 0 | F46: =IF(НАСТРОЙКИ!$B$5<>"Да",0,IFERROR(SUMIF(INDIRECT("'["&НАСТРОЙКИ!$D$5&"]CF'!$L$3:$EO$3"),F$22,INDIRECT("'["&НАСТРОЙКИ!$D$5&"]CF'!$L$20:$EO$20")),0)) -> 0 | G46: =IF(НАСТРОЙКИ!$B$5<>"Да",0,IFERROR(SUMIF(INDIRECT("'["&НАСТРОЙКИ!$D$5&"]CF'!$L$3:$EO$3"),G$22,INDIRECT("'["&НАСТРОЙКИ!$D$5&"]CF'!$L$20:$EO$20")),0)) -> 0 | H46: =IF(НАСТРОЙКИ!$B$5<>"Да",0,IFERROR(SUMIF(INDIRECT("'["&НАСТРОЙКИ!$D$5&"]CF'!$L$3:$EO$3"),H$22,INDIRECT("'["&НАСТРОЙКИ!$D$5&"]CF'!$L$20:$EO$20")),0)) -> 0 | I46: =IF(НАСТРОЙКИ!$B$5<>"Да",0,IFERROR(SUMIF(INDIRECT("'["&НАСТРОЙКИ!$D$5&"]CF'!$L$3:$EO$3"),I$22,INDIRECT("'["&НАСТРОЙКИ!$D$5&"]CF'!$L$20:$EO$20")),0)) -> 0 | J46: =IF(НАСТРОЙКИ!$B$5<>"Да",0,IFERROR(SUMIF(INDIRECT("'["&НАСТРОЙКИ!$D$5&"]CF'!$L$3:$EO$3"),J$22,INDIRECT("'["&НАСТРОЙКИ!$D$5&"]CF'!$L$20:$EO$20")),0)) -> 0 | ... DF46: =IF(НАСТРОЙКИ!$B$5<>"Да",0,IFERROR(SUMIF(INDIRECT("'["&НАСТРОЙКИ!$D$5&"]CF'!$L$3:$EO$3"),DF$22,INDIRECT("'["&НАСТРОЙКИ!$D$5&"]CF'!$L$20:$EO$20")),0)) -> 0
A47: Инвестиционные расходы | B47: млн ₽ | C47: =IF(НАСТРОЙКИ!$B$5<>"Да",0,IFERROR(SUMIF(INDIRECT("'["&НАСТРОЙКИ!$D$5&"]CF'!$L$3:$EO$3"),C$22,INDIRECT("'["&НАСТРОЙКИ!$D$5&"]CF'!$L$25:$EO$25")),0)) -> 0 | D47: =IF(НАСТРОЙКИ!$B$5<>"Да",0,IFERROR(SUMIF(INDIRECT("'["&НАСТРОЙКИ!$D$5&"]CF'!$L$3:$EO$3"),D$22,INDIRECT("'["&НАСТРОЙКИ!$D$5&"]CF'!$L$25:$EO$25")),0)) -> 0 | E47: =IF(НАСТРОЙКИ!$B$5<>"Да",0,IFERROR(SUMIF(INDIRECT("'["&НАСТРОЙКИ!$D$5&"]CF'!$L$3:$EO$3"),E$22,INDIRECT("'["&НАСТРОЙКИ!$D$5&"]CF'!$L$25:$EO$25")),0)) -> 0 | F47: =IF(НАСТРОЙКИ!$B$5<>"Да",0,IFERROR(SUMIF(INDIRECT("'["&НАСТРОЙКИ!$D$5&"]CF'!$L$3:$EO$3"),F$22,INDIRECT("'["&НАСТРОЙКИ!$D$5&"]CF'!$L$25:$EO$25")),0)) -> 0 | G47: =IF(НАСТРОЙКИ!$B$5<>"Да",0,IFERROR(SUMIF(INDIRECT("'["&НАСТРОЙКИ!$D$5&"]CF'!$L$3:$EO$3"),G$22,INDIRECT("'["&НАСТРОЙКИ!$D$5&"]CF'!$L$25:$EO$25")),0)) -> 0 | H47: =IF(НАСТРОЙКИ!$B$5<>"Да",0,IFERROR(SUMIF(INDIRECT("'["&НАСТРОЙКИ!$D$5&"]CF'!$L$3:$EO$3"),H$22,INDIRECT("'["&НАСТРОЙКИ!$D$5&"]CF'!$L$25:$EO$25")),0)) -> 0 | I47: =IF(НАСТРОЙКИ!$B$5<>"Да",0,IFERROR(SUMIF(INDIRECT("'["&НАСТРОЙКИ!$D$5&"]CF'!$L$3:$EO$3"),I$22,INDIRECT("'["&НАСТРОЙКИ!$D$5&"]CF'!$L$25:$EO$25")),0)) -> 0 | J47: =IF(НАСТРОЙКИ!$B$5<>"Да",0,IFERROR(SUMIF(INDIRECT("'["&НАСТРОЙКИ!$D$5&"]CF'!$L$3:$EO$3"),J$22,INDIRECT("'["&НАСТРОЙКИ!$D$5&"]CF'!$L$25:$EO$25")),0)) -> 0 | ... DF47: =IF(НАСТРОЙКИ!$B$5<>"Да",0,IFERROR(SUMIF(INDIRECT("'["&НАСТРОЙКИ!$D$5&"]CF'!$L$3:$EO$3"),DF$22,INDIRECT("'["&НАСТРОЙКИ!$D$5&"]CF'!$L$25:$EO$25")),0)) -> 0
A48: Проценты и комиссии | B48: млн ₽ | C48: =IF(НАСТРОЙКИ!$B$5<>"Да",0,IFERROR(SUMIF(INDIRECT("'["&НАСТРОЙКИ!$D$5&"]CF'!$L$3:$EO$3"),C$22,INDIRECT("'["&НАСТРОЙКИ!$D$5&"]CF'!$L$51:$EO$51")),0)) -> 0 | D48: =IF(НАСТРОЙКИ!$B$5<>"Да",0,IFERROR(SUMIF(INDIRECT("'["&НАСТРОЙКИ!$D$5&"]CF'!$L$3:$EO$3"),D$22,INDIRECT("'["&НАСТРОЙКИ!$D$5&"]CF'!$L$51:$EO$51")),0)) -> 0 | E48: =IF(НАСТРОЙКИ!$B$5<>"Да",0,IFERROR(SUMIF(INDIRECT("'["&НАСТРОЙКИ!$D$5&"]CF'!$L$3:$EO$3"),E$22,INDIRECT("'["&НАСТРОЙКИ!$D$5&"]CF'!$L$51:$EO$51")),0)) -> 0 | F48: =IF(НАСТРОЙКИ!$B$5<>"Да",0,IFERROR(SUMIF(INDIRECT("'["&НАСТРОЙКИ!$D$5&"]CF'!$L$3:$EO$3"),F$22,INDIRECT("'["&НАСТРОЙКИ!$D$5&"]CF'!$L$51:$EO$51")),0)) -> 0 | G48: =IF(НАСТРОЙКИ!$B$5<>"Да",0,IFERROR(SUMIF(INDIRECT("'["&НАСТРОЙКИ!$D$5&"]CF'!$L$3:$EO$3"),G$22,INDIRECT("'["&НАСТРОЙКИ!$D$5&"]CF'!$L$51:$EO$51")),0)) -> 0 | H48: =IF(НАСТРОЙКИ!$B$5<>"Да",0,IFERROR(SUMIF(INDIRECT("'["&НАСТРОЙКИ!$D$5&"]CF'!$L$3:$EO$3"),H$22,INDIRECT("'["&НАСТРОЙКИ!$D$5&"]CF'!$L$51:$EO$51")),0)) -> 0 | I48: =IF(НАСТРОЙКИ!$B$5<>"Да",0,IFERROR(SUMIF(INDIRECT("'["&НАСТРОЙКИ!$D$5&"]CF'!$L$3:$EO$3"),I$22,INDIRECT("'["&НАСТРОЙКИ!$D$5&"]CF'!$L$51:$EO$51")),0)) -> 0 | J48: =IF(НАСТРОЙКИ!$B$5<>"Да",0,IFERROR(SUMIF(INDIRECT("'["&НАСТРОЙКИ!$D$5&"]CF'!$L$3:$EO$3"),J$22,INDIRECT("'["&НАСТРОЙКИ!$D$5&"]CF'!$L$51:$EO$51")),0)) -> 0 | ... DF48: =IF(НАСТРОЙКИ!$B$5<>"Да",0,IFERROR(SUMIF(INDIRECT("'["&НАСТРОЙКИ!$D$5&"]CF'!$L$3:$EO$3"),DF$22,INDIRECT("'["&НАСТРОЙКИ!$D$5&"]CF'!$L$51:$EO$51")),0)) -> 0
...

Sheet БРИДЖ
A1: ПЛАТО — РАСПРЕДЕЛЕНИЕ БРИДЖ И ВРИ МЕЖДУ ОЧЕРЕДЯМИ
A3: Консолидатор поддерживает два режима: (1) весь БРИДЖ, его накопленные проценты и ВРИ рефинансируются в ПФ первой очереди; (2) общие обязательства распределяются по заданным долям. Переключатель находится на листе «НАСТРОЙКИ».
A7: Параметр | B7: Значение | C7: Ед. изм. | D7: Комментарий
A8: Режим БРИДЖ | B8: =НАСТРОЙКИ!B14 -> Весь БРИДЖ в О1 | D8: НАСТРОЙКИ!B14
A9: БРИДЖ уже включен в моделях | B9: =НАСТРОЙКИ!B15 -> Да | D9: НАСТРОЙКИ!B15
A10: Общий основной долг БРИДЖ | B10: =НАСТРОЙКИ!B16 -> 0 | C10: млн ₽ | D10: НАСТРОЙКИ!B16
A11: Накопленные проценты БРИДЖ | B11: =НАСТРОЙКИ!B17 -> 0 | C11: млн ₽ | D11: НАСТРОЙКИ!B17
A12: Смена ВРИ | B12: =НАСТРОЙКИ!B18 -> 0 | C12: млн ₽ | D12: НАСТРОЙКИ!B18
A15: Очередь | B15: РнС | C15: Ручная доля | D15: Эффективная доля | E15: Тело БРИДЖ | F15: Проценты БРИДЖ | G15: ВРИ | H15: ПФ по модели | I15: ПФ скорр. | J15: Комментарий
A16: =НАСТРОЙКИ!C5 -> Очередь 1 | B16: =СВОД!E10 -> 46935 | C16: =НАСТРОЙКИ!E5 -> 0.25 | D16: =НАСТРОЙКИ!F5 -> 1 | E16: =НАСТРОЙКИ!G5 -> 0 | F16: =НАСТРОЙКИ!H5 -> 0 | G16: =НАСТРОЙКИ!I5 -> 0 | H16: =СВОД!Q10 -> 30011.506 | I16: =СВОД!R10 -> 30011.506 | J16: =IF(НАСТРОЙКИ!$B$15="Да","Контроль: уже учтено в модели","Добавлено консолидатором") -> Контроль: уже учтено в модели
A17: =НАСТРОЙКИ!C6 -> Очередь 2 | B17: =СВОД!E11 -> 47300 | C17: =НАСТРОЙКИ!E6 -> 0.25 | D17: =НАСТРОЙКИ!F6 -> 0 | E17: =НАСТРОЙКИ!G6 -> 0 | F17: =НАСТРОЙКИ!H6 -> 0 | G17: =НАСТРОЙКИ!I6 -> 0 | H17: =СВОД!Q11 -> 27765.555 | I17: =СВОД!R11 -> 27765.555 | J17: =IF(НАСТРОЙКИ!$B$15="Да","Контроль: уже учтено в модели","Добавлено консолидатором") -> Контроль: уже учтено в модели
A18: =НАСТРОЙКИ!C7 -> Очередь 3 | B18: =СВОД!E12 -> 47665 | C18: =НАСТРОЙКИ!E7 -> 0.25 | D18: =НАСТРОЙКИ!F7 -> 0 | E18: =НАСТРОЙКИ!G7 -> 0 | F18: =НАСТРОЙКИ!H7 -> 0 | G18: =НАСТРОЙКИ!I7 -> 0 | H18: =СВОД!Q12 -> 23843.816 | I18: =СВОД!R12 -> 23843.816 | J18: =IF(НАСТРОЙКИ!$B$15="Да","Контроль: уже учтено в модели","Добавлено консолидатором") -> Контроль: уже учтено в модели
A19: =НАСТРОЙКИ!C8 -> Очередь 4 | B19: =СВОД!E13 -> 0 | C19: =НАСТРОЙКИ!E8 -> 0.25 | D19: =НАСТРОЙКИ!F8 -> 0 | E19: =НАСТРОЙКИ!G8 -> 0 | F19: =НАСТРОЙКИ!H8 -> 0 | G19: =НАСТРОЙКИ!I8 -> 0 | H19: =СВОД!Q13 -> 0 | I19: =СВОД!R13 -> 0 | J19: =IF(НАСТРОЙКИ!$B$15="Да","Контроль: уже учтено в модели","Добавлено консолидатором") -> Контроль: уже учтено в модели
A20: ИТОГО / КОНТРОЛЬ | C20: =SUM(C16:C19) -> 1 | D20: =SUM(D16:D19) -> 1 | E20: =SUM(E16:E19) -> 0 | F20: =SUM(F16:F19) -> 0 | G20: =SUM(G16:G19) -> 0 | H20: =SUM(H16:H19) -> 81620.877 | I20: =SUM(I16:I19) -> 81620.877 | J20: =IF(ABS(D20-1)<0.0001,"OK","ПРОВЕРИТЬ ДОЛИ") -> OK
A23: ИНТЕРПРЕТАЦИЯ
A24: Режим | B24: Банковская логика | C24: Экономическая логика | D24: Что должно быть в моделях очередей
A25: Весь БРИДЖ в О1 | B25: 100% тела, процентов и ВРИ входят в первую выборку ПФ-1 | C25: Общие затраты можно распределять между очередями управленчески | D25: Только модель О1 содержит общий БРИДЖ; О2–О4 — без него
A26: По долям | B26: Каждая очередь рефинансирует свою долю общего БРИДЖ | C26: Доли задаются на листе «НАСТРОЙКИ» | D26: Каждая модель содержит только свою долю тела, процентов и ВРИ
A27: Контроль | B27: Нельзя одновременно включить общий БРИДЖ во все четыре модели | C27: Иначе долг, проценты и ПФ будут задвоены | D27: Сверять ПФ по модели и ПФ скорректированный
A28: Помесячный свод | B28: Суммирует фактические графики из четырех моделей | C28: Не заменяет формулы внутри моделей очередей | D28: Режим БРИДЖ в моделях должен соответствовать выбранному режиму

Sheet ГАНТ
A1: ГРАФИК ОСНОВНЫХ ВЕХ СТРОИТЕЛЬСТВА ПО ОЧЕРЕДЯМ
E2: =DATE(YEAR(НАСТРОЙКИ!$B$25),3*INT((MONTH(НАСТРОЙКИ!$B$25)-1)/3)+1,1) -> 46388 | F2: =EDATE(E2,3) -> 46478 | G2: =EDATE(F2,3) -> 46569 | H2: =EDATE(G2,3) -> 46661 | I2: =EDATE(H2,3) -> 46753 | J2: =EDATE(I2,3) -> 46844 | K2: =EDATE(J2,3) -> 46935 | L2: =EDATE(K2,3) -> 47027 | M2: =EDATE(L2,3) -> 47119 | ... AN2: =EDATE(AM2,3) -> 49583
A3: Очередь | B3: Этап | C3: Начало | D3: Окончание | E3: ="кв. "&ROUNDUP(MONTH(E2)/3,0)&" "&YEAR(E2) -> кв. 1 2027 | F3: ="кв. "&ROUNDUP(MONTH(F2)/3,0)&" "&YEAR(F2) -> кв. 2 2027 | G3: ="кв. "&ROUNDUP(MONTH(G2)/3,0)&" "&YEAR(G2) -> кв. 3 2027 | H3: ="кв. "&ROUNDUP(MONTH(H2)/3,0)&" "&YEAR(H2) -> кв. 4 2027 | I3: ="кв. "&ROUNDUP(MONTH(I2)/3,0)&" "&YEAR(I2) -> кв. 1 2028 | J3: ="кв. "&ROUNDUP(MONTH(J2)/3,0)&" "&YEAR(J2) -> кв. 2 2028 | K3: ="кв. "&ROUNDUP(MONTH(K2)/3,0)&" "&YEAR(K2) -> кв. 3 2028 | L3: ="кв. "&ROUNDUP(MONTH(L2)/3,0)&" "&YEAR(L2) -> кв. 4 2028 | ... AN3: ="кв. "&ROUNDUP(MONTH(AN2)/3,0)&" "&YEAR(AN2) -> кв. 4 2035
A5: =НАСТРОЙКИ!C5 -> Очередь 1 | B5: РнС | C5: =IF(NOT(НАСТРОЙКИ!$B$5="Да"),0,IFERROR(INDIRECT("'["&НАСТРОЙКИ!$D$5&"]Вводные'!$G$8"),0)) -> 46935 | D5: =IF(NOT(НАСТРОЙКИ!$B$5="Да"),0,IFERROR(INDIRECT("'["&НАСТРОЙКИ!$D$5&"]Вводные'!$G$8"),0)) -> 46935 | E5: =IF(OR($C5=0,$D5=0),0,--AND(E$2<=$D5,EOMONTH(E$2,2)>=$C5)) -> 0 | F5: =IF(OR($C5=0,$D5=0),0,--AND(F$2<=$D5,EOMONTH(F$2,2)>=$C5)) -> 0 | G5: =IF(OR($C5=0,$D5=0),0,--AND(G$2<=$D5,EOMONTH(G$2,2)>=$C5)) -> 0 | H5: =IF(OR($C5=0,$D5=0),0,--AND(H$2<=$D5,EOMONTH(H$2,2)>=$C5)) -> 0 | I5: =IF(OR($C5=0,$D5=0),0,--AND(I$2<=$D5,EOMONTH(I$2,2)>=$C5)) -> 0 | J5: =IF(OR($C5=0,$D5=0),0,--AND(J$2<=$D5,EOMONTH(J$2,2)>=$C5)) -> 0 | K5: =IF(OR($C5=0,$D5=0),0,--AND(K$2<=$D5,EOMONTH(K$2,2)>=$C5)) -> 1 | L5: =IF(OR($C5=0,$D5=0),0,--AND(L$2<=$D5,EOMONTH(L$2,2)>=$C5)) -> 0 | ... AN5: =IF(OR($C5=0,$D5=0),0,--AND(AN$2<=$D5,EOMONTH(AN$2,2)>=$C5)) -> 0
A6: =НАСТРОЙКИ!C5 -> Очередь 1 | B6: Строительство ЖК | C6: =IF(NOT(НАСТРОЙКИ!$B$5="Да"),0,IFERROR(INDIRECT("'["&НАСТРОЙКИ!$D$5&"]СРОКИ'!$C$29"),0)) -> 46935 | D6: =IF(NOT(НАСТРОЙКИ!$B$5="Да"),0,IFERROR(INDIRECT("'["&НАСТРОЙКИ!$D$5&"]СРОКИ'!$E$29"),0)) -> 47665 | E6: =IF(OR($C6=0,$D6=0),0,--AND(E$2<=$D6,EOMONTH(E$2,2)>=$C6)) -> 0 | F6: =IF(OR($C6=0,$D6=0),0,--AND(F$2<=$D6,EOMONTH(F$2,2)>=$C6)) -> 0 | G6: =IF(OR($C6=0,$D6=0),0,--AND(G$2<=$D6,EOMONTH(G$2,2)>=$C6)) -> 0 | H6: =IF(OR($C6=0,$D6=0),0,--AND(H$2<=$D6,EOMONTH(H$2,2)>=$C6)) -> 0 | I6: =IF(OR($C6=0,$D6=0),0,--AND(I$2<=$D6,EOMONTH(I$2,2)>=$C6)) -> 0 | J6: =IF(OR($C6=0,$D6=0),0,--AND(J$2<=$D6,EOMONTH(J$2,2)>=$C6)) -> 0 | K6: =IF(OR($C6=0,$D6=0),0,--AND(K$2<=$D6,EOMONTH(K$2,2)>=$C6)) -> 1 | L6: =IF(OR($C6=0,$D6=0),0,--AND(L$2<=$D6,EOMONTH(L$2,2)>=$C6)) -> 1 | ... AN6: =IF(OR($C6=0,$D6=0),0,--AND(AN$2<=$D6,EOMONTH(AN$2,2)>=$C6)) -> 0
A7: =НАСТРОЙКИ!C5 -> Очередь 1 | B7: Наружные сети | C7: =IF(NOT(НАСТРОЙКИ!$B$5="Да"),0,IFERROR(INDIRECT("'["&НАСТРОЙКИ!$D$5&"]СРОКИ'!$C$34"),0)) -> 46844 | D7: =IF(NOT(НАСТРОЙКИ!$B$5="Да"),0,IFERROR(INDIRECT("'["&НАСТРОЙКИ!$D$5&"]СРОКИ'!$E$34"),0)) -> 47635 | E7: =IF(OR($C7=0,$D7=0),0,--AND(E$2<=$D7,EOMONTH(E$2,2)>=$C7)) -> 0 | F7: =IF(OR($C7=0,$D7=0),0,--AND(F$2<=$D7,EOMONTH(F$2,2)>=$C7)) -> 0 | G7: =IF(OR($C7=0,$D7=0),0,--AND(G$2<=$D7,EOMONTH(G$2,2)>=$C7)) -> 0 | H7: =IF(OR($C7=0,$D7=0),0,--AND(H$2<=$D7,EOMONTH(H$2,2)>=$C7)) -> 0 | I7: =IF(OR($C7=0,$D7=0),0,--AND(I$2<=$D7,EOMONTH(I$2,2)>=$C7)) -> 0 | J7: =IF(OR($C7=0,$D7=0),0,--AND(J$2<=$D7,EOMONTH(J$2,2)>=$C7)) -> 1 | K7: =IF(OR($C7=0,$D7=0),0,--AND(K$2<=$D7,EOMONTH(K$2,2)>=$C7)) -> 1 | L7: =IF(OR($C7=0,$D7=0),0,--AND(L$2<=$D7,EOMONTH(L$2,2)>=$C7)) -> 1 | ... AN7: =IF(OR($C7=0,$D7=0),0,--AND(AN$2<=$D7,EOMONTH(AN$2,2)>=$C7)) -> 0
A8: =НАСТРОЙКИ!C5 -> Очередь 1 | B8: Благоустройство | C8: =IF(NOT(НАСТРОЙКИ!$B$5="Да"),0,IFERROR(INDIRECT("'["&НАСТРОЙКИ!$D$5&"]СРОКИ'!$C$35"),0)) -> 47604 | D8: =IF(NOT(НАСТРОЙКИ!$B$5="Да"),0,IFERROR(INDIRECT("'["&НАСТРОЙКИ!$D$5&"]СРОКИ'!$E$35"),0)) -> 47696 | E8: =IF(OR($C8=0,$D8=0),0,--AND(E$2<=$D8,EOMONTH(E$2,2)>=$C8)) -> 0 | F8: =IF(OR($C8=0,$D8=0),0,--AND(F$2<=$D8,EOMONTH(F$2,2)>=$C8)) -> 0 | G8: =IF(OR($C8=0,$D8=0),0,--AND(G$2<=$D8,EOMONTH(G$2,2)>=$C8)) -> 0 | H8: =IF(OR($C8=0,$D8=0),0,--AND(H$2<=$D8,EOMONTH(H$2,2)>=$C8)) -> 0 | I8: =IF(OR($C8=0,$D8=0),0,--AND(I$2<=$D8,EOMONTH(I$2,2)>=$C8)) -> 0 | J8: =IF(OR($C8=0,$D8=0),0,--AND(J$2<=$D8,EOMONTH(J$2,2)>=$C8)) -> 0 | K8: =IF(OR($C8=0,$D8=0),0,--AND(K$2<=$D8,EOMONTH(K$2,2)>=$C8)) -> 0 | L8: =IF(OR($C8=0,$D8=0),0,--AND(L$2<=$D8,EOMONTH(L$2,2)>=$C8)) -> 0 | ... AN8: =IF(OR($C8=0,$D8=0),0,--AND(AN$2<=$D8,EOMONTH(AN$2,2)>=$C8)) -> 0
A9: =НАСТРОЙКИ!C5 -> Очередь 1 | B9: РВЭ | C9: =IF(NOT(НАСТРОЙКИ!$B$5="Да"),0,IFERROR(EDATE(INDIRECT("'["&НАСТРОЙКИ!$D$5&"]Вводные'!$G$8"),INDIRECT("'["&НАСТРОЙКИ!$D$5&"]Вводные'!$G$9")),0)) -> 47665 | D9: =IF(NOT(НАСТРОЙКИ!$B$5="Да"),0,IFERROR(EDATE(INDIRECT("'["&НАСТРОЙКИ!$D$5&"]Вводные'!$G$8"),INDIRECT("'["&НАСТРОЙКИ!$D$5&"]Вводные'!$G$9")),0)) -> 47665 | E9: =IF(OR($C9=0,$D9=0),0,--AND(E$2<=$D9,EOMONTH(E$2,2)>=$C9)) -> 0 | F9: =IF(OR($C9=0,$D9=0),0,--AND(F$2<=$D9,EOMONTH(F$2,2)>=$C9)) -> 0 | G9: =IF(OR($C9=0,$D9=0),0,--AND(G$2<=$D9,EOMONTH(G$2,2)>=$C9)) -> 0 | H9: =IF(OR($C9=0,$D9=0),0,--AND(H$2<=$D9,EOMONTH(H$2,2)>=$C9)) -> 0 | I9: =IF(OR($C9=0,$D9=0),0,--AND(I$2<=$D9,EOMONTH(I$2,2)>=$C9)) -> 0 | J9: =IF(OR($C9=0,$D9=0),0,--AND(J$2<=$D9,EOMONTH(J$2,2)>=$C9)) -> 0 | K9: =IF(OR($C9=0,$D9=0),0,--AND(K$2<=$D9,EOMONTH(K$2,2)>=$C9)) -> 0 | L9: =IF(OR($C9=0,$D9=0),0,--AND(L$2<=$D9,EOMONTH(L$2,2)>=$C9)) -> 0 | ... AN9: =IF(OR($C9=0,$D9=0),0,--AND(AN$2<=$D9,EOMONTH(AN$2,2)>=$C9)) -> 0
A10: =НАСТРОЙКИ!C6 -> Очередь 2 | B10: РнС | C10: =IF(NOT(НАСТРОЙКИ!$B$6="Да"),0,IFERROR(INDIRECT("'["&НАСТРОЙКИ!$D$6&"]Вводные'!$G$8"),0)) -> 47300 | D10: =IF(NOT(НАСТРОЙКИ!$B$6="Да"),0,IFERROR(INDIRECT("'["&НАСТРОЙКИ!$D$6&"]Вводные'!$G$8"),0)) -> 47300 | E10: =IF(OR($C10=0,$D10=0),0,--AND(E$2<=$D10,EOMONTH(E$2,2)>=$C10)) -> 0 | F10: =IF(OR($C10=0,$D10=0),0,--AND(F$2<=$D10,EOMONTH(F$2,2)>=$C10)) -> 0 | G10: =IF(OR($C10=0,$D10=0),0,--AND(G$2<=$D10,EOMONTH(G$2,2)>=$C10)) -> 0 | H10: =IF(OR($C10=0,$D10=0),0,--AND(H$2<=$D10,EOMONTH(H$2,2)>=$C10)) -> 0 | I10: =IF(OR($C10=0,$D10=0),0,--AND(I$2<=$D10,EOMONTH(I$2,2)>=$C10)) -> 0 | J10: =IF(OR($C10=0,$D10=0),0,--AND(J$2<=$D10,EOMONTH(J$2,2)>=$C10)) -> 0 | K10: =IF(OR($C10=0,$D10=0),0,--AND(K$2<=$D10,EOMONTH(K$2,2)>=$C10)) -> 0 | L10: =IF(OR($C10=0,$D10=0),0,--AND(L$2<=$D10,EOMONTH(L$2,2)>=$C10)) -> 0 | ... AN10: =IF(OR($C10=0,$D10=0),0,--AND(AN$2<=$D10,EOMONTH(AN$2,2)>=$C10)) -> 0
A11: =НАСТРОЙКИ!C6 -> Очередь 2 | B11: Строительство ЖК | C11: =IF(NOT(НАСТРОЙКИ!$B$6="Да"),0,IFERROR(INDIRECT("'["&НАСТРОЙКИ!$D$6&"]СРОКИ'!$C$29"),0)) -> 47300 | D11: =IF(NOT(НАСТРОЙКИ!$B$6="Да"),0,IFERROR(INDIRECT("'["&НАСТРОЙКИ!$D$6&"]СРОКИ'!$E$29"),0)) -> 48030 | E11: =IF(OR($C11=0,$D11=0),0,--AND(E$2<=$D11,EOMONTH(E$2,2)>=$C11)) -> 0 | F11: =IF(OR($C11=0,$D11=0),0,--AND(F$2<=$D11,EOMONTH(F$2,2)>=$C11)) -> 0 | G11: =IF(OR($C11=0,$D11=0),0,--AND(G$2<=$D11,EOMONTH(G$2,2)>=$C11)) -> 0 | H11: =IF(OR($C11=0,$D11=0),0,--AND(H$2<=$D11,EOMONTH(H$2,2)>=$C11)) -> 0 | I11: =IF(OR($C11=0,$D11=0),0,--AND(I$2<=$D11,EOMONTH(I$2,2)>=$C11)) -> 0 | J11: =IF(OR($C11=0,$D11=0),0,--AND(J$2<=$D11,EOMONTH(J$2,2)>=$C11)) -> 0 | K11: =IF(OR($C11=0,$D11=0),0,--AND(K$2<=$D11,EOMONTH(K$2,2)>=$C11)) -> 0 | L11: =IF(OR($C11=0,$D11=0),0,--AND(L$2<=$D11,EOMONTH(L$2,2)>=$C11)) -> 0 | ... AN11: =IF(OR($C11=0,$D11=0),0,--AND(AN$2<=$D11,EOMONTH(AN$2,2)>=$C11)) -> 0
A12: =НАСТРОЙКИ!C6 -> Очередь 2 | B12: Наружные сети | C12: =IF(NOT(НАСТРОЙКИ!$B$6="Да"),0,IFERROR(INDIRECT("'["&НАСТРОЙКИ!$D$6&"]СРОКИ'!$C$34"),0)) -> 47209 | D12: =IF(NOT(НАСТРОЙКИ!$B$6="Да"),0,IFERROR(INDIRECT("'["&НАСТРОЙКИ!$D$6&"]СРОКИ'!$E$34"),0)) -> 48000 | E12: =IF(OR($C12=0,$D12=0),0,--AND(E$2<=$D12,EOMONTH(E$2,2)>=$C12)) -> 0 | F12: =IF(OR($C12=0,$D12=0),0,--AND(F$2<=$D12,EOMONTH(F$2,2)>=$C12)) -> 0 | G12: =IF(OR($C12=0,$D12=0),0,--AND(G$2<=$D12,EOMONTH(G$2,2)>=$C12)) -> 0 | H12: =IF(OR($C12=0,$D12=0),0,--AND(H$2<=$D12,EOMONTH(H$2,2)>=$C12)) -> 0 | I12: =IF(OR($C12=0,$D12=0),0,--AND(I$2<=$D12,EOMONTH(I$2,2)>=$C12)) -> 0 | J12: =IF(OR($C12=0,$D12=0),0,--AND(J$2<=$D12,EOMONTH(J$2,2)>=$C12)) -> 0 | K12: =IF(OR($C12=0,$D12=0),0,--AND(K$2<=$D12,EOMONTH(K$2,2)>=$C12)) -> 0 | L12: =IF(OR($C12=0,$D12=0),0,--AND(L$2<=$D12,EOMONTH(L$2,2)>=$C12)) -> 0 | ... AN12: =IF(OR($C12=0,$D12=0),0,--AND(AN$2<=$D12,EOMONTH(AN$2,2)>=$C12)) -> 0
A13: =НАСТРОЙКИ!C6 -> Очередь 2 | B13: Благоустройство | C13: =IF(NOT(НАСТРОЙКИ!$B$6="Да"),0,IFERROR(INDIRECT("'["&НАСТРОЙКИ!$D$6&"]СРОКИ'!$C$35"),0)) -> 47969 | D13: =IF(NOT(НАСТРОЙКИ!$B$6="Да"),0,IFERROR(INDIRECT("'["&НАСТРОЙКИ!$D$6&"]СРОКИ'!$E$35"),0)) -> 48061 | E13: =IF(OR($C13=0,$D13=0),0,--AND(E$2<=$D13,EOMONTH(E$2,2)>=$C13)) -> 0 | F13: =IF(OR($C13=0,$D13=0),0,--AND(F$2<=$D13,EOMONTH(F$2,2)>=$C13)) -> 0 | G13: =IF(OR($C13=0,$D13=0),0,--AND(G$2<=$D13,EOMONTH(G$2,2)>=$C13)) -> 0 | H13: =IF(OR($C13=0,$D13=0),0,--AND(H$2<=$D13,EOMONTH(H$2,2)>=$C13)) -> 0 | I13: =IF(OR($C13=0,$D13=0),0,--AND(I$2<=$D13,EOMONTH(I$2,2)>=$C13)) -> 0 | J13: =IF(OR($C13=0,$D13=0),0,--AND(J$2<=$D13,EOMONTH(J$2,2)>=$C13)) -> 0 | K13: =IF(OR($C13=0,$D13=0),0,--AND(K$2<=$D13,EOMONTH(K$2,2)>=$C13)) -> 0 | L13: =IF(OR($C13=0,$D13=0),0,--AND(L$2<=$D13,EOMONTH(L$2,2)>=$C13)) -> 0 | ... AN13: =IF(OR($C13=0,$D13=0),0,--AND(AN$2<=$D13,EOMONTH(AN$2,2)>=$C13)) -> 0
A14: =НАСТРОЙКИ!C6 -> Очередь 2 | B14: РВЭ | C14: =IF(NOT(НАСТРОЙКИ!$B$6="Да"),0,IFERROR(EDATE(INDIRECT("'["&НАСТРОЙКИ!$D$6&"]Вводные'!$G$8"),INDIRECT("'["&НАСТРОЙКИ!$D$6&"]Вводные'!$G$9")),0)) -> 48030 | D14: =IF(NOT(НАСТРОЙКИ!$B$6="Да"),0,IFERROR(EDATE(INDIRECT("'["&НАСТРОЙКИ!$D$6&"]Вводные'!$G$8"),INDIRECT("'["&НАСТРОЙКИ!$D$6&"]Вводные'!$G$9")),0)) -> 48030 | E14: =IF(OR($C14=0,$D14=0),0,--AND(E$2<=$D14,EOMONTH(E$2,2)>=$C14)) -> 0 | F14: =IF(OR($C14=0,$D14=0),0,--AND(F$2<=$D14,EOMONTH(F$2,2)>=$C14)) -> 0 | G14: =IF(OR($C14=0,$D14=0),0,--AND(G$2<=$D14,EOMONTH(G$2,2)>=$C14)) -> 0 | H14: =IF(OR($C14=0,$D14=0),0,--AND(H$2<=$D14,EOMONTH(H$2,2)>=$C14)) -> 0 | I14: =IF(OR($C14=0,$D14=0),0,--AND(I$2<=$D14,EOMONTH(I$2,2)>=$C14)) -> 0 | J14: =IF(OR($C14=0,$D14=0),0,--AND(J$2<=$D14,EOMONTH(J$2,2)>=$C14)) -> 0 | K14: =IF(OR($C14=0,$D14=0),0,--AND(K$2<=$D14,EOMONTH(K$2,2)>=$C14)) -> 0 | L14: =IF(OR($C14=0,$D14=0),0,--AND(L$2<=$D14,EOMONTH(L$2,2)>=$C14)) -> 0 | ... AN14: =IF(OR($C14=0,$D14=0),0,--AND(AN$2<=$D14,EOMONTH(AN$2,2)>=$C14)) -> 0
A15: =НАСТРОЙКИ!C7 -> Очередь 3 | B15: РнС | C15: =IF(NOT(НАСТРОЙКИ!$B$7="Да"),0,IFERROR(INDIRECT("'["&НАСТРОЙКИ!$D$7&"]Вводные'!$G$8"),0)) -> 47665 | D15: =IF(NOT(НАСТРОЙКИ!$B$7="Да"),0,IFERROR(INDIRECT("'["&НАСТРОЙКИ!$D$7&"]Вводные'!$G$8"),0)) -> 47665 | E15: =IF(OR($C15=0,$D15=0),0,--AND(E$2<=$D15,EOMONTH(E$2,2)>=$C15)) -> 0 | F15: =IF(OR($C15=0,$D15=0),0,--AND(F$2<=$D15,EOMONTH(F$2,2)>=$C15)) -> 0 | G15: =IF(OR($C15=0,$D15=0),0,--AND(G$2<=$D15,EOMONTH(G$2,2)>=$C15)) -> 0 | H15: =IF(OR($C15=0,$D15=0),0,--AND(H$2<=$D15,EOMONTH(H$2,2)>=$C15)) -> 0 | I15: =IF(OR($C15=0,$D15=0),0,--AND(I$2<=$D15,EOMONTH(I$2,2)>=$C15)) -> 0 | J15: =IF(OR($C15=0,$D15=0),0,--AND(J$2<=$D15,EOMONTH(J$2,2)>=$C15)) -> 0 | K15: =IF(OR($C15=0,$D15=0),0,--AND(K$2<=$D15,EOMONTH(K$2,2)>=$C15)) -> 0 | L15: =IF(OR($C15=0,$D15=0),0,--AND(L$2<=$D15,EOMONTH(L$2,2)>=$C15)) -> 0 | ... AN15: =IF(OR($C15=0,$D15=0),0,--AND(AN$2<=$D15,EOMONTH(AN$2,2)>=$C15)) -> 0
A16: =НАСТРОЙКИ!C7 -> Очередь 3 | B16: Строительство ЖК | C16: =IF(NOT(НАСТРОЙКИ!$B$7="Да"),0,IFERROR(INDIRECT("'["&НАСТРОЙКИ!$D$7&"]СРОКИ'!$C$29"),0)) -> 47665 | D16: =IF(NOT(НАСТРОЙКИ!$B$7="Да"),0,IFERROR(INDIRECT("'["&НАСТРОЙКИ!$D$7&"]СРОКИ'!$E$29"),0)) -> 48396 | E16: =IF(OR($C16=0,$D16=0),0,--AND(E$2<=$D16,EOMONTH(E$2,2)>=$C16)) -> 0 | F16: =IF(OR($C16=0,$D16=0),0,--AND(F$2<=$D16,EOMONTH(F$2,2)>=$C16)) -> 0 | G16: =IF(OR($C16=0,$D16=0),0,--AND(G$2<=$D16,EOMONTH(G$2,2)>=$C16)) -> 0 | H16: =IF(OR($C16=0,$D16=0),0,--AND(H$2<=$D16,EOMONTH(H$2,2)>=$C16)) -> 0 | I16: =IF(OR($C16=0,$D16=0),0,--AND(I$2<=$D16,EOMONTH(I$2,2)>=$C16)) -> 0 | J16: =IF(OR($C16=0,$D16=0),0,--AND(J$2<=$D16,EOMONTH(J$2,2)>=$C16)) -> 0 | K16: =IF(OR($C16=0,$D16=0),0,--AND(K$2<=$D16,EOMONTH(K$2,2)>=$C16)) -> 0 | L16: =IF(OR($C16=0,$D16=0),0,--AND(L$2<=$D16,EOMONTH(L$2,2)>=$C16)) -> 0 | ... AN16: =IF(OR($C16=0,$D16=0),0,--AND(AN$2<=$D16,EOMONTH(AN$2,2)>=$C16)) -> 0
A17: =НАСТРОЙКИ!C7 -> Очередь 3 | B17: Наружные сети | C17: =IF(NOT(НАСТРОЙКИ!$B$7="Да"),0,IFERROR(INDIRECT("'["&НАСТРОЙКИ!$D$7&"]СРОКИ'!$C$34"),0)) -> 47574 | D17: =IF(NOT(НАСТРОЙКИ!$B$7="Да"),0,IFERROR(INDIRECT("'["&НАСТРОЙКИ!$D$7&"]СРОКИ'!$E$34"),0)) -> 48366 | E17: =IF(OR($C17=0,$D17=0),0,--AND(E$2<=$D17,EOMONTH(E$2,2)>=$C17)) -> 0 | F17: =IF(OR($C17=0,$D17=0),0,--AND(F$2<=$D17,EOMONTH(F$2,2)>=$C17)) -> 0 | G17: =IF(OR($C17=0,$D17=0),0,--AND(G$2<=$D17,EOMONTH(G$2,2)>=$C17)) -> 0 | H17: =IF(OR($C17=0,$D17=0),0,--AND(H$2<=$D17,EOMONTH(H$2,2)>=$C17)) -> 0 | I17: =IF(OR($C17=0,$D17=0),0,--AND(I$2<=$D17,EOMONTH(I$2,2)>=$C17)) -> 0 | J17: =IF(OR($C17=0,$D17=0),0,--AND(J$2<=$D17,EOMONTH(J$2,2)>=$C17)) -> 0 | K17: =IF(OR($C17=0,$D17=0),0,--AND(K$2<=$D17,EOMONTH(K$2,2)>=$C17)) -> 0 | L17: =IF(OR($C17=0,$D17=0),0,--AND(L$2<=$D17,EOMONTH(L$2,2)>=$C17)) -> 0 | ... AN17: =IF(OR($C17=0,$D17=0),0,--AND(AN$2<=$D17,EOMONTH(AN$2,2)>=$C17)) -> 0
A18: =НАСТРОЙКИ!C7 -> Очередь 3 | B18: Благоустройство | C18: =IF(NOT(НАСТРОЙКИ!$B$7="Да"),0,IFERROR(INDIRECT("'["&НАСТРОЙКИ!$D$7&"]СРОКИ'!$C$35"),0)) -> 48335 | D18: =IF(NOT(НАСТРОЙКИ!$B$7="Да"),0,IFERROR(INDIRECT("'["&НАСТРОЙКИ!$D$7&"]СРОКИ'!$E$35"),0)) -> 48427 | E18: =IF(OR($C18=0,$D18=0),0,--AND(E$2<=$D18,EOMONTH(E$2,2)>=$C18)) -> 0 | F18: =IF(OR($C18=0,$D18=0),0,--AND(F$2<=$D18,EOMONTH(F$2,2)>=$C18)) -> 0 | G18: =IF(OR($C18=0,$D18=0),0,--AND(G$2<=$D18,EOMONTH(G$2,2)>=$C18)) -> 0 | H18: =IF(OR($C18=0,$D18=0),0,--AND(H$2<=$D18,EOMONTH(H$2,2)>=$C18)) -> 0 | I18: =IF(OR($C18=0,$D18=0),0,--AND(I$2<=$D18,EOMONTH(I$2,2)>=$C18)) -> 0 | J18: =IF(OR($C18=0,$D18=0),0,--AND(J$2<=$D18,EOMONTH(J$2,2)>=$C18)) -> 0 | K18: =IF(OR($C18=0,$D18=0),0,--AND(K$2<=$D18,EOMONTH(K$2,2)>=$C18)) -> 0 | L18: =IF(OR($C18=0,$D18=0),0,--AND(L$2<=$D18,EOMONTH(L$2,2)>=$C18)) -> 0 | ... AN18: =IF(OR($C18=0,$D18=0),0,--AND(AN$2<=$D18,EOMONTH(AN$2,2)>=$C18)) -> 0
A19: =НАСТРОЙКИ!C7 -> Очередь 3 | B19: РВЭ | C19: =IF(NOT(НАСТРОЙКИ!$B$7="Да"),0,IFERROR(EDATE(INDIRECT("'["&НАСТРОЙКИ!$D$7&"]Вводные'!$G$8"),INDIRECT("'["&НАСТРОЙКИ!$D$7&"]Вводные'!$G$9")),0)) -> 48396 | D19: =IF(NOT(НАСТРОЙКИ!$B$7="Да"),0,IFERROR(EDATE(INDIRECT("'["&НАСТРОЙКИ!$D$7&"]Вводные'!$G$8"),INDIRECT("'["&НАСТРОЙКИ!$D$7&"]Вводные'!$G$9")),0)) -> 48396 | E19: =IF(OR($C19=0,$D19=0),0,--AND(E$2<=$D19,EOMONTH(E$2,2)>=$C19)) -> 0 | F19: =IF(OR($C19=0,$D19=0),0,--AND(F$2<=$D19,EOMONTH(F$2,2)>=$C19)) -> 0 | G19: =IF(OR($C19=0,$D19=0),0,--AND(G$2<=$D19,EOMONTH(G$2,2)>=$C19)) -> 0 | H19: =IF(OR($C19=0,$D19=0),0,--AND(H$2<=$D19,EOMONTH(H$2,2)>=$C19)) -> 0 | I19: =IF(OR($C19=0,$D19=0),0,--AND(I$2<=$D19,EOMONTH(I$2,2)>=$C19)) -> 0 | J19: =IF(OR($C19=0,$D19=0),0,--AND(J$2<=$D19,EOMONTH(J$2,2)>=$C19)) -> 0 | K19: =IF(OR($C19=0,$D19=0),0,--AND(K$2<=$D19,EOMONTH(K$2,2)>=$C19)) -> 0 | L19: =IF(OR($C19=0,$D19=0),0,--AND(L$2<=$D19,EOMONTH(L$2,2)>=$C19)) -> 0 | ... AN19: =IF(OR($C19=0,$D19=0),0,--AND(AN$2<=$D19,EOMONTH(AN$2,2)>=$C19)) -> 0
A20: =НАСТРОЙКИ!C8 -> Очередь 4 | B20: РнС | C20: =IF(NOT(НАСТРОЙКИ!$B$8="Да"),0,IFERROR(INDIRECT("'["&НАСТРОЙКИ!$D$8&"]Вводные'!$G$8"),0)) -> 0 | D20: =IF(NOT(НАСТРОЙКИ!$B$8="Да"),0,IFERROR(INDIRECT("'["&НАСТРОЙКИ!$D$8&"]Вводные'!$G$8"),0)) -> 0 | E20: =IF(OR($C20=0,$D20=0),0,--AND(E$2<=$D20,EOMONTH(E$2,2)>=$C20)) -> 0 | F20: =IF(OR($C20=0,$D20=0),0,--AND(F$2<=$D20,EOMONTH(F$2,2)>=$C20)) -> 0 | G20: =IF(OR($C20=0,$D20=0),0,--AND(G$2<=$D20,EOMONTH(G$2,2)>=$C20)) -> 0 | H20: =IF(OR($C20=0,$D20=0),0,--AND(H$2<=$D20,EOMONTH(H$2,2)>=$C20)) -> 0 | I20: =IF(OR($C20=0,$D20=0),0,--AND(I$2<=$D20,EOMONTH(I$2,2)>=$C20)) -> 0 | J20: =IF(OR($C20=0,$D20=0),0,--AND(J$2<=$D20,EOMONTH(J$2,2)>=$C20)) -> 0 | K20: =IF(OR($C20=0,$D20=0),0,--AND(K$2<=$D20,EOMONTH(K$2,2)>=$C20)) -> 0 | L20: =IF(OR($C20=0,$D20=0),0,--AND(L$2<=$D20,EOMONTH(L$2,2)>=$C20)) -> 0 | ... AN20: =IF(OR($C20=0,$D20=0),0,--AND(AN$2<=$D20,EOMONTH(AN$2,2)>=$C20)) -> 0
A21: =НАСТРОЙКИ!C8 -> Очередь 4 | B21: Строительство ЖК | C21: =IF(NOT(НАСТРОЙКИ!$B$8="Да"),0,IFERROR(INDIRECT("'["&НАСТРОЙКИ!$D$8&"]СРОКИ'!$C$29"),0)) -> 0 | D21: =IF(NOT(НАСТРОЙКИ!$B$8="Да"),0,IFERROR(INDIRECT("'["&НАСТРОЙКИ!$D$8&"]СРОКИ'!$E$29"),0)) -> 0 | E21: =IF(OR($C21=0,$D21=0),0,--AND(E$2<=$D21,EOMONTH(E$2,2)>=$C21)) -> 0 | F21: =IF(OR($C21=0,$D21=0),0,--AND(F$2<=$D21,EOMONTH(F$2,2)>=$C21)) -> 0 | G21: =IF(OR($C21=0,$D21=0),0,--AND(G$2<=$D21,EOMONTH(G$2,2)>=$C21)) -> 0 | H21: =IF(OR($C21=0,$D21=0),0,--AND(H$2<=$D21,EOMONTH(H$2,2)>=$C21)) -> 0 | I21: =IF(OR($C21=0,$D21=0),0,--AND(I$2<=$D21,EOMONTH(I$2,2)>=$C21)) -> 0 | J21: =IF(OR($C21=0,$D21=0),0,--AND(J$2<=$D21,EOMONTH(J$2,2)>=$C21)) -> 0 | K21: =IF(OR($C21=0,$D21=0),0,--AND(K$2<=$D21,EOMONTH(K$2,2)>=$C21)) -> 0 | L21: =IF(OR($C21=0,$D21=0),0,--AND(L$2<=$D21,EOMONTH(L$2,2)>=$C21)) -> 0 | ... AN21: =IF(OR($C21=0,$D21=0),0,--AND(AN$2<=$D21,EOMONTH(AN$2,2)>=$C21)) -> 0
A22: =НАСТРОЙКИ!C8 -> Очередь 4 | B22: Наружные сети | C22: =IF(NOT(НАСТРОЙКИ!$B$8="Да"),0,IFERROR(INDIRECT("'["&НАСТРОЙКИ!$D$8&"]СРОКИ'!$C$34"),0)) -> 0 | D22: =IF(NOT(НАСТРОЙКИ!$B$8="Да"),0,IFERROR(INDIRECT("'["&НАСТРОЙКИ!$D$8&"]СРОКИ'!$E$34"),0)) -> 0 | E22: =IF(OR($C22=0,$D22=0),0,--AND(E$2<=$D22,EOMONTH(E$2,2)>=$C22)) -> 0 | F22: =IF(OR($C22=0,$D22=0),0,--AND(F$2<=$D22,EOMONTH(F$2,2)>=$C22)) -> 0 | G22: =IF(OR($C22=0,$D22=0),0,--AND(G$2<=$D22,EOMONTH(G$2,2)>=$C22)) -> 0 | H22: =IF(OR($C22=0,$D22=0),0,--AND(H$2<=$D22,EOMONTH(H$2,2)>=$C22)) -> 0 | I22: =IF(OR($C22=0,$D22=0),0,--AND(I$2<=$D22,EOMONTH(I$2,2)>=$C22)) -> 0 | J22: =IF(OR($C22=0,$D22=0),0,--AND(J$2<=$D22,EOMONTH(J$2,2)>=$C22)) -> 0 | K22: =IF(OR($C22=0,$D22=0),0,--AND(K$2<=$D22,EOMONTH(K$2,2)>=$C22)) -> 0 | L22: =IF(OR($C22=0,$D22=0),0,--AND(L$2<=$D22,EOMONTH(L$2,2)>=$C22)) -> 0 | ... AN22: =IF(OR($C22=0,$D22=0),0,--AND(AN$2<=$D22,EOMONTH(AN$2,2)>=$C22)) -> 0
A23: =НАСТРОЙКИ!C8 -> Очередь 4 | B23: Благоустройство | C23: =IF(NOT(НАСТРОЙКИ!$B$8="Да"),0,IFERROR(INDIRECT("'["&НАСТРОЙКИ!$D$8&"]СРОКИ'!$C$35"),0)) -> 0 | D23: =IF(NOT(НАСТРОЙКИ!$B$8="Да"),0,IFERROR(INDIRECT("'["&НАСТРОЙКИ!$D$8&"]СРОКИ'!$E$35"),0)) -> 0 | E23: =IF(OR($C23=0,$D23=0),0,--AND(E$2<=$D23,EOMONTH(E$2,2)>=$C23)) -> 0 | F23: =IF(OR($C23=0,$D23=0),0,--AND(F$2<=$D23,EOMONTH(F$2,2)>=$C23)) -> 0 | G23: =IF(OR($C23=0,$D23=0),0,--AND(G$2<=$D23,EOMONTH(G$2,2)>=$C23)) -> 0 | H23: =IF(OR($C23=0,$D23=0),0,--AND(H$2<=$D23,EOMONTH(H$2,2)>=$C23)) -> 0 | I23: =IF(OR($C23=0,$D23=0),0,--AND(I$2<=$D23,EOMONTH(I$2,2)>=$C23)) -> 0 | J23: =IF(OR($C23=0,$D23=0),0,--AND(J$2<=$D23,EOMONTH(J$2,2)>=$C23)) -> 0 | K23: =IF(OR($C23=0,$D23=0),0,--AND(K$2<=$D23,EOMONTH(K$2,2)>=$C23)) -> 0 | L23: =IF(OR($C23=0,$D23=0),0,--AND(L$2<=$D23,EOMONTH(L$2,2)>=$C23)) -> 0 | ... AN23: =IF(OR($C23=0,$D23=0),0,--AND(AN$2<=$D23,EOMONTH(AN$2,2)>=$C23)) -> 0
A24: =НАСТРОЙКИ!C8 -> Очередь 4 | B24: РВЭ | C24: =IF(NOT(НАСТРОЙКИ!$B$8="Да"),0,IFERROR(EDATE(INDIRECT("'["&НАСТРОЙКИ!$D$8&"]Вводные'!$G$8"),INDIRECT("'["&НАСТРОЙКИ!$D$8&"]Вводные'!$G$9")),0)) -> 0 | D24: =IF(NOT(НАСТРОЙКИ!$B$8="Да"),0,IFERROR(EDATE(INDIRECT("'["&НАСТРОЙКИ!$D$8&"]Вводные'!$G$8"),INDIRECT("'["&НАСТРОЙКИ!$D$8&"]Вводные'!$G$9")),0)) -> 0 | E24: =IF(OR($C24=0,$D24=0),0,--AND(E$2<=$D24,EOMONTH(E$2,2)>=$C24)) -> 0 | F24: =IF(OR($C24=0,$D24=0),0,--AND(F$2<=$D24,EOMONTH(F$2,2)>=$C24)) -> 0 | G24: =IF(OR($C24=0,$D24=0),0,--AND(G$2<=$D24,EOMONTH(G$2,2)>=$C24)) -> 0 | H24: =IF(OR($C24=0,$D24=0),0,--AND(H$2<=$D24,EOMONTH(H$2,2)>=$C24)) -> 0 | I24: =IF(OR($C24=0,$D24=0),0,--AND(I$2<=$D24,EOMONTH(I$2,2)>=$C24)) -> 0 | J24: =IF(OR($C24=0,$D24=0),0,--AND(J$2<=$D24,EOMONTH(J$2,2)>=$C24)) -> 0 | K24: =IF(OR($C24=0,$D24=0),0,--AND(K$2<=$D24,EOMONTH(K$2,2)>=$C24)) -> 0 | L24: =IF(OR($C24=0,$D24=0),0,--AND(L$2<=$D24,EOMONTH(L$2,2)>=$C24)) -> 0 | ... AN24: =IF(OR($C24=0,$D24=0),0,--AND(AN$2<=$D24,EOMONTH(AN$2,2)>=$C24)) -> 0

Sheet СВОД ТЭП
A1: СВОД ТЭП ПО ОЧЕРЕДЯМ И КОНТРОЛЬ ОБЩЕПРОЕКТНЫХ ПАРАМЕТРОВ
A3: Показатель | B3: Ед. изм. | C3: Очередь 1 | D3: Очередь 2 | E3: Очередь 3 | F3: Очередь 4 | G3: Сумма очередей | H3: Контроль проекта | I3: Отклонение | J3: Статус
A4: ГНС | B4: м² | C4: =IF(НАСТРОЙКИ!$B$5<>"Да",0,IFERROR(INDIRECT("'["&НАСТРОЙКИ!$D$5&"]ТЭП'!$C$4"),0)) -> 182143.71 | D4: =IF(НАСТРОЙКИ!$B$6<>"Да",0,IFERROR(INDIRECT("'["&НАСТРОЙКИ!$D$6&"]ТЭП'!$C$4"),0)) -> 164167.78 | E4: =IF(НАСТРОЙКИ!$B$7<>"Да",0,IFERROR(INDIRECT("'["&НАСТРОЙКИ!$D$7&"]ТЭП'!$C$4"),0)) -> 137357.78 | F4: =IF(НАСТРОЙКИ!$B$8<>"Да",0,IFERROR(INDIRECT("'["&НАСТРОЙКИ!$D$8&"]ТЭП'!$C$4"),0)) -> 0 | G4: =SUM(C4:F4) -> 483669.27 | I4: =IF(H4="","",G4-H4) | J4: =IF(H4="","НЕТ КОНТРОЛЯ",IF(ABS(I4)<=IF(B4="м²",1,0.01),"OK","ОТКЛОНЕНИЕ")) -> НЕТ КОНТРОЛЯ
A5: Общая площадь (GBA) | B5: м² | C5: =IF(НАСТРОЙКИ!$B$5<>"Да",0,IFERROR(INDIRECT("'["&НАСТРОЙКИ!$D$5&"]ТЭП'!$D$4"),0)) -> 168105.71 | D5: =IF(НАСТРОЙКИ!$B$6<>"Да",0,IFERROR(INDIRECT("'["&НАСТРОЙКИ!$D$6&"]ТЭП'!$D$4"),0)) -> 153639.28 | E5: =IF(НАСТРОЙКИ!$B$7<>"Да",0,IFERROR(INDIRECT("'["&НАСТРОЙКИ!$D$7&"]ТЭП'!$D$4"),0)) -> 126829.28 | F5: =IF(НАСТРОЙКИ!$B$8<>"Да",0,IFERROR(INDIRECT("'["&НАСТРОЙКИ!$D$8&"]ТЭП'!$D$4"),0)) -> 0 | G5: =SUM(C5:F5) -> 448574.28 | I5: =IF(H5="","",G5-H5) | J5: =IF(H5="","НЕТ КОНТРОЛЯ",IF(ABS(I5)<=IF(B5="м²",1,0.01),"OK","ОТКЛОНЕНИЕ")) -> НЕТ КОНТРОЛЯ
A6: Полезная площадь | B6: м² | C6: =IF(НАСТРОЙКИ!$B$5<>"Да",0,IFERROR(INDIRECT("'["&НАСТРОЙКИ!$D$5&"]ТЭП'!$F$4"),0)) -> 87826.087 | D6: =IF(НАСТРОЙКИ!$B$6<>"Да",0,IFERROR(INDIRECT("'["&НАСТРОЙКИ!$D$6&"]ТЭП'!$F$4"),0)) -> 76549.565 | E6: =IF(НАСТРОЙКИ!$B$7<>"Да",0,IFERROR(INDIRECT("'["&НАСТРОЙКИ!$D$7&"]ТЭП'!$F$4"),0)) -> 65869.565 | F6: =IF(НАСТРОЙКИ!$B$8<>"Да",0,IFERROR(INDIRECT("'["&НАСТРОЙКИ!$D$8&"]ТЭП'!$F$4"),0)) -> 0 | G6: =SUM(C6:F6) -> 230245.22 | I6: =IF(H6="","",G6-H6) | J6: =IF(H6="","НЕТ КОНТРОЛЯ",IF(ABS(I6)<=IF(B6="м²",1,0.01),"OK","ОТКЛОНЕНИЕ")) -> НЕТ КОНТРОЛЯ
A7: Продаваемая площадь | B7: м² | C7: =IF(НАСТРОЙКИ!$B$5<>"Да",0,IFERROR(INDIRECT("'["&НАСТРОЙКИ!$D$5&"]ТЭП'!$G$4"),0)) -> 87826.087 | D7: =IF(НАСТРОЙКИ!$B$6<>"Да",0,IFERROR(INDIRECT("'["&НАСТРОЙКИ!$D$6&"]ТЭП'!$G$4"),0)) -> 76549.565 | E7: =IF(НАСТРОЙКИ!$B$7<>"Да",0,IFERROR(INDIRECT("'["&НАСТРОЙКИ!$D$7&"]ТЭП'!$G$4"),0)) -> 65869.565 | F7: =IF(НАСТРОЙКИ!$B$8<>"Да",0,IFERROR(INDIRECT("'["&НАСТРОЙКИ!$D$8&"]ТЭП'!$G$4"),0)) -> 0 | G7: =SUM(C7:F7) -> 230245.22 | H7: 200000 | I7: =IF(H7="","",G7-H7) -> 30245.217 | J7: =IF(H7="","НЕТ КОНТРОЛЯ",IF(ABS(I7)<=IF(B7="м²",1,0.01),"OK","ОТКЛОНЕНИЕ")) -> ОТКЛОНЕНИЕ
A8: Передаваемая площадь | B8: м² | C8: =IF(НАСТРОЙКИ!$B$5<>"Да",0,IFERROR(INDIRECT("'["&НАСТРОЙКИ!$D$5&"]ТЭП'!$H$4"),0)) -> 3000 | D8: =IF(НАСТРОЙКИ!$B$6<>"Да",0,IFERROR(INDIRECT("'["&НАСТРОЙКИ!$D$6&"]ТЭП'!$H$4"),0)) -> 8450 | E8: =IF(НАСТРОЙКИ!$B$7<>"Да",0,IFERROR(INDIRECT("'["&НАСТРОЙКИ!$D$7&"]ТЭП'!$H$4"),0)) -> 3000 | F8: =IF(НАСТРОЙКИ!$B$8<>"Да",0,IFERROR(INDIRECT("'["&НАСТРОЙКИ!$D$8&"]ТЭП'!$H$4"),0)) -> 0 | G8: =SUM(C8:F8) -> 14450 | I8: =IF(H8="","",G8-H8) | J8: =IF(H8="","НЕТ КОНТРОЛЯ",IF(ABS(I8)<=IF(B8="м²",1,0.01),"OK","ОТКЛОНЕНИЕ")) -> НЕТ КОНТРОЛЯ
A9: Квартиры — продаваемая площадь | B9: м² | C9: =IF(НАСТРОЙКИ!$B$5<>"Да",0,IFERROR(INDIRECT("'["&НАСТРОЙКИ!$D$5&"]ТЭП'!$G$7"),0)) -> 80000 | D9: =IF(НАСТРОЙКИ!$B$6<>"Да",0,IFERROR(INDIRECT("'["&НАСТРОЙКИ!$D$6&"]ТЭП'!$G$7"),0)) -> 60000 | E9: =IF(НАСТРОЙКИ!$B$7<>"Да",0,IFERROR(INDIRECT("'["&НАСТРОЙКИ!$D$7&"]ТЭП'!$G$7"),0)) -> 60000 | F9: =IF(НАСТРОЙКИ!$B$8<>"Да",0,IFERROR(INDIRECT("'["&НАСТРОЙКИ!$D$8&"]ТЭП'!$G$7"),0)) -> 0 | G9: =SUM(C9:F9) -> 200000 | I9: =IF(H9="","",G9-H9) | J9: =IF(H9="","НЕТ КОНТРОЛЯ",IF(ABS(I9)<=IF(B9="м²",1,0.01),"OK","ОТКЛОНЕНИЕ")) -> НЕТ КОНТРОЛЯ
