Workbook

Sheet расчет_200 тыс кв
A1: Ориентировочный расчет (математический) технико-экономических показтелей целевой показатель 200,0 тыс.кв.м площади квартир
A3: № п.п. | B3: Наименование показателя | C3: Ед.изм. | D3: Показатель | E3: Примечание
A4: Баланс территории
A5: 1 | B5: Площадь территории проектирования | C5: га | D5: 22.89
A6: 1.1. | B6: озелененные территории общего пользования | C6: га | D6: =D30/10000 -> 3.14292 | E6: расчетно по нормативу с учетом озеленения в красных линиях удс
A7: 1.2. | B7: УДС (полотно дорог в красных линиях без учета озеленения) | C7: га | D7: 1.64 | E7: в соответствии с прошлым эскизом
A8: 1.3. | B8: участок СОШ | C8: га | D8: =D35 -> 3.0225
A9: 1.4. | B9: участок МФК | C9: га | D9: 0.89 | E9: в соответствии с прошлым эскизом | I9: 1 | J9: 2 | K9: 3 | L9: 4 | M9: 5 | N9: 14
A10: 1.5. | B10: участок поликлиники | C10: га | D10: =D38 -> 0.3
A11: 1.6. | B11: расчетная площадь участков жилых домов | C11: га | D11: =(D18*P11)/10000 -> 10.193061 | E11: рассчитан ориентировочно для эт. 9-17 эт. | I11: 1.71 | J11: 0.21 | K11: 0.92 | L11: 0.16 | M11: 0.07 | N11: 11.2 | P11: =I11+J11+K11+L11+M11+N11 -> 14.27
A12: 1.7. | B12: участок ДОО | C12: га | D12: =D33 -> 1.767
A13: 1.8. | B13: площадь наземных парковок (временные) | C13: га | D13: =(D24*22.5)/10000 -> 1.0305 | E13: 22,5 кв.м на 1 м/м
A14: 1.9. | B14: площадь наземных парковок (приобъектные кроме парковок для МФК) | C14: га | D14: =((D25-D43)*22.5)/10000 -> 1.378737 | E14: 22,5 кв.м на 1 м/м
B15: Дефицит (-) / Профицит (+) территории | C15: га | D15: =D5-D6-D7-D8-D9-D10-D11-D12-D13-D14 -> -0.474718 | E15: без учета резерва для размещения инженерных объектов, приобъектных парковок
A17: 2 | B17: Целевой показатель: общая площадь квартир | C17: кв.м | D17: 200000
A18: 3 | B18: население | C18: чел. | D18: =ROUNDUP(D17/28,0.1) -> 7143 | E18: РНГП: 28 кв.м общ.пл. кв. на 1 чел
A19: расчет потребности:
A20: 4 | B20: места в ДОО | C20: мест | D20: =D18*65/1000 -> 464.295 | E20: 65 мест на 1000 жит
A21: 5 | B21: места в СОШ | C21: мест | D21: =D18*135/1000 -> 964.305 | E21: 135 мест на 1000 жит
A22: 6 | B22: поликлиника | C22: пос./смену | D22: =D18*17.75/1000 -> 126.78825 | E22: 17,75 пос./смену на 1000 жит
A23: 7 | B23: места хранения автотранспорта (постоянные) | C23: м/м | D23: =ROUNDUP(D18*0.356*0.9,0.1) -> 2289 | E23: 90% от 356 м/м на 1 тыс. чел. (РНГП п. 5.12) | K23: =8900*0.6 -> 5340 | L23: =K23*5 -> 26700
A24: 8 | B24: места хранения автотранспорта (временные) | C24: м/м | D24: =ROUNDUP(D18*0.356*0.18,0.1) -> 458 | E24: 18% от уровня автомобилизации (РНГП п. 5.12)
A25: 9 | B25: места хранения автотранспорта (приобъектные) | C25: м/м | D25: =м_м!E5 -> 1046.772
A26: 10 | B26: рабочие места | C26: раб.мест | D26: =D18*0.5 -> 3571.5 | E26: 50% населения (РНГП п. 1.17)
A27: 11 | B27: объекты физкультуры и спорта | C27: Многофункциональная хоккейная площадка размером 60 м в длину и от 26 до 30 м в ширину, спортивная площадка для игры в мини-футбол от 42 до 65 в длину и от 25 до 35 в ширину.
C28: Физкультурно-оздоровительный комплекс, включающий спортивный зал для игровых видов спорта размером 30(36) м на 18 м с высотой потолка не менее 5 метров, тренажерный зал, фитнес зал (варианты № 1, № 2) (последовательность приведена с учетом уменьшения уровня приоритизации)
A29: 12 | B29: Озелененные территории (озеленение жилых кварталов, земельных участков соц.объектов | C29: кв.м | D29: =D18*6.5 -> 46429.5 | E29: 6,5 кв.м на 1 человека
A30: 13 | B30: Озелененные территории общего пользования (в т.ч. Бульвар, озеленении УДС, спорт площадки общего пользования) | C30: кв.м | D30: =D18*4.4 -> 31429.2 | E30: 4,4 кв.м. на 1 человека
A31: необходимо разместить:
A32: 14 | B32: ДОО | C32: мест | D32: =ROUNDUP(D20,0.1) -> 465
C33: площадь участка, га | D33: =D32*38/10000 -> 1.767 | E33: 38 кв.м на 1 место
A34: 15 | B34: СОШ | C34: мест | D34: =39*25 -> 975 | E34: кратное 25 мест
C35: площадь участка, га | D35: =D34*31/10000 -> 3.0225 | E35: 31 кв.м на 1 место
A36: 16 | B36: Подземный паркинг (постоянного хренения) | C36: кв.м | D36: =D23*35 -> 80115 | E36: 35 кв.м на 1 м/м
A37: 17 | B37: Поликлиника | C37: пос./смену | D37: =ROUNDUP(D22,0.1) -> 127
C38: площадь участка, га | D38: 0.3
A39: 18 | B39: Нежилые помещения для общественных объектов | C39: кв.м | D39: =соц!I33 -> 20718.928
A40: 19 | B40: Дополнительно нежилые помещения для компенсации потребности в рабочих местах | C40: кв.м | D40: ='раб места'!D17 -> 21700
A41: 20 | B41: МФК | C41: кв.м общ.пл | D41: =(D9*10000)*0.6*5*0.8 -> 21360 | E41: максимальная площадь объекта определена от площади участка 0,89 га; 60% пятна застройки; 5 этажей; коэффициент от СПП ГНС - 0,8
C42: кв.м подземная | D42: =D43*35 -> 15190 | E42: при площади участка 0,89 га, подземный паркинг 2 уровня
...

Sheet соц
A1: Расчет потребности в объектах социальной инфраструктуры для планируемого населения
K2: Население | L2: ='расчет_200 тыс кв'!D18 -> 7143
L3: Таблица 2.1.1.
A4: № п.п | B4: № зоны на чертеже | C4: Наименование объекта | D4: ед.изм | E4: норматив | F4: Требуется по нормативу | H4: Встроенные (1-й этаж жилых домов) | J4: Отдельностоящие объекты | K4: Дефицит (-) / Профиит (+) | L4: Примечание
F5: в ед.изм | G5: общ пл кв.м | H5: в ед.изм | I5: общ. пл. кв.м
A6: 1 | B6: 2 | C6: 2 | D6: 3 | E6: 4 | F6: 5 | G6: 6 | H6: 7 | I6: 8 | J6: 9 | K6: 10 | L6: 11
A7: 1 | C7: ДОО | D7: мест | E7: 65 мест на 1000 жит | F7: =L2*0.065 -> 464.295
D8: кв.м общ.пл. | E8: 27 кв.м общ.пл.
A9: 2 | C9: ОО | D9: мест | E9: 135 мест на 1000 жит | F9: =L2*0.135 -> 964.305 | O9: =F9*0.12 -> 115.7166
D10: кв.м общ.пл. | E10: 27 кв.м общ.пл.
A11: 3 | C11: Стационар | D11: коек | E11: 6 коек на 1000 жит | F11: =L2*0.006 -> 42.858
A12: 4 | C12: Подстанция скорой помощи | D12: машин | E12: 0,1 машина на 1000 жит | F12: =L2*0.0001 -> 0.7143
A13: 12 | C13: Амбулатория для детей и взрослых | D13: пос./смену | E13: 17,75 пос./смену на 1000 жит | F13: =L2*0.01775 -> 126.78825
A15: 5 | C15: Торговые объекты | D15: кв.м торг. пл. | E15: 1 530 кв.м торг.пл на 1000 жит | F15: =L2*1.53 -> 10928.79 | G15: =F15*1.3 -> 14207.427 | I15: =G15-J16 -> 11417.427
C16: в т.ч. отдельно стоящие | D16: кв.м торг. пл. | E16: 300 кв.м торг.пл на 1000 жит | F16: =L2*0.3 -> 2142.9 | G16: =F16*1.3 -> 2785.77 | J16: 2790
A17: 6 | C17: Бытовое обслуживание | D17: раб.мест | E17: 10,9 раб на 1000 жит | F17: =L2*0.0109 -> 77.8587 | G17: =F17*30 -> 2335.761 | H17: 78 | I17: =H17*30 -> 2340
D18: кв.м общ пл | E18: 30 кв.м на 1 работающего
A19: 7 | C19: Общественное питание | D19: пос.мест | E19: 40 посад.мест на 1000 жит | F19: =L2*0.04 -> 285.72 | G19: =F19*6 -> 1714.32 | H19: 286 | I19: =H19*6 -> 1716
D20: кв.м общ.пл | E20: 6 кв.м на 1 пос.место
A21: 8 | C21: Спортивные залы | D21: кв.м | E21: 106 кв.м общ.пл на 1000 жит | F21: =L2*0.106 -> 757.158 | I21: 988
A22: 9 | C22: Бассейн | D22: кв.м зеркала воды | E22: 9,96 кв.м зеркала воды на 1000 жит. | F22: =L2*0.00996 -> 71.14428 | H22: 75 | I22: =H22*1.5 -> 112.5 | O22: =1100-I22 -> 987.5
A23: 10 | C23: Открытые плоскостные спортивные сооружения | D23: кв.м | E23: 948,3 кв.м тер-рии на 1000 жит | F23: =L2*0.9483 -> 6773.7069
A24: 11 | C24: учреждения клубного типа | D24: кв.м | E24: 15 кв.м общ.пл | G24: =L2*0.15 -> 1071.45 | I24: 1200
C25: Библиотека | D25: ед.изм | E25: 1 объект | F25: 1 объект
C26: Школа исскуств | D26: детей | E26: 12% детей в возрасте 6-15 лет | F26: =116*0.12 -> 13.92 | G26: =F26*5 -> 69.6
C27: музейно-выставочный зал | D27: кв.м | E27: 4-6 кв.м. на 1000 человек | G27: =4*L2/1000 -> 28.572
A28: 14 | C28: Аптека | D28: кв.м | E28: 60-70 кв.м общ.пл. на объект | G28: 60 | I28: =G28 -> 60
A29: 15 | C29: МФЦ | D29: кв.м | E29: 14 кв.м общ.пл на 2 тыс чел | G29: =L2*14/2000 -> 50.001 | I29: =G29 -> 50.001
A30: 16 | C30: Отделение полиции | D30: кв.м | E30: 1 участковый на 2,8 тыс чел; 45 кв.м на 1 пункт | F30: =L2/2800 -> 2.5510714 | G30: 45 | I30: =G30 -> 45
A31: 17 | C31: Пожарное депо | D31: кв.м | E31: 0,2 машины на 1000 жит | F31: =0.2*(L2/1000) -> 1.4286 | G31: -
A32: 18 | C32: Отделение связи | D32: кв.м
A33: ИТОГО ОБЩЕЙ ПЛОЩАДИ | I33: =I15+J16+I17+I19+I21+I22+I24+I28+I29+I30 -> 20718.928

Sheet раб места
A1: Расчет потребности в рабочих местах для планируемого населения
A3: № п.п | B3: Наименование объекта | C3: ед.изм | D3: Емкость объекта | E3: Принято по ППТ (раб.мест) | F3: Примечание (нормативный показатель на 1 раб.место)
A4: 1 | B4: 2 | C4: 3 | D4: 4 | E4: 5 | F4: 6
B5: Население | C5: чел. | D5: ='расчет_200 тыс кв'!D18 -> 7143
A6: 1 | B6: Дошкольная образовательная организация | C6: место | D6: ='расчет_200 тыс кв'!D32 -> 465 | E6: =ROUND(D6*0.2,0) -> 93 | F6: 20 раб.мест на 100 ед емкости
A7: 2 | B7: Общеобразовательная организация | C7: место | D7: ='расчет_200 тыс кв'!D34 -> 975 | E7: =_xlfn.CEILING.MATH(D7*15/100,1) -> 147 | F7: 15 рабочих мест на 100 единиц емкости
A8: 3 | B8: Поликлиника | C8: пос./смену | D8: ='расчет_200 тыс кв'!D37 -> 127 | E8: =_xlfn.CEILING.MATH(D8*30/100,1) -> 39 | F8: 30 рабочих мест на 100 посещений
B9: торговые объекты | C9: кв.м общ. пл. | D9: =соц!I15+соц!J16 -> 14207.427 | E9: =ROUND(D9/15,0) -> 947 | F9: 15 кв.м общей площади здания
B10: бытовое обслуживания | C10: раб.мест | D10: =соц!H17 -> 78 | E10: =D10 -> 78 | F10: 30 кв. метров общей площади здания
B11: общественное питание | C11: пос.мест | D11: =соц!H19 -> 286 | E11: =ROUND(D11/6,0) -> 48 | F11: 6 пос.мест
B12: досуговый центр | C12: кв.м | D12: =соц!I24 -> 1200 | E12: =_xlfn.CEILING.MATH(D12/60,1) -> 20 | F12: 60 кв. метров общей площади здания
B13: аптека | C13: кв.м | D13: =соц!I28 -> 60 | E13: =ROUND(D13/15,0) -> 4 | F13: 15 кв.м общей площади помещений
B14: отделение полиции | C14: кв.м | D14: =соц!I30 -> 45 | E14: ='[1]расчет мм для социалки'!C13 -> 2 | F14: 1 участковый на 2,8 тыс.жителей
B15: спортивный зал | C15: кв.м | D15: =соц!I21+соц!I22 -> 1100.5 | E15: =_xlfn.CEILING.MATH(D15/60,1) -> 19 | F15: 60 кв. метров общей площади здания
B16: МФЦ | D16: =соц!I29 -> 50.001 | E16: =ROUND(D16/10,0) -> 5 | F16: 10 кв.м общей площади здания
B17: офисные помещения | C17: кв.м | D17: 21700 | E17: =ROUND(D17/10,0) -> 2170 | F17: 10 кв.м общей площади здания
A18: ИТОГО: | E18: =SUM(E6:E17) -> 3572
B19: потребность в раб местах | D19: =ROUNDUP(D5*0.5,0) -> 3572
B20: дефицит (-) / профицит (+) | E20: =E18-D19 -> 0

Sheet м_м
A2: Расчет потребности в м/м для объектов социальной инфраструктуры
B4: 1 м/м на | C4: Емкость | D4: Общая площадь, кв.м | E4: Потребность в м/м
E5: =E6+E7+E8+E9+E10+E11+E12+E13+E14+E15+E16+E17 -> 1046.772
A6: торговые объекты | B6: 40-50 кв.м общей площади - периодич.спрос; 60-70 кв.м - специализир.магазины для расчета принят средний показатель | D6: =соц!I15+соц!J16 -> 14207.427 | E6: =ROUND(D6/55,0) -> 258
A7: амбулатория | B7: 10-12 м/м на 100 сотрудников, 4-6 м/м на 100 посещений | C7: ='расчет_200 тыс кв'!D37 -> 127 | E7: =_xlfn.CEILING.MATH(('раб места'!E8*10/100)+(D7*4/100),1) -> 4
A8: бытовое обслуживания | B8: 10-15 кв.м общей площади | C8: =соц!H17 -> 78 | D8: =C8*30 -> 2340 | E8: =ROUND(D8/15,0) -> 156
A9: общественное питание | B9: 4-5 пос.мест | C9: =соц!H19 -> 286 | D9: =C9*6 -> 1716 | E9: =ROUND(C9/5,0) -> 57
A10: досуговый центр | B10: 20-25 кв.м общей площади | D10: =соц!I24 -> 1200 | E10: =ROUND(D10/25,0) -> 48
A11: аптека | B11: 40-50 кв.м общей площади | D11: =соц!I28 -> 60 | E11: =ROUND(D11/40,0) -> 2
A12: отделение полиции | B12: - | C12: ='[2]расчет социалки'!H30 -> 2 | D12: =соц!I30 -> 45 | E12: 1
A13: спортивный зал | B13: 20-40 кв.м общей площади | D13: =соц!I21+соц!I22 -> 1100.5 | E13: =ROUND(D13/40,0) -> 28
A14: офисы | B14: 50 кв.м. общей площади | D14: ='раб места'!D17 -> 21700 | E14: =ROUND(D14/50,0) -> 434
A15: ДОО | C15: ='расчет_200 тыс кв'!D32 -> 465 | E15: 10
A16: ОО | B16: 1 м/м на 100 мест; 7 м/м на 100 раб. | C16: ='расчет_200 тыс кв'!D34 -> 975 | E16: =(C16*1/1000)+([2]раб_места!E7*7/100) -> 8.115
A17: поликлиника | C17: ='расчет_200 тыс кв'!D37 -> 127 | E17: =(C17*1/1000)+([2]раб_места!E8*7/100) -> 40.657
